Qubicle Exchange Format
Version 0.2
www.minddesk.com
16 16 16
572
0.325490 0.172549 0.031373
0.325490 0.176471 0.031373
0.329412 0.176471 0.031373
0.333333 0.180392 0.031373
0.337255 0.184314 0.035294
0.341176 0.188235 0.039216
0.341176 0.188235 0.043137
0.341176 0.192157 0.043137
0.345098 0.196078 0.047059
0.349020 0.200000 0.050980
0.352941 0.200000 0.054902
0.352941 0.203922 0.058824
0.419608 0.243137 0.031373
0.423529 0.243137 0.031373
0.423529 0.247059 0.031373
0.427451 0.247059 0.031373
0.431373 0.250980 0.031373
0.435294 0.250980 0.035294
0.435294 0.254902 0.039216
0.439216 0.258824 0.043137
0.439216 0.262745 0.047059
0.443137 0.266667 0.050980
0.447059 0.266667 0.054902
0.447059 0.270588 0.058824
0.529412 0.321569 0.031373
0.529412 0.325490 0.031373
0.533333 0.325490 0.031373
0.533333 0.329412 0.031373
0.537255 0.329412 0.031373
0.541176 0.329412 0.031373
0.545098 0.333333 0.031373
0.545098 0.337255 0.035294
0.549020 0.337255 0.039216
0.549020 0.341176 0.043137
0.549020 0.345098 0.043137
0.549020 0.345098 0.047059
0.552941 0.345098 0.050980
0.552941 0.349020 0.054902
0.556863 0.349020 0.058824
0.705882 0.384314 0.031373
0.709804 0.388235 0.031373
0.717647 0.392157 0.031373
0.721569 0.392157 0.031373
0.725490 0.403922 0.043137
0.733333 0.411765 0.058824
0.772549 0.545098 0.141176
0.776471 0.545098 0.141176
0.776471 0.549020 0.141176
0.780392 0.549020 0.141176
0.784314 0.549020 0.141176
0.784314 0.549020 0.145098
0.784314 0.552941 0.145098
0.788235 0.549020 0.145098
0.788235 0.552941 0.145098
0.788235 0.556863 0.145098
0.788235 0.572549 0.203922
0.788235 0.572549 0.207843
0.792157 0.552941 0.145098
0.792157 0.556863 0.145098
0.792157 0.560784 0.145098
0.796078 0.552941 0.145098
0.796078 0.556863 0.145098
0.796078 0.556863 0.149020
0.796078 0.560784 0.145098
0.796078 0.560784 0.149020
0.796078 0.560784 0.152941
0.796078 0.560784 0.156863
0.796078 0.564706 0.152941
0.796078 0.564706 0.156863
0.796078 0.580392 0.207843
0.800000 0.556863 0.149020
0.800000 0.560784 0.145098
0.800000 0.560784 0.149020
0.800000 0.564706 0.145098
0.800000 0.564706 0.149020
0.800000 0.564706 0.152941
0.800000 0.564706 0.156863
0.800000 0.564706 0.160784
0.800000 0.564706 0.164706
0.800000 0.564706 0.168627
0.800000 0.568627 0.164706
0.800000 0.568627 0.168627
0.800000 0.568627 0.172549
0.800000 0.572549 0.172549
0.800000 0.580392 0.196078
0.803922 0.564706 0.149020
0.803922 0.564706 0.152941
0.803922 0.568627 0.160784
0.803922 0.572549 0.164706
0.803922 0.572549 0.168627
0.803922 0.580392 0.211765
0.807843 0.564706 0.149020
0.807843 0.564706 0.152941
0.807843 0.568627 0.149020
0.807843 0.568627 0.152941
0.807843 0.568627 0.156863
0.811765 0.564706 0.149020
0.811765 0.564706 0.152941
0.811765 0.568627 0.152941
0.811765 0.568627 0.156863
0.811765 0.572549 0.149020
0.811765 0.572549 0.156863
0.811765 0.572549 0.160784
0.811765 0.572549 0.164706
0.811765 0.576471 0.168627
0.811765 0.576471 0.172549
0.811765 0.580392 0.172549
0.811765 0.584314 0.211765
0.815686 0.568627 0.149020
0.815686 0.568627 0.152941
0.815686 0.572549 0.149020
0.815686 0.572549 0.152941
0.815686 0.572549 0.156863
0.815686 0.572549 0.160784
0.815686 0.572549 0.164706
0.815686 0.576471 0.149020
0.815686 0.576471 0.152941
0.815686 0.576471 0.156863
0.815686 0.576471 0.164706
0.815686 0.576471 0.168627
0.815686 0.576471 0.172549
0.815686 0.580392 0.156863
0.815686 0.580392 0.160784
0.815686 0.580392 0.164706
0.815686 0.580392 0.168627
0.815686 0.580392 0.172549
0.815686 0.584314 0.168627
0.815686 0.584314 0.172549
0.815686 0.600000 0.219608
0.819608 0.572549 0.156863
0.819608 0.576471 0.156863
0.819608 0.580392 0.156863
0.819608 0.580392 0.160784
0.819608 0.580392 0.164706
0.819608 0.580392 0.168627
0.819608 0.584314 0.168627
0.819608 0.584314 0.172549
0.823529 0.576471 0.156863
0.823529 0.580392 0.156863
0.823529 0.584314 0.172549
0.823529 0.588235 0.172549
0.823529 0.588235 0.176471
0.823529 0.588235 0.180392
0.823529 0.596078 0.215686
0.823529 0.600000 0.219608
0.827451 0.580392 0.156863
0.827451 0.584314 0.156863
0.827451 0.584314 0.160784
0.827451 0.584314 0.164706
0.827451 0.603922 0.219608
0.831373 0.580392 0.156863
0.831373 0.584314 0.156863
0.831373 0.584314 0.160784
0.831373 0.584314 0.164706
0.831373 0.584314 0.168627
0.831373 0.588235 0.156863
0.831373 0.588235 0.160784
0.831373 0.588235 0.164706
0.831373 0.588235 0.168627
0.831373 0.588235 0.172549
0.831373 0.592157 0.168627
0.831373 0.592157 0.172549
0.831373 0.592157 0.176471
0.831373 0.603922 0.219608
0.835294 0.584314 0.156863
0.835294 0.588235 0.156863
0.835294 0.588235 0.160784
0.835294 0.592157 0.156863
0.835294 0.592157 0.160784
0.835294 0.592157 0.164706
0.835294 0.592157 0.172549
0.835294 0.596078 0.172549
0.835294 0.596078 0.176471
0.835294 0.596078 0.180392
0.835294 0.607843 0.219608
0.835294 0.611765 0.227451
0.839216 0.592157 0.156863
0.839216 0.592157 0.160784
0.839216 0.596078 0.160784
0.839216 0.596078 0.164706
0.839216 0.596078 0.168627
0.839216 0.596078 0.172549
0.839216 0.596078 0.176471
0.839216 0.607843 0.203922
0.839216 0.611765 0.219608
0.839216 0.611765 0.235294
0.843137 0.588235 0.156863
0.843137 0.592157 0.160784
0.843137 0.596078 0.160784
0.843137 0.596078 0.172549
0.843137 0.596078 0.176471
0.843137 0.600000 0.180392
0.843137 0.611765 0.219608
0.847059 0.592157 0.160784
0.847059 0.596078 0.160784
0.847059 0.596078 0.164706
0.847059 0.596078 0.172549
0.847059 0.596078 0.176471
0.847059 0.600000 0.160784
0.847059 0.600000 0.168627
0.847059 0.600000 0.172549
0.847059 0.600000 0.184314
0.847059 0.603922 0.172549
0.847059 0.611765 0.200000
0.847059 0.615686 0.223529
0.847059 0.615686 0.227451
0.847059 0.623529 0.235294
0.850980 0.600000 0.160784
0.850980 0.600000 0.164706
0.850980 0.603922 0.160784
0.850980 0.603922 0.164706
0.850980 0.603922 0.168627
0.850980 0.603922 0.172549
0.850980 0.603922 0.176471
0.850980 0.603922 0.180392
0.850980 0.607843 0.172549
0.850980 0.607843 0.188235
0.854902 0.600000 0.164706
0.854902 0.603922 0.160784
0.854902 0.603922 0.164706
0.854902 0.607843 0.160784
0.854902 0.607843 0.164706
0.854902 0.607843 0.168627
0.854902 0.607843 0.172549
0.854902 0.607843 0.176471
0.854902 0.607843 0.180392
0.854902 0.611765 0.172549
0.854902 0.611765 0.176471
0.854902 0.611765 0.184314
0.854902 0.611765 0.188235
0.854902 0.627451 0.235294
0.858824 0.603922 0.164706
0.858824 0.607843 0.160784
0.858824 0.607843 0.164706
0.858824 0.611765 0.164706
0.858824 0.611765 0.168627
0.858824 0.611765 0.172549
0.858824 0.611765 0.176471
0.858824 0.611765 0.184314
0.858824 0.611765 0.188235
0.858824 0.627451 0.231373
0.858824 0.627451 0.239216
0.858824 0.631373 0.247059
0.862745 0.607843 0.164706
0.862745 0.607843 0.168627
0.862745 0.607843 0.172549
0.862745 0.611765 0.164706
0.862745 0.611765 0.168627
0.862745 0.611765 0.172549
0.862745 0.611765 0.176471
0.862745 0.611765 0.180392
0.862745 0.611765 0.184314
0.862745 0.615686 0.180392
0.862745 0.615686 0.184314
0.862745 0.615686 0.188235
0.862745 0.619608 0.180392
0.862745 0.619608 0.188235
0.862745 0.619608 0.192157
0.862745 0.619608 0.196078
0.862745 0.623529 0.196078
0.862745 0.623529 0.200000
0.862745 0.627451 0.207843
0.862745 0.627451 0.211765
0.862745 0.627451 0.231373
0.862745 0.631373 0.231373
0.862745 0.631373 0.235294
0.866667 0.556863 0.031373
0.866667 0.611765 0.164706
0.866667 0.611765 0.168627
0.866667 0.611765 0.172549
0.866667 0.611765 0.176471
0.866667 0.615686 0.168627
0.866667 0.615686 0.172549
0.866667 0.615686 0.176471
0.866667 0.615686 0.180392
0.866667 0.619608 0.184314
0.866667 0.623529 0.180392
0.866667 0.623529 0.192157
0.866667 0.623529 0.196078
0.866667 0.623529 0.203922
0.866667 0.627451 0.200000
0.866667 0.627451 0.203922
0.866667 0.627451 0.207843
0.866667 0.627451 0.211765
0.866667 0.631373 0.219608
0.866667 0.631373 0.223529
0.866667 0.631373 0.235294
0.866667 0.635294 0.227451
0.866667 0.635294 0.231373
0.866667 0.635294 0.235294
0.870588 0.611765 0.164706
0.870588 0.611765 0.172549
0.870588 0.615686 0.164706
0.870588 0.615686 0.168627
0.870588 0.615686 0.172549
0.870588 0.615686 0.176471
0.870588 0.615686 0.184314
0.870588 0.619608 0.168627
0.870588 0.619608 0.172549
0.870588 0.619608 0.176471
0.870588 0.619608 0.188235
0.870588 0.623529 0.176471
0.870588 0.623529 0.180392
0.870588 0.623529 0.184314
0.870588 0.623529 0.188235
0.870588 0.627451 0.188235
0.870588 0.627451 0.192157
0.870588 0.627451 0.196078
0.870588 0.627451 0.200000
0.870588 0.627451 0.203922
0.870588 0.627451 0.207843
0.870588 0.627451 0.211765
0.870588 0.627451 0.215686
0.870588 0.631373 0.215686
0.870588 0.635294 0.219608
0.870588 0.635294 0.223529
0.870588 0.635294 0.235294
0.870588 0.639216 0.231373
0.870588 0.639216 0.235294
0.870588 0.639216 0.243137
0.870588 0.643137 0.247059
0.874510 0.615686 0.168627
0.874510 0.615686 0.172549
0.874510 0.619608 0.168627
0.874510 0.619608 0.172549
0.874510 0.619608 0.176471
0.874510 0.619608 0.180392
0.874510 0.623529 0.172549
0.874510 0.623529 0.176471
0.874510 0.623529 0.180392
0.874510 0.623529 0.184314
0.874510 0.623529 0.188235
0.874510 0.627451 0.180392
0.874510 0.627451 0.184314
0.874510 0.627451 0.188235
0.874510 0.627451 0.192157
0.874510 0.627451 0.196078
0.874510 0.631373 0.207843
0.874510 0.631373 0.211765
0.874510 0.631373 0.215686
0.874510 0.631373 0.219608
0.874510 0.639216 0.219608
0.874510 0.639216 0.227451
0.874510 0.639216 0.235294
0.874510 0.643137 0.227451
0.874510 0.643137 0.231373
0.874510 0.643137 0.235294
0.874510 0.643137 0.243137
0.874510 0.643137 0.247059
0.874510 0.643137 0.250980
0.874510 0.643137 0.254902
0.878431 0.564706 0.031373
0.878431 0.619608 0.168627
0.878431 0.619608 0.172549
0.878431 0.623529 0.168627
0.878431 0.623529 0.172549
0.878431 0.623529 0.176471
0.878431 0.623529 0.180392
0.878431 0.627451 0.172549
0.878431 0.627451 0.176471
0.878431 0.627451 0.180392
0.878431 0.627451 0.184314
0.878431 0.627451 0.188235
0.878431 0.627451 0.192157
0.878431 0.627451 0.196078
0.878431 0.627451 0.200000
0.878431 0.627451 0.203922
0.878431 0.631373 0.192157
0.878431 0.631373 0.196078
0.878431 0.631373 0.200000
0.878431 0.631373 0.207843
0.878431 0.631373 0.211765
0.878431 0.631373 0.215686
0.878431 0.635294 0.203922
0.878431 0.635294 0.207843
0.878431 0.635294 0.211765
0.878431 0.635294 0.215686
0.878431 0.635294 0.219608
0.878431 0.639216 0.215686
0.878431 0.643137 0.219608
0.878431 0.643137 0.227451
0.878431 0.643137 0.231373
0.878431 0.643137 0.235294
0.878431 0.643137 0.239216
0.878431 0.643137 0.243137
0.878431 0.643137 0.247059
0.878431 0.647059 0.235294
0.878431 0.647059 0.239216
0.878431 0.647059 0.247059
0.878431 0.647059 0.250980
0.878431 0.650980 0.262745
0.878431 0.654902 0.278431
0.878431 0.658824 0.282353
0.878431 0.658824 0.286275
0.878431 0.662745 0.298039
0.882353 0.564706 0.031373
0.882353 0.623529 0.168627
0.882353 0.627451 0.180392
0.882353 0.627451 0.188235
0.882353 0.627451 0.192157
0.882353 0.631373 0.184314
0.882353 0.631373 0.192157
0.882353 0.631373 0.196078
0.882353 0.631373 0.200000
0.882353 0.635294 0.203922
0.882353 0.639216 0.211765
0.882353 0.639216 0.215686
0.882353 0.639216 0.219608
0.882353 0.643137 0.219608
0.882353 0.643137 0.227451
0.882353 0.647059 0.231373
0.882353 0.647059 0.235294
0.882353 0.647059 0.239216
0.882353 0.647059 0.247059
0.882353 0.650980 0.247059
0.882353 0.650980 0.250980
0.882353 0.654902 0.258824
0.882353 0.658824 0.282353
0.882353 0.662745 0.282353
0.882353 0.666667 0.298039
0.882353 0.670588 0.305882
0.886275 0.568627 0.031373
0.886275 0.627451 0.168627
0.886275 0.627451 0.172549
0.886275 0.627451 0.176471
0.886275 0.627451 0.180392
0.886275 0.627451 0.184314
0.886275 0.627451 0.188235
0.886275 0.631373 0.184314
0.886275 0.631373 0.188235
0.886275 0.631373 0.192157
0.886275 0.635294 0.184314
0.886275 0.635294 0.188235
0.886275 0.635294 0.192157
0.886275 0.635294 0.196078
0.886275 0.635294 0.200000
0.886275 0.635294 0.203922
0.886275 0.639216 0.192157
0.886275 0.639216 0.196078
0.886275 0.639216 0.203922
0.886275 0.639216 0.211765
0.886275 0.639216 0.215686
0.886275 0.639216 0.219608
0.886275 0.643137 0.200000
0.886275 0.643137 0.219608
0.886275 0.647059 0.223529
0.886275 0.647059 0.231373
0.886275 0.650980 0.235294
0.886275 0.650980 0.239216
0.886275 0.654902 0.250980
0.886275 0.658824 0.258824
0.886275 0.658824 0.266667
0.886275 0.666667 0.294118
0.890196 0.572549 0.031373
0.890196 0.627451 0.176471
0.890196 0.627451 0.180392
0.890196 0.631373 0.184314
0.890196 0.635294 0.188235
0.890196 0.635294 0.192157
0.890196 0.635294 0.196078
0.890196 0.639216 0.192157
0.890196 0.639216 0.196078
0.890196 0.639216 0.200000
0.890196 0.639216 0.203922
0.890196 0.643137 0.203922
0.890196 0.643137 0.207843
0.890196 0.643137 0.211765
0.890196 0.643137 0.215686
0.890196 0.643137 0.219608
0.890196 0.647059 0.219608
0.890196 0.647059 0.223529
0.890196 0.650980 0.223529
0.890196 0.650980 0.235294
0.890196 0.654902 0.235294
0.890196 0.654902 0.239216
0.890196 0.654902 0.247059
0.890196 0.658824 0.250980
0.890196 0.670588 0.298039
0.890196 0.670588 0.305882
0.894118 0.576471 0.031373
0.894118 0.580392 0.039216
0.894118 0.643137 0.203922
0.894118 0.643137 0.207843
0.894118 0.643137 0.211765
0.894118 0.643137 0.215686
0.894118 0.643137 0.219608
0.894118 0.643137 0.223529
0.894118 0.647059 0.219608
0.894118 0.647059 0.223529
0.894118 0.647059 0.227451
0.894118 0.647059 0.231373
0.894118 0.650980 0.223529
0.894118 0.650980 0.227451
0.894118 0.650980 0.231373
0.894118 0.650980 0.235294
0.894118 0.650980 0.239216
0.894118 0.654902 0.223529
0.894118 0.654902 0.227451
0.894118 0.654902 0.231373
0.894118 0.654902 0.235294
0.894118 0.654902 0.239216
0.894118 0.654902 0.243137
0.894118 0.654902 0.250980
0.894118 0.658824 0.235294
0.894118 0.658824 0.239216
0.894118 0.658824 0.243137
0.894118 0.658824 0.247059
0.894118 0.658824 0.250980
0.894118 0.658824 0.258824
0.894118 0.662745 0.250980
0.894118 0.662745 0.254902
0.894118 0.662745 0.258824
0.894118 0.662745 0.274510
0.894118 0.674510 0.294118
0.894118 0.674510 0.301961
0.898039 0.658824 0.239216
0.898039 0.658824 0.243137
0.898039 0.658824 0.247059
0.898039 0.658824 0.250980
0.898039 0.658824 0.254902
0.898039 0.662745 0.247059
0.898039 0.662745 0.250980
0.898039 0.662745 0.254902
0.898039 0.662745 0.258824
0.898039 0.662745 0.262745
0.898039 0.666667 0.254902
0.898039 0.666667 0.258824
0.898039 0.666667 0.262745
0.898039 0.666667 0.266667
0.898039 0.666667 0.270588
0.898039 0.670588 0.266667
0.898039 0.670588 0.270588
0.898039 0.670588 0.274510
0.898039 0.670588 0.278431
0.898039 0.670588 0.282353
0.901961 0.674510 0.298039
0.901961 0.678431 0.305882
0.905882 0.674510 0.282353
0.905882 0.678431 0.298039
0.905882 0.678431 0.305882
0.909804 0.682353 0.305882
0.909804 0.682353 0.313726
0.909804 0.686275 0.305882
0.909804 0.686275 0.313726
0.909804 0.690196 0.313726
0.909804 0.690196 0.317647
0.909804 0.690196 0.321569
0.909804 0.690196 0.325490
0.909804 0.694118 0.325490
0.909804 0.694118 0.329412
0.909804 0.698039 0.329412
0.937255 0.447059 0.141176
0.941176 0.447059 0.141176
0.941176 0.450980 0.141176
0.941176 0.862745 0.800000
0.945098 0.450980 0.141176
0.949020 0.454902 0.145098
0.952941 0.454902 0.145098
0.956863 0.454902 0.145098
0.956863 0.882353 0.819608
0.960784 0.458824 0.145098
0.960784 0.882353 0.823529
0.964706 0.458824 0.145098
0.964706 0.462745 0.149020
0.964706 0.462745 0.152941
0.964706 0.466667 0.156863
0.964706 0.470588 0.160784
0.964706 0.470588 0.164706
0.964706 0.470588 0.168627
0.964706 0.474510 0.172549
0.964706 0.886275 0.827451
0.968627 0.890196 0.831373
1 2 2 493 84
1 2 3 172 20
1 2 4 199 20
1 2 5 256 20
1 2 6 499 20
1 2 7 278 20
1 2 8 505 20
1 2 9 422 20
1 2 10 312 20
1 2 11 112 20
1 2 12 253 20
1 2 13 415 20
1 2 14 503 52
1 3 2 50 68
1 3 3 382 4
1 3 4 154 4
1 3 5 380 4
1 3 6 499 4
1 3 7 429 4
1 3 8 267 4
1 3 9 470 4
1 3 10 354 4
1 3 11 133 4
1 3 12 429 4
1 3 13 155 4
1 3 14 72 36
1 4 2 172 68
1 4 3 215 4
1 4 4 112 4
1 4 5 507 4
1 4 6 125 4
1 4 7 485 4
1 4 8 103 4
1 4 9 173 4
1 4 10 503 4
1 4 11 495 4
1 4 12 231 4
1 4 13 215 4
1 4 14 363 36
1 5 2 194 68
1 5 3 259 4
1 5 4 323 4
1 5 5 243 4
1 5 6 113 4
1 5 7 188 4
1 5 8 503 4
1 5 9 195 4
1 5 10 129 4
1 5 11 465 4
1 5 12 251 4
1 5 13 75 4
1 5 14 194 36
1 6 2 271 68
1 6 3 299 4
1 6 4 476 4
1 6 5 356 4
1 6 6 227 4
1 6 7 259 4
1 6 8 333 4
1 6 9 258 4
1 6 10 138 4
1 6 11 465 4
1 6 12 151 4
1 6 13 462 4
1 6 14 424 36
1 7 2 250 68
1 7 3 77 4
1 7 4 315 4
1 7 5 323 4
1 7 6 171 4
1 7 7 558 4
1 7 8 233 4
1 7 9 461 4
1 7 10 566 4
1 7 11 45 4
1 7 12 225 4
1 7 13 527 4
1 7 14 556 36
1 8 2 217 68
1 8 3 396 4
1 8 4 219 4
1 8 5 407 4
1 8 6 567 4
1 8 7 569 4
1 8 8 488 4
1 8 9 551 4
1 8 10 553 4
1 8 11 465 4
1 8 12 436 4
1 8 13 105 4
1 8 14 566 36
1 9 2 507 68
1 9 3 198 4
1 9 4 466 4
1 9 5 565 4
1 9 6 565 4
1 9 7 518 4
1 9 8 468 4
1 9 9 564 4
1 9 10 558 4
1 9 11 487 4
1 9 12 493 4
1 9 13 555 4
1 9 14 555 44
1 10 2 112 68
1 10 3 211 4
1 10 4 569 4
1 10 5 557 4
1 10 6 515 4
1 10 7 247 4
1 10 8 562 4
1 10 9 560 4
1 10 10 449 4
1 10 11 91 4
1 10 12 566 4
1 10 13 563 44
1 11 0 1 86
1 11 1 2 22
1 11 2 363 4
1 11 3 558 4
1 11 4 563 4
1 11 5 248 4
1 11 6 48 4
1 11 7 556 4
1 11 8 556 4
1 11 9 448 4
1 11 10 122 4
1 11 11 563 4
1 11 12 551 44
1 12 0 1 76
1 12 1 3 12
1 12 2 217 4
1 12 3 565 4
1 12 4 567 12
1 12 5 111 12
1 12 6 207 12
1 12 7 552 12
1 12 8 569 12
1 12 9 488 12
1 12 10 150 12
1 12 11 568 44
1 13 2 26 68
1 13 3 34 36
1 14 2 27 78
1 14 3 26 44
2 0 5 15 116
2 0 11 14 116
2 1 4 16 84
2 1 5 22 4
2 1 6 13 52
2 1 10 12 84
2 1 11 14 4
2 1 12 20 52
2 2 2 468 80
2 2 3 372 16
2 2 4 433 0
2 2 5 293 0
2 2 6 344 0
2 2 7 170 16
2 2 8 290 16
2 2 9 411 16
2 2 10 112 0
2 2 11 138 0
2 2 12 194 0
2 2 13 102 16
2 2 14 381 48
2 3 2 506 64
2 3 3 406 0
2 3 4 423 0
2 3 5 221 0
2 3 6 506 0
2 3 7 171 0
2 3 8 464 0
2 3 9 85 0
2 3 10 73 0
2 3 11 102 0
2 3 12 77 0
2 3 13 252 0
2 3 14 341 32
2 4 2 346 64
2 4 3 131 0
2 4 4 327 0
2 4 5 117 0
2 4 6 434 0
2 4 7 355 0
2 4 8 504 0
2 4 9 76 0
2 4 10 469 0
2 4 11 125 0
2 4 12 361 0
2 4 13 527 0
2 4 14 335 32
2 5 2 487 64
2 5 3 355 0
2 5 4 492 0
2 5 5 318 0
2 5 6 225 0
2 5 7 70 0
2 5 8 221 0
2 5 9 195 0
2 5 10 176 0
2 5 11 211 0
2 5 12 498 0
2 5 13 466 0
2 5 14 151 32
2 6 2 209 64
2 6 3 408 0
2 6 4 233 0
2 6 5 112 0
2 6 6 45 0
2 6 7 361 0
2 6 8 200 0
2 6 9 485 0
2 6 10 101 0
2 6 11 63 0
2 6 12 469 0
2 6 13 323 0
2 6 14 521 32
2 7 2 323 64
2 7 3 528 0
2 7 4 210 0
2 7 5 209 0
2 7 6 471 0
2 7 7 253 0
2 7 8 130 0
2 7 9 522 0
2 7 10 362 0
2 7 11 217 0
2 7 12 424 0
2 7 13 247 0
2 7 14 493 32
2 8 2 323 64
2 8 3 444 0
2 8 4 336 0
2 8 5 299 0
2 8 6 150 0
2 8 7 233 0
2 8 8 503 0
2 8 9 503 0
2 8 10 511 0
2 8 11 277 0
2 8 12 483 0
2 8 13 160 0
2 8 14 562 32
2 9 2 464 64
2 9 3 85 0
2 9 4 138 0
2 9 5 474 0
2 9 6 521 0
2 9 7 194 0
2 9 8 471 0
2 9 9 66 0
2 9 10 137 0
2 9 11 285 0
2 9 12 267 0
2 9 13 444 0
2 9 14 563 40
2 10 2 491 64
2 10 3 504 0
2 10 4 398 0
2 10 5 425 0
2 10 6 243 0
2 10 7 267 0
2 10 8 207 0
2 10 9 499 0
2 10 10 253 0
2 10 11 382 0
2 10 12 300 0
2 10 13 565 40
2 11 2 253 64
2 11 3 494 0
2 11 4 193 0
2 11 5 515 0
2 11 6 476 0
2 11 7 404 0
2 11 8 159 0
2 11 9 194 0
2 11 10 293 0
2 11 11 310 0
2 11 12 557 40
2 12 0 2 88
2 12 1 8 24
2 12 2 217 0
2 12 3 495 0
2 12 4 435 0
2 12 5 352 8
2 12 6 221 8
2 12 7 59 8
2 12 8 457 8
2 12 9 460 8
2 12 10 249 8
2 12 11 566 40
2 13 2 26 72
2 13 3 28 0
2 13 4 29 44
2 14 3 15 96
2 15 3 34 108
3 0 5 19 112
3 0 11 13 112
3 1 4 23 80
3 1 5 20 0
3 1 6 17 48
3 1 10 13 80
3 1 11 12 0
3 1 12 23 48
3 2 2 408 80
3 2 3 48 16
3 2 4 378 0
3 2 5 131 0
3 2 6 487 0
3 2 7 209 16
3 2 8 323 16
3 2 9 307 16
3 2 10 85 0
3 2 11 138 0
3 2 12 182 0
3 2 13 276 16
3 2 14 63 48
3 3 0 1 124
3 3 2 521 64
3 3 3 429 0
3 3 4 279 0
3 3 5 169 0
3 3 6 249 0
3 3 7 352 0
3 3 8 159 0
3 3 9 507 0
3 3 10 51 0
3 3 11 53 0
3 3 12 367 0
3 3 13 139 0
3 3 14 156 32
3 4 2 227 64
3 4 3 324 0
3 4 4 155 0
3 4 5 362 0
3 4 6 427 0
3 4 7 434 0
3 4 8 243 0
3 4 9 194 0
3 4 10 145 0
3 4 11 476 0
3 4 12 131 0
3 4 13 363 0
3 4 14 376 32
3 5 0 9 124
3 5 2 476 64
3 5 3 467 0
3 5 4 484 0
3 5 5 187 0
3 5 6 464 0
3 5 7 516 0
3 5 8 485 0
3 5 9 164 0
3 5 10 103 0
3 5 11 123 0
3 5 12 468 0
3 5 13 160 0
3 5 14 433 32
3 6 2 464 64
3 6 3 503 0
3 6 4 282 0
3 6 5 194 0
3 6 6 467 0
3 6 7 151 0
3 6 8 67 0
3 6 9 505 0
3 6 10 463 0
3 6 11 145 0
3 6 12 207 0
3 6 13 470 0
3 6 14 352 32
3 7 2 506 64
3 7 3 188 0
3 7 4 273 0
3 7 5 463 0
3 7 6 518 0
3 7 7 464 0
3 7 8 92 0
3 7 9 433 0
3 7 10 92 0
3 7 11 500 0
3 7 12 157 0
3 7 13 53 0
3 7 14 431 32
3 8 1 571 84
3 8 2 488 0
3 8 3 507 0
3 8 4 281 0
3 8 5 247 0
3 8 6 411 0
3 8 7 423 0
3 8 8 194 0
3 8 9 323 0
3 8 10 99 0
3 8 11 177 0
3 8 12 430 0
3 8 13 384 0
3 8 14 507 32
3 9 1 571 68
3 9 2 367 0
3 9 3 138 0
3 9 4 233 0
3 9 5 85 0
3 9 6 465 0
3 9 7 523 0
3 9 8 424 0
3 9 9 209 0
3 9 10 346 0
3 9 11 194 0
3 9 12 283 0
3 9 13 120 0
3 9 14 254 40
3 10 1 571 76
3 10 2 426 0
3 10 3 50 0
3 10 4 467 0
3 10 5 127 0
3 10 6 165 0
3 10 7 316 0
3 10 8 141 0
3 10 9 193 0
3 10 10 108 0
3 10 11 249 0
3 10 12 422 0
3 10 13 521 40
3 11 2 284 64
3 11 3 261 0
3 11 4 86 0
3 11 5 194 0
3 11 6 218 0
3 11 7 67 0
3 11 8 194 0
3 11 9 249 0
3 11 10 446 0
3 11 11 269 0
3 11 12 523 40
3 12 0 5 88
3 12 1 2 24
3 12 2 232 0
3 12 3 50 0
3 12 4 267 0
3 12 5 313 0
3 12 6 505 8
3 12 7 188 8
3 12 8 489 8
3 12 9 503 8
3 12 10 465 8
3 12 11 297 40
3 13 2 25 72
3 13 3 25 0
3 13 4 37 0
3 13 5 27 44
3 14 3 15 64
3 14 4 28 44
3 15 3 33 104
4 0 5 18 114
4 0 11 22 114
4 1 4 23 82
4 1 5 12 2
4 1 6 15 50
4 1 10 14 82
4 1 11 15 2
4 1 12 13 50
4 2 2 346 80
4 2 3 429 16
4 2 4 145 0
4 2 5 112 0
4 2 6 166 0
4 2 7 362 16
4 2 8 507 16
4 2 9 318 16
4 2 10 74 0
4 2 11 46 0
4 2 12 95 0
4 2 13 488 16
4 2 14 342 48
4 3 0 7 120
4 3 2 104 64
4 3 3 188 0
4 3 4 136 0
4 3 5 423 0
4 3 6 61 0
4 3 7 499 0
4 3 8 285 0
4 3 9 379 0
4 3 10 462 0
4 3 11 207 0
4 3 12 360 0
4 3 13 457 0
4 3 14 51 32
4 4 2 108 64
4 4 3 518 0
4 4 4 194 0
4 4 5 422 0
4 4 6 138 0
4 4 7 320 0
4 4 8 504 0
4 4 9 425 0
4 4 10 209 0
4 4 11 506 0
4 4 12 518 0
4 4 13 225 0
4 4 14 532 32
4 5 0 11 120
4 5 2 488 64
4 5 3 400 0
4 5 4 429 0
4 5 5 171 0
4 5 6 50 0
4 5 7 88 0
4 5 8 465 0
4 5 9 85 0
4 5 10 288 0
4 5 11 221 0
4 5 12 46 0
4 5 13 85 0
4 5 14 62 32
4 6 2 223 64
4 6 3 484 0
4 6 4 61 0
4 6 5 250 0
4 6 6 509 0
4 6 7 517 0
4 6 8 402 0
4 6 9 151 0
4 6 10 468 0
4 6 11 95 0
4 6 12 358 0
4 6 13 194 0
4 6 14 226 32
4 7 2 49 64
4 7 3 326 0
4 7 4 95 0
4 7 5 466 0
4 7 6 173 0
4 7 7 212 0
4 7 8 228 0
4 7 9 95 0
4 7 10 467 0
4 7 11 526 0
4 7 12 303 0
4 7 13 117 0
4 7 14 320 32
4 8 1 2 80
4 8 2 211 0
4 8 3 68 0
4 8 4 370 0
4 8 5 376 0
4 8 6 300 0
4 8 7 404 0
4 8 8 358 0
4 8 9 247 0
4 8 10 357 0
4 8 11 404 0
4 8 12 507 0
4 8 13 145 0
4 8 14 271 32
4 9 1 11 64
4 9 2 188 0
4 9 3 503 0
4 9 4 269 0
4 9 5 98 0
4 9 6 499 0
4 9 7 246 0
4 9 8 449 0
4 9 9 463 0
4 9 10 99 0
4 9 11 270 0
4 9 12 239 0
4 9 13 159 0
4 9 14 506 40
4 10 1 559 72
4 10 2 293 0
4 10 3 85 0
4 10 4 290 0
4 10 5 425 0
4 10 6 262 0
4 10 7 145 0
4 10 8 102 0
4 10 9 298 0
4 10 10 81 0
4 10 11 270 0
4 10 12 155 0
4 10 13 463 40
4 11 2 494 64
4 11 3 465 0
4 11 4 207 0
4 11 5 494 0
4 11 6 297 0
4 11 7 509 0
4 11 8 488 0
4 11 9 425 0
4 11 10 487 0
4 11 11 82 0
4 11 12 507 40
4 12 0 8 88
4 12 1 10 24
4 12 2 463 0
4 12 3 268 0
4 12 4 250 0
4 12 5 503 0
4 12 6 274 8
4 12 7 190 8
4 12 8 466 8
4 12 9 302 8
4 12 10 272 8
4 12 11 361 40
4 13 2 34 72
4 13 3 28 0
4 13 4 37 0
4 13 5 33 42
4 14 3 23 64
4 14 4 25 42
4 15 3 32 104
5 2 1 35 84
5 2 2 34 16
5 2 3 500 16
5 2 4 464 16
5 2 5 121 16
5 2 6 525 16
5 2 7 462 16
5 2 8 207 16
5 2 9 194 16
5 2 10 338 16
5 2 11 467 16
5 2 12 325 16
5 2 13 489 16
5 2 14 169 48
5 3 0 1 90
5 3 1 33 4
5 3 2 76 0
5 3 3 72 0
5 3 4 405 0
5 3 5 528 0
5 3 6 361 0
5 3 7 515 0
5 3 8 435 0
5 3 9 112 0
5 3 10 359 0
5 3 11 169 0
5 3 12 103 0
5 3 13 295 0
5 3 14 303 32
5 4 1 33 68
5 4 2 486 0
5 4 3 153 0
5 4 4 346 0
5 4 5 483 0
5 4 6 182 0
5 4 7 387 0
5 4 8 341 0
5 4 9 50 0
5 4 10 305 0
5 4 11 87 0
5 4 12 309 0
5 4 13 465 0
5 4 14 367 32
5 5 0 2 90
5 5 1 26 4
5 5 2 210 0
5 5 3 108 0
5 5 4 115 0
5 5 5 63 0
5 5 6 428 0
5 5 7 248 0
5 5 8 397 0
5 5 9 363 0
5 5 10 287 0
5 5 11 176 0
5 5 12 57 0
5 5 13 457 0
5 5 14 505 32
5 6 1 28 76
5 6 2 371 0
5 6 3 221 0
5 6 4 321 0
5 6 5 305 0
5 6 6 354 0
5 6 7 138 0
5 6 8 516 0
5 6 9 194 0
5 6 10 470 0
5 6 11 60 0
5 6 12 352 0
5 6 13 318 0
5 6 14 118 32
5 7 2 465 64
5 7 3 422 0
5 7 4 127 0
5 7 5 95 0
5 7 6 177 0
5 7 7 528 0
5 7 8 415 0
5 7 9 493 0
5 7 10 531 0
5 7 11 376 0
5 7 12 248 0
5 7 13 282 0
5 7 14 493 32
5 8 1 2 80
5 8 2 491 0
5 8 3 308 0
5 8 4 258 0
5 8 5 255 0
5 8 6 67 0
5 8 7 528 0
5 8 8 423 0
5 8 9 411 0
5 8 10 485 0
5 8 11 167 0
5 8 12 85 0
5 8 13 528 0
5 8 14 359 32
5 9 1 6 64
5 9 2 354 0
5 9 3 491 0
5 9 4 77 0
5 9 5 449 0
5 9 6 158 0
5 9 7 308 0
5 9 8 382 0
5 9 9 237 0
5 9 10 72 0
5 9 11 429 0
5 9 12 488 0
5 9 13 248 0
5 9 14 469 40
5 10 1 571 72
5 10 2 95 0
5 10 3 125 0
5 10 4 73 0
5 10 5 256 0
5 10 6 282 0
5 10 7 254 0
5 10 8 520 0
5 10 9 198 0
5 10 10 521 0
5 10 11 314 0
5 10 12 526 0
5 10 13 489 40
5 11 2 493 64
5 11 3 188 0
5 11 4 49 0
5 11 5 115 0
5 11 6 463 0
5 11 7 526 0
5 11 8 140 0
5 11 9 298 0
5 11 10 290 0
5 11 11 210 0
5 11 12 345 40
5 12 0 1 88
5 12 1 3 24
5 12 2 489 0
5 12 3 522 0
5 12 4 412 0
5 12 5 485 8
5 12 6 331 8
5 12 7 503 8
5 12 8 556 8
5 12 9 112 8
5 12 10 243 8
5 12 11 558 40
5 13 2 35 72
5 13 3 27 0
5 13 4 29 42
5 14 3 23 96
5 15 3 34 106
6 2 1 31 80
6 2 2 51 16
6 2 3 123 16
6 2 4 361 16
6 2 5 467 16
6 2 6 145 16
6 2 7 413 16
6 2 8 111 16
6 2 9 503 16
6 2 10 463 16
6 2 11 57 16
6 2 12 482 16
6 2 13 125 16
6 2 14 223 48
6 3 1 44 64
6 3 2 446 0
6 3 3 280 0
6 3 4 505 0
6 3 5 467 0
6 3 6 522 0
6 3 7 503 0
6 3 8 148 0
6 3 9 468 0
6 3 10 485 0
6 3 11 525 0
6 3 12 409 0
6 3 13 231 0
6 3 14 493 32
6 4 1 42 64
6 4 2 528 0
6 4 3 428 0
6 4 4 233 0
6 4 5 51 0
6 4 6 127 0
6 4 7 528 0
6 4 8 457 0
6 4 9 516 0
6 4 10 213 0
6 4 11 489 0
6 4 12 136 0
6 4 13 254 0
6 4 14 411 32
6 5 1 40 64
6 5 2 443 0
6 5 3 463 0
6 5 4 172 0
6 5 5 194 0
6 5 6 81 0
6 5 7 507 0
6 5 8 252 0
6 5 9 493 0
6 5 10 138 0
6 5 11 506 0
6 5 12 423 0
6 5 13 92 0
6 5 14 519 32
6 6 1 27 72
6 6 2 145 0
6 6 3 136 0
6 6 4 57 0
6 6 5 501 0
6 6 6 194 0
6 6 7 507 0
6 6 8 505 0
6 6 9 234 0
6 6 10 95 0
6 6 11 112 0
6 6 12 434 0
6 6 13 248 0
6 6 14 218 32
6 7 2 99 64
6 7 3 145 0
6 7 4 481 0
6 7 5 125 0
6 7 6 194 0
6 7 7 116 0
6 7 8 401 0
6 7 9 509 0
6 7 10 273 0
6 7 11 121 0
6 7 12 168 0
6 7 13 58 0
6 7 14 165 32
6 8 1 571 82
6 8 2 352 0
6 8 3 386 0
6 8 4 440 0
6 8 5 258 0
6 8 6 108 0
6 8 7 292 0
6 8 8 256 0
6 8 9 218 0
6 8 10 77 0
6 8 11 253 0
6 8 12 325 0
6 8 13 72 0
6 8 14 283 32
6 9 1 554 66
6 9 2 517 0
6 9 3 499 0
6 9 4 523 0
6 9 5 187 0
6 9 6 432 0
6 9 7 179 0
6 9 8 429 0
6 9 9 138 0
6 9 10 499 0
6 9 11 91 0
6 9 12 433 0
6 9 13 238 0
6 9 14 139 40
6 10 1 570 74
6 10 2 316 0
6 10 3 57 0
6 10 4 290 0
6 10 5 293 0
6 10 6 196 0
6 10 7 279 0
6 10 8 333 0
6 10 9 73 0
6 10 10 72 0
6 10 11 521 0
6 10 12 369 0
6 10 13 167 40
6 11 2 429 64
6 11 3 234 0
6 11 4 461 0
6 11 5 481 0
6 11 6 151 0
6 11 7 169 0
6 11 8 122 0
6 11 9 468 0
6 11 10 97 0
6 11 11 294 0
6 11 12 526 40
6 12 0 9 90
6 12 1 1 26
6 12 2 177 0
6 12 3 145 0
6 12 4 502 8
6 12 5 110 8
6 12 6 246 8
6 12 7 553 8
6 12 8 362 8
6 12 9 48 8
6 12 10 567 8
6 12 11 211 40
6 13 2 35 66
6 13 3 27 34
6 14 2 36 78
6 14 3 38 42
7 2 1 33 80
7 2 2 271 16
7 2 3 66 16
7 2 4 212 16
7 2 5 243 16
7 2 6 152 16
7 2 7 409 16
7 2 8 236 16
7 2 9 482 16
7 2 10 132 16
7 2 11 98 16
7 2 12 352 16
7 2 13 405 16
7 2 14 421 48
7 3 1 44 64
7 3 2 267 0
7 3 3 506 0
7 3 4 165 0
7 3 5 115 0
7 3 6 194 0
7 3 7 267 0
7 3 8 151 0
7 3 9 503 0
7 3 10 357 0
7 3 11 463 0
7 3 12 256 0
7 3 13 217 0
7 3 14 395 32
7 4 0 7 84
7 4 1 456 0
7 4 2 521 0
7 4 3 248 0
7 4 4 492 0
7 4 5 89 0
7 4 6 465 0
7 4 7 212 0
7 4 8 262 0
7 4 9 278 0
7 4 10 246 0
7 4 11 427 0
7 4 12 251 0
7 4 13 464 0
7 4 14 479 32
7 5 0 9 76
7 5 1 454 0
7 5 2 447 0
7 5 3 138 0
7 5 4 356 0
7 5 5 194 0
7 5 6 50 0
7 5 7 119 0
7 5 8 151 0
7 5 9 485 0
7 5 10 78 0
7 5 11 194 0
7 5 12 522 0
7 5 13 362 0
7 5 14 266 32
7 6 1 30 72
7 6 2 63 0
7 6 3 426 0
7 6 4 465 0
7 6 5 516 0
7 6 6 481 0
7 6 7 100 0
7 6 8 354 0
7 6 9 435 0
7 6 10 293 0
7 6 11 311 0
7 6 12 102 0
7 6 13 181 0
7 6 14 480 32
7 7 2 371 64
7 7 3 499 0
7 7 4 446 0
7 7 5 347 0
7 7 6 145 0
7 7 7 463 0
7 7 8 521 0
7 7 9 346 0
7 7 10 249 0
7 7 11 495 0
7 7 12 422 0
7 7 13 125 0
7 7 14 351 32
7 8 2 462 64
7 8 3 159 0
7 8 4 95 0
7 8 5 237 0
7 8 6 461 0
7 8 7 108 0
7 8 8 444 0
7 8 9 115 0
7 8 10 436 0
7 8 11 354 0
7 8 12 194 0
7 8 13 123 0
7 8 14 395 32
7 9 2 58 64
7 9 3 220 0
7 9 4 181 0
7 9 5 63 0
7 9 6 61 0
7 9 7 397 0
7 9 8 375 0
7 9 9 355 0
7 9 10 437 0
7 9 11 371 0
7 9 12 142 0
7 9 13 507 0
7 9 14 568 8
7 9 15 2 60
7 10 2 488 64
7 10 3 96 0
7 10 4 498 0
7 10 5 150 0
7 10 6 425 0
7 10 7 402 0
7 10 8 252 0
7 10 9 291 0
7 10 10 488 0
7 10 11 307 0
7 10 12 505 0
7 10 13 566 40
7 11 2 59 64
7 11 3 98 0
7 11 4 430 0
7 11 5 125 0
7 11 6 256 0
7 11 7 522 0
7 11 8 224 0
7 11 9 403 0
7 11 10 180 0
7 11 11 472 0
7 11 12 551 40
7 12 2 558 72
7 12 3 568 8
7 12 4 568 8
7 12 5 551 8
7 12 6 553 8
7 12 7 565 8
7 12 8 566 8
7 12 9 556 8
7 12 10 564 8
7 12 11 555 40
8 2 1 36 80
8 2 2 487 16
8 2 3 257 16
8 2 4 85 16
8 2 5 74 16
8 2 6 293 16
8 2 7 435 16
8 2 8 499 16
8 2 9 424 16
8 2 10 306 16
8 2 11 432 16
8 2 12 462 16
8 2 13 346 16
8 2 14 421 48
8 3 1 39 64
8 3 2 434 0
8 3 3 324 0
8 3 4 248 0
8 3 5 53 0
8 3 6 304 0
8 3 7 112 0
8 3 8 444 0
8 3 9 315 0
8 3 10 96 0
8 3 11 151 0
8 3 12 429 0
8 3 13 177 0
8 3 14 479 32
8 4 0 9 82
8 4 1 455 0
8 4 2 117 0
8 4 3 366 0
8 4 4 256 0
8 4 5 360 0
8 4 6 336 0
8 4 7 506 0
8 4 8 522 0
8 4 9 369 0
8 4 10 429 0
8 4 11 499 0
8 4 12 98 0
8 4 13 524 0
8 4 14 480 32
8 5 0 8 74
8 5 1 353 0
8 5 2 352 0
8 5 3 316 0
8 5 4 409 0
8 5 5 318 0
8 5 6 182 0
8 5 7 54 0
8 5 8 52 0
8 5 9 123 0
8 5 10 124 0
8 5 11 277 0
8 5 12 506 0
8 5 13 172 0
8 5 14 479 32
8 6 1 29 72
8 6 2 507 0
8 6 3 74 0
8 6 4 425 0
8 6 5 518 0
8 6 6 114 0
8 6 7 77 0
8 6 8 505 0
8 6 9 485 0
8 6 10 522 0
8 6 11 101 0
8 6 12 422 0
8 6 13 112 0
8 6 14 453 32
8 7 2 425 64
8 7 3 347 0
8 7 4 463 0
8 7 5 171 0
8 7 6 287 0
8 7 7 194 0
8 7 8 101 0
8 7 9 178 0
8 7 10 484 0
8 7 11 311 0
8 7 12 61 0
8 7 13 319 0
8 7 14 421 32
8 8 2 382 64
8 8 3 298 0
8 8 4 518 0
8 8 5 334 0
8 8 6 440 0
8 8 7 65 0
8 8 8 380 0
8 8 9 435 0
8 8 10 330 0
8 8 11 483 0
8 8 12 194 0
8 8 13 221 0
8 8 14 479 32
8 9 2 362 64
8 9 3 95 0
8 9 4 494 0
8 9 5 296 0
8 9 6 112 0
8 9 7 151 0
8 9 8 465 0
8 9 9 467 0
8 9 10 499 0
8 9 11 188 0
8 9 12 387 0
8 9 13 292 0
8 9 14 557 8
8 9 15 4 56
8 10 2 162 64
8 10 3 61 0
8 10 4 468 0
8 10 5 177 0
8 10 6 104 0
8 10 7 243 0
8 10 8 362 0
8 10 9 411 0
8 10 10 381 0
8 10 11 523 0
8 10 12 359 0
8 10 13 568 40
8 11 2 94 64
8 11 3 176 0
8 11 4 318 0
8 11 5 435 0
8 11 6 254 0
8 11 7 461 0
8 11 8 233 0
8 11 9 458 0
8 11 10 64 0
8 11 11 57 0
8 11 12 565 40
8 12 2 562 72
8 12 3 557 8
8 12 4 563 8
8 12 5 557 8
8 12 6 563 8
8 12 7 563 8
8 12 8 553 8
8 12 9 552 8
8 12 10 556 8
8 12 11 552 40
9 2 1 34 80
9 2 2 442 16
9 2 3 312 16
9 2 4 147 16
9 2 5 145 16
9 2 6 131 16
9 2 7 211 16
9 2 8 274 16
9 2 9 176 16
9 2 10 235 16
9 2 11 295 16
9 2 12 424 16
9 2 13 98 16
9 2 14 462 48
9 3 1 41 64
9 3 2 369 0
9 3 3 377 0
9 3 4 253 0
9 3 5 484 0
9 3 6 207 0
9 3 7 288 0
9 3 8 168 0
9 3 9 510 0
9 3 10 168 0
9 3 11 248 0
9 3 12 236 0
9 3 13 108 0
9 3 14 172 32
9 4 1 43 64
9 4 2 68 0
9 4 3 530 0
9 4 4 208 0
9 4 5 354 0
9 4 6 138 0
9 4 7 388 0
9 4 8 371 0
9 4 9 66 0
9 4 10 212 0
9 4 11 505 0
9 4 12 216 0
9 4 13 487 0
9 4 14 99 32
9 5 1 39 64
9 5 2 504 0
9 5 3 506 0
9 5 4 334 0
9 5 5 462 0
9 5 6 117 0
9 5 7 187 0
9 5 8 458 0
9 5 9 111 0
9 5 10 145 0
9 5 11 530 0
9 5 12 470 0
9 5 13 347 0
9 5 14 150 0
9 5 15 7 52
9 6 1 36 72
9 6 2 465 0
9 6 3 464 0
9 6 4 436 0
9 6 5 504 0
9 6 6 207 0
9 6 7 506 0
9 6 8 146 0
9 6 9 99 0
9 6 10 319 0
9 6 11 140 0
9 6 12 249 0
9 6 13 91 0
9 6 14 441 0
9 6 15 2 38
9 7 2 430 64
9 7 3 93 0
9 7 4 191 0
9 7 5 248 0
9 7 6 146 0
9 7 7 133 0
9 7 8 449 0
9 7 9 360 0
9 7 10 116 0
9 7 11 249 0
9 7 12 145 0
9 7 13 334 0
9 7 14 262 0
9 7 15 0 38
9 8 1 571 84
9 8 2 117 0
9 8 3 389 0
9 8 4 468 0
9 8 5 53 0
9 8 6 271 0
9 8 7 359 0
9 8 8 152 0
9 8 9 122 0
9 8 10 85 0
9 8 11 487 0
9 8 12 488 0
9 8 13 198 0
9 8 14 207 0
9 8 15 1 38
9 9 1 571 68
9 9 2 140 0
9 9 3 368 0
9 9 4 405 0
9 9 5 528 0
9 9 6 66 0
9 9 7 61 0
9 9 8 173 0
9 9 9 510 0
9 9 10 388 0
9 9 11 198 0
9 9 12 485 0
9 9 13 85 0
9 9 14 515 8
9 9 15 1 42
9 10 1 570 76
9 10 2 198 0
9 10 3 151 0
9 10 4 510 0
9 10 5 215 0
9 10 6 254 0
9 10 7 464 0
9 10 8 404 0
9 10 9 407 0
9 10 10 269 0
9 10 11 301 0
9 10 12 254 0
9 10 13 354 40
9 11 2 369 64
9 11 3 75 0
9 11 4 467 0
9 11 5 275 0
9 11 6 440 0
9 11 7 357 0
9 11 8 435 0
9 11 9 321 0
9 11 10 59 0
9 11 11 505 0
9 11 12 49 40
9 12 0 1 92
9 12 1 5 28
9 12 2 48 0
9 12 3 250 0
9 12 4 95 8
9 12 5 228 8
9 12 6 499 8
9 12 7 565 8
9 12 8 212 8
9 12 9 142 8
9 12 10 566 8
9 12 11 425 40
9 13 2 31 68
9 13 3 29 36
9 14 2 31 78
9 14 3 27 44
10 2 1 33 82
10 2 2 29 16
10 2 3 487 16
10 2 4 135 16
10 2 5 65 16
10 2 6 305 16
10 2 7 434 16
10 2 8 275 16
10 2 9 64 16
10 2 10 121 16
10 2 11 121 16
10 2 12 337 16
10 2 13 232 16
10 2 14 467 48
10 3 0 8 92
10 3 1 35 2
10 3 2 487 0
10 3 3 484 0
10 3 4 138 0
10 3 5 46 0
10 3 6 70 0
10 3 7 464 0
10 3 8 504 0
10 3 9 468 0
10 3 10 173 0
10 3 11 527 0
10 3 12 360 0
10 3 13 525 0
10 3 14 499 32
10 4 1 26 66
10 4 2 500 0
10 4 3 252 0
10 4 4 483 0
10 4 5 197 0
10 4 6 378 0
10 4 7 497 0
10 4 8 77 0
10 4 9 326 0
10 4 10 463 0
10 4 11 487 0
10 4 12 459 0
10 4 13 196 0
10 4 14 332 32
10 5 0 0 92
10 5 1 33 2
10 5 2 312 0
10 5 3 229 0
10 5 4 88 0
10 5 5 139 0
10 5 6 441 0
10 5 7 130 0
10 5 8 424 0
10 5 9 465 0
10 5 10 50 0
10 5 11 475 0
10 5 12 462 0
10 5 13 362 0
10 5 14 339 0
10 5 15 2 56
10 6 1 34 74
10 6 2 467 0
10 6 3 246 0
10 6 4 61 0
10 6 5 138 0
10 6 6 487 0
10 6 7 114 0
10 6 8 292 0
10 6 9 431 0
10 6 10 274 0
10 6 11 515 0
10 6 12 362 0
10 6 13 518 0
10 6 14 408 32
10 7 2 474 64
10 7 3 253 0
10 7 4 130 0
10 7 5 463 0
10 7 6 232 0
10 7 7 145 0
10 7 8 484 0
10 7 9 188 0
10 7 10 312 0
10 7 11 439 0
10 7 12 151 0
10 7 13 64 0
10 7 14 77 32
10 8 1 2 80
10 8 2 503 0
10 8 3 473 0
10 8 4 404 0
10 8 5 356 0
10 8 6 430 0
10 8 7 101 0
10 8 8 334 0
10 8 9 91 0
10 8 10 298 0
10 8 11 467 0
10 8 12 468 0
10 8 13 375 0
10 8 14 50 32
10 9 1 11 64
10 9 2 308 0
10 9 3 86 0
10 9 4 74 0
10 9 5 145 0
10 9 6 87 0
10 9 7 293 0
10 9 8 493 0
10 9 9 151 0
10 9 10 434 0
10 9 11 301 0
10 9 12 329 0
10 9 13 307 0
10 9 14 436 40
10 10 1 571 72
10 10 2 141 0
10 10 3 148 0
10 10 4 100 0
10 10 5 161 0
10 10 6 305 0
10 10 7 79 0
10 10 8 499 0
10 10 9 357 0
10 10 10 249 0
10 10 11 103 0
10 10 12 334 0
10 10 13 340 40
10 11 2 429 64
10 11 3 503 0
10 11 4 313 0
10 11 5 426 0
10 11 6 119 0
10 11 7 528 0
10 11 8 382 0
10 11 9 467 0
10 11 10 208 0
10 11 11 487 0
10 11 12 112 40
10 12 0 2 88
10 12 1 3 24
10 12 2 348 0
10 12 3 117 0
10 12 4 269 0
10 12 5 503 8
10 12 6 467 8
10 12 7 170 8
10 12 8 562 8
10 12 9 449 8
10 12 10 87 8
10 12 11 555 40
10 13 2 28 72
10 13 3 35 0
10 13 4 30 44
10 14 3 13 96
10 15 3 34 108
11 0 5 14 116
11 0 11 15 116
11 1 4 20 84
11 1 5 15 4
11 1 6 19 52
11 1 10 15 84
11 1 11 13 4
11 1 12 12 52
11 2 2 99 80
11 2 3 302 16
11 2 4 129 0
11 2 5 244 0
11 2 6 48 0
11 2 7 491 16
11 2 8 121 16
11 2 9 92 16
11 2 10 494 0
11 2 11 505 0
11 2 12 382 0
11 2 13 57 16
11 2 14 218 48
11 3 0 3 120
11 3 2 150 64
11 3 3 78 0
11 3 4 314 0
11 3 5 96 0
11 3 6 502 0
11 3 7 290 0
11 3 8 61 0
11 3 9 348 0
11 3 10 515 0
11 3 11 166 0
11 3 12 375 0
11 3 13 121 0
11 3 14 429 32
11 4 2 402 64
11 4 3 352 0
11 4 4 469 0
11 4 5 117 0
11 4 6 437 0
11 4 7 361 0
11 4 8 488 0
11 4 9 463 0
11 4 10 487 0
11 4 11 113 0
11 4 12 161 0
11 4 13 302 0
11 4 14 85 32
11 5 0 1 120
11 5 2 496 64
11 5 3 138 0
11 5 4 145 0
11 5 5 189 0
11 5 6 45 0
11 5 7 156 0
11 5 8 76 0
11 5 9 425 0
11 5 10 504 0
11 5 11 208 0
11 5 12 440 0
11 5 13 73 0
11 5 14 464 0
11 5 15 1 58
11 6 2 212 64
11 6 3 403 0
11 6 4 301 0
11 6 5 130 0
11 6 6 521 0
11 6 7 48 0
11 6 8 379 0
11 6 9 150 0
11 6 10 181 0
11 6 11 211 0
11 6 12 58 0
11 6 13 332 0
11 6 14 176 32
11 7 2 245 64
11 7 3 281 0
11 7 4 171 0
11 7 5 323 0
11 7 6 58 0
11 7 7 267 0
11 7 8 518 0
11 7 9 447 0
11 7 10 423 0
11 7 11 136 0
11 7 12 466 0
11 7 13 131 0
11 7 14 57 32
11 8 1 2 80
11 8 2 194 0
11 8 3 468 0
11 8 4 504 0
11 8 5 371 0
11 8 6 488 0
11 8 7 104 0
11 8 8 425 0
11 8 9 245 0
11 8 10 516 0
11 8 11 322 0
11 8 12 122 0
11 8 13 494 0
11 8 14 457 32
11 9 1 1 64
11 9 2 375 0
11 9 3 431 0
11 9 4 503 0
11 9 5 382 0
11 9 6 256 0
11 9 7 54 0
11 9 8 500 0
11 9 9 80 0
11 9 10 484 0
11 9 11 151 0
11 9 12 494 0
11 9 13 425 0
11 9 14 319 40
11 10 1 571 72
11 10 2 99 0
11 10 3 122 0
11 10 4 352 0
11 10 5 91 0
11 10 6 438 0
11 10 7 494 0
11 10 8 71 0
11 10 9 362 0
11 10 10 153 0
11 10 11 151 0
11 10 12 348 0
11 10 13 80 40
11 11 2 324 64
11 11 3 247 0
11 11 4 145 0
11 11 5 176 0
11 11 6 505 0
11 11 7 100 0
11 11 8 302 0
11 11 9 145 0
11 11 10 201 0
11 11 11 86 0
11 11 12 425 40
11 12 0 10 88
11 12 1 8 24
11 12 2 109 0
11 12 3 358 0
11 12 4 423 0
11 12 5 268 0
11 12 6 50 8
11 12 7 188 8
11 12 8 186 8
11 12 9 290 8
11 12 10 50 8
11 12 11 246 40
11 13 2 28 72
11 13 3 30 0
11 13 4 29 0
11 13 5 29 44
11 14 3 16 64
11 14 4 24 44
11 15 3 36 104
12 0 5 21 112
12 0 11 19 112
12 1 4 17 80
12 1 5 23 0
12 1 6 22 48
12 1 10 13 80
12 1 11 15 0
12 1 12 13 48
12 2 2 46 80
12 2 3 293 16
12 2 4 99 0
12 2 5 259 0
12 2 6 465 0
12 2 7 91 16
12 2 8 433 16
12 2 9 145 16
12 2 10 521 0
12 2 11 386 0
12 2 12 487 0
12 2 13 246 16
12 2 14 71 48
12 3 0 2 122
12 3 2 247 64
12 3 3 466 0
12 3 4 303 0
12 3 5 517 0
12 3 6 505 0
12 3 7 464 0
12 3 8 194 0
12 3 9 116 0
12 3 10 85 0
12 3 11 430 0
12 3 12 380 0
12 3 13 246 0
12 3 14 448 32
12 4 2 176 64
12 4 3 401 0
12 4 4 73 0
12 4 5 516 0
12 4 6 353 0
12 4 7 125 0
12 4 8 49 0
12 4 9 328 0
12 4 10 109 0
12 4 11 485 0
12 4 12 198 0
12 4 13 463 0
12 4 14 494 32
12 5 0 9 122
12 5 2 348 64
12 5 3 125 0
12 5 4 117 0
12 5 5 247 0
12 5 6 65 0
12 5 7 426 0
12 5 8 388 0
12 5 9 76 0
12 5 10 364 0
12 5 11 116 0
12 5 12 49 0
12 5 13 48 0
12 5 14 365 32
12 6 2 429 64
12 6 3 187 0
12 6 4 75 0
12 6 5 130 0
12 6 6 256 0
12 6 7 59 0
12 6 8 380 0
12 6 9 363 0
12 6 10 210 0
12 6 11 425 0
12 6 12 194 0
12 6 13 464 0
12 6 14 467 32
12 7 2 195 64
12 7 3 467 0
12 7 4 124 0
12 7 5 188 0
12 7 6 375 0
12 7 7 118 0
12 7 8 115 0
12 7 9 386 0
12 7 10 87 0
12 7 11 342 0
12 7 12 462 0
12 7 13 362 0
12 7 14 461 32
12 8 1 554 82
12 8 2 458 0
12 8 3 288 0
12 8 4 315 0
12 8 5 396 0
12 8 6 103 0
12 8 7 288 0
12 8 8 460 0
12 8 9 337 0
12 8 10 317 0
12 8 11 503 0
12 8 12 134 0
12 8 13 399 0
12 8 14 303 32
12 9 1 571 66
12 9 2 363 0
12 9 3 173 0
12 9 4 463 0
12 9 5 150 0
12 9 6 188 0
12 9 7 426 0
12 9 8 85 0
12 9 9 312 0
12 9 10 522 0
12 9 11 522 0
12 9 12 138 0
12 9 13 45 0
12 9 14 464 40
12 10 1 561 74
12 10 2 342 0
12 10 3 231 0
12 10 4 254 0
12 10 5 377 0
12 10 6 318 0
12 10 7 353 0
12 10 8 213 0
12 10 9 249 0
12 10 10 357 0
12 10 11 521 0
12 10 12 424 0
12 10 13 75 40
12 11 2 445 64
12 11 3 489 0
12 11 4 444 0
12 11 5 162 0
12 11 6 51 0
12 11 7 131 0
12 11 8 317 0
12 11 9 435 0
12 11 10 423 0
12 11 11 83 0
12 11 12 151 40
12 12 0 5 88
12 12 1 2 24
12 12 2 262 0
12 12 3 251 0
12 12 4 187 0
12 12 5 256 0
12 12 6 58 8
12 12 7 117 8
12 12 8 221 8
12 12 9 495 8
12 12 10 427 8
12 12 11 106 40
12 13 2 28 72
12 13 3 27 0
12 13 4 33 0
12 13 5 27 42
12 14 3 14 64
12 14 4 27 42
12 15 3 34 104
13 0 5 15 114
13 0 11 18 114
13 1 4 16 82
13 1 5 20 2
13 1 6 12 50
13 1 10 20 82
13 1 11 19 2
13 1 12 19 50
13 2 2 465 80
13 2 3 431 16
13 2 4 99 0
13 2 5 126 0
13 2 6 435 0
13 2 7 214 16
13 2 8 259 16
13 2 9 99 16
13 2 10 465 0
13 2 11 214 0
13 2 12 509 0
13 2 13 485 16
13 2 14 117 48
13 3 2 482 64
13 3 3 503 0
13 3 4 528 0
13 3 5 211 0
13 3 6 521 0
13 3 7 252 0
13 3 8 181 0
13 3 9 178 0
13 3 10 474 0
13 3 11 499 0
13 3 12 434 0
13 3 13 150 0
13 3 14 119 32
13 4 2 177 64
13 4 3 85 0
13 4 4 292 0
13 4 5 177 0
13 4 6 525 0
13 4 7 59 0
13 4 8 352 0
13 4 9 57 0
13 4 10 373 0
13 4 11 181 0
13 4 12 352 0
13 4 13 466 0
13 4 14 47 32
13 5 2 529 64
13 5 3 77 0
13 5 4 401 0
13 5 5 156 0
13 5 6 425 0
13 5 7 260 0
13 5 8 145 0
13 5 9 54 0
13 5 10 72 0
13 5 11 494 0
13 5 12 493 0
13 5 13 81 0
13 5 14 528 32
13 6 2 246 64
13 6 3 464 0
13 6 4 195 0
13 6 5 324 0
13 6 6 252 0
13 6 7 526 0
13 6 8 314 0
13 6 9 76 0
13 6 10 496 0
13 6 11 145 0
13 6 12 248 0
13 6 13 58 0
13 6 14 463 32
13 7 2 87 64
13 7 3 489 0
13 7 4 410 0
13 7 5 357 0
13 7 6 49 0
13 7 7 194 0
13 7 8 115 0
13 7 9 222 0
13 7 10 121 0
13 7 11 309 0
13 7 12 507 0
13 7 13 244 0
13 7 14 380 32
13 8 2 374 64
13 8 3 68 0
13 8 4 424 0
13 8 5 401 0
13 8 6 526 0
13 8 7 51 0
13 8 8 519 0
13 8 9 182 0
13 8 10 267 0
13 8 11 260 0
13 8 12 81 0
13 8 13 519 0
13 8 14 556 32
13 9 2 138 64
13 9 3 191 0
13 9 4 320 0
13 9 5 370 0
13 9 6 462 0
13 9 7 155 0
13 9 8 77 0
13 9 9 282 0
13 9 10 181 0
13 9 11 212 0
13 9 12 429 0
13 9 13 504 0
13 9 14 558 40
13 10 2 114 64
13 10 3 343 0
13 10 4 170 0
13 10 5 413 0
13 10 6 401 0
13 10 7 187 0
13 10 8 307 0
13 10 9 498 0
13 10 10 100 0
13 10 11 267 0
13 10 12 424 0
13 10 13 564 40
13 11 2 171 64
13 11 3 110 0
13 11 4 468 0
13 11 5 503 0
13 11 6 202 0
13 11 7 236 0
13 11 8 259 0
13 11 9 522 0
13 11 10 427 0
13 11 11 470 0
13 11 12 563 40
13 12 0 1 88
13 12 1 4 24
13 12 2 60 0
13 12 3 458 0
13 12 4 173 0
13 12 5 290 8
13 12 6 181 8
13 12 7 253 8
13 12 8 229 8
13 12 9 256 8
13 12 10 66 8
13 12 11 569 40
13 13 2 28 72
13 13 3 28 0
13 13 4 27 42
13 14 3 13 96
13 15 3 34 106
14 2 2 490 82
14 2 3 512 18
14 2 4 184 18
14 2 5 534 18
14 2 6 264 18
14 2 7 412 18
14 2 8 548 18
14 2 9 240 18
14 2 10 183 18
14 2 11 394 18
14 2 12 192 18
14 2 13 544 18
14 2 14 452 50
14 3 2 350 66
14 3 3 185 2
14 3 4 416 2
14 3 5 343 2
14 3 6 548 2
14 3 7 204 2
14 3 8 175 2
14 3 9 144 2
14 3 10 549 2
14 3 11 449 2
14 3 12 538 2
14 3 13 289 2
14 3 14 508 34
14 4 2 533 66
14 4 3 511 2
14 4 4 511 2
14 4 5 286 2
14 4 6 537 2
14 4 7 542 2
14 4 8 539 2
14 4 9 56 2
14 4 10 84 2
14 4 11 440 2
14 4 12 393 2
14 4 13 529 2
14 4 14 529 34
14 5 2 540 66
14 5 3 149 2
14 5 4 542 2
14 5 5 90 2
14 5 6 346 2
14 5 7 343 2
14 5 8 417 2
14 5 9 535 2
14 5 10 241 2
14 5 11 56 2
14 5 12 507 2
14 5 13 206 2
14 5 14 420 34
14 6 2 511 66
14 6 3 289 2
14 6 4 536 2
14 6 5 546 2
14 6 6 532 2
14 6 7 546 2
14 6 8 546 2
14 6 9 143 2
14 6 10 478 2
14 6 11 343 2
14 6 12 393 2
14 6 13 128 2
14 6 14 418 34
14 7 2 541 66
14 7 3 144 2
14 7 4 265 2
14 7 5 450 2
14 7 6 349 2
14 7 7 128 2
14 7 8 389 2
14 7 9 507 2
14 7 10 569 2
14 7 11 263 2
14 7 12 385 2
14 7 13 55 2
14 7 14 560 34
14 8 2 121 66
14 8 3 203 2
14 8 4 390 2
14 8 5 529 2
14 8 6 565 2
14 8 7 451 2
14 8 8 513 2
14 8 9 558 2
14 8 10 562 2
14 8 11 417 2
14 8 12 230 2
14 8 13 383 2
14 8 14 564 34
14 9 2 391 66
14 9 3 543 2
14 9 4 514 2
14 9 5 558 2
14 9 6 551 2
14 9 7 414 2
14 9 8 545 2
14 9 9 558 2
14 9 10 565 2
14 9 11 204 2
14 9 12 163 2
14 9 13 558 2
14 9 14 558 42
14 10 2 550 66
14 10 3 382 2
14 10 4 568 2
14 10 5 567 2
14 10 6 415 2
14 10 7 263 2
14 10 8 553 2
14 10 9 557 2
14 10 10 242 2
14 10 11 205 2
14 10 12 551 2
14 10 13 563 42
14 11 0 4 86
14 11 1 6 22
14 11 2 477 2
14 11 3 562 2
14 11 4 567 2
14 11 5 107 2
14 11 6 382 2
14 11 7 566 2
14 11 8 555 2
14 11 9 392 2
14 11 10 547 2
14 11 11 560 2
14 11 12 565 42
14 12 0 1 74
14 12 1 1 10
14 12 2 174 2
14 12 3 566 2
14 12 4 556 10
14 12 5 419 10
14 12 6 544 10
14 12 7 562 10
14 12 8 558 10
14 12 9 69 10
14 12 10 343 10
14 12 11 556 42
14 13 2 32 66
14 13 3 38 34
14 14 2 28 78
14 14 3 30 42
