Qubicle Exchange Format
Version 0.2
www.minddesk.com
16 16 16
558
0.325490 0.172549 0.031373
0.325490 0.176471 0.031373
0.329412 0.176471 0.031373
0.333333 0.180392 0.031373
0.337255 0.184314 0.035294
0.341176 0.188235 0.039216
0.341176 0.188235 0.043137
0.341176 0.192157 0.043137
0.345098 0.196078 0.047059
0.349020 0.200000 0.050980
0.352941 0.200000 0.054902
0.352941 0.203922 0.058824
0.419608 0.243137 0.031373
0.423529 0.243137 0.031373
0.423529 0.247059 0.031373
0.427451 0.247059 0.031373
0.431373 0.250980 0.031373
0.435294 0.250980 0.035294
0.435294 0.254902 0.039216
0.439216 0.258824 0.043137
0.439216 0.262745 0.047059
0.443137 0.266667 0.050980
0.447059 0.266667 0.054902
0.447059 0.270588 0.058824
0.529412 0.321569 0.031373
0.529412 0.325490 0.031373
0.533333 0.325490 0.031373
0.533333 0.329412 0.031373
0.537255 0.329412 0.031373
0.541176 0.329412 0.031373
0.545098 0.333333 0.031373
0.545098 0.337255 0.035294
0.549020 0.337255 0.039216
0.549020 0.341176 0.043137
0.549020 0.345098 0.043137
0.549020 0.345098 0.047059
0.552941 0.345098 0.050980
0.552941 0.349020 0.054902
0.556863 0.349020 0.058824
0.705882 0.384314 0.031373
0.709804 0.388235 0.031373
0.717647 0.392157 0.031373
0.721569 0.392157 0.031373
0.725490 0.403922 0.043137
0.733333 0.411765 0.058824
0.772549 0.545098 0.141176
0.776471 0.545098 0.141176
0.776471 0.549020 0.141176
0.780392 0.549020 0.141176
0.784314 0.549020 0.141176
0.784314 0.549020 0.145098
0.784314 0.552941 0.145098
0.788235 0.549020 0.145098
0.788235 0.552941 0.145098
0.788235 0.556863 0.145098
0.788235 0.572549 0.207843
0.792157 0.552941 0.145098
0.792157 0.556863 0.145098
0.792157 0.560784 0.145098
0.796078 0.552941 0.145098
0.796078 0.556863 0.145098
0.796078 0.556863 0.149020
0.796078 0.560784 0.145098
0.796078 0.560784 0.149020
0.796078 0.560784 0.152941
0.796078 0.560784 0.156863
0.796078 0.564706 0.152941
0.796078 0.564706 0.156863
0.796078 0.580392 0.207843
0.800000 0.556863 0.149020
0.800000 0.560784 0.145098
0.800000 0.560784 0.149020
0.800000 0.564706 0.145098
0.800000 0.564706 0.149020
0.800000 0.564706 0.152941
0.800000 0.564706 0.156863
0.800000 0.564706 0.160784
0.800000 0.564706 0.164706
0.800000 0.564706 0.168627
0.800000 0.568627 0.164706
0.800000 0.568627 0.168627
0.800000 0.568627 0.172549
0.800000 0.572549 0.172549
0.800000 0.580392 0.196078
0.803922 0.564706 0.149020
0.803922 0.564706 0.152941
0.803922 0.568627 0.160784
0.803922 0.572549 0.164706
0.803922 0.572549 0.168627
0.803922 0.580392 0.211765
0.807843 0.564706 0.149020
0.807843 0.564706 0.152941
0.807843 0.568627 0.152941
0.807843 0.568627 0.156863
0.811765 0.564706 0.149020
0.811765 0.564706 0.152941
0.811765 0.568627 0.152941
0.811765 0.568627 0.156863
0.811765 0.572549 0.149020
0.811765 0.572549 0.156863
0.811765 0.572549 0.160784
0.811765 0.572549 0.164706
0.811765 0.576471 0.168627
0.811765 0.576471 0.172549
0.811765 0.580392 0.172549
0.811765 0.584314 0.211765
0.815686 0.568627 0.149020
0.815686 0.568627 0.152941
0.815686 0.572549 0.149020
0.815686 0.572549 0.152941
0.815686 0.572549 0.156863
0.815686 0.572549 0.160784
0.815686 0.572549 0.164706
0.815686 0.576471 0.149020
0.815686 0.576471 0.152941
0.815686 0.576471 0.156863
0.815686 0.576471 0.164706
0.815686 0.576471 0.168627
0.815686 0.576471 0.172549
0.815686 0.580392 0.156863
0.815686 0.580392 0.160784
0.815686 0.580392 0.164706
0.815686 0.580392 0.168627
0.815686 0.580392 0.172549
0.815686 0.584314 0.168627
0.815686 0.584314 0.172549
0.815686 0.600000 0.219608
0.819608 0.572549 0.156863
0.819608 0.576471 0.156863
0.819608 0.580392 0.156863
0.819608 0.580392 0.160784
0.819608 0.580392 0.164706
0.819608 0.580392 0.168627
0.819608 0.584314 0.168627
0.819608 0.584314 0.172549
0.823529 0.576471 0.156863
0.823529 0.580392 0.156863
0.823529 0.584314 0.172549
0.823529 0.588235 0.172549
0.823529 0.588235 0.176471
0.823529 0.588235 0.180392
0.823529 0.596078 0.215686
0.823529 0.600000 0.219608
0.827451 0.580392 0.156863
0.827451 0.584314 0.156863
0.827451 0.584314 0.160784
0.827451 0.584314 0.164706
0.827451 0.603922 0.219608
0.831373 0.580392 0.156863
0.831373 0.584314 0.156863
0.831373 0.584314 0.160784
0.831373 0.584314 0.164706
0.831373 0.584314 0.168627
0.831373 0.588235 0.156863
0.831373 0.588235 0.160784
0.831373 0.588235 0.168627
0.831373 0.588235 0.172549
0.831373 0.592157 0.168627
0.831373 0.592157 0.172549
0.831373 0.592157 0.176471
0.831373 0.603922 0.219608
0.835294 0.584314 0.156863
0.835294 0.588235 0.156863
0.835294 0.588235 0.160784
0.835294 0.592157 0.156863
0.835294 0.592157 0.160784
0.835294 0.592157 0.164706
0.835294 0.592157 0.172549
0.835294 0.596078 0.172549
0.835294 0.596078 0.176471
0.835294 0.596078 0.180392
0.835294 0.607843 0.219608
0.835294 0.611765 0.227451
0.839216 0.592157 0.156863
0.839216 0.592157 0.160784
0.839216 0.596078 0.160784
0.839216 0.596078 0.164706
0.839216 0.596078 0.168627
0.839216 0.596078 0.172549
0.839216 0.596078 0.176471
0.839216 0.607843 0.203922
0.839216 0.611765 0.219608
0.839216 0.611765 0.235294
0.843137 0.588235 0.156863
0.843137 0.592157 0.160784
0.843137 0.596078 0.160784
0.843137 0.596078 0.172549
0.843137 0.596078 0.176471
0.843137 0.600000 0.180392
0.843137 0.611765 0.219608
0.847059 0.592157 0.160784
0.847059 0.596078 0.160784
0.847059 0.596078 0.164706
0.847059 0.596078 0.172549
0.847059 0.596078 0.176471
0.847059 0.600000 0.160784
0.847059 0.600000 0.168627
0.847059 0.600000 0.172549
0.847059 0.600000 0.184314
0.847059 0.603922 0.172549
0.847059 0.611765 0.200000
0.847059 0.615686 0.223529
0.847059 0.615686 0.227451
0.847059 0.623529 0.235294
0.850980 0.600000 0.160784
0.850980 0.600000 0.164706
0.850980 0.603922 0.160784
0.850980 0.603922 0.164706
0.850980 0.603922 0.168627
0.850980 0.603922 0.172549
0.850980 0.603922 0.176471
0.850980 0.603922 0.180392
0.850980 0.607843 0.172549
0.850980 0.607843 0.188235
0.854902 0.600000 0.164706
0.854902 0.603922 0.160784
0.854902 0.603922 0.164706
0.854902 0.607843 0.160784
0.854902 0.607843 0.164706
0.854902 0.607843 0.172549
0.854902 0.607843 0.176471
0.854902 0.607843 0.180392
0.854902 0.611765 0.172549
0.854902 0.611765 0.176471
0.854902 0.611765 0.184314
0.854902 0.611765 0.188235
0.854902 0.627451 0.235294
0.858824 0.603922 0.164706
0.858824 0.607843 0.160784
0.858824 0.607843 0.164706
0.858824 0.611765 0.164706
0.858824 0.611765 0.168627
0.858824 0.611765 0.172549
0.858824 0.611765 0.176471
0.858824 0.611765 0.184314
0.858824 0.611765 0.188235
0.858824 0.627451 0.231373
0.858824 0.627451 0.239216
0.858824 0.631373 0.247059
0.862745 0.607843 0.164706
0.862745 0.607843 0.168627
0.862745 0.607843 0.172549
0.862745 0.611765 0.164706
0.862745 0.611765 0.168627
0.862745 0.611765 0.172549
0.862745 0.611765 0.176471
0.862745 0.611765 0.180392
0.862745 0.611765 0.184314
0.862745 0.615686 0.180392
0.862745 0.615686 0.184314
0.862745 0.615686 0.188235
0.862745 0.619608 0.180392
0.862745 0.619608 0.188235
0.862745 0.619608 0.192157
0.862745 0.619608 0.196078
0.862745 0.623529 0.196078
0.862745 0.623529 0.200000
0.862745 0.627451 0.207843
0.862745 0.627451 0.211765
0.862745 0.627451 0.231373
0.862745 0.631373 0.231373
0.866667 0.556863 0.031373
0.866667 0.611765 0.164706
0.866667 0.611765 0.168627
0.866667 0.611765 0.172549
0.866667 0.611765 0.176471
0.866667 0.615686 0.168627
0.866667 0.615686 0.172549
0.866667 0.615686 0.180392
0.866667 0.619608 0.184314
0.866667 0.623529 0.180392
0.866667 0.623529 0.192157
0.866667 0.623529 0.196078
0.866667 0.623529 0.203922
0.866667 0.627451 0.200000
0.866667 0.627451 0.203922
0.866667 0.627451 0.207843
0.866667 0.627451 0.211765
0.866667 0.631373 0.219608
0.866667 0.631373 0.223529
0.866667 0.631373 0.235294
0.866667 0.635294 0.227451
0.866667 0.635294 0.231373
0.866667 0.635294 0.235294
0.870588 0.611765 0.164706
0.870588 0.611765 0.172549
0.870588 0.615686 0.164706
0.870588 0.615686 0.168627
0.870588 0.615686 0.172549
0.870588 0.615686 0.176471
0.870588 0.615686 0.184314
0.870588 0.619608 0.168627
0.870588 0.619608 0.172549
0.870588 0.619608 0.176471
0.870588 0.619608 0.188235
0.870588 0.623529 0.176471
0.870588 0.623529 0.180392
0.870588 0.623529 0.184314
0.870588 0.623529 0.188235
0.870588 0.627451 0.188235
0.870588 0.627451 0.192157
0.870588 0.627451 0.196078
0.870588 0.627451 0.200000
0.870588 0.627451 0.203922
0.870588 0.627451 0.207843
0.870588 0.627451 0.211765
0.870588 0.627451 0.215686
0.870588 0.631373 0.215686
0.870588 0.635294 0.219608
0.870588 0.635294 0.223529
0.870588 0.635294 0.235294
0.870588 0.639216 0.231373
0.870588 0.639216 0.235294
0.870588 0.639216 0.243137
0.870588 0.643137 0.247059
0.874510 0.615686 0.168627
0.874510 0.615686 0.172549
0.874510 0.619608 0.168627
0.874510 0.619608 0.172549
0.874510 0.619608 0.176471
0.874510 0.619608 0.180392
0.874510 0.623529 0.172549
0.874510 0.623529 0.176471
0.874510 0.623529 0.180392
0.874510 0.623529 0.184314
0.874510 0.623529 0.188235
0.874510 0.627451 0.180392
0.874510 0.627451 0.184314
0.874510 0.627451 0.188235
0.874510 0.627451 0.192157
0.874510 0.627451 0.196078
0.874510 0.631373 0.207843
0.874510 0.631373 0.211765
0.874510 0.631373 0.215686
0.874510 0.631373 0.219608
0.874510 0.639216 0.219608
0.874510 0.639216 0.227451
0.874510 0.639216 0.235294
0.874510 0.643137 0.227451
0.874510 0.643137 0.231373
0.874510 0.643137 0.235294
0.874510 0.643137 0.243137
0.874510 0.643137 0.247059
0.874510 0.643137 0.254902
0.878431 0.619608 0.168627
0.878431 0.619608 0.172549
0.878431 0.623529 0.168627
0.878431 0.623529 0.172549
0.878431 0.623529 0.176471
0.878431 0.623529 0.180392
0.878431 0.627451 0.172549
0.878431 0.627451 0.176471
0.878431 0.627451 0.180392
0.878431 0.627451 0.184314
0.878431 0.627451 0.188235
0.878431 0.627451 0.192157
0.878431 0.627451 0.196078
0.878431 0.627451 0.200000
0.878431 0.627451 0.203922
0.878431 0.631373 0.192157
0.878431 0.631373 0.196078
0.878431 0.631373 0.200000
0.878431 0.631373 0.207843
0.878431 0.631373 0.211765
0.878431 0.631373 0.215686
0.878431 0.635294 0.203922
0.878431 0.635294 0.207843
0.878431 0.635294 0.211765
0.878431 0.635294 0.215686
0.878431 0.635294 0.219608
0.878431 0.639216 0.215686
0.878431 0.643137 0.219608
0.878431 0.643137 0.227451
0.878431 0.643137 0.231373
0.878431 0.643137 0.235294
0.878431 0.643137 0.239216
0.878431 0.643137 0.243137
0.878431 0.647059 0.235294
0.878431 0.647059 0.239216
0.878431 0.647059 0.247059
0.878431 0.647059 0.250980
0.878431 0.650980 0.262745
0.878431 0.654902 0.278431
0.878431 0.658824 0.282353
0.878431 0.658824 0.286275
0.878431 0.662745 0.298039
0.882353 0.564706 0.031373
0.882353 0.623529 0.168627
0.882353 0.627451 0.180392
0.882353 0.627451 0.188235
0.882353 0.627451 0.192157
0.882353 0.631373 0.184314
0.882353 0.631373 0.192157
0.882353 0.631373 0.196078
0.882353 0.631373 0.200000
0.882353 0.635294 0.203922
0.882353 0.639216 0.211765
0.882353 0.639216 0.215686
0.882353 0.639216 0.219608
0.882353 0.643137 0.219608
0.882353 0.643137 0.227451
0.882353 0.647059 0.235294
0.882353 0.647059 0.239216
0.882353 0.647059 0.247059
0.882353 0.650980 0.247059
0.882353 0.650980 0.250980
0.882353 0.654902 0.258824
0.882353 0.658824 0.282353
0.882353 0.662745 0.282353
0.882353 0.666667 0.298039
0.882353 0.670588 0.305882
0.886275 0.568627 0.031373
0.886275 0.627451 0.168627
0.886275 0.627451 0.172549
0.886275 0.627451 0.176471
0.886275 0.627451 0.180392
0.886275 0.627451 0.184314
0.886275 0.627451 0.188235
0.886275 0.631373 0.184314
0.886275 0.631373 0.188235
0.886275 0.631373 0.192157
0.886275 0.635294 0.184314
0.886275 0.635294 0.188235
0.886275 0.635294 0.192157
0.886275 0.635294 0.196078
0.886275 0.635294 0.200000
0.886275 0.635294 0.203922
0.886275 0.639216 0.192157
0.886275 0.639216 0.196078
0.886275 0.639216 0.211765
0.886275 0.639216 0.215686
0.886275 0.639216 0.219608
0.886275 0.643137 0.200000
0.886275 0.643137 0.219608
0.886275 0.647059 0.223529
0.886275 0.647059 0.231373
0.886275 0.650980 0.235294
0.886275 0.650980 0.239216
0.886275 0.654902 0.250980
0.886275 0.658824 0.266667
0.886275 0.666667 0.294118
0.890196 0.572549 0.031373
0.890196 0.627451 0.176471
0.890196 0.627451 0.180392
0.890196 0.631373 0.184314
0.890196 0.635294 0.188235
0.890196 0.635294 0.192157
0.890196 0.635294 0.196078
0.890196 0.639216 0.192157
0.890196 0.639216 0.196078
0.890196 0.639216 0.200000
0.890196 0.639216 0.203922
0.890196 0.643137 0.203922
0.890196 0.643137 0.207843
0.890196 0.643137 0.211765
0.890196 0.643137 0.215686
0.890196 0.643137 0.219608
0.890196 0.647059 0.219608
0.890196 0.647059 0.223529
0.890196 0.650980 0.223529
0.890196 0.650980 0.235294
0.890196 0.654902 0.235294
0.890196 0.654902 0.239216
0.890196 0.654902 0.247059
0.890196 0.658824 0.250980
0.890196 0.670588 0.298039
0.890196 0.670588 0.305882
0.894118 0.576471 0.031373
0.894118 0.580392 0.039216
0.894118 0.643137 0.203922
0.894118 0.643137 0.207843
0.894118 0.643137 0.211765
0.894118 0.643137 0.215686
0.894118 0.643137 0.219608
0.894118 0.643137 0.223529
0.894118 0.647059 0.219608
0.894118 0.647059 0.223529
0.894118 0.647059 0.227451
0.894118 0.647059 0.231373
0.894118 0.650980 0.223529
0.894118 0.650980 0.227451
0.894118 0.650980 0.231373
0.894118 0.650980 0.235294
0.894118 0.650980 0.239216
0.894118 0.654902 0.223529
0.894118 0.654902 0.227451
0.894118 0.654902 0.231373
0.894118 0.654902 0.235294
0.894118 0.654902 0.239216
0.894118 0.654902 0.243137
0.894118 0.654902 0.250980
0.894118 0.658824 0.235294
0.894118 0.658824 0.239216
0.894118 0.658824 0.243137
0.894118 0.658824 0.247059
0.894118 0.658824 0.250980
0.894118 0.658824 0.258824
0.894118 0.662745 0.250980
0.894118 0.662745 0.254902
0.894118 0.662745 0.258824
0.894118 0.662745 0.274510
0.894118 0.674510 0.294118
0.894118 0.674510 0.301961
0.898039 0.658824 0.239216
0.898039 0.658824 0.243137
0.898039 0.658824 0.247059
0.898039 0.658824 0.250980
0.898039 0.658824 0.254902
0.898039 0.662745 0.247059
0.898039 0.662745 0.250980
0.898039 0.662745 0.254902
0.898039 0.662745 0.258824
0.898039 0.662745 0.262745
0.898039 0.666667 0.254902
0.898039 0.666667 0.258824
0.898039 0.666667 0.262745
0.898039 0.666667 0.266667
0.898039 0.666667 0.270588
0.898039 0.670588 0.266667
0.898039 0.670588 0.274510
0.898039 0.670588 0.278431
0.898039 0.670588 0.282353
0.901961 0.674510 0.298039
0.901961 0.678431 0.305882
0.905882 0.674510 0.282353
0.905882 0.678431 0.298039
0.905882 0.678431 0.305882
0.909804 0.682353 0.305882
0.909804 0.686275 0.305882
0.909804 0.686275 0.313726
0.909804 0.690196 0.313726
0.909804 0.690196 0.317647
0.909804 0.690196 0.321569
0.909804 0.690196 0.325490
0.909804 0.694118 0.325490
0.909804 0.694118 0.329412
0.909804 0.698039 0.329412
0.937255 0.447059 0.141176
0.941176 0.447059 0.141176
0.941176 0.450980 0.141176
0.941176 0.862745 0.800000
0.945098 0.450980 0.141176
0.949020 0.454902 0.145098
0.952941 0.454902 0.145098
0.956863 0.454902 0.145098
0.956863 0.882353 0.819608
0.960784 0.458824 0.145098
0.960784 0.882353 0.823529
0.964706 0.458824 0.145098
0.964706 0.462745 0.149020
0.964706 0.462745 0.152941
0.964706 0.466667 0.156863
0.964706 0.470588 0.160784
0.964706 0.470588 0.164706
0.964706 0.470588 0.168627
0.964706 0.474510 0.172549
0.964706 0.886275 0.827451
0.968627 0.890196 0.831373
1 3 2 481 84
1 3 3 169 20
1 3 4 196 20
1 3 5 252 20
1 3 6 487 20
1 3 7 272 20
1 3 8 493 20
1 3 9 412 20
1 3 10 306 20
1 3 11 110 20
1 3 12 249 20
1 3 13 405 20
1 3 14 491 52
1 4 2 50 68
1 4 3 374 4
1 4 4 152 4
1 4 5 372 4
1 4 6 487 4
1 4 7 419 4
1 4 8 262 4
1 4 9 458 4
1 4 10 346 4
1 4 11 131 4
1 4 12 419 4
1 4 13 153 4
1 4 14 71 36
1 5 2 169 68
1 5 3 212 4
1 5 4 110 4
1 5 5 495 4
1 5 6 123 4
1 5 7 473 4
1 5 8 101 4
1 5 9 170 4
1 5 10 491 4
1 5 11 483 4
1 5 12 227 4
1 5 13 212 4
1 5 14 355 36
1 6 2 191 68
1 6 3 255 4
1 6 4 317 4
1 6 5 239 4
1 6 6 111 4
1 6 7 185 4
1 6 8 491 4
1 6 9 192 4
1 6 10 127 4
1 6 11 453 4
1 6 12 247 4
1 6 13 74 4
1 6 14 191 36
1 7 2 266 68
1 7 3 293 4
1 7 4 464 4
1 7 5 348 4
1 7 6 223 4
1 7 7 255 4
1 7 8 327 4
1 7 9 254 4
1 7 10 136 4
1 7 11 453 4
1 7 12 149 4
1 7 13 450 4
1 7 14 414 36
1 8 2 214 68
1 8 3 387 4
1 8 4 216 4
1 8 5 398 4
1 8 6 553 4
1 8 7 555 4
1 8 8 476 4
1 8 9 537 4
1 8 10 539 4
1 8 11 453 4
1 8 12 426 4
1 8 13 103 4
1 8 14 552 36
1 9 2 495 68
1 9 3 195 4
1 9 4 454 4
1 9 5 551 4
1 9 6 551 4
1 9 7 506 4
1 9 8 456 4
1 9 9 550 4
1 9 10 544 4
1 9 11 475 4
1 9 12 481 4
1 9 13 541 4
1 9 14 541 44
1 10 2 110 68
1 10 3 208 4
1 10 4 555 4
1 10 5 543 4
1 10 6 503 4
1 10 7 243 4
1 10 8 548 4
1 10 9 546 4
1 10 10 438 4
1 10 11 90 4
1 10 12 552 4
1 10 13 549 44
1 11 0 1 86
1 11 1 2 22
1 11 2 355 4
1 11 3 544 4
1 11 4 549 4
1 11 5 244 4
1 11 6 48 4
1 11 7 542 4
1 11 8 542 4
1 11 9 437 4
1 11 10 120 4
1 11 11 549 4
1 11 12 537 44
1 12 0 1 76
1 12 1 3 12
1 12 2 214 4
1 12 3 551 4
1 12 4 553 12
1 12 5 109 12
1 12 6 204 12
1 12 7 538 12
1 12 8 555 12
1 12 9 476 12
1 12 10 148 12
1 12 11 554 44
1 13 2 26 68
1 13 3 34 36
1 14 2 27 78
1 14 3 26 44
2 0 2 15 92
2 0 3 15 52
2 0 12 14 92
2 0 13 14 52
2 1 3 15 100
2 1 13 14 100
2 2 2 16 84
2 2 3 22 4
2 2 4 13 52
2 2 12 12 84
2 2 13 14 4
2 2 14 20 52
2 3 2 456 64
2 3 3 364 0
2 3 4 423 0
2 3 5 287 16
2 3 6 338 16
2 3 7 167 16
2 3 8 284 16
2 3 9 401 16
2 3 10 110 16
2 3 11 136 16
2 3 12 191 0
2 3 13 100 0
2 3 14 373 32
2 4 2 494 64
2 4 3 397 0
2 4 4 413 0
2 4 5 218 0
2 4 6 494 0
2 4 7 168 0
2 4 8 452 0
2 4 9 84 0
2 4 10 72 0
2 4 11 100 0
2 4 12 76 0
2 4 13 248 0
2 4 14 335 32
2 5 2 340 64
2 5 3 129 0
2 5 4 321 0
2 5 5 115 0
2 5 6 424 0
2 5 7 347 0
2 5 8 492 0
2 5 9 75 0
2 5 10 457 0
2 5 11 123 0
2 5 12 353 0
2 5 13 515 0
2 5 14 329 32
2 6 2 475 64
2 6 3 347 0
2 6 4 480 0
2 6 5 312 0
2 6 6 221 0
2 6 7 69 0
2 6 8 218 0
2 6 9 192 0
2 6 10 173 0
2 6 11 208 0
2 6 12 486 0
2 6 13 454 0
2 6 14 149 32
2 7 2 206 64
2 7 3 399 0
2 7 4 229 0
2 7 5 110 0
2 7 6 45 0
2 7 7 353 0
2 7 8 197 0
2 7 9 473 0
2 7 10 99 0
2 7 11 62 0
2 7 12 457 0
2 7 13 317 0
2 7 14 509 32
2 8 2 317 64
2 8 3 433 0
2 8 4 330 0
2 8 5 293 0
2 8 6 148 0
2 8 7 229 0
2 8 8 491 0
2 8 9 491 0
2 8 10 499 0
2 8 11 271 0
2 8 12 471 0
2 8 13 157 0
2 8 14 548 32
2 9 2 452 64
2 9 3 84 0
2 9 4 136 0
2 9 5 462 0
2 9 6 509 0
2 9 7 191 0
2 9 8 459 0
2 9 9 65 0
2 9 10 135 0
2 9 11 279 0
2 9 12 262 0
2 9 13 433 0
2 9 14 549 40
2 10 2 479 64
2 10 3 492 0
2 10 4 389 0
2 10 5 415 0
2 10 6 239 0
2 10 7 262 0
2 10 8 204 0
2 10 9 487 0
2 10 10 249 0
2 10 11 374 0
2 10 12 294 0
2 10 13 551 40
2 11 2 249 64
2 11 3 482 0
2 11 4 190 0
2 11 5 503 0
2 11 6 464 0
2 11 7 395 0
2 11 8 156 0
2 11 9 191 0
2 11 10 287 0
2 11 11 304 0
2 11 12 543 40
2 12 0 2 88
2 12 1 8 24
2 12 2 214 0
2 12 3 483 0
2 12 4 425 0
2 12 5 344 8
2 12 6 218 8
2 12 7 58 8
2 12 8 445 8
2 12 9 448 8
2 12 10 245 8
2 12 11 552 40
2 13 2 26 72
2 13 3 28 0
2 13 4 29 44
2 14 3 15 96
2 15 3 34 108
3 0 2 19 88
3 0 3 19 48
3 0 12 13 88
3 0 13 13 48
3 1 3 19 96
3 1 13 13 96
3 2 2 23 80
3 2 3 20 0
3 2 4 17 48
3 2 12 13 80
3 2 13 12 0
3 2 14 23 48
3 3 2 399 64
3 3 3 48 0
3 3 4 370 0
3 3 5 129 16
3 3 6 475 16
3 3 7 206 16
3 3 8 317 16
3 3 9 301 16
3 3 10 84 16
3 3 11 136 16
3 3 12 179 0
3 3 13 270 0
3 3 14 62 32
3 4 0 1 124
3 4 2 509 64
3 4 3 419 0
3 4 4 273 0
3 4 5 166 0
3 4 6 245 0
3 4 7 344 0
3 4 8 156 0
3 4 9 495 0
3 4 10 51 0
3 4 11 53 0
3 4 12 359 0
3 4 13 137 0
3 4 14 154 32
3 5 2 223 64
3 5 3 318 0
3 5 4 153 0
3 5 5 354 0
3 5 6 417 0
3 5 7 424 0
3 5 8 239 0
3 5 9 191 0
3 5 10 143 0
3 5 11 464 0
3 5 12 129 0
3 5 13 355 0
3 5 14 368 32
3 6 0 9 124
3 6 2 464 64
3 6 3 455 0
3 6 4 472 0
3 6 5 184 0
3 6 6 452 0
3 6 7 504 0
3 6 8 473 0
3 6 9 161 0
3 6 10 101 0
3 6 11 121 0
3 6 12 456 0
3 6 13 157 0
3 6 14 423 32
3 7 2 452 64
3 7 3 491 0
3 7 4 276 0
3 7 5 191 0
3 7 6 455 0
3 7 7 149 0
3 7 8 66 0
3 7 9 493 0
3 7 10 451 0
3 7 11 143 0
3 7 12 204 0
3 7 13 458 0
3 7 14 344 32
3 8 1 557 84
3 8 2 476 0
3 8 3 495 0
3 8 4 275 0
3 8 5 243 0
3 8 6 401 0
3 8 7 413 0
3 8 8 191 0
3 8 9 317 0
3 8 10 97 0
3 8 11 174 0
3 8 12 420 0
3 8 13 376 0
3 8 14 495 32
3 9 1 557 68
3 9 2 359 0
3 9 3 136 0
3 9 4 229 0
3 9 5 84 0
3 9 6 453 0
3 9 7 511 0
3 9 8 414 0
3 9 9 206 0
3 9 10 340 0
3 9 11 191 0
3 9 12 277 0
3 9 13 118 0
3 9 14 250 40
3 10 1 557 76
3 10 2 416 0
3 10 3 50 0
3 10 4 455 0
3 10 5 125 0
3 10 6 162 0
3 10 7 310 0
3 10 8 139 0
3 10 9 190 0
3 10 10 106 0
3 10 11 245 0
3 10 12 412 0
3 10 13 509 40
3 11 2 278 64
3 11 3 257 0
3 11 4 85 0
3 11 5 191 0
3 11 6 215 0
3 11 7 66 0
3 11 8 191 0
3 11 9 245 0
3 11 10 435 0
3 11 11 264 0
3 11 12 511 40
3 12 0 5 88
3 12 1 2 24
3 12 2 228 0
3 12 3 50 0
3 12 4 262 0
3 12 5 307 0
3 12 6 493 8
3 12 7 185 8
3 12 8 477 8
3 12 9 491 8
3 12 10 453 8
3 12 11 291 40
3 13 2 25 72
3 13 3 25 0
3 13 4 37 0
3 13 5 27 44
3 14 3 15 64
3 14 4 28 44
3 15 3 33 104
4 0 2 18 90
4 0 3 18 50
4 0 12 22 90
4 0 13 22 50
4 1 3 18 98
4 1 13 22 98
4 2 2 23 82
4 2 3 12 2
4 2 4 15 50
4 2 12 14 82
4 2 13 15 2
4 2 14 13 50
4 3 2 340 64
4 3 3 419 0
4 3 4 143 0
4 3 5 110 16
4 3 6 163 16
4 3 7 354 16
4 3 8 495 16
4 3 9 312 16
4 3 10 73 16
4 3 11 46 16
4 3 12 93 0
4 3 13 476 0
4 3 14 336 32
4 4 0 7 120
4 4 2 102 64
4 4 3 185 0
4 4 4 134 0
4 4 5 413 0
4 4 6 60 0
4 4 7 487 0
4 4 8 279 0
4 4 9 371 0
4 4 10 450 0
4 4 11 204 0
4 4 12 352 0
4 4 13 445 0
4 4 14 51 32
4 5 2 106 64
4 5 3 506 0
4 5 4 191 0
4 5 5 412 0
4 5 6 136 0
4 5 7 314 0
4 5 8 492 0
4 5 9 415 0
4 5 10 206 0
4 5 11 494 0
4 5 12 506 0
4 5 13 221 0
4 5 14 519 32
4 6 0 11 120
4 6 2 476 64
4 6 3 391 0
4 6 4 419 0
4 6 5 168 0
4 6 6 50 0
4 6 7 87 0
4 6 8 453 0
4 6 9 84 0
4 6 10 282 0
4 6 11 218 0
4 6 12 46 0
4 6 13 84 0
4 6 14 61 32
4 7 2 219 64
4 7 3 472 0
4 7 4 60 0
4 7 5 246 0
4 7 6 497 0
4 7 7 505 0
4 7 8 393 0
4 7 9 149 0
4 7 10 456 0
4 7 11 93 0
4 7 12 350 0
4 7 13 191 0
4 7 14 222 32
4 8 1 2 80
4 8 2 208 0
4 8 3 67 0
4 8 4 362 0
4 8 5 368 0
4 8 6 294 0
4 8 7 395 0
4 8 8 350 0
4 8 9 243 0
4 8 10 349 0
4 8 11 395 0
4 8 12 495 0
4 8 13 143 0
4 8 14 266 32
4 9 1 11 64
4 9 2 185 0
4 9 3 491 0
4 9 4 264 0
4 9 5 96 0
4 9 6 487 0
4 9 7 242 0
4 9 8 438 0
4 9 9 451 0
4 9 10 97 0
4 9 11 265 0
4 9 12 235 0
4 9 13 156 0
4 9 14 494 40
4 10 1 545 72
4 10 2 287 0
4 10 3 84 0
4 10 4 284 0
4 10 5 415 0
4 10 6 258 0
4 10 7 143 0
4 10 8 100 0
4 10 9 292 0
4 10 10 80 0
4 10 11 265 0
4 10 12 153 0
4 10 13 451 40
4 11 2 482 64
4 11 3 453 0
4 11 4 204 0
4 11 5 482 0
4 11 6 291 0
4 11 7 497 0
4 11 8 476 0
4 11 9 415 0
4 11 10 475 0
4 11 11 81 0
4 11 12 495 40
4 12 0 8 88
4 12 1 10 24
4 12 2 451 0
4 12 3 263 0
4 12 4 246 0
4 12 5 491 0
4 12 6 268 8
4 12 7 187 8
4 12 8 454 8
4 12 9 296 8
4 12 10 267 8
4 12 11 353 40
4 13 2 34 72
4 13 3 28 0
4 13 4 37 0
4 13 5 33 42
4 14 3 23 64
4 14 4 25 42
4 15 3 32 104
5 3 1 35 84
5 3 2 34 16
5 3 3 488 16
5 3 4 452 16
5 3 5 119 16
5 3 6 513 16
5 3 7 450 16
5 3 8 204 16
5 3 9 191 16
5 3 10 332 16
5 3 11 455 16
5 3 12 319 16
5 3 13 477 16
5 3 14 166 48
5 4 0 1 90
5 4 1 33 4
5 4 2 75 0
5 4 3 71 0
5 4 4 396 0
5 4 5 516 0
5 4 6 353 0
5 4 7 503 0
5 4 8 425 0
5 4 9 110 0
5 4 10 351 0
5 4 11 166 0
5 4 12 101 0
5 4 13 289 0
5 4 14 297 32
5 5 1 33 68
5 5 2 474 0
5 5 3 151 0
5 5 4 340 0
5 5 5 471 0
5 5 6 179 0
5 5 7 378 0
5 5 8 335 0
5 5 9 50 0
5 5 10 299 0
5 5 11 86 0
5 5 12 303 0
5 5 13 453 0
5 5 14 359 32
5 6 0 2 90
5 6 1 26 4
5 6 2 207 0
5 6 3 106 0
5 6 4 113 0
5 6 5 62 0
5 6 6 418 0
5 6 7 244 0
5 6 8 388 0
5 6 9 355 0
5 6 10 281 0
5 6 11 173 0
5 6 12 56 0
5 6 13 445 0
5 6 14 493 32
5 7 1 28 68
5 7 2 363 0
5 7 3 218 0
5 7 4 315 0
5 7 5 299 0
5 7 6 346 0
5 7 7 136 0
5 7 8 504 0
5 7 9 191 0
5 7 10 458 0
5 7 11 59 0
5 7 12 344 0
5 7 13 312 0
5 7 14 116 32
5 8 1 2 64
5 8 2 479 0
5 8 3 302 0
5 8 4 254 0
5 8 5 251 0
5 8 6 66 0
5 8 7 516 0
5 8 8 413 0
5 8 9 401 0
5 8 10 473 0
5 8 11 164 0
5 8 12 84 0
5 8 13 516 0
5 8 14 351 32
5 9 1 6 64
5 9 2 346 0
5 9 3 479 0
5 9 4 76 0
5 9 5 438 0
5 9 6 155 0
5 9 7 302 0
5 9 8 374 0
5 9 9 233 0
5 9 10 71 0
5 9 11 419 0
5 9 12 476 0
5 9 13 244 0
5 9 14 457 40
5 10 1 557 72
5 10 2 93 0
5 10 3 123 0
5 10 4 72 0
5 10 5 252 0
5 10 6 276 0
5 10 7 250 0
5 10 8 508 0
5 10 9 195 0
5 10 10 509 0
5 10 11 308 0
5 10 12 514 0
5 10 13 477 40
5 11 2 481 64
5 11 3 185 0
5 11 4 49 0
5 11 5 113 0
5 11 6 451 0
5 11 7 514 0
5 11 8 138 0
5 11 9 292 0
5 11 10 284 0
5 11 11 207 0
5 11 12 339 40
5 12 0 1 88
5 12 1 3 24
5 12 2 477 0
5 12 3 510 0
5 12 4 402 0
5 12 5 473 8
5 12 6 325 8
5 12 7 491 8
5 12 8 542 8
5 12 9 110 8
5 12 10 239 8
5 12 11 544 40
5 13 2 35 72
5 13 3 27 0
5 13 4 29 42
5 14 3 23 96
5 15 3 34 106
6 3 1 31 80
6 3 2 51 16
6 3 3 121 16
6 3 4 353 16
6 3 5 455 16
6 3 6 143 16
6 3 7 403 16
6 3 8 109 16
6 3 9 491 16
6 3 10 451 16
6 3 11 56 16
6 3 12 470 16
6 3 13 123 16
6 3 14 219 48
6 4 1 44 64
6 4 2 435 0
6 4 3 274 0
6 4 4 493 0
6 4 5 455 0
6 4 6 510 0
6 4 7 491 0
6 4 8 146 0
6 4 9 456 0
6 4 10 473 0
6 4 11 513 0
6 4 12 400 0
6 4 13 227 0
6 4 14 481 32
6 5 1 42 64
6 5 2 516 0
6 5 3 418 0
6 5 4 229 0
6 5 5 51 0
6 5 6 125 0
6 5 7 516 0
6 5 8 445 0
6 5 9 504 0
6 5 10 210 0
6 5 11 477 0
6 5 12 134 0
6 5 13 250 0
6 5 14 401 32
6 6 1 40 64
6 6 2 432 0
6 6 3 451 0
6 6 4 169 0
6 6 5 191 0
6 6 6 80 0
6 6 7 495 0
6 6 8 248 0
6 6 9 481 0
6 6 10 136 0
6 6 11 494 0
6 6 12 413 0
6 6 13 91 0
6 6 14 507 32
6 7 1 27 64
6 7 2 143 0
6 7 3 134 0
6 7 4 56 0
6 7 5 489 0
6 7 6 191 0
6 7 7 495 0
6 7 8 493 0
6 7 9 230 0
6 7 10 93 0
6 7 11 110 0
6 7 12 424 0
6 7 13 244 0
6 7 14 215 32
6 8 1 557 66
6 8 2 344 0
6 8 3 377 0
6 8 4 429 0
6 8 5 254 0
6 8 6 106 0
6 8 7 286 0
6 8 8 252 0
6 8 9 215 0
6 8 10 76 0
6 8 11 249 0
6 8 12 319 0
6 8 13 71 0
6 8 14 277 32
6 9 1 540 66
6 9 2 505 0
6 9 3 487 0
6 9 4 511 0
6 9 5 184 0
6 9 6 422 0
6 9 7 176 0
6 9 8 419 0
6 9 9 136 0
6 9 10 487 0
6 9 11 90 0
6 9 12 423 0
6 9 13 234 0
6 9 14 137 40
6 10 1 556 74
6 10 2 310 0
6 10 3 56 0
6 10 4 284 0
6 10 5 287 0
6 10 6 193 0
6 10 7 273 0
6 10 8 327 0
6 10 9 72 0
6 10 10 71 0
6 10 11 509 0
6 10 12 361 0
6 10 13 164 40
6 11 2 419 64
6 11 3 230 0
6 11 4 449 0
6 11 5 469 0
6 11 6 149 0
6 11 7 166 0
6 11 8 120 0
6 11 9 456 0
6 11 10 95 0
6 11 11 288 0
6 11 12 514 40
6 12 0 9 90
6 12 1 1 26
6 12 2 174 0
6 12 3 143 0
6 12 4 490 8
6 12 5 108 8
6 12 6 242 8
6 12 7 539 8
6 12 8 354 8
6 12 9 48 8
6 12 10 553 8
6 12 11 208 40
6 13 2 35 66
6 13 3 27 34
6 14 2 36 78
6 14 3 38 42
7 3 1 33 80
7 3 2 266 16
7 3 3 65 16
7 3 4 209 16
7 3 5 239 16
7 3 6 150 16
7 3 7 400 16
7 3 8 232 16
7 3 9 470 16
7 3 10 130 16
7 3 11 96 16
7 3 12 344 16
7 3 13 396 16
7 3 14 411 48
7 4 1 44 64
7 4 2 262 0
7 4 3 494 0
7 4 4 162 0
7 4 5 113 0
7 4 6 191 0
7 4 7 262 0
7 4 8 149 0
7 4 9 491 0
7 4 10 349 0
7 4 11 451 0
7 4 12 252 0
7 4 13 214 0
7 4 14 386 32
7 5 0 7 84
7 5 1 444 0
7 5 2 509 0
7 5 3 244 0
7 5 4 480 0
7 5 5 88 0
7 5 6 453 0
7 5 7 209 0
7 5 8 258 0
7 5 9 272 0
7 5 10 242 0
7 5 11 417 0
7 5 12 247 0
7 5 13 452 0
7 5 14 467 32
7 6 0 9 76
7 6 1 442 0
7 6 2 436 0
7 6 3 136 0
7 6 4 348 0
7 6 5 191 0
7 6 6 50 0
7 6 7 117 0
7 6 8 149 0
7 6 9 473 0
7 6 10 77 0
7 6 11 191 0
7 6 12 510 0
7 6 13 354 0
7 6 14 261 32
7 7 1 30 72
7 7 2 62 0
7 7 3 416 0
7 7 4 453 0
7 7 5 504 0
7 7 6 469 0
7 7 7 98 0
7 7 8 346 0
7 7 9 425 0
7 7 10 287 0
7 7 11 305 0
7 7 12 100 0
7 7 13 178 0
7 7 14 468 32
7 8 2 450 64
7 8 3 156 0
7 8 4 93 0
7 8 5 233 0
7 8 6 449 0
7 8 7 106 0
7 8 8 433 0
7 8 9 113 0
7 8 10 426 0
7 8 11 346 0
7 8 12 191 0
7 8 13 121 0
7 8 14 386 32
7 9 2 57 64
7 9 3 217 0
7 9 4 178 0
7 9 5 62 0
7 9 6 60 0
7 9 7 388 0
7 9 8 367 0
7 9 9 347 0
7 9 10 427 0
7 9 11 363 0
7 9 12 140 0
7 9 13 495 0
7 9 14 554 8
7 9 15 2 60
7 10 2 476 64
7 10 3 94 0
7 10 4 486 0
7 10 5 148 0
7 10 6 415 0
7 10 7 393 0
7 10 8 248 0
7 10 9 285 0
7 10 10 476 0
7 10 11 301 0
7 10 12 493 0
7 10 13 552 40
7 11 2 58 64
7 11 3 96 0
7 11 4 420 0
7 11 5 123 0
7 11 6 252 0
7 11 7 510 0
7 11 8 220 0
7 11 9 394 0
7 11 10 177 0
7 11 11 460 0
7 11 12 537 40
7 12 2 544 72
7 12 3 554 8
7 12 4 554 8
7 12 5 537 8
7 12 6 539 8
7 12 7 551 8
7 12 8 552 8
7 12 9 542 8
7 12 10 550 8
7 12 11 541 40
8 3 1 36 80
8 3 2 475 16
8 3 3 253 16
8 3 4 84 16
8 3 5 73 16
8 3 6 287 16
8 3 7 425 16
8 3 8 487 16
8 3 9 414 16
8 3 10 300 16
8 3 11 422 16
8 3 12 450 16
8 3 13 340 16
8 3 14 411 48
8 4 1 39 64
8 4 2 424 0
8 4 3 318 0
8 4 4 244 0
8 4 5 53 0
8 4 6 298 0
8 4 7 110 0
8 4 8 433 0
8 4 9 309 0
8 4 10 94 0
8 4 11 149 0
8 4 12 419 0
8 4 13 174 0
8 4 14 467 32
8 5 0 9 82
8 5 1 443 0
8 5 2 115 0
8 5 3 358 0
8 5 4 252 0
8 5 5 352 0
8 5 6 330 0
8 5 7 494 0
8 5 8 510 0
8 5 9 361 0
8 5 10 419 0
8 5 11 487 0
8 5 12 96 0
8 5 13 512 0
8 5 14 468 32
8 6 0 8 74
8 6 1 345 0
8 6 2 344 0
8 6 3 310 0
8 6 4 400 0
8 6 5 312 0
8 6 6 179 0
8 6 7 54 0
8 6 8 52 0
8 6 9 121 0
8 6 10 122 0
8 6 11 271 0
8 6 12 494 0
8 6 13 169 0
8 6 14 467 32
8 7 1 29 72
8 7 2 495 0
8 7 3 73 0
8 7 4 415 0
8 7 5 506 0
8 7 6 112 0
8 7 7 76 0
8 7 8 493 0
8 7 9 473 0
8 7 10 510 0
8 7 11 99 0
8 7 12 412 0
8 7 13 110 0
8 7 14 441 32
8 8 2 374 64
8 8 3 292 0
8 8 4 506 0
8 8 5 328 0
8 8 6 429 0
8 8 7 64 0
8 8 8 372 0
8 8 9 425 0
8 8 10 324 0
8 8 11 471 0
8 8 12 191 0
8 8 13 218 0
8 8 14 467 32
8 9 2 354 64
8 9 3 93 0
8 9 4 482 0
8 9 5 290 0
8 9 6 110 0
8 9 7 149 0
8 9 8 453 0
8 9 9 455 0
8 9 10 487 0
8 9 11 185 0
8 9 12 378 0
8 9 13 286 0
8 9 14 543 8
8 9 15 4 56
8 10 2 159 64
8 10 3 60 0
8 10 4 456 0
8 10 5 174 0
8 10 6 102 0
8 10 7 239 0
8 10 8 354 0
8 10 9 401 0
8 10 10 373 0
8 10 11 511 0
8 10 12 351 0
8 10 13 554 40
8 11 2 92 64
8 11 3 173 0
8 11 4 312 0
8 11 5 425 0
8 11 6 250 0
8 11 7 449 0
8 11 8 229 0
8 11 9 446 0
8 11 10 63 0
8 11 11 56 0
8 11 12 551 40
8 12 2 548 72
8 12 3 543 8
8 12 4 549 8
8 12 5 543 8
8 12 6 549 8
8 12 7 549 8
8 12 8 539 8
8 12 9 538 8
8 12 10 542 8
8 12 11 538 40
9 3 1 34 80
9 3 2 431 16
9 3 3 306 16
9 3 4 145 16
9 3 5 143 16
9 3 6 129 16
9 3 7 208 16
9 3 8 268 16
9 3 9 173 16
9 3 10 231 16
9 3 11 289 16
9 3 12 414 16
9 3 13 96 16
9 3 14 450 48
9 4 1 41 64
9 4 2 361 0
9 4 3 369 0
9 4 4 249 0
9 4 5 472 0
9 4 6 204 0
9 4 7 282 0
9 4 8 165 0
9 4 9 498 0
9 4 10 165 0
9 4 11 244 0
9 4 12 232 0
9 4 13 106 0
9 4 14 169 32
9 5 1 43 64
9 5 2 67 0
9 5 3 518 0
9 5 4 205 0
9 5 5 346 0
9 5 6 136 0
9 5 7 379 0
9 5 8 363 0
9 5 9 65 0
9 5 10 209 0
9 5 11 493 0
9 5 12 213 0
9 5 13 475 0
9 5 14 97 32
9 6 1 39 64
9 6 2 492 0
9 6 3 494 0
9 6 4 328 0
9 6 5 450 0
9 6 6 115 0
9 6 7 184 0
9 6 8 446 0
9 6 9 109 0
9 6 10 143 0
9 6 11 518 0
9 6 12 458 0
9 6 13 341 0
9 6 14 148 0
9 6 15 7 52
9 7 1 36 64
9 7 2 453 0
9 7 3 452 0
9 7 4 426 0
9 7 5 492 0
9 7 6 204 0
9 7 7 494 0
9 7 8 144 0
9 7 9 97 0
9 7 10 313 0
9 7 11 138 0
9 7 12 245 0
9 7 13 90 0
9 7 14 430 0
9 7 15 2 38
9 8 1 557 68
9 8 2 115 0
9 8 3 380 0
9 8 4 456 0
9 8 5 53 0
9 8 6 266 0
9 8 7 351 0
9 8 8 150 0
9 8 9 120 0
9 8 10 84 0
9 8 11 475 0
9 8 12 476 0
9 8 13 195 0
9 8 14 204 0
9 8 15 1 38
9 9 1 557 68
9 9 2 138 0
9 9 3 360 0
9 9 4 396 0
9 9 5 516 0
9 9 6 65 0
9 9 7 60 0
9 9 8 170 0
9 9 9 498 0
9 9 10 379 0
9 9 11 195 0
9 9 12 473 0
9 9 13 84 0
9 9 14 503 8
9 9 15 1 42
9 10 1 556 76
9 10 2 195 0
9 10 3 149 0
9 10 4 498 0
9 10 5 212 0
9 10 6 250 0
9 10 7 452 0
9 10 8 395 0
9 10 9 398 0
9 10 10 264 0
9 10 11 295 0
9 10 12 250 0
9 10 13 346 40
9 11 2 361 64
9 11 3 74 0
9 11 4 455 0
9 11 5 269 0
9 11 6 429 0
9 11 7 349 0
9 11 8 425 0
9 11 9 315 0
9 11 10 58 0
9 11 11 493 0
9 11 12 49 40
9 12 0 1 92
9 12 1 5 28
9 12 2 48 0
9 12 3 246 0
9 12 4 93 8
9 12 5 224 8
9 12 6 487 8
9 12 7 551 8
9 12 8 209 8
9 12 9 140 8
9 12 10 552 8
9 12 11 415 40
9 13 2 31 68
9 13 3 29 36
9 14 2 31 78
9 14 3 27 44
10 3 1 33 82
10 3 2 29 16
10 3 3 475 16
10 3 4 133 16
10 3 5 64 16
10 3 6 299 16
10 3 7 424 16
10 3 8 269 16
10 3 9 63 16
10 3 10 119 16
10 3 11 119 16
10 3 12 331 16
10 3 13 228 16
10 3 14 455 48
10 4 0 8 92
10 4 1 35 2
10 4 2 475 0
10 4 3 472 0
10 4 4 136 0
10 4 5 46 0
10 4 6 69 0
10 4 7 452 0
10 4 8 492 0
10 4 9 456 0
10 4 10 170 0
10 4 11 515 0
10 4 12 352 0
10 4 13 513 0
10 4 14 487 32
10 5 1 26 66
10 5 2 488 0
10 5 3 248 0
10 5 4 471 0
10 5 5 194 0
10 5 6 370 0
10 5 7 485 0
10 5 8 76 0
10 5 9 320 0
10 5 10 451 0
10 5 11 475 0
10 5 12 447 0
10 5 13 193 0
10 5 14 326 32
10 6 0 0 92
10 6 1 33 2
10 6 2 306 0
10 6 3 225 0
10 6 4 87 0
10 6 5 137 0
10 6 6 430 0
10 6 7 128 0
10 6 8 414 0
10 6 9 453 0
10 6 10 50 0
10 6 11 463 0
10 6 12 450 0
10 6 13 354 0
10 6 14 333 0
10 6 15 2 56
10 7 1 34 66
10 7 2 455 0
10 7 3 242 0
10 7 4 60 0
10 7 5 136 0
10 7 6 475 0
10 7 7 112 0
10 7 8 286 0
10 7 9 421 0
10 7 10 268 0
10 7 11 503 0
10 7 12 354 0
10 7 13 506 0
10 7 14 399 32
10 8 1 2 64
10 8 2 491 0
10 8 3 461 0
10 8 4 395 0
10 8 5 348 0
10 8 6 420 0
10 8 7 99 0
10 8 8 328 0
10 8 9 90 0
10 8 10 292 0
10 8 11 455 0
10 8 12 456 0
10 8 13 367 0
10 8 14 50 32
10 9 1 11 64
10 9 2 302 0
10 9 3 85 0
10 9 4 73 0
10 9 5 143 0
10 9 6 86 0
10 9 7 287 0
10 9 8 481 0
10 9 9 149 0
10 9 10 424 0
10 9 11 295 0
10 9 12 323 0
10 9 13 301 0
10 9 14 426 40
10 10 1 557 72
10 10 2 139 0
10 10 3 146 0
10 10 4 98 0
10 10 5 158 0
10 10 6 299 0
10 10 7 78 0
10 10 8 487 0
10 10 9 349 0
10 10 10 245 0
10 10 11 101 0
10 10 12 328 0
10 10 13 334 40
10 11 2 419 64
10 11 3 491 0
10 11 4 307 0
10 11 5 416 0
10 11 6 117 0
10 11 7 516 0
10 11 8 374 0
10 11 9 455 0
10 11 10 205 0
10 11 11 475 0
10 11 12 110 40
10 12 0 2 88
10 12 1 3 24
10 12 2 342 0
10 12 3 115 0
10 12 4 264 0
10 12 5 491 8
10 12 6 455 8
10 12 7 167 8
10 12 8 548 8
10 12 9 438 8
10 12 10 86 8
10 12 11 541 40
10 13 2 28 72
10 13 3 35 0
10 13 4 30 44
10 14 3 13 96
10 15 3 34 108
11 0 2 14 92
11 0 3 14 52
11 0 12 15 92
11 0 13 15 52
11 1 3 14 100
11 1 13 15 100
11 2 2 20 84
11 2 3 15 4
11 2 4 19 52
11 2 12 15 84
11 2 13 13 4
11 2 14 12 52
11 3 2 97 64
11 3 3 296 0
11 3 4 127 0
11 3 5 240 16
11 3 6 48 16
11 3 7 479 16
11 3 8 119 16
11 3 9 91 16
11 3 10 482 16
11 3 11 493 16
11 3 12 374 0
11 3 13 56 0
11 3 14 215 32
11 4 0 3 120
11 4 2 148 64
11 4 3 77 0
11 4 4 308 0
11 4 5 94 0
11 4 6 490 0
11 4 7 284 0
11 4 8 60 0
11 4 9 342 0
11 4 10 503 0
11 4 11 163 0
11 4 12 367 0
11 4 13 119 0
11 4 14 419 32
11 5 2 393 64
11 5 3 344 0
11 5 4 457 0
11 5 5 115 0
11 5 6 427 0
11 5 7 353 0
11 5 8 476 0
11 5 9 451 0
11 5 10 475 0
11 5 11 111 0
11 5 12 158 0
11 5 13 296 0
11 5 14 84 32
11 6 0 1 120
11 6 2 484 64
11 6 3 136 0
11 6 4 143 0
11 6 5 186 0
11 6 6 45 0
11 6 7 154 0
11 6 8 75 0
11 6 9 415 0
11 6 10 492 0
11 6 11 205 0
11 6 12 429 0
11 6 13 72 0
11 6 14 452 0
11 6 15 1 58
11 7 2 209 64
11 7 3 394 0
11 7 4 295 0
11 7 5 128 0
11 7 6 509 0
11 7 7 48 0
11 7 8 371 0
11 7 9 148 0
11 7 10 178 0
11 7 11 208 0
11 7 12 57 0
11 7 13 326 0
11 7 14 173 32
11 8 1 2 80
11 8 2 191 0
11 8 3 456 0
11 8 4 492 0
11 8 5 363 0
11 8 6 476 0
11 8 7 102 0
11 8 8 415 0
11 8 9 241 0
11 8 10 504 0
11 8 11 316 0
11 8 12 120 0
11 8 13 482 0
11 8 14 445 32
11 9 1 1 64
11 9 2 367 0
11 9 3 421 0
11 9 4 491 0
11 9 5 374 0
11 9 6 252 0
11 9 7 54 0
11 9 8 488 0
11 9 9 79 0
11 9 10 472 0
11 9 11 149 0
11 9 12 482 0
11 9 13 415 0
11 9 14 313 40
11 10 1 557 72
11 10 2 97 0
11 10 3 120 0
11 10 4 344 0
11 10 5 90 0
11 10 6 428 0
11 10 7 482 0
11 10 8 70 0
11 10 9 354 0
11 10 10 151 0
11 10 11 149 0
11 10 12 342 0
11 10 13 79 40
11 11 2 318 64
11 11 3 243 0
11 11 4 143 0
11 11 5 173 0
11 11 6 493 0
11 11 7 98 0
11 11 8 296 0
11 11 9 143 0
11 11 10 198 0
11 11 11 85 0
11 11 12 415 40
11 12 0 10 88
11 12 1 8 24
11 12 2 107 0
11 12 3 350 0
11 12 4 413 0
11 12 5 263 0
11 12 6 50 8
11 12 7 185 8
11 12 8 183 8
11 12 9 284 8
11 12 10 50 8
11 12 11 242 40
11 13 2 28 72
11 13 3 30 0
11 13 4 29 0
11 13 5 29 44
11 14 3 16 64
11 14 4 24 44
11 15 3 36 104
12 0 2 21 88
12 0 3 21 48
12 0 12 19 88
12 0 13 19 48
12 1 3 21 96
12 1 13 19 96
12 2 2 17 80
12 2 3 23 0
12 2 4 22 48
12 2 12 13 80
12 2 13 15 0
12 2 14 13 48
12 3 2 46 64
12 3 3 287 0
12 3 4 97 0
12 3 5 255 16
12 3 6 453 16
12 3 7 90 16
12 3 8 423 16
12 3 9 143 16
12 3 10 509 16
12 3 11 377 16
12 3 12 475 0
12 3 13 242 0
12 3 14 70 32
12 4 0 2 122
12 4 2 243 64
12 4 3 454 0
12 4 4 297 0
12 4 5 505 0
12 4 6 493 0
12 4 7 452 0
12 4 8 191 0
12 4 9 114 0
12 4 10 84 0
12 4 11 420 0
12 4 12 372 0
12 4 13 242 0
12 4 14 437 32
12 5 2 173 64
12 5 3 392 0
12 5 4 72 0
12 5 5 504 0
12 5 6 345 0
12 5 7 123 0
12 5 8 49 0
12 5 9 322 0
12 5 10 107 0
12 5 11 473 0
12 5 12 195 0
12 5 13 451 0
12 5 14 482 32
12 6 0 9 122
12 6 2 342 64
12 6 3 123 0
12 6 4 115 0
12 6 5 243 0
12 6 6 64 0
12 6 7 416 0
12 6 8 379 0
12 6 9 75 0
12 6 10 356 0
12 6 11 114 0
12 6 12 49 0
12 6 13 48 0
12 6 14 357 32
12 7 2 419 64
12 7 3 184 0
12 7 4 74 0
12 7 5 128 0
12 7 6 252 0
12 7 7 58 0
12 7 8 372 0
12 7 9 355 0
12 7 10 207 0
12 7 11 415 0
12 7 12 191 0
12 7 13 452 0
12 7 14 455 32
12 8 1 540 82
12 8 2 446 0
12 8 3 282 0
12 8 4 309 0
12 8 5 387 0
12 8 6 101 0
12 8 7 282 0
12 8 8 448 0
12 8 9 331 0
12 8 10 311 0
12 8 11 491 0
12 8 12 132 0
12 8 13 390 0
12 8 14 297 32
12 9 1 557 66
12 9 2 355 0
12 9 3 170 0
12 9 4 451 0
12 9 5 148 0
12 9 6 185 0
12 9 7 416 0
12 9 8 84 0
12 9 9 306 0
12 9 10 510 0
12 9 11 510 0
12 9 12 136 0
12 9 13 45 0
12 9 14 452 40
12 10 1 547 74
12 10 2 336 0
12 10 3 227 0
12 10 4 250 0
12 10 5 369 0
12 10 6 312 0
12 10 7 345 0
12 10 8 210 0
12 10 9 245 0
12 10 10 349 0
12 10 11 509 0
12 10 12 414 0
12 10 13 74 40
12 11 2 434 64
12 11 3 477 0
12 11 4 433 0
12 11 5 159 0
12 11 6 51 0
12 11 7 129 0
12 11 8 311 0
12 11 9 425 0
12 11 10 413 0
12 11 11 82 0
12 11 12 149 40
12 12 0 5 88
12 12 1 2 24
12 12 2 258 0
12 12 3 247 0
12 12 4 184 0
12 12 5 252 0
12 12 6 57 8
12 12 7 115 8
12 12 8 218 8
12 12 9 483 8
12 12 10 417 8
12 12 11 104 40
12 13 2 28 72
12 13 3 27 0
12 13 4 33 0
12 13 5 27 42
12 14 3 14 64
12 14 4 27 42
12 15 3 34 104
13 0 2 15 90
13 0 3 15 50
13 0 12 18 90
13 0 13 18 50
13 1 3 15 98
13 1 13 18 98
13 2 2 16 82
13 2 3 20 2
13 2 4 12 50
13 2 12 20 82
13 2 13 19 2
13 2 14 19 50
13 3 2 453 64
13 3 3 421 0
13 3 4 97 0
13 3 5 124 16
13 3 6 425 16
13 3 7 211 16
13 3 8 255 16
13 3 9 97 16
13 3 10 453 16
13 3 11 211 16
13 3 12 497 0
13 3 13 473 0
13 3 14 115 32
13 4 2 470 64
13 4 3 491 0
13 4 4 516 0
13 4 5 208 0
13 4 6 509 0
13 4 7 248 0
13 4 8 178 0
13 4 9 175 0
13 4 10 462 0
13 4 11 487 0
13 4 12 424 0
13 4 13 148 0
13 4 14 117 32
13 5 2 174 64
13 5 3 84 0
13 5 4 286 0
13 5 5 174 0
13 5 6 513 0
13 5 7 58 0
13 5 8 344 0
13 5 9 56 0
13 5 10 365 0
13 5 11 178 0
13 5 12 344 0
13 5 13 454 0
13 5 14 47 32
13 6 2 517 64
13 6 3 76 0
13 6 4 392 0
13 6 5 154 0
13 6 6 415 0
13 6 7 256 0
13 6 8 143 0
13 6 9 54 0
13 6 10 71 0
13 6 11 482 0
13 6 12 481 0
13 6 13 80 0
13 6 14 516 32
13 7 2 242 64
13 7 3 452 0
13 7 4 192 0
13 7 5 318 0
13 7 6 248 0
13 7 7 514 0
13 7 8 308 0
13 7 9 75 0
13 7 10 484 0
13 7 11 143 0
13 7 12 244 0
13 7 13 57 0
13 7 14 451 32
13 8 2 366 64
13 8 3 67 0
13 8 4 414 0
13 8 5 392 0
13 8 6 514 0
13 8 7 51 0
13 8 8 507 0
13 8 9 179 0
13 8 10 262 0
13 8 11 256 0
13 8 12 80 0
13 8 13 507 0
13 8 14 542 32
13 9 2 136 64
13 9 3 188 0
13 9 4 314 0
13 9 5 362 0
13 9 6 450 0
13 9 7 153 0
13 9 8 76 0
13 9 9 276 0
13 9 10 178 0
13 9 11 209 0
13 9 12 419 0
13 9 13 492 0
13 9 14 544 40
13 10 2 112 64
13 10 3 337 0
13 10 4 167 0
13 10 5 403 0
13 10 6 392 0
13 10 7 184 0
13 10 8 301 0
13 10 9 486 0
13 10 10 98 0
13 10 11 262 0
13 10 12 414 0
13 10 13 550 40
13 11 2 168 64
13 11 3 108 0
13 11 4 456 0
13 11 5 491 0
13 11 6 199 0
13 11 7 232 0
13 11 8 255 0
13 11 9 510 0
13 11 10 417 0
13 11 11 458 0
13 11 12 549 40
13 12 0 1 88
13 12 1 4 24
13 12 2 59 0
13 12 3 446 0
13 12 4 170 0
13 12 5 284 8
13 12 6 178 8
13 12 7 249 8
13 12 8 225 8
13 12 9 252 8
13 12 10 65 8
13 12 11 555 40
13 13 2 28 72
13 13 3 28 0
13 13 4 27 42
13 14 3 13 96
13 15 3 34 106
14 3 2 478 82
14 3 3 500 18
14 3 4 181 18
14 3 5 521 18
14 3 6 260 18
14 3 7 402 18
14 3 8 534 18
14 3 9 236 18
14 3 10 180 18
14 3 11 385 18
14 3 12 189 18
14 3 13 530 18
14 3 14 440 50
14 4 2 343 66
14 4 3 182 2
14 4 4 406 2
14 4 5 337 2
14 4 6 534 2
14 4 7 201 2
14 4 8 172 2
14 4 9 142 2
14 4 10 535 2
14 4 11 438 2
14 4 12 525 2
14 4 13 283 2
14 4 14 496 34
14 5 2 520 66
14 5 3 499 2
14 5 4 499 2
14 5 5 280 2
14 5 6 524 2
14 5 7 528 2
14 5 8 526 2
14 5 9 55 2
14 5 10 83 2
14 5 11 429 2
14 5 12 384 2
14 5 13 517 2
14 5 14 517 34
14 6 2 527 66
14 6 3 147 2
14 6 4 528 2
14 6 5 89 2
14 6 6 340 2
14 6 7 337 2
14 6 8 407 2
14 6 9 522 2
14 6 10 237 2
14 6 11 55 2
14 6 12 495 2
14 6 13 203 2
14 6 14 410 34
14 7 2 499 66
14 7 3 283 2
14 7 4 523 2
14 7 5 532 2
14 7 6 519 2
14 7 7 532 2
14 7 8 532 2
14 7 9 141 2
14 7 10 466 2
14 7 11 337 2
14 7 12 384 2
14 7 13 126 2
14 7 14 408 34
14 8 2 119 66
14 8 3 200 2
14 8 4 381 2
14 8 5 517 2
14 8 6 551 2
14 8 7 439 2
14 8 8 501 2
14 8 9 544 2
14 8 10 548 2
14 8 11 407 2
14 8 12 226 2
14 8 13 375 2
14 8 14 550 34
14 9 2 382 66
14 9 3 529 2
14 9 4 502 2
14 9 5 544 2
14 9 6 537 2
14 9 7 404 2
14 9 8 531 2
14 9 9 544 2
14 9 10 551 2
14 9 11 201 2
14 9 12 160 2
14 9 13 544 2
14 9 14 544 42
14 10 2 536 66
14 10 3 374 2
14 10 4 554 2
14 10 5 553 2
14 10 6 405 2
14 10 7 259 2
14 10 8 539 2
14 10 9 543 2
14 10 10 238 2
14 10 11 202 2
14 10 12 537 2
14 10 13 549 42
14 11 0 4 86
14 11 1 6 22
14 11 2 465 2
14 11 3 548 2
14 11 4 553 2
14 11 5 105 2
14 11 6 374 2
14 11 7 552 2
14 11 8 541 2
14 11 9 383 2
14 11 10 533 2
14 11 11 546 2
14 11 12 551 42
14 12 0 1 74
14 12 1 1 10
14 12 2 171 2
14 12 3 552 2
14 12 4 542 10
14 12 5 409 10
14 12 6 530 10
14 12 7 548 10
14 12 8 544 10
14 12 9 68 10
14 12 10 337 10
14 12 11 542 42
14 13 2 32 66
14 13 3 38 34
14 14 2 28 78
14 14 3 30 42
