Qubicle Exchange Format
Version 0.2
www.minddesk.com
12 16 12
490
0.372549 0.325490 0.294118
0.376471 0.329412 0.294118
0.380392 0.333333 0.298039
0.384314 0.337255 0.301961
0.388235 0.337255 0.301961
0.388235 0.341176 0.301961
0.388235 0.341176 0.305882
0.388235 0.341176 0.309804
0.388235 0.345098 0.309804
0.392157 0.345098 0.305882
0.396078 0.345098 0.305882
0.396078 0.345098 0.309804
0.396078 0.349020 0.313726
0.396078 0.352941 0.313726
0.400000 0.349020 0.313726
0.400000 0.352941 0.313726
0.400000 0.356863 0.317647
0.400000 0.360784 0.321569
0.403922 0.352941 0.313726
0.403922 0.352941 0.317647
0.403922 0.356863 0.321569
0.403922 0.360784 0.325490
0.407843 0.356863 0.317647
0.407843 0.356863 0.325490
0.407843 0.360784 0.321569
0.407843 0.360784 0.325490
0.411765 0.360784 0.325490
0.411765 0.364706 0.325490
0.411765 0.368627 0.329412
0.411765 0.368627 0.333333
0.411765 0.368627 0.337255
0.415686 0.364706 0.325490
0.415686 0.364706 0.329412
0.415686 0.368627 0.329412
0.415686 0.368627 0.333333
0.415686 0.372549 0.333333
0.419608 0.368627 0.329412
0.419608 0.368627 0.333333
0.419608 0.372549 0.333333
0.419608 0.376471 0.337255
0.423529 0.372549 0.333333
0.423529 0.372549 0.337255
0.423529 0.376471 0.337255
0.423529 0.376471 0.341176
0.423529 0.388235 0.349020
0.427451 0.376471 0.341176
0.427451 0.380392 0.341176
0.427451 0.384314 0.349020
0.431373 0.380392 0.341176
0.431373 0.380392 0.345098
0.431373 0.384314 0.345098
0.431373 0.384314 0.349020
0.431373 0.388235 0.349020
0.435294 0.384314 0.345098
0.435294 0.384314 0.349020
0.435294 0.384314 0.352941
0.435294 0.388235 0.349020
0.435294 0.392157 0.352941
0.435294 0.392157 0.356863
0.435294 0.396078 0.356863
0.439216 0.388235 0.349020
0.439216 0.388235 0.352941
0.439216 0.392157 0.352941
0.439216 0.392157 0.356863
0.439216 0.396078 0.356863
0.439216 0.396078 0.360784
0.439216 0.400000 0.364706
0.443137 0.392157 0.352941
0.443137 0.392157 0.356863
0.443137 0.396078 0.356863
0.443137 0.396078 0.360784
0.443137 0.400000 0.360784
0.443137 0.400000 0.364706
0.443137 0.407843 0.368627
0.447059 0.400000 0.360784
0.447059 0.400000 0.364706
0.447059 0.403922 0.364706
0.447059 0.403922 0.368627
0.447059 0.407843 0.368627
0.447059 0.411765 0.376471
0.450980 0.400000 0.360784
0.450980 0.403922 0.364706
0.450980 0.407843 0.368627
0.450980 0.407843 0.372549
0.450980 0.411765 0.372549
0.450980 0.415686 0.376471
0.454902 0.403922 0.364706
0.454902 0.403922 0.372549
0.454902 0.407843 0.368627
0.454902 0.407843 0.372549
0.454902 0.411765 0.372549
0.454902 0.419608 0.384314
0.458824 0.407843 0.368627
0.458824 0.411765 0.372549
0.458824 0.411765 0.376471
0.458824 0.411765 0.380392
0.458824 0.415686 0.376471
0.458824 0.415686 0.380392
0.458824 0.419608 0.380392
0.458824 0.419608 0.384314
0.462745 0.415686 0.376471
0.462745 0.415686 0.380392
0.462745 0.419608 0.380392
0.466667 0.419608 0.380392
0.466667 0.419608 0.384314
0.466667 0.423529 0.388235
0.466667 0.427451 0.388235
0.466667 0.431373 0.396078
0.470588 0.419608 0.384314
0.470588 0.423529 0.384314
0.470588 0.423529 0.388235
0.470588 0.423529 0.392157
0.470588 0.427451 0.388235
0.470588 0.431373 0.396078
0.470588 0.435294 0.396078
0.470588 0.435294 0.400000
0.474510 0.423529 0.388235
0.474510 0.431373 0.392157
0.474510 0.435294 0.396078
0.474510 0.439216 0.400000
0.478431 0.427451 0.392157
0.478431 0.431373 0.392157
0.478431 0.435294 0.400000
0.478431 0.439216 0.400000
0.478431 0.443137 0.403922
0.478431 0.443137 0.407843
0.482353 0.435294 0.400000
0.482353 0.443137 0.403922
0.482353 0.447059 0.407843
0.486275 0.439216 0.403922
0.486275 0.443137 0.403922
0.486275 0.447059 0.407843
0.486275 0.447059 0.411765
0.486275 0.450980 0.411765
0.490196 0.443137 0.407843
0.490196 0.447059 0.411765
0.490196 0.450980 0.415686
0.490196 0.454902 0.415686
0.494118 0.450980 0.415686
0.494118 0.454902 0.415686
0.494118 0.454902 0.419608
0.494118 0.458824 0.419608
0.498039 0.458824 0.419608
0.498039 0.458824 0.423529
0.498039 0.462745 0.423529
0.501961 0.462745 0.423529
0.501961 0.462745 0.427451
0.501961 0.466667 0.427451
0.505882 0.466667 0.427451
0.505882 0.470588 0.431373
0.509804 0.470588 0.431373
0.509804 0.470588 0.435294
0.509804 0.474510 0.435294
0.513726 0.474510 0.435294
0.513726 0.474510 0.439216
0.513726 0.478431 0.439216
0.517647 0.478431 0.443137
0.517647 0.482353 0.443137
0.521569 0.482353 0.447059
0.521569 0.486275 0.447059
0.525490 0.486275 0.450980
0.525490 0.490196 0.450980
0.525490 0.490196 0.454902
0.529412 0.490196 0.454902
0.529412 0.494118 0.458824
0.533333 0.498039 0.458824
0.537255 0.501961 0.462745
0.537255 0.501961 0.466667
0.541176 0.505882 0.466667
0.541176 0.505882 0.470588
0.694118 0.470588 0.074510
0.698039 0.109804 0.074510
0.701961 0.113725 0.074510
0.705882 0.313726 0.074510
0.709804 0.478431 0.074510
0.713726 0.113725 0.074510
0.713726 0.113725 0.078431
0.717647 0.113725 0.078431
0.717647 0.321569 0.078431
0.721569 0.113725 0.074510
0.721569 0.113725 0.078431
0.721569 0.321569 0.078431
0.725490 0.117647 0.078431
0.725490 0.321569 0.078431
0.725490 0.325490 0.078431
0.725490 0.490196 0.074510
0.729412 0.117647 0.078431
0.733333 0.113725 0.078431
0.733333 0.325490 0.078431
0.733333 0.498039 0.078431
0.737255 0.117647 0.078431
0.737255 0.329412 0.078431
0.737255 0.501961 0.078431
0.741176 0.121569 0.086275
0.741176 0.329412 0.078431
0.741176 0.329412 0.082353
0.741176 0.501961 0.078431
0.741176 0.505882 0.078431
0.745098 0.329412 0.082353
0.745098 0.333333 0.078431
0.745098 0.333333 0.082353
0.745098 0.345098 0.101961
0.745098 0.360784 0.125490
0.745098 0.505882 0.078431
0.745098 0.603922 0.188235
0.749020 0.117647 0.078431
0.749020 0.125490 0.090196
0.749020 0.137255 0.101961
0.749020 0.149020 0.109804
0.749020 0.152941 0.113725
0.749020 0.333333 0.082353
0.749020 0.349020 0.105882
0.749020 0.509804 0.078431
0.752941 0.117647 0.078431
0.752941 0.121569 0.082353
0.752941 0.133333 0.098039
0.752941 0.333333 0.078431
0.752941 0.349020 0.105882
0.752941 0.356863 0.117647
0.752941 0.513726 0.078431
0.752941 0.517647 0.098039
0.752941 0.607843 0.192157
0.756863 0.145098 0.109804
0.756863 0.152941 0.117647
0.756863 0.333333 0.078431
0.756863 0.337255 0.078431
0.756863 0.337255 0.082353
0.756863 0.345098 0.101961
0.756863 0.352941 0.105882
0.756863 0.364706 0.121569
0.756863 0.372549 0.129412
0.756863 0.513726 0.086275
0.756863 0.521569 0.105882
0.756863 0.611765 0.192157
0.760784 0.117647 0.078431
0.760784 0.121569 0.082353
0.760784 0.152941 0.117647
0.760784 0.337255 0.082353
0.760784 0.341176 0.082353
0.760784 0.352941 0.105882
0.760784 0.521569 0.105882
0.760784 0.615686 0.192157
0.764706 0.117647 0.082353
0.764706 0.121569 0.082353
0.764706 0.125490 0.086275
0.764706 0.152941 0.117647
0.764706 0.164706 0.129412
0.764706 0.176471 0.141176
0.764706 0.345098 0.082353
0.764706 0.349020 0.094118
0.764706 0.356863 0.105882
0.764706 0.529412 0.101961
0.764706 0.615686 0.192157
0.764706 0.615686 0.196078
0.764706 0.619608 0.192157
0.768627 0.117647 0.078431
0.768627 0.121569 0.082353
0.768627 0.125490 0.090196
0.768627 0.164706 0.125490
0.768627 0.352941 0.101961
0.768627 0.360784 0.109804
0.768627 0.521569 0.082353
0.768627 0.619608 0.196078
0.768627 0.627451 0.196078
0.772549 0.117647 0.078431
0.772549 0.121569 0.082353
0.772549 0.145098 0.105882
0.772549 0.176471 0.141176
0.772549 0.180392 0.145098
0.772549 0.525490 0.090196
0.772549 0.533333 0.117647
0.772549 0.537255 0.129412
0.772549 0.541176 0.133333
0.772549 0.623529 0.192157
0.772549 0.623529 0.196078
0.776471 0.121569 0.082353
0.776471 0.129412 0.094118
0.776471 0.149020 0.109804
0.776471 0.164706 0.125490
0.776471 0.345098 0.082353
0.776471 0.345098 0.086275
0.776471 0.356863 0.101961
0.776471 0.360784 0.109804
0.776471 0.529412 0.082353
0.776471 0.533333 0.094118
0.776471 0.627451 0.196078
0.776471 0.631373 0.200000
0.780392 0.121569 0.082353
0.780392 0.133333 0.094118
0.780392 0.172549 0.133333
0.780392 0.356863 0.094118
0.780392 0.368627 0.117647
0.780392 0.368627 0.121569
0.780392 0.376471 0.133333
0.780392 0.541176 0.109804
0.780392 0.541176 0.113725
0.784314 0.125490 0.086275
0.784314 0.184314 0.149020
0.784314 0.349020 0.082353
0.784314 0.356863 0.098039
0.784314 0.380392 0.129412
0.784314 0.545098 0.121569
0.788235 0.129412 0.090196
0.788235 0.133333 0.094118
0.788235 0.149020 0.113725
0.788235 0.168627 0.129412
0.788235 0.180392 0.145098
0.788235 0.184314 0.149020
0.788235 0.349020 0.082353
0.788235 0.372549 0.117647
0.788235 0.384314 0.137255
0.788235 0.392157 0.149020
0.788235 0.533333 0.086275
0.788235 0.556863 0.137255
0.788235 0.635294 0.196078
0.788235 0.635294 0.200000
0.788235 0.639216 0.200000
0.788235 0.639216 0.203922
0.788235 0.643137 0.203922
0.788235 0.647059 0.227451
0.792157 0.125490 0.086275
0.792157 0.145098 0.105882
0.792157 0.156863 0.117647
0.792157 0.164706 0.125490
0.792157 0.184314 0.149020
0.792157 0.392157 0.141176
0.792157 0.537255 0.086275
0.792157 0.639216 0.200000
0.796078 0.125490 0.086275
0.796078 0.360784 0.090196
0.796078 0.364706 0.094118
0.796078 0.368627 0.113725
0.796078 0.372549 0.117647
0.796078 0.643137 0.200000
0.796078 0.643137 0.203922
0.796078 0.647059 0.215686
0.796078 0.647059 0.223529
0.796078 0.650980 0.227451
0.800000 0.129412 0.090196
0.800000 0.145098 0.105882
0.800000 0.149020 0.109804
0.800000 0.168627 0.129412
0.800000 0.172549 0.133333
0.800000 0.176471 0.137255
0.800000 0.176471 0.141176
0.800000 0.180392 0.145098
0.800000 0.356863 0.090196
0.800000 0.364706 0.098039
0.800000 0.364706 0.101961
0.800000 0.364706 0.105882
0.800000 0.368627 0.109804
0.800000 0.372549 0.109804
0.800000 0.384314 0.133333
0.800000 0.400000 0.152941
0.800000 0.545098 0.090196
0.800000 0.549020 0.109804
0.800000 0.647059 0.200000
0.800000 0.650980 0.219608
0.800000 0.654902 0.239216
0.803922 0.141176 0.101961
0.803922 0.145098 0.105882
0.803922 0.149020 0.109804
0.803922 0.149020 0.113725
0.803922 0.160784 0.121569
0.803922 0.164706 0.125490
0.803922 0.164706 0.129412
0.803922 0.176471 0.137255
0.803922 0.192157 0.152941
0.803922 0.360784 0.090196
0.803922 0.364706 0.101961
0.803922 0.368627 0.101961
0.803922 0.384314 0.125490
0.803922 0.388235 0.133333
0.803922 0.396078 0.145098
0.803922 0.400000 0.152941
0.803922 0.556863 0.113725
0.803922 0.564706 0.145098
0.803922 0.572549 0.152941
0.803922 0.647059 0.203922
0.803922 0.650980 0.200000
0.803922 0.650980 0.215686
0.803922 0.654902 0.223529
0.803922 0.658824 0.231373
0.807843 0.160784 0.125490
0.807843 0.164706 0.125490
0.807843 0.164706 0.129412
0.807843 0.168627 0.129412
0.807843 0.168627 0.133333
0.807843 0.172549 0.137255
0.807843 0.176471 0.137255
0.807843 0.184314 0.149020
0.807843 0.188235 0.152941
0.807843 0.196078 0.160784
0.807843 0.207843 0.168627
0.807843 0.376471 0.113725
0.807843 0.392157 0.141176
0.807843 0.396078 0.149020
0.807843 0.403922 0.156863
0.807843 0.407843 0.160784
0.807843 0.572549 0.145098
0.807843 0.658824 0.207843
0.807843 0.662745 0.227451
0.811765 0.160784 0.125490
0.811765 0.184314 0.145098
0.811765 0.184314 0.149020
0.811765 0.188235 0.152941
0.811765 0.200000 0.164706
0.811765 0.207843 0.172549
0.811765 0.211765 0.176471
0.811765 0.223529 0.184314
0.811765 0.392157 0.133333
0.811765 0.403922 0.156863
0.811765 0.411765 0.168627
0.811765 0.423529 0.184314
0.811765 0.576471 0.164706
0.811765 0.580392 0.164706
0.811765 0.584314 0.176471
0.811765 0.654902 0.207843
0.811765 0.662745 0.227451
0.811765 0.666667 0.247059
0.815686 0.211765 0.176471
0.815686 0.215686 0.176471
0.815686 0.219608 0.184314
0.815686 0.235294 0.200000
0.815686 0.415686 0.172549
0.815686 0.419608 0.176471
0.815686 0.419608 0.180392
0.815686 0.427451 0.188235
0.815686 0.431373 0.196078
0.815686 0.431373 0.200000
0.815686 0.596078 0.200000
0.815686 0.658824 0.207843
0.815686 0.662745 0.227451
0.815686 0.670588 0.250980
0.815686 0.674510 0.258824
0.819608 0.662745 0.203922
0.819608 0.662745 0.207843
0.819608 0.674510 0.235294
0.823529 0.662745 0.211765
0.823529 0.666667 0.207843
0.823529 0.674510 0.243137
0.823529 0.678431 0.250980
0.827451 0.666667 0.211765
0.827451 0.670588 0.219608
0.827451 0.674510 0.235294
0.827451 0.678431 0.239216
0.827451 0.678431 0.243137
0.827451 0.686275 0.254902
0.831373 0.678431 0.235294
0.831373 0.682353 0.239216
0.831373 0.682353 0.250980
0.831373 0.682353 0.254902
0.835294 0.678431 0.219608
0.835294 0.686275 0.247059
0.835294 0.686275 0.258824
0.839216 0.686275 0.243137
0.847059 0.694118 0.239216
0.847059 0.698039 0.262745
0.847059 0.698039 0.266667
0.847059 0.701961 0.266667
0.850980 0.690196 0.219608
0.850980 0.690196 0.223529
0.850980 0.694118 0.231373
0.850980 0.698039 0.247059
0.850980 0.698039 0.250980
0.850980 0.701961 0.254902
0.850980 0.701961 0.274510
0.854902 0.698039 0.243137
0.854902 0.698039 0.250980
0.854902 0.701961 0.250980
0.854902 0.701961 0.254902
0.854902 0.701961 0.258824
0.854902 0.705882 0.262745
0.854902 0.705882 0.266667
0.854902 0.705882 0.278431
0.854902 0.709804 0.266667
0.854902 0.709804 0.270588
0.854902 0.709804 0.278431
0.858824 0.705882 0.258824
0.858824 0.705882 0.262745
0.858824 0.705882 0.266667
0.858824 0.705882 0.270588
0.858824 0.709804 0.274510
0.858824 0.713726 0.294118
0.858824 0.713726 0.298039
0.858824 0.717647 0.301961
0.858824 0.717647 0.309804
0.862745 0.713726 0.274510
0.862745 0.717647 0.294118
0.862745 0.721569 0.313726
1 2 1 75 84
1 2 2 148 20
1 2 3 167 20
1 2 4 35 20
1 2 5 92 20
1 2 6 48 20
1 2 7 76 20
1 2 8 119 20
1 2 9 145 20
1 2 10 25 52
1 3 1 71 68
1 3 2 157 4
1 3 3 87 4
1 3 4 2 4
1 3 5 93 4
1 3 6 90 4
1 3 7 75 4
1 3 8 6 4
1 3 9 163 4
1 3 10 76 36
1 4 1 16 76
1 4 2 145 12
1 4 3 46 14
1 4 4 94 14
1 4 5 117 14
1 4 6 49 14
1 4 7 14 14
1 4 8 46 14
1 4 9 141 12
1 4 10 97 44
1 7 5 265 84
1 7 6 235 52
1 8 4 406 92
1 8 5 370 4
1 8 6 176 4
1 8 7 390 60
1 9 5 420 76
1 9 6 296 44
2 2 1 144 80
2 2 2 150 16
2 2 3 63 16
2 2 4 8 16
2 2 5 11 16
2 2 6 19 16
2 2 7 68 16
2 2 8 108 16
2 2 9 125 16
2 2 10 125 48
2 3 1 152 64
2 3 2 85 0
2 3 3 69 8
2 3 4 39 8
2 3 5 63 8
2 3 6 135 8
2 3 7 56 8
2 3 8 15 8
2 3 9 164 0
2 3 10 115 32
2 4 1 114 72
2 4 2 146 40
2 4 9 162 72
2 4 10 168 40
2 7 4 287 84
2 7 5 264 16
2 7 6 384 16
2 7 7 383 52
2 8 3 339 84
2 8 4 302 0
2 8 5 255 0
2 8 6 387 0
2 8 7 215 0
2 8 8 266 52
2 9 3 216 76
2 9 4 359 12
2 9 5 365 0
2 9 6 302 0
2 9 7 339 12
2 9 8 293 44
2 10 5 328 76
2 10 6 405 44
3 0 3 160 84
3 0 4 128 20
3 0 5 43 20
3 0 6 20 20
3 0 7 125 20
3 0 8 166 52
3 1 3 145 68
3 1 4 75 4
3 1 5 81 4
3 1 6 70 4
3 1 7 50 4
3 1 8 140 36
3 2 1 153 80
3 2 2 127 16
3 2 3 16 0
3 2 4 63 0
3 2 5 29 0
3 2 6 49 0
3 2 7 40 0
3 2 8 93 0
3 2 9 143 16
3 2 10 158 48
3 3 1 167 64
3 3 2 123 0
3 3 3 32 8
3 3 4 80 8
3 3 5 48 8
3 3 6 39 8
3 3 7 15 8
3 3 8 56 8
3 3 9 98 0
3 3 10 147 32
3 4 1 169 72
3 4 2 133 42
3 4 9 139 74
3 4 10 161 40
3 6 3 177 84
3 6 4 388 20
3 6 5 305 20
3 6 6 175 20
3 6 7 179 20
3 6 8 255 52
3 7 3 257 68
3 7 4 254 2
3 7 5 281 0
3 7 6 374 0
3 7 7 439 2
3 7 8 389 36
3 8 2 251 92
3 8 3 468 0
3 8 4 460 0
3 8 5 203 0
3 8 6 326 0
3 8 7 454 0
3 8 8 459 0
3 8 9 220 60
3 9 3 294 64
3 9 4 399 0
3 9 5 180 0
3 9 6 387 0
3 9 7 170 0
3 9 8 295 32
3 10 3 299 76
3 10 4 363 4
3 10 5 223 0
3 10 6 304 0
3 10 7 367 4
3 10 8 238 44
3 11 4 366 76
3 11 5 205 12
3 11 6 237 12
3 11 7 403 44
3 15 4 258 92
3 15 5 392 28
3 15 6 288 28
3 15 7 276 60
4 0 3 144 80
4 0 4 3 16
4 0 5 93 16
4 0 6 81 16
4 0 7 67 16
4 0 8 145 48
4 1 3 23 64
4 1 4 112 0
4 1 5 76 0
4 1 6 122 0
4 1 7 12 0
4 1 8 43 32
4 2 1 144 80
4 2 2 132 16
4 2 3 2 0
4 2 4 40 0
4 2 5 43 0
4 2 6 59 0
4 2 7 70 0
4 2 8 83 0
4 2 9 124 16
4 2 10 113 48
4 3 1 34 64
4 3 2 155 8
4 3 3 27 8
4 3 4 35 8
4 3 5 121 8
4 3 6 13 8
4 3 7 135 8
4 3 8 34 8
4 3 9 165 8
4 3 10 50 32
4 4 1 33 106
4 4 10 56 106
4 5 3 355 84
4 5 4 275 20
4 5 5 404 20
4 5 6 267 20
4 5 7 207 20
4 5 8 284 52
4 6 3 313 64
4 6 4 195 8
4 6 5 397 0
4 6 6 178 0
4 6 7 279 8
4 6 8 272 32
4 7 2 232 84
4 7 3 469 32
4 7 5 375 64
4 7 6 192 32
4 7 8 463 64
4 7 9 185 52
4 8 1 440 92
4 8 2 253 0
4 8 3 442 0
4 8 4 449 16
4 8 5 471 0
4 8 6 448 0
4 8 7 314 16
4 8 8 469 0
4 8 9 337 0
4 8 10 466 60
4 9 2 451 76
4 9 3 356 0
4 9 4 221 0
4 9 5 330 0
4 9 6 191 0
4 9 7 441 0
4 9 8 327 0
4 9 9 274 44
4 10 3 350 72
4 10 4 415 0
4 10 5 264 0
4 10 6 408 0
4 10 7 269 0
4 10 8 184 40
4 11 4 173 64
4 11 5 256 0
4 11 6 258 0
4 11 7 396 32
4 12 4 267 76
4 12 5 198 4
4 12 6 179 4
4 12 7 321 44
4 13 5 235 68
4 13 6 210 36
4 14 4 268 84
4 14 5 237 6
4 14 6 410 6
4 14 7 343 52
4 15 4 297 74
4 15 5 423 10
4 15 6 193 10
4 15 7 289 42
5 0 3 81 80
5 0 4 52 16
5 0 5 91 16
5 0 6 127 16
5 0 7 117 16
5 0 8 27 48
5 1 3 12 64
5 1 4 22 0
5 1 5 31 0
5 1 6 15 0
5 1 7 116 0
5 1 8 25 32
5 2 1 42 80
5 2 2 78 16
5 2 3 7 0
5 2 4 50 0
5 2 5 105 0
5 2 6 95 0
5 2 7 6 0
5 2 8 86 0
5 2 9 118 16
5 2 10 33 48
5 3 1 62 72
5 3 2 142 8
5 3 3 24 0
5 3 4 65 0
5 3 5 22 0
5 3 6 69 0
5 3 7 1 0
5 3 8 106 0
5 3 9 150 8
5 3 10 28 40
5 4 3 391 68
5 4 4 422 4
5 4 5 363 4
5 4 6 222 4
5 4 7 206 4
5 4 8 186 36
5 5 3 381 64
5 5 4 309 0
5 5 5 426 0
5 5 6 413 0
5 5 7 411 0
5 5 8 465 32
5 6 2 251 84
5 6 3 472 0
5 6 4 197 0
5 6 5 301 0
5 6 6 430 0
5 6 7 219 0
5 6 8 438 0
5 6 9 271 52
5 7 1 456 84
5 7 2 252 0
5 7 3 333 0
5 7 4 252 4
5 7 5 417 0
5 7 6 487 0
5 7 7 433 4
5 7 8 431 0
5 7 9 457 0
5 7 10 315 52
5 8 0 489 92
5 8 1 461 0
5 8 2 453 0
5 8 3 455 0
5 8 4 233 0
5 8 5 481 0
5 8 6 401 0
5 8 7 418 0
5 8 8 241 0
5 8 9 478 0
5 8 10 474 0
5 8 11 286 60
5 9 1 437 76
5 9 2 470 0
5 9 3 446 0
5 9 4 400 0
5 9 5 442 0
5 9 6 488 0
5 9 7 316 0
5 9 8 483 0
5 9 9 479 0
5 9 10 445 44
5 10 2 329 76
5 10 3 396 0
5 10 4 291 0
5 10 5 188 0
5 10 6 230 0
5 10 7 248 0
5 10 8 225 0
5 10 9 250 44
5 11 3 259 68
5 11 4 352 0
5 11 5 188 0
5 11 6 369 0
5 11 7 428 0
5 11 8 311 36
5 12 3 348 78
5 12 4 178 8
5 12 5 396 0
5 12 6 349 0
5 12 7 396 8
5 12 8 249 46
5 13 5 307 72
5 13 6 171 40
5 14 4 172 122
5 14 7 409 122
6 0 3 134 80
6 0 4 15 16
6 0 5 142 16
6 0 6 127 16
6 0 7 47 16
6 0 8 80 48
6 1 3 138 64
6 1 4 0 0
6 1 5 24 0
6 1 6 36 0
6 1 7 12 0
6 1 8 96 32
6 2 1 38 80
6 2 2 66 16
6 2 3 21 0
6 2 4 74 0
6 2 5 9 0
6 2 6 51 0
6 2 7 63 0
6 2 8 120 0
6 2 9 44 16
6 2 10 42 48
6 3 1 33 72
6 3 2 145 8
6 3 3 82 0
6 3 4 38 0
6 3 5 4 0
6 3 6 2 0
6 3 7 58 0
6 3 8 1 0
6 3 9 119 8
6 3 10 42 40
6 4 3 359 66
6 4 4 323 2
6 4 5 171 2
6 4 6 190 2
6 4 7 385 2
6 4 8 340 34
6 5 3 486 64
6 5 4 310 0
6 5 5 194 0
6 5 6 371 0
6 5 7 229 0
6 5 8 432 32
6 6 2 189 82
6 6 3 440 0
6 6 4 354 0
6 6 5 283 0
6 6 6 212 0
6 6 7 174 0
6 6 8 334 0
6 6 9 270 50
6 7 1 327 82
6 7 2 273 0
6 7 3 204 0
6 7 4 317 0
6 7 5 485 0
6 7 6 442 0
6 7 7 473 0
6 7 8 456 0
6 7 9 382 0
6 7 10 452 50
6 8 0 462 90
6 8 1 444 0
6 8 2 467 0
6 8 3 439 0
6 8 4 482 0
6 8 5 336 0
6 8 6 315 0
6 8 7 436 0
6 8 8 318 0
6 8 9 357 0
6 8 10 327 0
6 8 11 475 58
6 9 1 450 74
6 9 2 476 0
6 9 3 327 0
6 9 4 319 0
6 9 5 380 0
6 9 6 378 0
6 9 7 480 0
6 9 8 484 0
6 9 9 458 0
6 9 10 358 42
6 10 2 194 74
6 10 3 308 0
6 10 4 371 0
6 10 5 218 0
6 10 6 429 0
6 10 7 347 0
6 10 8 181 0
6 10 9 290 42
6 11 3 373 74
6 11 4 237 0
6 11 5 202 0
6 11 6 238 0
6 11 7 199 0
6 11 8 331 42
6 12 4 366 64
6 12 5 244 0
6 12 6 306 0
6 12 7 213 32
6 13 4 387 78
6 13 5 421 10
6 13 6 368 10
6 13 7 423 46
7 0 3 140 80
7 0 4 54 16
7 0 5 41 16
7 0 6 51 16
7 0 7 108 16
7 0 8 128 48
7 1 3 10 64
7 1 4 64 0
7 1 5 103 0
7 1 6 86 0
7 1 7 17 0
7 1 8 49 32
7 2 1 167 80
7 2 2 114 16
7 2 3 20 0
7 2 4 41 0
7 2 5 32 0
7 2 6 102 0
7 2 7 38 0
7 2 8 62 0
7 2 9 149 16
7 2 10 136 48
7 3 1 38 64
7 3 2 154 8
7 3 3 12 8
7 3 4 130 8
7 3 5 101 8
7 3 6 20 8
7 3 7 63 8
7 3 8 62 8
7 3 9 98 8
7 3 10 16 32
7 4 1 52 108
7 4 10 34 108
7 5 3 283 82
7 5 4 242 18
7 5 5 405 18
7 5 6 247 18
7 5 7 245 18
7 5 8 261 50
7 6 3 196 64
7 6 4 425 0
7 6 5 424 0
7 6 6 353 0
7 6 7 395 0
7 6 8 416 32
7 7 2 376 82
7 7 3 435 0
7 7 4 379 0
7 7 5 220 0
7 7 6 312 0
7 7 7 443 0
7 7 8 419 0
7 7 9 377 50
7 8 1 285 90
7 8 2 447 2
7 8 3 464 0
7 8 4 204 0
7 8 5 379 0
7 8 6 233 0
7 8 7 262 0
7 8 8 477 0
7 8 9 473 2
7 8 10 434 58
7 9 2 263 74
7 9 3 351 0
7 9 4 346 0
7 9 5 196 0
7 9 6 240 0
7 9 7 228 0
7 9 8 239 0
7 9 9 335 42
7 10 3 325 74
7 10 4 183 0
7 10 5 178 0
7 10 6 200 0
7 10 7 227 0
7 10 8 292 42
7 11 4 342 64
7 11 5 341 0
7 11 6 187 0
7 11 7 190 32
7 12 4 361 74
7 12 5 394 10
7 12 6 236 10
7 12 7 407 42
8 0 3 157 82
8 0 4 155 18
8 0 5 105 18
8 0 6 110 18
8 0 7 140 18
8 0 8 136 50
8 1 3 169 66
8 1 4 3 2
8 1 5 40 2
8 1 6 72 2
8 1 7 27 2
8 1 8 128 34
8 2 1 169 80
8 2 2 161 16
8 2 3 45 0
8 2 4 80 0
8 2 5 40 0
8 2 6 126 0
8 2 7 18 0
8 2 8 109 0
8 2 9 84 16
8 2 10 145 48
8 3 1 159 64
8 3 2 73 0
8 3 3 26 8
8 3 4 52 8
8 3 5 53 8
8 3 6 69 8
8 3 7 36 8
8 3 8 77 8
8 3 9 79 0
8 3 10 168 32
8 4 1 153 72
8 4 2 99 44
8 4 9 151 76
8 4 10 137 40
8 6 3 393 82
8 6 4 256 18
8 6 5 280 18
8 6 6 214 18
8 6 7 208 18
8 6 8 362 50
8 7 3 209 66
8 7 4 246 2
8 7 5 282 0
8 7 6 427 0
8 7 7 386 2
8 7 8 324 34
8 8 3 224 66
8 8 4 367 0
8 8 5 414 0
8 8 6 231 0
8 8 7 277 0
8 8 8 412 34
8 9 3 398 74
8 9 4 300 0
8 9 5 372 0
8 9 6 217 0
8 9 7 332 0
8 9 8 199 42
8 10 4 201 66
8 10 5 298 0
8 10 6 211 0
8 10 7 260 34
8 11 4 338 74
8 11 5 322 10
8 11 6 226 10
8 11 7 275 42
9 2 1 156 80
9 2 2 107 16
9 2 3 43 16
9 2 4 47 16
9 2 5 25 16
9 2 6 22 16
9 2 7 57 16
9 2 8 37 16
9 2 9 141 16
9 2 10 160 48
9 3 1 164 64
9 3 2 139 0
9 3 3 31 8
9 3 4 81 8
9 3 5 56 8
9 3 6 60 8
9 3 7 75 8
9 3 8 111 8
9 3 9 142 0
9 3 10 144 32
9 4 1 159 72
9 4 2 107 40
9 4 9 131 72
9 4 10 155 40
9 7 5 345 82
9 7 6 243 50
9 8 4 182 82
9 8 5 303 0
9 8 6 344 0
9 8 7 360 50
9 9 4 385 74
9 9 5 234 0
9 9 6 364 0
9 9 7 289 42
9 10 5 320 74
9 10 6 245 42
10 2 1 69 82
10 2 2 148 18
10 2 3 168 18
10 2 4 50 18
10 2 5 101 18
10 2 6 104 18
10 2 7 129 18
10 2 8 157 18
10 2 9 142 18
10 2 10 46 50
10 3 1 35 66
10 3 2 160 2
10 3 3 30 2
10 3 4 100 2
10 3 5 67 2
10 3 6 56 2
10 3 7 74 2
10 3 8 88 2
10 3 9 114 2
10 3 10 76 34
10 4 1 82 74
10 4 2 163 10
10 4 3 101 14
10 4 4 55 14
10 4 5 61 14
10 4 6 5 14
10 4 7 89 14
10 4 8 16 14
10 4 9 144 10
10 4 10 52 42
10 8 5 256 82
10 8 6 359 50
10 9 5 278 74
10 9 6 402 42
