Qubicle Exchange Format
Version 0.2
www.minddesk.com
16 16 16
661
0.039216 0.133333 0.043137
0.200000 0.298039 0.027451
0.282353 0.215686 0.062745
0.290196 0.439216 0.027451
0.325490 0.254902 0.101961
0.376471 0.564706 0.039216
0.376471 0.568627 0.039216
0.376471 0.572549 0.039216
0.388235 0.588235 0.039216
0.400000 0.603922 0.043137
0.400000 0.603922 0.047059
0.419608 0.647059 0.015686
0.423529 0.615686 0.082353
0.431373 0.658824 0.035294
0.435294 0.627451 0.105882
0.439216 0.662745 0.047059
0.443137 0.698039 0.000000
0.447059 0.698039 0.000000
0.447059 0.701961 0.000000
0.450980 0.705882 0.000000
0.454902 0.670588 0.078431
0.458824 0.713726 0.003922
0.458824 0.717647 0.000000
0.458824 0.717647 0.003922
0.458824 0.721569 0.000000
0.458824 0.721569 0.003922
0.462745 0.713726 0.019608
0.462745 0.717647 0.003922
0.462745 0.717647 0.011765
0.462745 0.717647 0.023529
0.462745 0.721569 0.000000
0.462745 0.721569 0.003922
0.462745 0.725490 0.000000
0.462745 0.725490 0.003922
0.462745 0.729412 0.003922
0.466667 0.725490 0.003922
0.466667 0.729412 0.000000
0.466667 0.729412 0.003922
0.466667 0.733333 0.000000
0.466667 0.737255 0.003922
0.470588 0.729412 0.000000
0.470588 0.733333 0.000000
0.470588 0.733333 0.003922
0.470588 0.737255 0.000000
0.470588 0.737255 0.003922
0.470588 0.741176 0.003922
0.474510 0.737255 0.000000
0.474510 0.737255 0.003922
0.474510 0.741176 0.003922
0.474510 0.745098 0.000000
0.474510 0.745098 0.003922
0.474510 0.749020 0.003922
0.478431 0.729412 0.043137
0.478431 0.741176 0.003922
0.478431 0.745098 0.000000
0.478431 0.745098 0.003922
0.478431 0.749020 0.003922
0.478431 0.752941 0.000000
0.478431 0.752941 0.003922
0.482353 0.733333 0.047059
0.482353 0.749020 0.003922
0.482353 0.749020 0.015686
0.482353 0.752941 0.000000
0.482353 0.752941 0.003922
0.482353 0.752941 0.007843
0.482353 0.756863 0.003922
0.482353 0.760784 0.003922
0.486275 0.749020 0.015686
0.486275 0.752941 0.000000
0.486275 0.752941 0.003922
0.486275 0.752941 0.011765
0.486275 0.752941 0.015686
0.486275 0.756863 0.003922
0.486275 0.760784 0.003922
0.486275 0.764706 0.000000
0.486275 0.764706 0.003922
0.486275 0.768627 0.003922
0.490196 0.745098 0.035294
0.490196 0.745098 0.043137
0.490196 0.749020 0.031373
0.490196 0.756863 0.023529
0.490196 0.756863 0.035294
0.490196 0.760784 0.003922
0.490196 0.760784 0.007843
0.490196 0.764706 0.003922
0.490196 0.768627 0.000000
0.490196 0.768627 0.003922
0.490196 0.772549 0.003922
0.494118 0.745098 0.050980
0.494118 0.756863 0.027451
0.494118 0.764706 0.000000
0.494118 0.764706 0.003922
0.494118 0.768627 0.000000
0.494118 0.768627 0.003922
0.494118 0.772549 0.003922
0.494118 0.772549 0.007843
0.494118 0.776471 0.000000
0.494118 0.776471 0.003922
0.498039 0.741176 0.070588
0.498039 0.749020 0.062745
0.498039 0.752941 0.027451
0.498039 0.756863 0.043137
0.498039 0.760784 0.023529
0.498039 0.760784 0.035294
0.498039 0.768627 0.015686
0.498039 0.768627 0.023529
0.498039 0.772549 0.003922
0.498039 0.772549 0.015686
0.498039 0.776471 0.003922
0.498039 0.776471 0.007843
0.498039 0.776471 0.015686
0.498039 0.780392 0.000000
0.498039 0.780392 0.003922
0.498039 0.780392 0.007843
0.498039 0.784314 0.000000
0.498039 0.784314 0.003922
0.501961 0.752941 0.050980
0.501961 0.752941 0.054902
0.501961 0.756863 0.039216
0.501961 0.756863 0.058824
0.501961 0.768627 0.035294
0.501961 0.772549 0.023529
0.501961 0.776471 0.011765
0.501961 0.776471 0.015686
0.501961 0.776471 0.019608
0.501961 0.776471 0.023529
0.501961 0.780392 0.003922
0.501961 0.780392 0.007843
0.501961 0.780392 0.011765
0.501961 0.780392 0.015686
0.501961 0.780392 0.019608
0.501961 0.784314 0.003922
0.501961 0.784314 0.007843
0.501961 0.784314 0.011765
0.501961 0.788235 0.003922
0.501961 0.792157 0.003922
0.505882 0.756863 0.058824
0.505882 0.760784 0.047059
0.505882 0.760784 0.062745
0.505882 0.764706 0.039216
0.505882 0.768627 0.043137
0.505882 0.772549 0.031373
0.505882 0.776471 0.019608
0.505882 0.776471 0.023529
0.505882 0.776471 0.027451
0.505882 0.776471 0.031373
0.505882 0.776471 0.039216
0.505882 0.780392 0.019608
0.505882 0.780392 0.023529
0.505882 0.780392 0.027451
0.505882 0.784314 0.011765
0.505882 0.784314 0.015686
0.505882 0.784314 0.023529
0.505882 0.788235 0.003922
0.505882 0.788235 0.007843
0.505882 0.788235 0.011765
0.505882 0.788235 0.015686
0.505882 0.792157 0.003922
0.505882 0.792157 0.007843
0.505882 0.796078 0.000000
0.505882 0.796078 0.003922
0.509804 0.756863 0.070588
0.509804 0.776471 0.031373
0.509804 0.776471 0.043137
0.509804 0.776471 0.047059
0.509804 0.780392 0.031373
0.509804 0.780392 0.039216
0.509804 0.780392 0.047059
0.509804 0.784314 0.023529
0.509804 0.784314 0.027451
0.509804 0.784314 0.031373
0.509804 0.788235 0.019608
0.509804 0.788235 0.023529
0.509804 0.788235 0.027451
0.509804 0.792157 0.003922
0.509804 0.792157 0.015686
0.509804 0.792157 0.019608
0.509804 0.796078 0.003922
0.509804 0.796078 0.007843
0.509804 0.796078 0.011765
0.509804 0.796078 0.015686
0.509804 0.800000 0.003922
0.509804 0.803922 0.000000
0.513726 0.764706 0.066667
0.513726 0.772549 0.066667
0.513726 0.776471 0.043137
0.513726 0.780392 0.035294
0.513726 0.780392 0.039216
0.513726 0.780392 0.043137
0.513726 0.780392 0.047059
0.513726 0.780392 0.050980
0.513726 0.780392 0.054902
0.513726 0.784314 0.035294
0.513726 0.784314 0.039216
0.513726 0.788235 0.023529
0.513726 0.788235 0.027451
0.513726 0.788235 0.031373
0.513726 0.788235 0.039216
0.513726 0.792157 0.023529
0.513726 0.792157 0.027451
0.513726 0.796078 0.007843
0.513726 0.796078 0.011765
0.513726 0.796078 0.015686
0.513726 0.796078 0.019608
0.513726 0.796078 0.023529
0.513726 0.800000 0.003922
0.513726 0.800000 0.007843
0.513726 0.800000 0.015686
0.513726 0.803922 0.000000
0.513726 0.803922 0.003922
0.513726 0.803922 0.007843
0.513726 0.807843 0.003922
0.517647 0.772549 0.070588
0.517647 0.776471 0.047059
0.517647 0.780392 0.047059
0.517647 0.780392 0.050980
0.517647 0.780392 0.058824
0.517647 0.780392 0.062745
0.517647 0.784314 0.039216
0.517647 0.784314 0.047059
0.517647 0.784314 0.050980
0.517647 0.784314 0.054902
0.517647 0.792157 0.035294
0.517647 0.792157 0.039216
0.517647 0.796078 0.027451
0.517647 0.796078 0.039216
0.517647 0.800000 0.011765
0.517647 0.800000 0.027451
0.517647 0.800000 0.031373
0.517647 0.803922 0.007843
0.517647 0.803922 0.011765
0.517647 0.807843 0.003922
0.517647 0.807843 0.007843
0.517647 0.811765 0.003922
0.517647 0.811765 0.007843
0.517647 0.815686 0.003922
0.521569 0.772549 0.070588
0.521569 0.780392 0.058824
0.521569 0.780392 0.066667
0.521569 0.784314 0.050980
0.521569 0.784314 0.054902
0.521569 0.784314 0.058824
0.521569 0.784314 0.062745
0.521569 0.788235 0.047059
0.521569 0.788235 0.054902
0.521569 0.788235 0.058824
0.521569 0.792157 0.043137
0.521569 0.792157 0.054902
0.521569 0.796078 0.035294
0.521569 0.796078 0.039216
0.521569 0.796078 0.047059
0.521569 0.800000 0.015686
0.521569 0.800000 0.019608
0.521569 0.800000 0.023529
0.521569 0.800000 0.027451
0.521569 0.800000 0.031373
0.521569 0.800000 0.035294
0.521569 0.800000 0.039216
0.521569 0.803922 0.019608
0.521569 0.803922 0.023529
0.521569 0.803922 0.027451
0.521569 0.803922 0.031373
0.521569 0.807843 0.011765
0.521569 0.807843 0.023529
0.521569 0.807843 0.027451
0.521569 0.811765 0.003922
0.521569 0.811765 0.011765
0.521569 0.811765 0.015686
0.521569 0.811765 0.019608
0.521569 0.815686 0.003922
0.521569 0.815686 0.007843
0.521569 0.819608 0.003922
0.525490 0.780392 0.066667
0.525490 0.780392 0.070588
0.525490 0.780392 0.078431
0.525490 0.784314 0.062745
0.525490 0.784314 0.066667
0.525490 0.784314 0.074510
0.525490 0.788235 0.058824
0.525490 0.788235 0.062745
0.525490 0.788235 0.066667
0.525490 0.792157 0.054902
0.525490 0.792157 0.058824
0.525490 0.792157 0.062745
0.525490 0.796078 0.043137
0.525490 0.796078 0.054902
0.525490 0.800000 0.035294
0.525490 0.800000 0.039216
0.525490 0.800000 0.043137
0.525490 0.803922 0.027451
0.525490 0.803922 0.031373
0.525490 0.803922 0.035294
0.525490 0.803922 0.039216
0.525490 0.803922 0.047059
0.525490 0.807843 0.027451
0.525490 0.807843 0.031373
0.525490 0.811765 0.019608
0.525490 0.811765 0.023529
0.525490 0.811765 0.031373
0.525490 0.815686 0.011765
0.525490 0.815686 0.015686
0.525490 0.819608 0.003922
0.525490 0.819608 0.007843
0.525490 0.823529 0.003922
0.525490 0.827451 0.003922
0.529412 0.784314 0.070588
0.529412 0.784314 0.074510
0.529412 0.788235 0.066667
0.529412 0.788235 0.070588
0.529412 0.788235 0.074510
0.529412 0.792157 0.062745
0.529412 0.792157 0.066667
0.529412 0.792157 0.074510
0.529412 0.796078 0.058824
0.529412 0.796078 0.062745
0.529412 0.800000 0.043137
0.529412 0.800000 0.047059
0.529412 0.800000 0.054902
0.529412 0.800000 0.066667
0.529412 0.803922 0.035294
0.529412 0.803922 0.039216
0.529412 0.803922 0.047059
0.529412 0.803922 0.054902
0.529412 0.807843 0.035294
0.529412 0.807843 0.050980
0.529412 0.811765 0.027451
0.529412 0.811765 0.031373
0.529412 0.815686 0.015686
0.529412 0.815686 0.019608
0.529412 0.815686 0.023529
0.529412 0.815686 0.027451
0.529412 0.815686 0.031373
0.529412 0.819608 0.015686
0.529412 0.823529 0.011765
0.529412 0.823529 0.015686
0.529412 0.827451 0.003922
0.529412 0.827451 0.007843
0.529412 0.831373 0.003922
0.529412 0.831373 0.007843
0.533333 0.784314 0.094118
0.533333 0.796078 0.066667
0.533333 0.796078 0.070588
0.533333 0.796078 0.074510
0.533333 0.796078 0.078431
0.533333 0.800000 0.066667
0.533333 0.800000 0.070588
0.533333 0.803922 0.050980
0.533333 0.803922 0.054902
0.533333 0.803922 0.058824
0.533333 0.803922 0.062745
0.533333 0.803922 0.066667
0.533333 0.807843 0.043137
0.533333 0.807843 0.047059
0.533333 0.807843 0.050980
0.533333 0.807843 0.054902
0.533333 0.807843 0.062745
0.533333 0.811765 0.035294
0.533333 0.811765 0.039216
0.533333 0.811765 0.043137
0.533333 0.811765 0.050980
0.533333 0.815686 0.023529
0.533333 0.815686 0.035294
0.533333 0.815686 0.039216
0.533333 0.819608 0.019608
0.533333 0.819608 0.023529
0.533333 0.819608 0.027451
0.533333 0.819608 0.031373
0.533333 0.823529 0.019608
0.533333 0.823529 0.023529
0.533333 0.827451 0.011765
0.533333 0.827451 0.015686
0.533333 0.827451 0.023529
0.533333 0.831373 0.011765
0.533333 0.831373 0.015686
0.533333 0.831373 0.019608
0.533333 0.835294 0.003922
0.533333 0.835294 0.007843
0.533333 0.835294 0.011765
0.537255 0.792157 0.086275
0.537255 0.800000 0.066667
0.537255 0.800000 0.070588
0.537255 0.800000 0.074510
0.537255 0.800000 0.078431
0.537255 0.800000 0.086275
0.537255 0.800000 0.090196
0.537255 0.803922 0.058824
0.537255 0.803922 0.066667
0.537255 0.803922 0.070588
0.537255 0.803922 0.078431
0.537255 0.807843 0.050980
0.537255 0.807843 0.066667
0.537255 0.807843 0.070588
0.537255 0.811765 0.047059
0.537255 0.811765 0.050980
0.537255 0.811765 0.054902
0.537255 0.815686 0.039216
0.537255 0.815686 0.043137
0.537255 0.815686 0.047059
0.537255 0.815686 0.058824
0.537255 0.819608 0.035294
0.537255 0.819608 0.039216
0.537255 0.819608 0.043137
0.537255 0.819608 0.047059
0.537255 0.823529 0.027451
0.537255 0.823529 0.031373
0.537255 0.827451 0.019608
0.537255 0.827451 0.023529
0.537255 0.827451 0.027451
0.537255 0.827451 0.031373
0.537255 0.831373 0.019608
0.537255 0.831373 0.023529
0.537255 0.835294 0.011765
0.537255 0.835294 0.015686
0.537255 0.835294 0.019608
0.541176 0.803922 0.074510
0.541176 0.803922 0.078431
0.541176 0.807843 0.058824
0.541176 0.807843 0.066667
0.541176 0.807843 0.070588
0.541176 0.807843 0.074510
0.541176 0.807843 0.078431
0.541176 0.811765 0.058824
0.541176 0.811765 0.062745
0.541176 0.811765 0.066667
0.541176 0.815686 0.050980
0.541176 0.819608 0.039216
0.541176 0.819608 0.043137
0.541176 0.819608 0.054902
0.541176 0.823529 0.039216
0.541176 0.823529 0.047059
0.541176 0.823529 0.050980
0.541176 0.827451 0.031373
0.541176 0.827451 0.035294
0.541176 0.827451 0.039216
0.541176 0.831373 0.023529
0.541176 0.831373 0.027451
0.541176 0.831373 0.031373
0.541176 0.835294 0.019608
0.541176 0.835294 0.023529
0.541176 0.835294 0.027451
0.541176 0.835294 0.031373
0.541176 0.843137 0.011765
0.545098 0.796078 0.109804
0.545098 0.800000 0.105882
0.545098 0.807843 0.074510
0.545098 0.807843 0.078431
0.545098 0.811765 0.066667
0.545098 0.811765 0.070588
0.545098 0.811765 0.074510
0.545098 0.811765 0.078431
0.545098 0.815686 0.062745
0.545098 0.815686 0.066667
0.545098 0.815686 0.070588
0.545098 0.815686 0.074510
0.545098 0.819608 0.058824
0.545098 0.819608 0.062745
0.545098 0.819608 0.066667
0.545098 0.823529 0.043137
0.545098 0.823529 0.047059
0.545098 0.823529 0.054902
0.545098 0.823529 0.058824
0.545098 0.827451 0.043137
0.545098 0.827451 0.050980
0.545098 0.831373 0.035294
0.545098 0.831373 0.039216
0.545098 0.831373 0.047059
0.545098 0.831373 0.050980
0.545098 0.835294 0.027451
0.545098 0.835294 0.031373
0.545098 0.835294 0.035294
0.545098 0.835294 0.039216
0.545098 0.835294 0.043137
0.545098 0.839216 0.027451
0.545098 0.839216 0.031373
0.545098 0.839216 0.035294
0.549020 0.792157 0.117647
0.549020 0.796078 0.105882
0.549020 0.811765 0.078431
0.549020 0.815686 0.074510
0.549020 0.815686 0.078431
0.549020 0.819608 0.066667
0.549020 0.819608 0.070588
0.549020 0.819608 0.074510
0.549020 0.819608 0.078431
0.549020 0.823529 0.058824
0.549020 0.823529 0.062745
0.549020 0.823529 0.066667
0.549020 0.823529 0.070588
0.549020 0.827451 0.047059
0.549020 0.827451 0.050980
0.549020 0.827451 0.054902
0.549020 0.831373 0.043137
0.549020 0.831373 0.047059
0.549020 0.831373 0.050980
0.549020 0.831373 0.054902
0.549020 0.831373 0.058824
0.549020 0.835294 0.035294
0.549020 0.835294 0.039216
0.549020 0.835294 0.043137
0.549020 0.835294 0.047059
0.549020 0.835294 0.050980
0.549020 0.839216 0.035294
0.549020 0.839216 0.039216
0.549020 0.839216 0.043137
0.549020 0.839216 0.047059
0.552941 0.811765 0.090196
0.552941 0.811765 0.098039
0.552941 0.819608 0.082353
0.552941 0.823529 0.070588
0.552941 0.823529 0.074510
0.552941 0.823529 0.078431
0.552941 0.827451 0.054902
0.552941 0.827451 0.062745
0.552941 0.827451 0.066667
0.552941 0.827451 0.070588
0.552941 0.827451 0.074510
0.552941 0.831373 0.058824
0.552941 0.831373 0.066667
0.552941 0.835294 0.054902
0.552941 0.835294 0.058824
0.552941 0.839216 0.043137
0.552941 0.839216 0.047059
0.552941 0.839216 0.050980
0.552941 0.839216 0.054902
0.552941 0.839216 0.058824
0.552941 0.843137 0.050980
0.552941 0.843137 0.054902
0.556863 0.800000 0.133333
0.556863 0.827451 0.078431
0.556863 0.831373 0.074510
0.556863 0.835294 0.062745
0.556863 0.835294 0.066667
0.556863 0.835294 0.074510
0.556863 0.839216 0.050980
0.556863 0.839216 0.054902
0.556863 0.839216 0.058824
0.556863 0.839216 0.062745
0.556863 0.839216 0.066667
0.556863 0.843137 0.054902
0.556863 0.843137 0.058824
0.556863 0.843137 0.062745
0.560784 0.803922 0.133333
0.560784 0.815686 0.105882
0.560784 0.819608 0.113725
0.560784 0.823529 0.105882
0.560784 0.827451 0.098039
0.560784 0.835294 0.070588
0.560784 0.835294 0.074510
0.560784 0.835294 0.078431
0.560784 0.839216 0.058824
0.560784 0.839216 0.062745
0.560784 0.839216 0.066667
0.560784 0.839216 0.070588
0.560784 0.839216 0.074510
0.560784 0.839216 0.078431
0.560784 0.843137 0.062745
0.560784 0.843137 0.066667
0.560784 0.843137 0.070588
0.560784 0.843137 0.074510
0.564706 0.815686 0.121569
0.564706 0.839216 0.078431
0.564706 0.839216 0.082353
0.564706 0.839216 0.086275
0.564706 0.839216 0.090196
0.564706 0.843137 0.066667
0.564706 0.843137 0.070588
0.564706 0.843137 0.074510
0.564706 0.843137 0.078431
0.564706 0.847059 0.074510
0.564706 0.847059 0.078431
0.564706 0.847059 0.082353
0.568627 0.823529 0.117647
0.568627 0.835294 0.105882
0.568627 0.839216 0.086275
0.568627 0.843137 0.078431
0.568627 0.843137 0.082353
0.568627 0.843137 0.086275
0.568627 0.847059 0.078431
0.568627 0.847059 0.082353
0.568627 0.847059 0.086275
0.568627 0.847059 0.090196
0.572549 0.835294 0.113725
0.572549 0.843137 0.086275
0.572549 0.843137 0.090196
0.572549 0.843137 0.094118
0.572549 0.847059 0.086275
0.572549 0.847059 0.090196
0.572549 0.847059 0.094118
0.572549 0.847059 0.098039
0.576471 0.839216 0.117647
0.576471 0.843137 0.098039
0.576471 0.847059 0.094118
0.576471 0.847059 0.098039
0.576471 0.847059 0.101961
0.576471 0.847059 0.105882
0.576471 0.847059 0.109804
0.576471 0.850980 0.101961
0.576471 0.850980 0.105882
0.580392 0.843137 0.109804
0.580392 0.843137 0.113725
0.580392 0.847059 0.105882
0.580392 0.847059 0.109804
0.580392 0.847059 0.113725
0.580392 0.850980 0.105882
0.580392 0.850980 0.109804
0.580392 0.850980 0.113725
0.584314 0.843137 0.117647
0.584314 0.847059 0.113725
0.584314 0.847059 0.117647
0.584314 0.847059 0.125490
0.584314 0.850980 0.113725
0.584314 0.850980 0.117647
0.584314 0.850980 0.121569
0.584314 0.854902 0.121569
0.588235 0.847059 0.125490
0.588235 0.850980 0.117647
0.588235 0.850980 0.121569
0.588235 0.850980 0.125490
0.588235 0.850980 0.129412
0.588235 0.850980 0.137255
0.588235 0.854902 0.125490
0.592157 0.850980 0.129412
0.592157 0.850980 0.133333
0.592157 0.850980 0.137255
0.592157 0.850980 0.141176
0.592157 0.854902 0.129412
0.592157 0.854902 0.133333
0.592157 0.854902 0.137255
0.596078 0.850980 0.141176
0.596078 0.854902 0.141176
0.596078 0.854902 0.145098
0.600000 0.850980 0.156863
0.600000 0.850980 0.160784
0.600000 0.854902 0.145098
0.600000 0.854902 0.149020
0.603922 0.854902 0.164706
0.607843 0.850980 0.172549
0.607843 0.854902 0.168627
0.607843 0.854902 0.172549
0.678431 0.294118 0.074510
0.737255 0.333333 0.101961
0.745098 0.023529 0.023529
0.819608 0.352941 0.086275
0.854902 0.368627 0.090196
0.858824 0.368627 0.090196
0.870588 0.376471 0.090196
0.890196 0.094118 0.094118
0.890196 0.403922 0.125490
0.890196 0.411765 0.137255
0.890196 0.619608 0.094118
0.894118 0.427451 0.160784
0.901961 0.901961 0.901961
0.917647 0.917647 0.917647
0.921569 0.921569 0.921569
0.925490 0.925490 0.925490
0.937255 0.937255 0.937255
0.960784 0.960784 0.960784
0.964706 0.964706 0.964706
0.968627 0.968627 0.968627
0.988235 0.988235 0.988235
0.992157 0.992157 0.992157
0 5 7 3 126
0 6 7 3 126
0 7 7 9 116
0 8 6 8 84
0 8 7 10 4
0 8 8 5 52
0 9 5 8 92
0 9 6 12 12
0 9 7 7 12
0 9 8 6 12
0 9 9 14 60
1 0 3 3 124
1 0 11 3 124
1 2 0 3 84
1 2 1 3 20
1 2 2 3 20
1 2 3 3 20
1 2 4 3 20
1 2 5 3 20
1 2 6 3 20
1 2 7 3 20
1 2 8 3 20
1 2 9 3 20
1 2 10 3 20
1 2 11 3 20
1 2 12 3 20
1 2 13 3 20
1 2 14 3 52
1 3 0 3 68
1 3 1 3 4
1 3 2 3 4
1 3 3 3 4
1 3 4 3 4
1 3 5 3 4
1 3 6 3 4
1 3 7 3 4
1 3 8 3 4
1 3 9 3 4
1 3 10 3 4
1 3 11 3 4
1 3 12 3 4
1 3 13 3 4
1 3 14 3 36
1 4 0 3 68
1 4 1 9 4
1 4 2 9 4
1 4 3 9 4
1 4 4 9 4
1 4 5 9 4
1 4 6 9 4
1 4 7 9 4
1 4 8 9 4
1 4 9 9 4
1 4 10 9 4
1 4 11 9 4
1 4 12 9 4
1 4 13 9 4
1 4 14 3 36
1 5 0 240 68
1 5 1 112 4
1 5 2 585 4
1 5 3 349 4
1 5 4 469 4
1 5 5 131 4
1 5 6 170 4
1 5 7 394 4
1 5 8 282 4
1 5 9 620 4
1 5 10 93 4
1 5 11 248 4
1 5 12 616 4
1 5 13 289 4
1 5 14 63 36
1 6 0 519 68
1 6 1 565 4
1 6 2 334 4
1 6 3 521 4
1 6 4 48 4
1 6 5 349 4
1 6 6 369 4
1 6 7 297 4
1 6 8 412 4
1 6 9 223 4
1 6 10 575 4
1 6 11 566 4
1 6 12 377 4
1 6 13 197 4
1 6 14 347 36
1 7 0 373 68
1 7 1 222 4
1 7 2 206 4
1 7 3 340 4
1 7 4 438 4
1 7 5 155 4
1 7 6 567 4
1 7 7 241 0
1 7 8 532 4
1 7 9 42 4
1 7 10 328 4
1 7 11 65 4
1 7 12 153 4
1 7 13 72 4
1 7 14 540 36
1 8 0 438 68
1 8 1 408 4
1 8 2 565 4
1 8 3 94 4
1 8 4 438 4
1 8 5 72 4
1 8 6 474 0
1 8 7 60 0
1 8 8 324 0
1 8 9 363 4
1 8 10 575 4
1 8 11 414 4
1 8 12 177 4
1 8 13 145 4
1 8 14 580 36
1 9 0 330 68
1 9 1 438 4
1 9 2 112 4
1 9 3 261 4
1 9 4 311 4
1 9 5 226 0
1 9 6 456 0
1 9 7 269 0
1 9 8 342 0
1 9 9 520 0
1 9 10 604 4
1 9 11 157 4
1 9 12 63 4
1 9 13 486 4
1 9 14 157 36
1 10 0 556 76
1 10 1 357 12
1 10 2 585 4
1 10 3 593 4
1 10 4 270 4
1 10 5 587 4
1 10 6 368 4
1 10 7 521 4
1 10 8 309 4
1 10 9 418 4
1 10 10 278 4
1 10 11 387 4
1 10 12 520 4
1 10 13 579 12
1 10 14 455 44
1 11 2 73 68
1 11 3 254 4
1 11 4 84 4
1 11 5 56 4
1 11 6 616 4
1 11 7 567 4
1 11 8 551 4
1 11 9 288 4
1 11 10 165 4
1 11 11 591 4
1 11 12 468 36
1 12 2 610 68
1 12 3 112 4
1 12 4 56 4
1 12 5 108 4
1 12 6 586 4
1 12 7 567 4
1 12 8 626 4
1 12 9 60 4
1 12 10 414 4
1 12 11 608 4
1 12 12 517 36
1 13 2 192 68
1 13 3 94 4
1 13 4 328 4
1 13 5 556 4
1 13 6 69 4
1 13 7 65 4
1 13 8 555 4
1 13 9 233 4
1 13 10 302 4
1 13 11 112 4
1 13 12 494 36
1 14 2 474 76
1 14 3 347 12
1 14 4 273 12
1 14 5 314 12
1 14 6 50 12
1 14 7 437 12
1 14 8 335 12
1 14 9 629 12
1 14 10 528 12
1 14 11 555 12
1 14 12 445 44
2 0 2 3 92
2 0 3 3 16
2 0 4 3 60
2 0 10 3 92
2 0 11 3 16
2 0 12 3 60
2 1 3 3 100
2 1 11 3 102
2 2 0 3 80
2 2 1 3 16
2 2 2 3 16
2 2 3 3 0
2 2 4 3 16
2 2 5 3 16
2 2 6 3 16
2 2 7 3 16
2 2 8 3 16
2 2 9 3 16
2 2 10 3 16
2 2 11 3 0
2 2 12 3 16
2 2 13 3 16
2 2 14 3 48
2 3 0 3 64
2 3 1 3 0
2 3 2 3 0
2 3 3 3 0
2 3 4 3 0
2 3 5 3 0
2 3 6 3 0
2 3 7 3 0
2 3 8 3 0
2 3 9 3 0
2 3 10 3 0
2 3 11 3 0
2 3 12 3 0
2 3 13 3 0
2 3 14 3 32
2 4 0 3 64
2 4 1 9 0
2 4 2 9 0
2 4 3 9 0
2 4 4 9 0
2 4 5 9 0
2 4 6 9 0
2 4 7 9 0
2 4 8 9 0
2 4 9 9 0
2 4 10 9 0
2 4 11 9 0
2 4 12 9 0
2 4 13 9 0
2 4 14 3 32
2 5 0 574 64
2 5 1 50 0
2 5 2 340 0
2 5 3 245 0
2 5 4 517 0
2 5 5 86 0
2 5 6 381 0
2 5 7 269 0
2 5 8 629 0
2 5 9 365 0
2 5 10 487 0
2 5 11 30 0
2 5 12 595 0
2 5 13 265 0
2 5 14 350 32
2 6 0 319 64
2 6 1 611 0
2 6 2 301 0
2 6 3 187 0
2 6 4 290 0
2 6 5 240 0
2 6 6 113 0
2 6 7 592 0
2 6 8 279 0
2 6 9 69 0
2 6 10 97 0
2 6 11 496 0
2 6 12 459 0
2 6 13 616 0
2 6 14 72 32
2 7 0 93 64
2 7 1 256 0
2 7 2 252 0
2 7 3 112 0
2 7 4 592 0
2 7 5 112 0
2 7 6 238 0
2 7 7 299 0
2 7 8 529 0
2 7 9 295 0
2 7 10 565 0
2 7 11 477 0
2 7 12 453 0
2 7 13 346 0
2 7 14 546 32
2 8 0 565 64
2 8 1 51 0
2 8 2 576 0
2 8 3 209 0
2 8 4 521 0
2 8 5 454 0
2 8 6 281 0
2 8 7 422 0
2 8 8 358 0
2 8 9 534 0
2 8 10 131 0
2 8 11 575 0
2 8 12 322 0
2 8 13 611 0
2 8 14 579 32
2 9 0 219 64
2 9 1 387 0
2 9 2 93 0
2 9 3 108 0
2 9 4 231 0
2 9 5 73 0
2 9 6 56 0
2 9 7 66 0
2 9 8 243 0
2 9 9 86 0
2 9 10 456 0
2 9 11 94 0
2 9 12 396 0
2 9 13 567 0
2 9 14 288 32
2 10 0 417 72
2 10 1 93 8
2 10 2 303 0
2 10 3 501 0
2 10 4 587 0
2 10 5 321 0
2 10 6 594 0
2 10 7 578 0
2 10 8 122 0
2 10 9 407 0
2 10 10 522 0
2 10 11 556 0
2 10 12 37 0
2 10 13 299 8
2 10 14 501 40
2 11 2 388 64
2 11 3 109 0
2 11 4 592 0
2 11 5 612 0
2 11 6 231 0
2 11 7 177 0
2 11 8 211 0
2 11 9 155 0
2 11 10 412 0
2 11 11 555 0
2 11 12 586 32
2 12 2 540 64
2 12 3 407 0
2 12 4 586 0
2 12 5 417 0
2 12 6 565 0
2 12 7 217 0
2 12 8 524 0
2 12 9 611 0
2 12 10 413 0
2 12 11 566 0
2 12 12 248 32
2 13 2 163 64
2 13 3 555 0
2 13 4 170 0
2 13 5 228 0
2 13 6 591 0
2 13 7 211 0
2 13 8 525 0
2 13 9 470 0
2 13 10 469 0
2 13 11 205 0
2 13 12 269 32
2 14 2 265 72
2 14 3 55 8
2 14 4 53 8
2 14 5 618 8
2 14 6 356 8
2 14 7 586 8
2 14 8 215 8
2 14 9 198 8
2 14 10 413 8
2 14 11 94 8
2 14 12 536 40
3 0 2 3 90
3 0 3 3 16
3 0 4 3 58
3 0 10 3 90
3 0 11 3 24
3 0 12 3 58
3 1 3 3 98
3 2 0 3 80
3 2 1 3 16
3 2 2 3 16
3 2 3 3 0
3 2 4 3 16
3 2 5 3 16
3 2 6 3 16
3 2 7 3 16
3 2 8 3 16
3 2 9 3 16
3 2 10 3 16
3 2 11 3 16
3 2 12 3 16
3 2 13 3 16
3 2 14 3 48
3 3 0 3 64
3 3 1 3 0
3 3 2 3 0
3 3 3 3 0
3 3 4 3 0
3 3 5 3 0
3 3 6 3 0
3 3 7 3 0
3 3 8 3 0
3 3 9 3 0
3 3 10 3 0
3 3 11 3 0
3 3 12 3 0
3 3 13 3 0
3 3 14 3 32
3 4 0 3 64
3 4 1 9 0
3 4 2 9 0
3 4 3 9 0
3 4 4 9 0
3 4 5 9 0
3 4 6 9 0
3 4 7 9 0
3 4 8 9 0
3 4 9 9 0
3 4 10 9 0
3 4 11 9 0
3 4 12 9 0
3 4 13 9 0
3 4 14 3 32
3 5 0 489 64
3 5 1 48 0
3 5 2 615 0
3 5 3 315 0
3 5 4 161 0
3 5 5 602 0
3 5 6 344 0
3 5 7 395 0
3 5 8 172 0
3 5 9 599 0
3 5 10 190 0
3 5 11 554 0
3 5 12 481 0
3 5 13 42 0
3 5 14 439 32
3 6 0 94 64
3 6 1 502 0
3 6 2 326 0
3 6 3 313 0
3 6 4 633 0
3 6 5 457 0
3 6 6 565 0
3 6 7 112 0
3 6 8 617 0
3 6 9 284 0
3 6 10 428 0
3 6 11 520 0
3 6 12 314 0
3 6 13 530 0
3 6 14 314 32
3 7 0 230 64
3 7 1 372 0
3 7 2 244 0
3 7 3 363 0
3 7 4 231 0
3 7 5 166 0
3 7 6 387 0
3 7 7 373 0
3 7 8 177 0
3 7 9 160 0
3 7 10 177 0
3 7 11 94 0
3 7 12 187 0
3 7 13 379 0
3 7 14 63 32
3 8 0 73 64
3 8 1 23 0
3 8 2 108 0
3 8 3 153 0
3 8 4 512 0
3 8 5 575 0
3 8 6 569 0
3 8 7 283 0
3 8 8 131 0
3 8 9 231 0
3 8 10 520 0
3 8 11 209 0
3 8 12 610 0
3 8 13 495 0
3 8 14 58 32
3 9 0 48 64
3 9 1 385 0
3 9 2 521 0
3 9 3 381 0
3 9 4 66 0
3 9 5 228 0
3 9 6 570 0
3 9 7 422 0
3 9 8 237 0
3 9 9 220 0
3 9 10 408 0
3 9 11 302 0
3 9 12 547 0
3 9 13 521 0
3 9 14 108 32
3 10 0 331 72
3 10 1 147 8
3 10 2 548 0
3 10 3 331 0
3 10 4 347 0
3 10 5 529 0
3 10 6 454 0
3 10 7 419 0
3 10 8 365 0
3 10 9 166 0
3 10 10 337 0
3 10 11 585 0
3 10 12 539 0
3 10 13 177 8
3 10 14 417 40
3 11 2 306 64
3 11 3 304 0
3 11 4 578 0
3 11 5 499 0
3 11 6 108 0
3 11 7 502 0
3 11 8 31 0
3 11 9 567 0
3 11 10 451 0
3 11 11 131 0
3 11 12 125 32
3 12 2 349 64
3 12 3 233 0
3 12 4 106 0
3 12 5 58 0
3 12 6 72 0
3 12 7 210 0
3 12 8 535 0
3 12 9 400 0
3 12 10 526 0
3 12 11 379 0
3 12 12 146 32
3 13 2 193 64
3 13 3 112 0
3 13 4 259 0
3 13 5 375 0
3 13 6 131 0
3 13 7 310 0
3 13 8 523 0
3 13 9 37 0
3 13 10 314 0
3 13 11 621 0
3 13 12 626 32
3 14 2 499 72
3 14 3 468 8
3 14 4 538 8
3 14 5 202 8
3 14 6 592 8
3 14 7 399 8
3 14 8 44 8
3 14 9 175 8
3 14 10 566 8
3 14 11 170 8
3 14 12 348 40
4 0 3 3 122
4 0 11 3 122
4 2 0 3 80
4 2 1 3 16
4 2 2 3 16
4 2 3 3 16
4 2 4 3 16
4 2 5 3 16
4 2 6 3 16
4 2 7 3 16
4 2 8 3 16
4 2 9 3 16
4 2 10 3 16
4 2 11 3 16
4 2 12 3 16
4 2 13 3 16
4 2 14 3 48
4 3 0 3 64
4 3 1 3 0
4 3 2 3 0
4 3 3 3 0
4 3 4 3 0
4 3 5 3 0
4 3 6 3 0
4 3 7 3 0
4 3 8 3 0
4 3 9 3 0
4 3 10 3 0
4 3 11 3 0
4 3 12 3 0
4 3 13 3 0
4 3 14 3 32
4 4 0 3 64
4 4 1 9 0
4 4 2 9 0
4 4 3 9 0
4 4 4 9 0
4 4 5 9 0
4 4 6 9 0
4 4 7 9 0
4 4 8 9 0
4 4 9 9 0
4 4 10 9 0
4 4 11 9 0
4 4 12 9 0
4 4 13 9 0
4 4 14 3 32
4 5 0 565 64
4 5 1 337 0
4 5 2 55 0
4 5 3 207 0
4 5 4 278 0
4 5 5 49 0
4 5 6 571 0
4 5 7 54 0
4 5 8 619 0
4 5 9 27 0
4 5 10 452 0
4 5 11 164 0
4 5 12 155 0
4 5 13 204 0
4 5 14 478 32
4 6 0 438 64
4 6 1 587 0
4 6 2 437 0
4 6 3 255 0
4 6 4 297 0
4 6 5 93 0
4 6 6 86 0
4 6 7 84 0
4 6 8 244 0
4 6 9 592 0
4 6 10 586 0
4 6 11 115 0
4 6 12 417 0
4 6 13 521 0
4 6 14 513 32
4 7 0 391 64
4 7 1 97 0
4 7 2 416 0
4 7 3 181 0
4 7 4 406 0
4 7 5 169 0
4 7 6 605 0
4 7 7 616 0
4 7 8 555 0
4 7 9 224 0
4 7 10 199 0
4 7 11 577 0
4 7 12 587 0
4 7 13 470 0
4 7 14 617 32
4 8 0 108 64
4 8 1 438 0
4 8 2 84 0
4 8 3 565 0
4 8 4 269 0
4 8 5 308 0
4 8 6 605 0
4 8 7 271 0
4 8 8 387 0
4 8 9 191 0
4 8 10 134 0
4 8 11 239 0
4 8 12 265 0
4 8 13 300 0
4 8 14 134 32
4 9 0 579 64
4 9 1 289 0
4 9 2 181 0
4 9 3 552 0
4 9 4 521 0
4 9 5 586 0
4 9 6 157 0
4 9 7 131 0
4 9 8 181 0
4 9 9 557 0
4 9 10 209 0
4 9 11 555 0
4 9 12 615 0
4 9 13 131 0
4 9 14 50 32
4 10 0 94 72
4 10 1 440 8
4 10 2 437 0
4 10 3 478 0
4 10 4 388 0
4 10 5 288 0
4 10 6 394 0
4 10 7 611 0
4 10 8 308 0
4 10 9 520 0
4 10 10 468 0
4 10 11 600 0
4 10 12 177 0
4 10 13 132 8
4 10 14 410 40
4 11 2 48 64
4 11 3 58 0
4 11 4 586 0
4 11 5 577 0
4 11 6 490 0
4 11 7 55 0
4 11 8 497 0
4 11 9 35 0
4 11 10 341 0
4 11 11 235 0
4 11 12 209 32
4 12 2 131 64
4 12 3 269 0
4 12 4 319 0
4 12 5 600 0
4 12 6 447 0
4 12 7 296 0
4 12 8 498 0
4 12 9 84 0
4 12 10 94 0
4 12 11 288 0
4 12 12 362 32
4 13 2 84 64
4 13 3 134 0
4 13 4 465 0
4 13 5 390 0
4 13 6 172 0
4 13 7 94 0
4 13 8 181 0
4 13 9 84 0
4 13 10 214 0
4 13 11 86 0
4 13 12 86 32
4 14 2 610 72
4 14 3 550 8
4 14 4 113 8
4 14 5 225 8
4 14 6 621 8
4 14 7 547 8
4 14 8 112 8
4 14 9 84 8
4 14 10 447 8
4 14 11 576 8
4 14 12 386 40
5 2 0 3 80
5 2 1 3 16
5 2 2 3 16
5 2 3 3 16
5 2 4 3 16
5 2 5 3 16
5 2 6 3 16
5 2 7 3 16
5 2 8 3 16
5 2 9 3 16
5 2 10 3 16
5 2 11 3 16
5 2 12 3 16
5 2 13 3 16
5 2 14 3 48
5 3 0 3 64
5 3 1 3 0
5 3 2 3 0
5 3 3 3 0
5 3 4 3 0
5 3 5 3 0
5 3 6 3 0
5 3 7 3 0
5 3 8 3 0
5 3 9 3 0
5 3 10 3 0
5 3 11 3 0
5 3 12 3 0
5 3 13 3 0
5 3 14 3 32
5 4 0 3 64
5 4 1 9 0
5 4 2 9 0
5 4 3 9 0
5 4 4 9 0
5 4 5 9 0
5 4 6 9 0
5 4 7 9 0
5 4 8 9 0
5 4 9 9 0
5 4 10 9 0
5 4 11 9 0
5 4 12 9 0
5 4 13 9 0
5 4 14 3 32
5 5 0 231 64
5 5 1 414 0
5 5 2 250 0
5 5 3 443 0
5 5 4 346 0
5 5 5 208 0
5 5 6 112 0
5 5 7 573 0
5 5 8 590 0
5 5 9 84 0
5 5 10 26 0
5 5 11 24 0
5 5 12 310 0
5 5 13 439 0
5 5 14 246 32
5 6 0 255 64
5 6 1 323 0
5 6 2 604 0
5 6 3 587 0
5 6 4 277 0
5 6 5 436 0
5 6 6 108 0
5 6 7 498 0
5 6 8 114 0
5 6 9 59 0
5 6 10 156 0
5 6 11 121 0
5 6 12 18 0
5 6 13 357 0
5 6 14 84 32
5 7 0 362 64
5 7 1 444 0
5 7 2 220 0
5 7 3 144 0
5 7 4 455 0
5 7 5 187 0
5 7 6 576 0
5 7 7 73 0
5 7 8 287 0
5 7 9 171 0
5 7 10 31 0
5 7 11 341 0
5 7 12 534 0
5 7 13 586 0
5 7 14 508 32
5 8 0 577 64
5 8 1 407 0
5 8 2 574 0
5 8 3 56 0
5 8 4 548 0
5 8 5 593 0
5 8 6 340 0
5 8 7 610 0
5 8 8 283 0
5 8 9 625 0
5 8 10 65 0
5 8 11 610 0
5 8 12 556 0
5 8 13 432 0
5 8 14 180 32
5 9 0 633 64
5 9 1 27 0
5 9 2 286 0
5 9 3 426 0
5 9 4 391 0
5 9 5 376 0
5 9 6 520 0
5 9 7 435 0
5 9 8 328 0
5 9 9 255 0
5 9 10 35 0
5 9 11 417 0
5 9 12 112 0
5 9 13 484 0
5 9 14 328 32
5 10 0 556 72
5 10 1 44 8
5 10 2 276 0
5 10 3 246 0
5 10 4 610 0
5 10 5 521 0
5 10 6 473 0
5 10 7 250 0
5 10 8 73 0
5 10 9 262 0
5 10 10 587 0
5 10 11 336 0
5 10 12 73 0
5 10 13 381 8
5 10 14 594 40
5 11 2 494 64
5 11 3 574 0
5 11 4 486 0
5 11 5 287 0
5 11 6 518 0
5 11 7 485 0
5 11 8 37 0
5 11 9 482 0
5 11 10 193 0
5 11 11 147 0
5 11 12 524 32
5 12 2 53 64
5 12 3 482 0
5 12 4 279 0
5 12 5 556 0
5 12 6 392 0
5 12 7 618 0
5 12 8 464 0
5 12 9 347 0
5 12 10 418 0
5 12 11 533 0
5 12 12 341 32
5 13 2 567 64
5 13 3 585 0
5 13 4 231 0
5 13 5 45 0
5 13 6 219 0
5 13 7 588 0
5 13 8 540 0
5 13 9 94 0
5 13 10 560 0
5 13 11 317 0
5 13 12 552 32
5 14 2 555 72
5 14 3 42 8
5 14 4 108 8
5 14 5 446 8
5 14 6 605 8
5 14 7 610 8
5 14 8 587 8
5 14 9 157 8
5 14 10 555 8
5 14 11 234 8
5 14 12 457 40
6 2 0 3 80
6 2 1 3 16
6 2 2 3 16
6 2 3 3 16
6 2 4 3 16
6 2 5 3 16
6 2 6 3 16
6 2 7 3 16
6 2 8 3 16
6 2 9 3 16
6 2 10 3 16
6 2 11 3 16
6 2 12 3 16
6 2 13 3 16
6 2 14 3 48
6 3 0 3 64
6 3 1 3 0
6 3 2 3 0
6 3 3 3 0
6 3 4 3 0
6 3 5 3 0
6 3 6 3 0
6 3 7 3 0
6 3 8 3 0
6 3 9 3 0
6 3 10 3 0
6 3 11 3 0
6 3 12 3 0
6 3 13 3 0
6 3 14 3 32
6 4 0 3 64
6 4 1 9 0
6 4 2 9 0
6 4 3 9 0
6 4 4 9 0
6 4 5 9 0
6 4 6 9 0
6 4 7 9 0
6 4 8 9 0
6 4 9 9 0
6 4 10 9 0
6 4 11 9 0
6 4 12 9 0
6 4 13 9 0
6 4 14 3 32
6 5 0 539 64
6 5 1 332 0
6 5 2 445 0
6 5 3 57 0
6 5 4 120 0
6 5 5 544 0
6 5 6 507 0
6 5 7 183 0
6 5 8 214 0
6 5 9 251 0
6 5 10 214 0
6 5 11 120 0
6 5 12 638 0
6 5 13 577 0
6 5 14 93 32
6 6 0 568 64
6 6 1 592 0
6 6 2 582 0
6 6 3 110 0
6 6 4 68 0
6 6 5 459 0
6 6 6 305 0
6 6 7 635 0
6 6 8 22 0
6 6 9 404 0
6 6 10 632 0
6 6 11 327 0
6 6 12 116 0
6 6 13 255 0
6 6 14 523 32
6 7 0 603 64
6 7 1 93 0
6 7 2 214 0
6 7 3 44 0
6 7 4 179 0
6 7 5 23 0
6 7 6 108 0
6 7 7 531 0
6 7 8 84 0
6 7 9 438 0
6 7 10 605 0
6 7 11 31 0
6 7 12 423 0
6 7 13 578 0
6 7 14 94 32
6 8 0 463 64
6 8 1 382 0
6 8 2 628 0
6 8 3 566 0
6 8 4 468 0
6 8 5 177 0
6 8 6 404 0
6 8 7 97 0
6 8 8 186 0
6 8 9 231 0
6 8 10 112 0
6 8 11 592 0
6 8 12 112 0
6 8 13 165 0
6 8 14 351 32
6 9 0 94 64
6 9 1 48 0
6 9 2 279 0
6 9 3 422 0
6 9 4 567 0
6 9 5 566 0
6 9 6 566 0
6 9 7 556 0
6 9 8 209 0
6 9 9 34 0
6 9 10 42 0
6 9 11 146 0
6 9 12 94 0
6 9 13 393 0
6 9 14 109 32
6 10 0 112 72
6 10 1 502 8
6 10 2 610 0
6 10 3 548 0
6 10 4 611 0
6 10 5 223 0
6 10 6 610 0
6 10 7 157 0
6 10 8 610 0
6 10 9 582 0
6 10 10 156 0
6 10 11 93 0
6 10 12 160 0
6 10 13 503 8
6 10 14 528 40
6 11 2 292 64
6 11 3 153 0
6 11 4 629 0
6 11 5 205 0
6 11 6 269 0
6 11 7 566 0
6 11 8 524 0
6 11 9 401 0
6 11 10 108 0
6 11 11 567 0
6 11 12 592 32
6 12 2 50 64
6 12 3 522 0
6 12 4 205 0
6 12 5 134 0
6 12 6 381 0
6 12 7 233 0
6 12 8 421 0
6 12 9 457 0
6 12 10 424 0
6 12 11 108 0
6 12 12 135 32
6 13 2 128 64
6 13 3 414 0
6 13 4 269 0
6 13 5 128 0
6 13 6 479 0
6 13 7 512 0
6 13 8 193 0
6 13 9 439 0
6 13 10 330 0
6 13 11 112 0
6 13 12 299 32
6 14 2 216 72
6 14 3 533 8
6 14 4 551 8
6 14 5 586 8
6 14 6 47 8
6 14 7 177 8
6 14 8 502 8
6 14 9 249 8
6 14 10 396 8
6 14 11 583 8
6 14 12 299 40
7 2 0 3 80
7 2 1 3 16
7 2 2 3 16
7 2 3 3 16
7 2 4 3 16
7 2 5 3 16
7 2 6 3 16
7 2 7 3 16
7 2 8 3 16
7 2 9 3 16
7 2 10 3 16
7 2 11 3 16
7 2 12 3 16
7 2 13 3 16
7 2 14 3 48
7 3 0 3 64
7 3 1 3 0
7 3 2 3 0
7 3 3 3 0
7 3 4 3 0
7 3 5 3 0
7 3 6 3 0
7 3 7 3 0
7 3 8 3 0
7 3 9 3 0
7 3 10 3 0
7 3 11 3 0
7 3 12 3 0
7 3 13 3 0
7 3 14 3 32
7 4 0 3 64
7 4 1 9 0
7 4 2 9 0
7 4 3 9 0
7 4 4 9 0
7 4 5 9 0
7 4 6 9 0
7 4 7 9 0
7 4 8 9 0
7 4 9 9 0
7 4 10 9 0
7 4 11 9 0
7 4 12 9 0
7 4 13 9 0
7 4 14 3 32
7 5 0 517 64
7 5 1 522 0
7 5 2 308 0
7 5 3 339 0
7 5 4 421 0
7 5 5 476 0
7 5 6 216 0
7 5 7 139 0
7 5 8 581 0
7 5 9 346 0
7 5 10 102 0
7 5 11 563 0
7 5 12 348 0
7 5 13 48 0
7 5 14 177 32
7 6 0 157 64
7 6 1 385 0
7 6 2 157 0
7 6 3 561 0
7 6 4 236 0
7 6 5 448 0
7 6 6 493 0
7 6 7 623 0
7 6 8 527 0
7 6 9 130 0
7 6 10 32 0
7 6 11 29 0
7 6 12 541 0
7 6 13 439 0
7 6 14 333 32
7 7 0 412 64
7 7 1 514 0
7 7 2 66 0
7 7 3 538 0
7 7 4 603 0
7 7 5 286 0
7 7 6 356 0
7 7 7 458 0
7 7 8 578 0
7 7 9 649 0
7 7 10 649 0
7 7 11 536 0
7 7 12 97 0
7 7 13 591 0
7 7 14 418 32
7 8 0 94 64
7 8 1 566 0
7 8 2 493 0
7 8 3 214 0
7 8 4 211 0
7 8 5 171 0
7 8 6 325 0
7 8 7 521 0
7 8 8 601 0
7 8 9 418 0
7 8 10 406 0
7 8 11 649 0
7 8 12 649 0
7 8 13 649 0
7 8 14 565 32
7 9 0 472 64
7 9 1 616 0
7 9 2 55 0
7 9 3 267 0
7 9 4 34 0
7 9 5 189 0
7 9 6 313 0
7 9 7 247 0
7 9 8 627 0
7 9 9 617 0
7 9 10 610 0
7 9 11 473 0
7 9 12 179 0
7 9 13 610 0
7 9 14 112 32
7 10 0 275 72
7 10 1 325 8
7 10 2 633 0
7 10 3 438 0
7 10 4 560 0
7 10 5 438 0
7 10 6 312 0
7 10 7 97 0
7 10 8 406 0
7 10 9 108 0
7 10 10 142 0
7 10 11 593 0
7 10 12 403 0
7 10 13 557 8
7 10 14 257 40
7 11 2 594 64
7 11 3 131 0
7 11 4 499 0
7 11 5 626 0
7 11 6 60 0
7 11 7 597 0
7 11 8 610 0
7 11 9 604 0
7 11 10 94 0
7 11 11 575 0
7 11 12 399 32
7 12 2 500 64
7 12 3 214 0
7 12 4 108 0
7 12 5 557 0
7 12 6 369 0
7 12 7 540 0
7 12 8 31 0
7 12 9 468 0
7 12 10 405 0
7 12 11 302 0
7 12 12 112 32
7 13 2 429 64
7 13 3 616 0
7 13 4 463 0
7 13 5 181 0
7 13 6 63 0
7 13 7 359 0
7 13 8 433 0
7 13 9 299 0
7 13 10 616 0
7 13 11 230 0
7 13 12 460 32
7 14 2 502 72
7 14 3 600 8
7 14 4 575 8
7 14 5 387 8
7 14 6 195 8
7 14 7 556 8
7 14 8 376 8
7 14 9 578 8
7 14 10 489 8
7 14 11 97 8
7 14 12 303 40
8 2 0 3 80
8 2 1 3 16
8 2 2 3 16
8 2 3 3 16
8 2 4 3 16
8 2 5 3 16
8 2 6 3 16
8 2 7 3 16
8 2 8 3 16
8 2 9 3 16
8 2 10 3 16
8 2 11 3 16
8 2 12 3 16
8 2 13 3 16
8 2 14 3 48
8 3 0 3 64
8 3 1 3 0
8 3 2 3 0
8 3 3 3 0
8 3 4 3 0
8 3 5 3 0
8 3 6 3 0
8 3 7 3 0
8 3 8 3 0
8 3 9 3 0
8 3 10 3 0
8 3 11 3 0
8 3 12 3 0
8 3 13 3 0
8 3 14 3 32
8 4 0 3 64
8 4 1 9 0
8 4 2 9 0
8 4 3 9 0
8 4 4 9 0
8 4 5 9 0
8 4 6 9 0
8 4 7 9 0
8 4 8 9 0
8 4 9 9 0
8 4 10 9 0
8 4 11 9 0
8 4 12 9 0
8 4 13 9 0
8 4 14 3 32
8 5 0 517 64
8 5 1 522 0
8 5 2 308 0
8 5 3 339 0
8 5 4 421 0
8 5 5 476 0
8 5 6 216 0
8 5 7 139 0
8 5 8 581 0
8 5 9 346 0
8 5 10 102 0
8 5 11 563 0
8 5 12 348 0
8 5 13 48 0
8 5 14 177 32
8 6 0 157 64
8 6 1 385 0
8 6 2 157 0
8 6 3 561 0
8 6 4 236 0
8 6 5 448 0
8 6 6 493 0
8 6 7 623 0
8 6 8 527 0
8 6 9 130 0
8 6 10 32 0
8 6 11 29 0
8 6 12 541 0
8 6 13 439 0
8 6 14 333 32
8 7 0 412 64
8 7 1 514 0
8 7 2 66 0
8 7 3 538 0
8 7 4 603 0
8 7 5 286 0
8 7 6 356 0
8 7 7 458 0
8 7 8 578 0
8 7 9 649 0
8 7 10 649 0
8 7 11 536 0
8 7 12 97 0
8 7 13 591 0
8 7 14 418 32
8 8 0 94 64
8 8 1 566 0
8 8 2 493 0
8 8 3 214 0
8 8 4 211 0
8 8 5 171 0
8 8 6 325 0
8 8 7 521 0
8 8 8 601 0
8 8 9 418 0
8 8 10 406 0
8 8 11 649 0
8 8 12 649 0
8 8 13 649 0
8 8 14 565 32
8 9 0 472 64
8 9 1 616 0
8 9 2 55 0
8 9 3 267 0
8 9 4 34 0
8 9 5 189 0
8 9 6 313 0
8 9 7 247 0
8 9 8 627 0
8 9 9 617 0
8 9 10 610 0
8 9 11 473 0
8 9 12 179 0
8 9 13 610 0
8 9 14 112 32
8 10 0 275 72
8 10 1 325 8
8 10 2 633 0
8 10 3 438 0
8 10 4 560 0
8 10 5 438 0
8 10 6 312 0
8 10 7 97 0
8 10 8 406 0
8 10 9 108 0
8 10 10 142 0
8 10 11 593 0
8 10 12 403 0
8 10 13 557 8
8 10 14 257 40
8 11 2 594 64
8 11 3 131 0
8 11 4 499 0
8 11 5 626 0
8 11 6 60 0
8 11 7 597 0
8 11 8 610 0
8 11 9 604 0
8 11 10 94 0
8 11 11 575 0
8 11 12 399 32
8 12 2 500 64
8 12 3 214 0
8 12 4 108 0
8 12 5 557 0
8 12 6 369 0
8 12 7 540 0
8 12 8 31 0
8 12 9 468 0
8 12 10 405 0
8 12 11 302 0
8 12 12 112 32
8 13 2 429 64
8 13 3 616 0
8 13 4 463 0
8 13 5 181 0
8 13 6 63 0
8 13 7 359 0
8 13 8 433 0
8 13 9 299 0
8 13 10 616 0
8 13 11 230 0
8 13 12 460 32
8 14 2 502 72
8 14 3 600 8
8 14 4 575 8
8 14 5 387 8
8 14 6 195 8
8 14 7 556 8
8 14 8 376 8
8 14 9 578 8
8 14 10 489 8
8 14 11 97 8
8 14 12 303 40
9 2 0 3 80
9 2 1 3 16
9 2 2 3 16
9 2 3 3 16
9 2 4 3 16
9 2 5 3 16
9 2 6 3 16
9 2 7 3 16
9 2 8 3 16
9 2 9 3 16
9 2 10 3 16
9 2 11 3 16
9 2 12 3 16
9 2 13 3 16
9 2 14 3 48
9 3 0 3 64
9 3 1 3 0
9 3 2 3 0
9 3 3 3 0
9 3 4 3 0
9 3 5 3 0
9 3 6 3 0
9 3 7 3 0
9 3 8 3 0
9 3 9 3 0
9 3 10 3 0
9 3 11 3 0
9 3 12 3 0
9 3 13 3 0
9 3 14 3 32
9 4 0 3 64
9 4 1 9 0
9 4 2 9 0
9 4 3 9 0
9 4 4 9 0
9 4 5 9 0
9 4 6 9 0
9 4 7 9 0
9 4 8 9 0
9 4 9 9 0
9 4 10 9 0
9 4 11 9 0
9 4 12 9 0
9 4 13 9 0
9 4 14 3 32
9 5 0 569 64
9 5 1 31 0
9 5 2 439 0
9 5 3 488 0
9 5 4 361 0
9 5 5 268 0
9 5 6 449 0
9 5 7 71 0
9 5 8 40 0
9 5 9 374 0
9 5 10 583 0
9 5 11 614 0
9 5 12 513 0
9 5 13 462 0
9 5 14 433 32
9 6 0 525 64
9 6 1 34 0
9 6 2 301 0
9 6 3 38 0
9 6 4 434 0
9 6 5 99 0
9 6 6 353 0
9 6 7 623 0
9 6 8 545 0
9 6 9 65 0
9 6 10 636 0
9 6 11 406 0
9 6 12 62 0
9 6 13 147 0
9 6 14 538 32
9 7 0 410 64
9 7 1 437 0
9 7 2 278 0
9 7 3 174 0
9 7 4 194 0
9 7 5 425 0
9 7 6 102 0
9 7 7 360 0
9 7 8 159 0
9 7 9 98 0
9 7 10 83 0
9 7 11 598 0
9 7 12 507 0
9 7 13 294 0
9 7 14 333 32
9 8 0 209 64
9 8 1 316 0
9 8 2 180 0
9 8 3 569 0
9 8 4 528 0
9 8 5 163 0
9 8 6 373 0
9 8 7 269 0
9 8 8 73 0
9 8 9 610 0
9 8 10 375 0
9 8 11 634 0
9 8 12 94 0
9 8 13 582 0
9 8 14 463 32
9 9 0 97 64
9 9 1 93 0
9 9 2 451 0
9 9 3 211 0
9 9 4 300 0
9 9 5 273 0
9 9 6 222 0
9 9 7 535 0
9 9 8 42 0
9 9 9 131 0
9 9 10 95 0
9 9 11 219 0
9 9 12 314 0
9 9 13 93 0
9 9 14 58 32
9 10 0 566 72
9 10 1 270 8
9 10 2 348 0
9 10 3 534 0
9 10 4 270 0
9 10 5 577 0
9 10 6 55 0
9 10 7 196 0
9 10 8 257 0
9 10 9 249 0
9 10 10 231 0
9 10 11 390 0
9 10 12 466 0
9 10 13 565 8
9 10 14 509 40
9 11 2 565 64
9 11 3 565 0
9 11 4 580 0
9 11 5 293 0
9 11 6 291 0
9 11 7 204 0
9 11 8 126 0
9 11 9 556 0
9 11 10 477 0
9 11 11 513 0
9 11 12 132 32
9 12 2 308 64
9 12 3 131 0
9 12 4 410 0
9 12 5 75 0
9 12 6 473 0
9 12 7 416 0
9 12 8 362 0
9 12 9 357 0
9 12 10 411 0
9 12 11 112 0
9 12 12 205 32
9 13 2 538 64
9 13 3 269 0
9 13 4 510 0
9 13 5 263 0
9 13 6 260 0
9 13 7 134 0
9 13 8 611 0
9 13 9 174 0
9 13 10 21 0
9 13 11 567 0
9 13 12 592 32
9 14 2 556 72
9 14 3 283 8
9 14 4 646 126
9 14 5 539 8
9 14 6 468 8
9 14 7 112 8
9 14 8 223 8
9 14 9 86 8
9 14 10 646 126
9 14 11 198 8
9 14 12 520 40
10 0 3 3 124
10 0 11 3 124
10 2 0 3 80
10 2 1 3 16
10 2 2 3 16
10 2 3 3 16
10 2 4 3 16
10 2 5 3 16
10 2 6 3 16
10 2 7 3 16
10 2 8 3 16
10 2 9 3 16
10 2 10 3 16
10 2 11 3 16
10 2 12 3 16
10 2 13 3 16
10 2 14 3 48
10 3 0 3 64
10 3 1 3 0
10 3 2 3 0
10 3 3 3 0
10 3 4 3 0
10 3 5 3 0
10 3 6 3 0
10 3 7 3 0
10 3 8 3 0
10 3 9 3 0
10 3 10 3 0
10 3 11 3 0
10 3 12 3 0
10 3 13 3 0
10 3 14 3 32
10 4 0 3 64
10 4 1 9 0
10 4 2 9 0
10 4 3 9 0
10 4 4 9 0
10 4 5 9 0
10 4 6 9 0
10 4 7 9 0
10 4 8 9 0
10 4 9 9 0
10 4 10 9 0
10 4 11 9 0
10 4 12 9 0
10 4 13 9 0
10 4 14 3 32
10 5 0 361 64
10 5 1 341 0
10 5 2 252 0
10 5 3 119 0
10 5 4 238 0
10 5 5 399 0
10 5 6 200 0
10 5 7 450 0
10 5 8 318 0
10 5 9 562 0
10 5 10 401 0
10 5 11 542 0
10 5 12 22 0
10 5 13 108 0
10 5 14 552 32
10 6 0 433 64
10 6 1 63 0
10 6 2 233 0
10 6 3 576 0
10 6 4 448 0
10 6 5 298 0
10 6 6 105 0
10 6 7 378 0
10 6 8 624 0
10 6 9 329 0
10 6 10 54 0
10 6 11 274 0
10 6 12 402 0
10 6 13 317 0
10 6 14 191 32
10 7 0 428 64
10 7 1 63 0
10 7 2 579 0
10 7 3 88 0
10 7 4 464 0
10 7 5 137 0
10 7 6 505 0
10 7 7 64 0
10 7 8 449 0
10 7 9 128 0
10 7 10 46 0
10 7 11 75 0
10 7 12 312 0
10 7 13 587 0
10 7 14 337 32
10 8 0 336 64
10 8 1 311 0
10 8 2 498 0
10 8 3 157 0
10 8 4 153 0
10 8 5 93 0
10 8 6 386 0
10 8 7 568 0
10 8 8 241 0
10 8 9 108 0
10 8 10 84 0
10 8 11 343 0
10 8 12 556 0
10 8 13 592 0
10 8 14 522 32
10 9 0 586 64
10 9 1 272 0
10 9 2 227 0
10 9 3 502 0
10 9 4 131 0
10 9 5 439 0
10 9 6 205 0
10 9 7 72 0
10 9 8 237 0
10 9 9 367 0
10 9 10 525 0
10 9 11 445 0
10 9 12 329 0
10 9 13 461 0
10 9 14 533 32
10 10 0 557 72
10 10 1 97 8
10 10 2 547 0
10 10 3 112 0
10 10 4 209 0
10 10 5 247 0
10 10 6 366 0
10 10 7 73 0
10 10 8 604 0
10 10 9 299 0
10 10 10 303 0
10 10 11 596 0
10 10 12 379 0
10 10 13 155 8
10 10 14 349 40
10 11 2 556 64
10 11 3 179 0
10 11 4 387 0
10 11 5 325 0
10 11 6 50 0
10 11 7 223 0
10 11 8 569 0
10 11 9 512 0
10 11 10 84 0
10 11 11 223 0
10 11 12 555 32
10 12 2 65 64
10 12 3 63 0
10 12 4 486 0
10 12 5 285 0
10 12 6 587 0
10 12 7 617 0
10 12 8 48 0
10 12 9 287 0
10 12 10 174 0
10 12 11 93 0
10 12 12 602 32
10 13 2 69 64
10 13 3 271 0
10 13 4 157 0
10 13 5 603 0
10 13 6 427 0
10 13 7 519 0
10 13 8 355 0
10 13 9 209 0
10 13 10 445 0
10 13 11 575 0
10 13 12 604 32
10 14 2 557 72
10 14 3 267 8
10 14 4 646 126
10 14 5 646 126
10 14 6 252 8
10 14 7 300 8
10 14 8 106 8
10 14 9 646 126
10 14 10 646 126
10 14 11 509 8
10 14 12 473 40
11 0 2 3 92
11 0 3 3 16
11 0 4 3 60
11 0 10 3 92
11 0 11 3 16
11 0 12 3 60
11 1 3 3 100
11 1 11 3 102
11 2 0 3 80
11 2 1 3 16
11 2 2 3 16
11 2 3 3 0
11 2 4 3 16
11 2 5 3 16
11 2 6 3 16
11 2 7 3 16
11 2 8 3 16
11 2 9 3 16
11 2 10 3 16
11 2 11 3 0
11 2 12 3 16
11 2 13 3 16
11 2 14 3 48
11 3 0 3 64
11 3 1 3 0
11 3 2 3 0
11 3 3 3 0
11 3 4 3 0
11 3 5 3 0
11 3 6 3 0
11 3 7 3 0
11 3 8 3 0
11 3 9 3 0
11 3 10 3 0
11 3 11 3 0
11 3 12 3 0
11 3 13 3 0
11 3 14 3 32
11 4 0 3 64
11 4 1 9 0
11 4 2 9 0
11 4 3 9 0
11 4 4 9 0
11 4 5 9 0
11 4 6 9 0
11 4 7 9 0
11 4 8 9 0
11 4 9 9 0
11 4 10 9 0
11 4 11 9 0
11 4 12 9 0
11 4 13 9 0
11 4 14 3 32
11 5 0 579 64
11 5 1 109 0
11 5 2 37 0
11 5 3 310 0
11 5 4 61 0
11 5 5 493 0
11 5 6 511 0
11 5 7 138 0
11 5 8 165 0
11 5 9 117 0
11 5 10 594 0
11 5 11 384 0
11 5 12 100 0
11 5 13 588 0
11 5 14 539 32
11 6 0 568 64
11 6 1 556 0
11 6 2 259 0
11 6 3 212 0
11 6 4 17 0
11 6 5 293 0
11 6 6 107 0
11 6 7 187 0
11 6 8 101 0
11 6 9 92 0
11 6 10 584 0
11 6 11 431 0
11 6 12 229 0
11 6 13 63 0
11 6 14 337 32
11 7 0 566 64
11 7 1 522 0
11 7 2 134 0
11 7 3 279 0
11 7 4 142 0
11 7 5 74 0
11 7 6 67 0
11 7 7 543 0
11 7 8 559 0
11 7 9 88 0
11 7 10 616 0
11 7 11 169 0
11 7 12 297 0
11 7 13 357 0
11 7 14 534 32
11 8 0 617 64
11 8 1 381 0
11 8 2 587 0
11 8 3 412 0
11 8 4 303 0
11 8 5 58 0
11 8 6 233 0
11 8 7 516 0
11 8 8 89 0
11 8 9 92 0
11 8 10 475 0
11 8 11 79 0
11 8 12 36 0
11 8 13 300 0
11 8 14 531 32
11 9 0 34 64
11 9 1 248 0
11 9 2 160 0
11 9 3 376 0
11 9 4 524 0
11 9 5 582 0
11 9 6 205 0
11 9 7 124 0
11 9 8 463 0
11 9 9 321 0
11 9 10 158 0
11 9 11 31 0
11 9 12 479 0
11 9 13 436 0
11 9 14 539 32
11 10 0 410 72
11 10 1 498 8
11 10 2 368 0
11 10 3 112 0
11 10 4 320 0
11 10 5 613 0
11 10 6 259 0
11 10 7 600 0
11 10 8 498 0
11 10 9 233 0
11 10 10 430 0
11 10 11 65 0
11 10 12 56 0
11 10 13 87 8
11 10 14 285 40
11 11 2 439 64
11 11 3 157 0
11 11 4 380 0
11 11 5 44 0
11 11 6 150 0
11 11 7 122 0
11 11 8 25 0
11 11 9 112 0
11 11 10 473 0
11 11 11 622 0
11 11 12 592 32
11 12 2 376 64
11 12 3 369 0
11 12 4 365 0
11 12 5 420 0
11 12 6 596 0
11 12 7 480 0
11 12 8 502 0
11 12 9 376 0
11 12 10 591 0
11 12 11 112 0
11 12 12 112 32
11 13 2 21 64
11 13 3 485 0
11 13 4 106 0
11 13 5 503 0
11 13 6 347 0
11 13 7 535 0
11 13 8 524 0
11 13 9 258 0
11 13 10 21 0
11 13 11 345 0
11 13 12 162 32
11 14 2 84 72
11 14 3 470 8
11 14 4 498 8
11 14 5 286 8
11 14 6 646 126
11 14 7 533 8
11 14 8 646 126
11 14 9 502 8
11 14 10 566 8
11 14 11 575 8
11 14 12 629 40
12 0 2 3 90
12 0 3 3 16
12 0 4 3 58
12 0 10 3 90
12 0 11 3 24
12 0 12 3 58
12 1 3 3 98
12 2 0 3 80
12 2 1 3 16
12 2 2 3 16
12 2 3 3 0
12 2 4 3 16
12 2 5 3 16
12 2 6 3 16
12 2 7 3 16
12 2 8 3 16
12 2 9 3 16
12 2 10 3 16
12 2 11 3 16
12 2 12 3 16
12 2 13 3 16
12 2 14 3 48
12 3 0 3 64
12 3 1 3 0
12 3 2 3 0
12 3 3 3 0
12 3 4 3 0
12 3 5 3 0
12 3 6 3 0
12 3 7 3 0
12 3 8 3 0
12 3 9 3 0
12 3 10 3 0
12 3 11 3 0
12 3 12 3 0
12 3 13 3 0
12 3 14 3 32
12 4 0 3 64
12 4 1 9 0
12 4 2 9 0
12 4 3 9 0
12 4 4 9 0
12 4 5 9 0
12 4 6 9 0
12 4 7 9 0
12 4 8 9 0
12 4 9 9 0
12 4 10 9 0
12 4 11 9 0
12 4 12 9 0
12 4 13 9 0
12 4 14 3 32
12 5 0 151 64
12 5 1 75 0
12 5 2 303 0
12 5 3 361 0
12 5 4 28 0
12 5 5 208 0
12 5 6 185 0
12 5 7 85 0
12 5 8 256 0
12 5 9 182 0
12 5 10 241 0
12 5 11 154 0
12 5 12 118 0
12 5 13 528 0
12 5 14 76 32
12 6 0 591 64
12 6 1 245 0
12 6 2 73 0
12 6 3 361 0
12 6 4 96 0
12 6 5 133 0
12 6 6 163 0
12 6 7 159 0
12 6 8 218 0
12 6 9 506 0
12 6 10 361 0
12 6 11 232 0
12 6 12 184 0
12 6 13 605 0
12 6 14 108 32
12 7 0 188 64
12 7 1 366 0
12 7 2 593 0
12 7 3 80 0
12 7 4 518 0
12 7 5 77 0
12 7 6 471 0
12 7 7 136 0
12 7 8 71 0
12 7 9 52 0
12 7 10 553 0
12 7 11 494 0
12 7 12 140 0
12 7 13 555 0
12 7 14 303 32
12 8 0 285 64
12 8 1 398 0
12 8 2 607 0
12 8 3 364 0
12 8 4 43 0
12 8 5 529 0
12 8 6 109 0
12 8 7 141 0
12 8 8 608 0
12 8 9 71 0
12 8 10 221 0
12 8 11 202 0
12 8 12 16 0
12 8 13 308 0
12 8 14 317 32
12 9 0 467 64
12 9 1 329 0
12 9 2 457 0
12 9 3 390 0
12 9 4 515 0
12 9 5 577 0
12 9 6 232 0
12 9 7 255 0
12 9 8 35 0
12 9 9 209 0
12 9 10 508 0
12 9 11 84 0
12 9 12 94 0
12 9 13 209 0
12 9 14 82 32
12 10 0 610 72
12 10 1 112 8
12 10 2 167 0
12 10 3 596 0
12 10 4 48 0
12 10 5 23 0
12 10 6 126 0
12 10 7 533 0
12 10 8 115 0
12 10 9 565 0
12 10 10 438 0
12 10 11 55 0
12 10 12 153 0
12 10 13 216 8
12 10 14 47 40
12 11 2 55 66
12 11 3 522 2
12 11 4 94 0
12 11 5 325 0
12 11 6 555 0
12 11 7 483 2
12 11 8 131 0
12 11 9 371 0
12 11 10 528 0
12 11 11 55 2
12 11 12 536 34
12 12 2 354 66
12 12 3 157 2
12 12 4 219 0
12 12 5 73 0
12 12 6 63 0
12 12 7 502 2
12 12 8 97 0
12 12 9 520 0
12 12 10 549 0
12 12 11 467 2
12 12 12 617 34
12 13 2 592 66
12 13 3 352 2
12 13 4 301 0
12 13 5 123 2
12 13 6 132 0
12 13 7 418 2
12 13 8 177 0
12 13 9 437 2
12 13 10 239 0
12 13 11 491 2
12 13 12 48 34
12 14 2 578 74
12 14 3 56 10
12 14 4 203 8
12 14 5 249 8
12 14 6 376 8
12 14 7 112 10
12 14 8 617 8
12 14 9 56 8
12 14 10 148 8
12 14 11 329 10
12 14 12 534 42
13 0 3 3 122
13 0 11 3 122
13 2 0 3 80
13 2 1 3 16
13 2 2 3 16
13 2 3 3 16
13 2 4 3 16
13 2 5 3 16
13 2 6 3 16
13 2 7 3 16
13 2 8 3 16
13 2 9 3 16
13 2 10 3 16
13 2 11 3 16
13 2 12 3 16
13 2 13 3 16
13 2 14 3 48
13 3 0 3 64
13 3 1 3 0
13 3 2 3 0
13 3 3 3 0
13 3 4 3 0
13 3 5 3 0
13 3 6 3 0
13 3 7 3 0
13 3 8 3 0
13 3 9 3 0
13 3 10 3 0
13 3 11 3 0
13 3 12 3 0
13 3 13 3 0
13 3 14 3 32
13 4 0 3 64
13 4 1 9 0
13 4 2 9 0
13 4 3 9 0
13 4 4 9 0
13 4 5 9 0
13 4 6 9 0
13 4 7 9 0
13 4 8 9 0
13 4 9 9 0
13 4 10 9 0
13 4 11 9 0
13 4 12 9 0
13 4 13 9 0
13 4 14 3 32
13 5 0 435 64
13 5 1 266 0
13 5 2 567 0
13 5 3 409 0
13 5 4 191 0
13 5 5 0 126
13 5 6 0 126
13 5 7 641 126
13 5 8 0 126
13 5 9 0 126
13 5 10 85 0
13 5 11 41 0
13 5 12 587 0
13 5 13 532 0
13 5 14 33 32
13 6 0 322 64
13 6 1 87 0
13 6 2 242 0
13 6 3 537 0
13 6 4 589 0
13 6 5 0 126
13 6 6 0 126
13 6 7 0 126
13 6 8 0 126
13 6 9 0 126
13 6 10 178 2
13 6 11 176 0
13 6 12 452 0
13 6 13 593 0
13 6 14 385 32
13 7 0 370 64
13 7 1 607 0
13 7 2 280 0
13 7 3 175 0
13 7 4 410 0
13 7 5 606 0
13 7 6 173 0
13 7 7 253 0
13 7 8 531 0
13 7 9 637 0
13 7 10 69 0
13 7 11 103 0
13 7 12 104 0
13 7 13 502 0
13 7 14 557 32
13 8 0 565 64
13 8 1 579 0
13 8 2 492 0
13 8 3 213 0
13 8 4 81 0
13 8 5 563 0
13 8 6 74 0
13 8 7 111 0
13 8 8 608 0
13 8 9 70 0
13 8 10 22 0
13 8 11 380 0
13 8 12 127 0
13 8 13 168 0
13 8 14 564 32
13 9 0 289 64
13 9 1 410 0
13 9 2 231 0
13 9 3 365 0
13 9 4 473 0
13 9 5 152 0
13 9 6 186 0
13 9 7 23 0
13 9 8 558 0
13 9 9 196 0
13 9 10 264 0
13 9 11 90 0
13 9 12 572 0
13 9 13 334 0
13 9 14 556 32
13 10 0 579 72
13 10 1 311 8
13 10 2 325 8
13 10 3 616 8
13 10 4 534 0
13 10 5 39 0
13 10 6 244 0
13 10 7 75 8
13 10 8 201 0
13 10 9 397 0
13 10 10 350 0
13 10 11 630 8
13 10 12 84 8
13 10 13 93 8
13 10 14 437 40
13 11 4 651 66
13 11 5 652 2
13 11 6 658 34
13 11 8 660 66
13 11 9 654 2
13 11 10 656 34
13 12 4 653 66
13 12 5 2 10
13 12 6 657 34
13 12 8 655 66
13 12 9 4 10
13 12 10 660 34
13 13 4 660 98
13 13 6 659 98
13 13 8 660 98
13 13 10 656 98
13 14 4 3 74
13 14 5 3 26
13 14 6 3 42
13 14 8 3 74
13 14 9 3 26
13 14 10 3 42
13 15 5 3 126
13 15 9 3 126
14 2 0 3 82
14 2 1 3 18
14 2 2 3 18
14 2 3 3 18
14 2 4 3 18
14 2 5 3 18
14 2 6 3 18
14 2 7 3 18
14 2 8 3 18
14 2 9 3 18
14 2 10 3 18
14 2 11 3 18
14 2 12 3 18
14 2 13 3 18
14 2 14 3 50
14 3 0 3 66
14 3 1 3 2
14 3 2 3 2
14 3 3 3 2
14 3 4 3 2
14 3 5 3 126
14 3 6 3 126
14 3 7 3 126
14 3 8 3 126
14 3 9 3 126
14 3 10 3 2
14 3 11 3 2
14 3 12 3 2
14 3 13 3 2
14 3 14 3 34
14 4 0 3 66
14 4 1 3 2
14 4 2 3 2
14 4 3 3 2
14 4 4 1 126
14 4 5 1 126
14 4 6 1 126
14 4 7 1 126
14 4 8 1 126
14 4 9 1 126
14 4 10 1 126
14 4 11 3 2
14 4 12 3 2
14 4 13 3 2
14 4 14 3 34
14 5 0 108 66
14 5 1 583 2
14 5 2 620 2
14 5 3 306 2
14 5 4 1 126
14 5 10 1 126
14 5 11 415 2
14 5 12 111 2
14 5 13 549 2
14 5 14 199 34
14 6 0 427 66
14 6 1 307 2
14 6 2 521 2
14 6 3 441 2
14 6 4 1 126
14 6 10 1 126
14 6 11 15 66
14 6 12 19 2
14 6 13 338 2
14 6 14 42 34
14 7 0 325 66
14 7 1 600 2
14 7 2 593 2
14 7 3 20 2
14 7 4 1 126
14 7 5 1 126
14 7 6 1 126
14 7 7 1 126
14 7 8 1 126
14 7 9 1 126
14 7 10 1 126
14 7 11 13 2
14 7 12 442 2
14 7 13 129 2
14 7 14 149 34
14 8 0 491 66
14 8 1 55 2
14 8 2 577 2
14 8 3 441 2
14 8 4 49 2
14 8 5 631 2
14 8 6 145 2
14 8 7 518 2
14 8 8 383 2
14 8 9 504 2
14 8 10 33 2
14 8 11 11 2
14 8 12 41 2
14 8 13 86 2
14 8 14 42 34
14 9 0 53 66
14 9 1 91 2
14 9 2 502 2
14 9 3 609 2
14 9 4 254 2
14 9 5 433 2
14 9 6 639 2
14 9 7 644 2
14 9 8 640 2
14 9 9 143 2
14 9 10 176 2
14 9 11 389 2
14 9 12 78 2
14 9 13 301 2
14 9 14 521 34
14 10 0 613 74
14 10 1 463 10
14 10 2 647 10
14 10 3 642 10
14 10 4 644 10
14 10 5 643 10
14 10 6 203 10
14 10 7 356 10
14 10 8 605 10
14 10 9 645 10
14 10 10 650 10
14 10 11 648 10
14 10 12 647 10
14 10 13 622 10
14 10 14 604 42
