Qubicle Exchange Format
Version 0.2
www.minddesk.com
16 16 16
683
0.039216 0.133333 0.043137
0.184314 0.129412 0.011765
0.192157 0.286275 0.023529
0.192157 0.290196 0.023529
0.196078 0.290196 0.023529
0.196078 0.294118 0.023529
0.200000 0.298039 0.027451
0.203922 0.301961 0.031373
0.207843 0.301961 0.035294
0.207843 0.305882 0.039216
0.211765 0.309804 0.043137
0.215686 0.309804 0.047059
0.219608 0.313726 0.050980
0.223529 0.317647 0.054902
0.223529 0.317647 0.058824
0.278431 0.419608 0.023529
0.278431 0.423529 0.023529
0.282353 0.427451 0.023529
0.282353 0.431373 0.023529
0.286275 0.431373 0.023529
0.286275 0.435294 0.023529
0.290196 0.439216 0.027451
0.294118 0.439216 0.031373
0.294118 0.443137 0.035294
0.298039 0.443137 0.039216
0.301961 0.447059 0.043137
0.301961 0.447059 0.047059
0.305882 0.450980 0.050980
0.309804 0.454902 0.054902
0.313726 0.454902 0.058824
0.376471 0.564706 0.039216
0.376471 0.568627 0.039216
0.376471 0.572549 0.039216
0.388235 0.588235 0.039216
0.400000 0.603922 0.043137
0.400000 0.603922 0.047059
0.407843 0.631373 0.015686
0.419608 0.647059 0.015686
0.419608 0.650980 0.015686
0.423529 0.615686 0.082353
0.423529 0.654902 0.023529
0.431373 0.658824 0.035294
0.435294 0.627451 0.105882
0.439216 0.662745 0.047059
0.443137 0.698039 0.000000
0.447059 0.698039 0.000000
0.447059 0.701961 0.000000
0.450980 0.705882 0.000000
0.454902 0.670588 0.078431
0.458824 0.713726 0.003922
0.458824 0.717647 0.000000
0.458824 0.717647 0.003922
0.458824 0.721569 0.000000
0.458824 0.721569 0.003922
0.462745 0.713726 0.019608
0.462745 0.717647 0.003922
0.462745 0.717647 0.011765
0.462745 0.717647 0.023529
0.462745 0.721569 0.000000
0.462745 0.721569 0.003922
0.462745 0.725490 0.000000
0.462745 0.725490 0.003922
0.462745 0.729412 0.003922
0.466667 0.725490 0.003922
0.466667 0.729412 0.000000
0.466667 0.729412 0.003922
0.466667 0.733333 0.000000
0.466667 0.737255 0.003922
0.470588 0.729412 0.000000
0.470588 0.733333 0.000000
0.470588 0.733333 0.003922
0.470588 0.737255 0.000000
0.470588 0.737255 0.003922
0.470588 0.741176 0.003922
0.474510 0.737255 0.000000
0.474510 0.737255 0.003922
0.474510 0.741176 0.003922
0.474510 0.745098 0.000000
0.474510 0.745098 0.003922
0.474510 0.749020 0.003922
0.478431 0.729412 0.043137
0.478431 0.741176 0.003922
0.478431 0.745098 0.000000
0.478431 0.745098 0.003922
0.478431 0.749020 0.003922
0.478431 0.752941 0.000000
0.478431 0.752941 0.003922
0.482353 0.733333 0.047059
0.482353 0.749020 0.003922
0.482353 0.749020 0.015686
0.482353 0.752941 0.000000
0.482353 0.752941 0.003922
0.482353 0.752941 0.007843
0.482353 0.756863 0.003922
0.482353 0.760784 0.003922
0.486275 0.749020 0.015686
0.486275 0.752941 0.000000
0.486275 0.752941 0.003922
0.486275 0.752941 0.011765
0.486275 0.752941 0.015686
0.486275 0.756863 0.003922
0.486275 0.760784 0.003922
0.486275 0.764706 0.000000
0.486275 0.764706 0.003922
0.486275 0.768627 0.003922
0.490196 0.745098 0.035294
0.490196 0.745098 0.043137
0.490196 0.749020 0.031373
0.490196 0.756863 0.023529
0.490196 0.756863 0.035294
0.490196 0.760784 0.003922
0.490196 0.760784 0.007843
0.490196 0.764706 0.003922
0.490196 0.768627 0.000000
0.490196 0.768627 0.003922
0.490196 0.772549 0.003922
0.494118 0.745098 0.050980
0.494118 0.756863 0.027451
0.494118 0.764706 0.000000
0.494118 0.764706 0.003922
0.494118 0.768627 0.000000
0.494118 0.768627 0.003922
0.494118 0.772549 0.003922
0.494118 0.772549 0.007843
0.494118 0.776471 0.000000
0.494118 0.776471 0.003922
0.498039 0.741176 0.070588
0.498039 0.749020 0.062745
0.498039 0.752941 0.027451
0.498039 0.756863 0.043137
0.498039 0.760784 0.023529
0.498039 0.760784 0.035294
0.498039 0.768627 0.015686
0.498039 0.768627 0.023529
0.498039 0.772549 0.003922
0.498039 0.772549 0.015686
0.498039 0.776471 0.003922
0.498039 0.776471 0.007843
0.498039 0.776471 0.015686
0.498039 0.780392 0.000000
0.498039 0.780392 0.003922
0.498039 0.780392 0.007843
0.498039 0.784314 0.000000
0.498039 0.784314 0.003922
0.501961 0.752941 0.050980
0.501961 0.752941 0.054902
0.501961 0.756863 0.039216
0.501961 0.756863 0.058824
0.501961 0.768627 0.035294
0.501961 0.772549 0.023529
0.501961 0.776471 0.011765
0.501961 0.776471 0.015686
0.501961 0.776471 0.019608
0.501961 0.776471 0.023529
0.501961 0.780392 0.003922
0.501961 0.780392 0.007843
0.501961 0.780392 0.011765
0.501961 0.780392 0.015686
0.501961 0.780392 0.019608
0.501961 0.784314 0.003922
0.501961 0.784314 0.007843
0.501961 0.784314 0.011765
0.501961 0.788235 0.003922
0.501961 0.792157 0.003922
0.505882 0.756863 0.058824
0.505882 0.760784 0.047059
0.505882 0.760784 0.062745
0.505882 0.764706 0.039216
0.505882 0.768627 0.043137
0.505882 0.772549 0.031373
0.505882 0.776471 0.019608
0.505882 0.776471 0.023529
0.505882 0.776471 0.027451
0.505882 0.776471 0.031373
0.505882 0.776471 0.039216
0.505882 0.780392 0.019608
0.505882 0.780392 0.023529
0.505882 0.780392 0.027451
0.505882 0.784314 0.011765
0.505882 0.784314 0.015686
0.505882 0.784314 0.023529
0.505882 0.788235 0.003922
0.505882 0.788235 0.007843
0.505882 0.788235 0.011765
0.505882 0.788235 0.015686
0.505882 0.792157 0.003922
0.505882 0.792157 0.007843
0.505882 0.796078 0.000000
0.505882 0.796078 0.003922
0.509804 0.756863 0.070588
0.509804 0.776471 0.031373
0.509804 0.776471 0.043137
0.509804 0.776471 0.047059
0.509804 0.780392 0.031373
0.509804 0.780392 0.039216
0.509804 0.780392 0.047059
0.509804 0.784314 0.023529
0.509804 0.784314 0.027451
0.509804 0.784314 0.031373
0.509804 0.788235 0.019608
0.509804 0.788235 0.023529
0.509804 0.792157 0.003922
0.509804 0.792157 0.015686
0.509804 0.792157 0.019608
0.509804 0.796078 0.003922
0.509804 0.796078 0.011765
0.509804 0.796078 0.015686
0.509804 0.800000 0.003922
0.509804 0.803922 0.000000
0.513726 0.764706 0.066667
0.513726 0.772549 0.066667
0.513726 0.776471 0.043137
0.513726 0.780392 0.035294
0.513726 0.780392 0.039216
0.513726 0.780392 0.043137
0.513726 0.780392 0.047059
0.513726 0.780392 0.050980
0.513726 0.780392 0.054902
0.513726 0.784314 0.035294
0.513726 0.784314 0.039216
0.513726 0.788235 0.023529
0.513726 0.788235 0.027451
0.513726 0.788235 0.031373
0.513726 0.788235 0.039216
0.513726 0.792157 0.023529
0.513726 0.792157 0.027451
0.513726 0.796078 0.007843
0.513726 0.796078 0.011765
0.513726 0.796078 0.015686
0.513726 0.796078 0.019608
0.513726 0.796078 0.023529
0.513726 0.800000 0.003922
0.513726 0.800000 0.007843
0.513726 0.800000 0.015686
0.513726 0.803922 0.000000
0.513726 0.803922 0.003922
0.513726 0.803922 0.007843
0.513726 0.807843 0.003922
0.517647 0.772549 0.070588
0.517647 0.776471 0.047059
0.517647 0.780392 0.047059
0.517647 0.780392 0.050980
0.517647 0.780392 0.058824
0.517647 0.780392 0.062745
0.517647 0.784314 0.039216
0.517647 0.784314 0.047059
0.517647 0.784314 0.050980
0.517647 0.784314 0.054902
0.517647 0.792157 0.035294
0.517647 0.792157 0.039216
0.517647 0.796078 0.027451
0.517647 0.796078 0.039216
0.517647 0.800000 0.011765
0.517647 0.800000 0.027451
0.517647 0.800000 0.031373
0.517647 0.803922 0.007843
0.517647 0.803922 0.011765
0.517647 0.807843 0.003922
0.517647 0.807843 0.007843
0.517647 0.811765 0.003922
0.517647 0.811765 0.007843
0.517647 0.815686 0.003922
0.521569 0.772549 0.070588
0.521569 0.780392 0.058824
0.521569 0.780392 0.066667
0.521569 0.784314 0.050980
0.521569 0.784314 0.054902
0.521569 0.784314 0.058824
0.521569 0.784314 0.062745
0.521569 0.788235 0.047059
0.521569 0.788235 0.054902
0.521569 0.788235 0.058824
0.521569 0.792157 0.043137
0.521569 0.792157 0.054902
0.521569 0.796078 0.035294
0.521569 0.796078 0.039216
0.521569 0.796078 0.047059
0.521569 0.800000 0.015686
0.521569 0.800000 0.019608
0.521569 0.800000 0.027451
0.521569 0.800000 0.031373
0.521569 0.800000 0.035294
0.521569 0.800000 0.039216
0.521569 0.803922 0.019608
0.521569 0.803922 0.023529
0.521569 0.803922 0.027451
0.521569 0.803922 0.031373
0.521569 0.807843 0.011765
0.521569 0.807843 0.023529
0.521569 0.807843 0.027451
0.521569 0.811765 0.003922
0.521569 0.811765 0.011765
0.521569 0.811765 0.015686
0.521569 0.811765 0.019608
0.521569 0.815686 0.003922
0.521569 0.815686 0.007843
0.521569 0.819608 0.003922
0.525490 0.780392 0.066667
0.525490 0.780392 0.070588
0.525490 0.780392 0.078431
0.525490 0.784314 0.062745
0.525490 0.784314 0.066667
0.525490 0.784314 0.074510
0.525490 0.788235 0.058824
0.525490 0.788235 0.062745
0.525490 0.788235 0.066667
0.525490 0.792157 0.054902
0.525490 0.792157 0.058824
0.525490 0.792157 0.062745
0.525490 0.796078 0.043137
0.525490 0.796078 0.054902
0.525490 0.800000 0.035294
0.525490 0.800000 0.039216
0.525490 0.800000 0.043137
0.525490 0.803922 0.027451
0.525490 0.803922 0.031373
0.525490 0.803922 0.035294
0.525490 0.803922 0.039216
0.525490 0.803922 0.047059
0.525490 0.807843 0.027451
0.525490 0.807843 0.031373
0.525490 0.811765 0.019608
0.525490 0.811765 0.023529
0.525490 0.811765 0.031373
0.525490 0.815686 0.011765
0.525490 0.815686 0.015686
0.525490 0.819608 0.003922
0.525490 0.819608 0.007843
0.525490 0.823529 0.003922
0.525490 0.827451 0.003922
0.529412 0.784314 0.070588
0.529412 0.784314 0.074510
0.529412 0.788235 0.066667
0.529412 0.788235 0.070588
0.529412 0.788235 0.074510
0.529412 0.792157 0.062745
0.529412 0.792157 0.066667
0.529412 0.792157 0.074510
0.529412 0.796078 0.058824
0.529412 0.796078 0.062745
0.529412 0.800000 0.043137
0.529412 0.800000 0.047059
0.529412 0.800000 0.054902
0.529412 0.800000 0.066667
0.529412 0.803922 0.035294
0.529412 0.803922 0.039216
0.529412 0.803922 0.047059
0.529412 0.803922 0.054902
0.529412 0.807843 0.035294
0.529412 0.807843 0.050980
0.529412 0.811765 0.027451
0.529412 0.811765 0.031373
0.529412 0.815686 0.015686
0.529412 0.815686 0.019608
0.529412 0.815686 0.023529
0.529412 0.815686 0.027451
0.529412 0.815686 0.031373
0.529412 0.819608 0.015686
0.529412 0.823529 0.011765
0.529412 0.823529 0.015686
0.529412 0.827451 0.003922
0.529412 0.827451 0.007843
0.529412 0.831373 0.003922
0.529412 0.831373 0.007843
0.533333 0.784314 0.094118
0.533333 0.796078 0.066667
0.533333 0.796078 0.070588
0.533333 0.796078 0.074510
0.533333 0.796078 0.078431
0.533333 0.800000 0.066667
0.533333 0.800000 0.070588
0.533333 0.803922 0.050980
0.533333 0.803922 0.054902
0.533333 0.803922 0.058824
0.533333 0.803922 0.062745
0.533333 0.803922 0.066667
0.533333 0.807843 0.043137
0.533333 0.807843 0.047059
0.533333 0.807843 0.050980
0.533333 0.807843 0.054902
0.533333 0.807843 0.062745
0.533333 0.811765 0.035294
0.533333 0.811765 0.039216
0.533333 0.811765 0.043137
0.533333 0.811765 0.050980
0.533333 0.815686 0.023529
0.533333 0.815686 0.035294
0.533333 0.815686 0.039216
0.533333 0.819608 0.019608
0.533333 0.819608 0.023529
0.533333 0.819608 0.027451
0.533333 0.819608 0.031373
0.533333 0.823529 0.019608
0.533333 0.823529 0.023529
0.533333 0.827451 0.011765
0.533333 0.827451 0.015686
0.533333 0.827451 0.023529
0.533333 0.831373 0.011765
0.533333 0.831373 0.015686
0.533333 0.831373 0.019608
0.533333 0.835294 0.003922
0.533333 0.835294 0.007843
0.533333 0.835294 0.011765
0.537255 0.792157 0.086275
0.537255 0.800000 0.066667
0.537255 0.800000 0.070588
0.537255 0.800000 0.074510
0.537255 0.800000 0.078431
0.537255 0.800000 0.086275
0.537255 0.800000 0.090196
0.537255 0.803922 0.058824
0.537255 0.803922 0.066667
0.537255 0.803922 0.070588
0.537255 0.803922 0.078431
0.537255 0.807843 0.050980
0.537255 0.807843 0.066667
0.537255 0.807843 0.070588
0.537255 0.811765 0.047059
0.537255 0.811765 0.050980
0.537255 0.811765 0.054902
0.537255 0.815686 0.039216
0.537255 0.815686 0.043137
0.537255 0.815686 0.047059
0.537255 0.815686 0.058824
0.537255 0.819608 0.035294
0.537255 0.819608 0.039216
0.537255 0.819608 0.043137
0.537255 0.819608 0.047059
0.537255 0.823529 0.027451
0.537255 0.823529 0.031373
0.537255 0.827451 0.019608
0.537255 0.827451 0.023529
0.537255 0.827451 0.027451
0.537255 0.827451 0.031373
0.537255 0.831373 0.019608
0.537255 0.831373 0.023529
0.537255 0.835294 0.011765
0.537255 0.835294 0.015686
0.537255 0.835294 0.019608
0.541176 0.803922 0.074510
0.541176 0.803922 0.078431
0.541176 0.807843 0.058824
0.541176 0.807843 0.066667
0.541176 0.807843 0.070588
0.541176 0.807843 0.074510
0.541176 0.807843 0.078431
0.541176 0.811765 0.058824
0.541176 0.811765 0.062745
0.541176 0.811765 0.066667
0.541176 0.815686 0.050980
0.541176 0.819608 0.039216
0.541176 0.819608 0.043137
0.541176 0.819608 0.054902
0.541176 0.823529 0.039216
0.541176 0.823529 0.047059
0.541176 0.823529 0.050980
0.541176 0.827451 0.031373
0.541176 0.827451 0.035294
0.541176 0.827451 0.039216
0.541176 0.831373 0.023529
0.541176 0.831373 0.027451
0.541176 0.831373 0.031373
0.541176 0.835294 0.019608
0.541176 0.835294 0.023529
0.541176 0.835294 0.027451
0.541176 0.835294 0.031373
0.541176 0.843137 0.011765
0.545098 0.796078 0.109804
0.545098 0.800000 0.105882
0.545098 0.807843 0.074510
0.545098 0.807843 0.078431
0.545098 0.811765 0.066667
0.545098 0.811765 0.070588
0.545098 0.811765 0.074510
0.545098 0.811765 0.078431
0.545098 0.815686 0.062745
0.545098 0.815686 0.066667
0.545098 0.815686 0.070588
0.545098 0.815686 0.074510
0.545098 0.819608 0.058824
0.545098 0.819608 0.062745
0.545098 0.819608 0.066667
0.545098 0.823529 0.043137
0.545098 0.823529 0.047059
0.545098 0.823529 0.054902
0.545098 0.823529 0.058824
0.545098 0.827451 0.043137
0.545098 0.827451 0.050980
0.545098 0.831373 0.035294
0.545098 0.831373 0.039216
0.545098 0.831373 0.047059
0.545098 0.831373 0.050980
0.545098 0.835294 0.027451
0.545098 0.835294 0.031373
0.545098 0.835294 0.035294
0.545098 0.835294 0.039216
0.545098 0.835294 0.043137
0.545098 0.839216 0.027451
0.545098 0.839216 0.031373
0.545098 0.839216 0.035294
0.549020 0.792157 0.117647
0.549020 0.796078 0.105882
0.549020 0.811765 0.078431
0.549020 0.815686 0.074510
0.549020 0.815686 0.078431
0.549020 0.819608 0.066667
0.549020 0.819608 0.070588
0.549020 0.819608 0.074510
0.549020 0.819608 0.078431
0.549020 0.823529 0.058824
0.549020 0.823529 0.062745
0.549020 0.823529 0.066667
0.549020 0.823529 0.070588
0.549020 0.827451 0.047059
0.549020 0.827451 0.050980
0.549020 0.827451 0.054902
0.549020 0.831373 0.043137
0.549020 0.831373 0.047059
0.549020 0.831373 0.050980
0.549020 0.831373 0.054902
0.549020 0.831373 0.058824
0.549020 0.835294 0.035294
0.549020 0.835294 0.039216
0.549020 0.835294 0.043137
0.549020 0.835294 0.047059
0.549020 0.835294 0.050980
0.549020 0.839216 0.035294
0.549020 0.839216 0.039216
0.549020 0.839216 0.043137
0.549020 0.839216 0.047059
0.552941 0.811765 0.090196
0.552941 0.811765 0.098039
0.552941 0.819608 0.082353
0.552941 0.823529 0.070588
0.552941 0.823529 0.074510
0.552941 0.823529 0.078431
0.552941 0.827451 0.054902
0.552941 0.827451 0.062745
0.552941 0.827451 0.066667
0.552941 0.827451 0.070588
0.552941 0.827451 0.074510
0.552941 0.831373 0.058824
0.552941 0.831373 0.066667
0.552941 0.835294 0.054902
0.552941 0.835294 0.058824
0.552941 0.839216 0.043137
0.552941 0.839216 0.047059
0.552941 0.839216 0.050980
0.552941 0.839216 0.054902
0.552941 0.839216 0.058824
0.552941 0.843137 0.050980
0.552941 0.843137 0.054902
0.556863 0.800000 0.133333
0.556863 0.827451 0.078431
0.556863 0.831373 0.074510
0.556863 0.835294 0.062745
0.556863 0.835294 0.066667
0.556863 0.835294 0.074510
0.556863 0.839216 0.050980
0.556863 0.839216 0.054902
0.556863 0.839216 0.058824
0.556863 0.839216 0.062745
0.556863 0.839216 0.066667
0.556863 0.843137 0.054902
0.556863 0.843137 0.058824
0.556863 0.843137 0.062745
0.560784 0.803922 0.133333
0.560784 0.815686 0.105882
0.560784 0.819608 0.113725
0.560784 0.823529 0.105882
0.560784 0.827451 0.098039
0.560784 0.835294 0.070588
0.560784 0.835294 0.074510
0.560784 0.835294 0.078431
0.560784 0.839216 0.058824
0.560784 0.839216 0.062745
0.560784 0.839216 0.066667
0.560784 0.839216 0.070588
0.560784 0.839216 0.074510
0.560784 0.839216 0.078431
0.560784 0.843137 0.062745
0.560784 0.843137 0.066667
0.560784 0.843137 0.070588
0.560784 0.843137 0.074510
0.564706 0.815686 0.121569
0.564706 0.839216 0.078431
0.564706 0.839216 0.082353
0.564706 0.839216 0.086275
0.564706 0.839216 0.090196
0.564706 0.843137 0.066667
0.564706 0.843137 0.070588
0.564706 0.843137 0.074510
0.564706 0.843137 0.078431
0.564706 0.847059 0.074510
0.564706 0.847059 0.078431
0.564706 0.847059 0.082353
0.568627 0.823529 0.117647
0.568627 0.835294 0.105882
0.568627 0.839216 0.086275
0.568627 0.843137 0.078431
0.568627 0.843137 0.082353
0.568627 0.843137 0.086275
0.568627 0.847059 0.078431
0.568627 0.847059 0.082353
0.568627 0.847059 0.086275
0.568627 0.847059 0.090196
0.572549 0.835294 0.113725
0.572549 0.843137 0.086275
0.572549 0.843137 0.090196
0.572549 0.843137 0.094118
0.572549 0.847059 0.086275
0.572549 0.847059 0.090196
0.572549 0.847059 0.094118
0.572549 0.847059 0.098039
0.576471 0.843137 0.098039
0.576471 0.847059 0.094118
0.576471 0.847059 0.098039
0.576471 0.847059 0.101961
0.576471 0.847059 0.105882
0.576471 0.847059 0.109804
0.576471 0.850980 0.101961
0.576471 0.850980 0.105882
0.580392 0.843137 0.109804
0.580392 0.843137 0.113725
0.580392 0.847059 0.105882
0.580392 0.847059 0.109804
0.580392 0.847059 0.113725
0.580392 0.850980 0.105882
0.580392 0.850980 0.109804
0.580392 0.850980 0.113725
0.584314 0.847059 0.113725
0.584314 0.847059 0.117647
0.584314 0.847059 0.125490
0.584314 0.850980 0.113725
0.584314 0.850980 0.117647
0.584314 0.850980 0.121569
0.584314 0.854902 0.121569
0.588235 0.847059 0.125490
0.588235 0.850980 0.117647
0.588235 0.850980 0.121569
0.588235 0.850980 0.125490
0.588235 0.850980 0.129412
0.588235 0.850980 0.137255
0.588235 0.854902 0.125490
0.592157 0.850980 0.129412
0.592157 0.850980 0.133333
0.592157 0.850980 0.137255
0.592157 0.850980 0.141176
0.592157 0.854902 0.129412
0.592157 0.854902 0.133333
0.592157 0.854902 0.137255
0.596078 0.850980 0.141176
0.596078 0.854902 0.141176
0.596078 0.854902 0.145098
0.600000 0.850980 0.156863
0.600000 0.850980 0.160784
0.600000 0.854902 0.145098
0.600000 0.854902 0.149020
0.603922 0.854902 0.164706
0.607843 0.850980 0.172549
0.607843 0.854902 0.172549
0.678431 0.294118 0.074510
0.737255 0.333333 0.101961
0.745098 0.023529 0.023529
0.819608 0.352941 0.086275
0.854902 0.368627 0.090196
0.858824 0.368627 0.090196
0.870588 0.376471 0.090196
0.890196 0.094118 0.094118
0.890196 0.403922 0.125490
0.890196 0.411765 0.137255
0.890196 0.619608 0.094118
0.894118 0.427451 0.160784
0.901961 0.901961 0.901961
0.917647 0.917647 0.917647
0.921569 0.921569 0.921569
0.925490 0.925490 0.925490
0.937255 0.937255 0.937255
0.960784 0.960784 0.960784
0.964706 0.964706 0.964706
0.968627 0.968627 0.968627
0.988235 0.988235 0.988235
0.992157 0.992157 0.992157
0 2 1 5 84
0 2 2 2 20
0 2 3 5 20
0 2 4 4 20
0 2 5 12 20
0 2 6 13 20
0 2 7 14 20
0 2 8 12 20
0 2 9 5 20
0 2 10 8 20
0 2 11 4 20
0 2 12 2 20
0 2 13 5 20
0 2 14 3 52
0 3 1 20 68
0 3 2 18 4
0 3 3 28 4
0 3 4 28 4
0 3 5 29 4
0 3 6 27 4
0 3 7 23 4
0 3 8 20 4
0 3 9 20 4
0 3 10 20 4
0 3 11 20 4
0 3 12 19 4
0 3 13 28 4
0 3 14 23 36
0 4 1 16 68
0 4 2 20 4
0 4 3 20 4
0 4 4 16 4
0 4 5 26 4
0 4 6 18 4
0 4 7 20 4
0 4 8 20 4
0 4 9 16 4
0 4 10 19 4
0 4 11 28 4
0 4 12 22 4
0 4 13 25 4
0 4 14 16 36
0 5 1 136 68
0 5 2 460 4
0 5 3 179 4
0 5 4 604 4
0 5 5 386 4
0 5 6 594 4
0 5 7 542 4
0 5 8 542 4
0 5 9 564 4
0 5 10 257 4
0 5 11 590 4
0 5 12 514 4
0 5 13 599 4
0 5 14 266 36
0 6 1 452 68
0 6 2 347 4
0 6 3 615 4
0 6 4 593 4
0 6 5 458 4
0 6 6 550 4
0 6 7 185 4
0 6 8 185 4
0 6 9 593 4
0 6 10 280 4
0 6 11 463 4
0 6 12 122 4
0 6 13 344 4
0 6 14 544 36
0 7 1 350 68
0 7 2 395 4
0 7 3 214 4
0 7 4 591 4
0 7 5 453 4
0 7 6 435 4
0 7 7 437 4
0 7 8 437 4
0 7 9 627 4
0 7 10 387 4
0 7 11 416 4
0 7 12 256 4
0 7 13 121 4
0 7 14 398 36
0 8 1 516 68
0 8 2 590 4
0 8 3 310 4
0 8 4 640 4
0 8 5 361 4
0 8 6 235 4
0 8 7 122 4
0 8 8 122 4
0 8 9 488 4
0 8 10 602 4
0 8 11 136 4
0 8 12 101 4
0 8 13 590 4
0 8 14 463 36
0 9 1 81 68
0 9 2 314 4
0 9 3 492 4
0 9 4 62 4
0 9 5 611 4
0 9 6 125 4
0 9 7 497 4
0 9 8 497 4
0 9 9 122 4
0 9 10 656 4
0 9 11 604 4
0 9 12 76 4
0 9 13 245 4
0 9 14 355 36
0 10 1 636 76
0 10 2 604 12
0 10 3 633 12
0 10 4 435 12
0 10 5 582 12
0 10 6 591 12
0 10 7 300 12
0 10 8 300 12
0 10 9 140 12
0 10 10 581 12
0 10 11 122 12
0 10 12 356 12
0 10 13 442 12
0 10 14 581 44
1 2 1 14 80
1 2 2 16 16
1 2 3 16 16
1 2 4 16 16
1 2 5 20 16
1 2 6 17 16
1 2 7 25 16
1 2 8 16 16
1 2 9 21 16
1 2 10 17 16
1 2 11 28 16
1 2 12 18 16
1 2 13 16 16
1 2 14 10 48
1 3 1 21 64
1 3 2 23 0
1 3 3 22 0
1 3 4 16 0
1 3 5 29 0
1 3 6 20 0
1 3 7 25 0
1 3 8 15 0
1 3 9 19 0
1 3 10 17 0
1 3 11 27 0
1 3 12 17 0
1 3 13 16 0
1 3 14 22 32
1 4 1 24 64
1 4 2 34 0
1 4 3 34 0
1 4 4 34 0
1 4 5 34 0
1 4 6 34 0
1 4 7 34 0
1 4 8 34 0
1 4 9 34 0
1 4 10 34 0
1 4 11 34 0
1 4 12 34 0
1 4 13 34 0
1 4 14 34 32
1 5 1 608 64
1 5 2 291 0
1 5 3 103 0
1 5 4 137 0
1 5 5 366 0
1 5 6 59 0
1 5 7 547 0
1 5 8 547 0
1 5 9 357 0
1 5 10 439 0
1 5 11 362 0
1 5 12 76 0
1 5 13 78 0
1 5 14 140 32
1 6 1 332 64
1 6 2 115 0
1 6 3 271 0
1 6 4 581 0
1 6 5 91 0
1 6 6 62 0
1 6 7 410 0
1 6 8 410 0
1 6 9 616 0
1 6 10 348 0
1 6 11 612 0
1 6 12 527 0
1 6 13 634 0
1 6 14 590 32
1 7 1 624 64
1 7 2 630 0
1 7 3 391 0
1 7 4 547 0
1 7 5 91 0
1 7 6 462 0
1 7 7 539 0
1 7 8 539 0
1 7 9 121 0
1 7 10 469 0
1 7 11 125 0
1 7 12 397 0
1 7 13 281 0
1 7 14 248 32
1 8 1 83 64
1 8 2 604 0
1 8 3 423 0
1 8 4 406 0
1 8 5 336 0
1 8 6 341 0
1 8 7 591 0
1 8 8 591 0
1 8 9 407 0
1 8 10 432 0
1 8 11 463 0
1 8 12 51 0
1 8 13 79 0
1 8 14 433 32
1 9 1 119 64
1 9 2 435 0
1 9 3 354 0
1 9 4 274 0
1 9 5 297 0
1 9 6 121 0
1 9 7 639 0
1 9 8 639 0
1 9 9 76 0
1 9 10 55 0
1 9 11 314 0
1 9 12 410 0
1 9 13 412 0
1 9 14 463 32
1 10 1 488 72
1 10 2 336 8
1 10 3 140 8
1 10 4 523 8
1 10 5 125 8
1 10 6 295 8
1 10 7 350 8
1 10 8 350 8
1 10 9 527 8
1 10 10 72 8
1 10 11 465 8
1 10 12 175 8
1 10 13 121 8
1 10 14 382 40
2 0 3 23 92
2 0 4 23 60
2 0 12 17 92
2 0 13 20 60
2 2 1 5 80
2 2 2 24 16
2 2 3 28 16
2 2 4 26 16
2 2 5 28 16
2 2 6 19 16
2 2 7 17 16
2 2 8 18 16
2 2 9 28 16
2 2 10 17 16
2 2 11 17 16
2 2 12 16 16
2 2 13 25 16
2 2 14 3 48
2 3 1 21 64
2 3 2 19 0
2 3 3 21 0
2 3 4 17 0
2 3 5 22 0
2 3 6 21 0
2 3 7 17 0
2 3 8 20 0
2 3 9 23 0
2 3 10 25 0
2 3 11 24 0
2 3 12 16 0
2 3 13 17 0
2 3 14 27 32
2 4 1 38 64
2 4 2 34 0
2 4 3 34 0
2 4 4 34 0
2 4 5 34 0
2 4 6 34 0
2 4 7 34 0
2 4 8 34 0
2 4 9 34 0
2 4 10 34 0
2 4 11 34 0
2 4 12 34 0
2 4 13 34 0
2 4 14 34 32
2 5 1 643 64
2 5 2 592 0
2 5 3 328 0
2 5 4 65 0
2 5 5 278 0
2 5 6 464 0
2 5 7 333 0
2 5 8 333 0
2 5 9 470 0
2 5 10 276 0
2 5 11 83 0
2 5 12 638 0
2 5 13 365 0
2 5 14 610 32
2 6 1 546 64
2 6 2 268 0
2 6 3 101 0
2 6 4 284 0
2 6 5 259 0
2 6 6 326 0
2 6 7 185 0
2 6 8 185 0
2 6 9 607 0
2 6 10 628 0
2 6 11 462 0
2 6 12 351 0
2 6 13 326 0
2 6 14 359 32
2 7 1 617 64
2 7 2 305 0
2 7 3 617 0
2 7 4 162 0
2 7 5 604 0
2 7 6 303 0
2 7 7 94 0
2 7 8 94 0
2 7 9 240 0
2 7 10 246 0
2 7 11 441 0
2 7 12 270 0
2 7 13 278 0
2 7 14 232 32
2 8 1 602 64
2 8 2 517 0
2 8 3 630 0
2 8 4 612 0
2 8 5 523 0
2 8 6 206 0
2 8 7 518 0
2 8 8 518 0
2 8 9 651 0
2 8 10 599 0
2 8 11 112 0
2 8 12 136 0
2 8 13 601 0
2 8 14 590 32
2 9 1 527 64
2 9 2 257 0
2 9 3 482 0
2 9 4 188 0
2 9 5 253 0
2 9 6 476 0
2 9 7 83 0
2 9 8 83 0
2 9 9 304 0
2 9 10 311 0
2 9 11 207 0
2 9 12 546 0
2 9 13 121 0
2 9 14 140 32
2 10 1 669 72
2 10 2 350 8
2 10 3 195 0
2 10 4 393 0
2 10 5 572 0
2 10 6 373 0
2 10 7 656 0
2 10 8 656 0
2 10 9 633 0
2 10 10 301 0
2 10 11 462 0
2 10 12 573 0
2 10 13 328 0
2 10 14 610 32
2 11 3 83 68
2 11 4 464 4
2 11 5 581 4
2 11 6 590 4
2 11 7 618 4
2 11 8 618 4
2 11 9 317 4
2 11 10 519 4
2 11 11 76 4
2 11 12 331 4
2 11 13 413 4
2 11 14 101 36
2 12 3 379 68
2 12 4 401 4
2 12 5 93 4
2 12 6 333 4
2 12 7 525 4
2 12 8 525 4
2 12 9 78 4
2 12 10 81 4
2 12 11 159 4
2 12 12 374 4
2 12 13 565 4
2 12 14 633 36
2 13 3 616 68
2 13 4 49 4
2 13 5 97 4
2 13 6 563 4
2 13 7 454 4
2 13 8 454 4
2 13 9 156 4
2 13 10 592 4
2 13 11 112 4
2 13 12 219 4
2 13 13 191 4
2 13 14 218 36
2 14 3 603 76
2 14 4 112 12
2 14 5 582 12
2 14 6 581 12
2 14 7 527 12
2 14 8 527 12
2 14 9 242 12
2 14 10 580 12
2 14 11 633 12
2 14 12 524 12
2 14 13 290 12
2 14 14 499 44
3 0 2 18 94
3 0 3 29 16
3 0 4 28 16
3 0 5 29 62
3 0 11 17 94
3 0 12 25 16
3 0 13 20 16
3 0 14 15 62
3 1 3 15 70
3 1 4 21 38
3 1 12 18 70
3 1 13 20 38
3 2 1 14 80
3 2 2 17 16
3 2 3 20 0
3 2 4 21 0
3 2 5 17 16
3 2 6 25 16
3 2 7 20 16
3 2 8 15 16
3 2 9 16 16
3 2 10 15 16
3 2 11 16 16
3 2 12 26 0
3 2 13 17 0
3 2 14 2 48
3 3 1 21 64
3 3 2 15 0
3 3 3 19 0
3 3 4 16 0
3 3 5 19 0
3 3 6 22 0
3 3 7 20 0
3 3 8 16 0
3 3 9 22 0
3 3 10 25 0
3 3 11 29 0
3 3 12 19 0
3 3 13 25 0
3 3 14 16 32
3 4 1 36 66
3 4 2 34 0
3 4 3 34 0
3 4 4 34 0
3 4 5 34 0
3 4 6 34 0
3 4 7 34 0
3 4 8 34 0
3 4 9 34 0
3 4 10 34 0
3 4 11 34 0
3 4 12 34 0
3 4 13 34 0
3 4 14 34 32
3 5 1 331 66
3 5 2 434 0
3 5 3 386 0
3 5 4 335 0
3 5 5 147 0
3 5 6 513 0
3 5 7 364 0
3 5 8 364 0
3 5 9 85 0
3 5 10 468 0
3 5 11 233 0
3 5 12 340 0
3 5 13 271 0
3 5 14 374 32
3 6 1 466 66
3 6 2 562 0
3 6 3 386 0
3 6 4 238 0
3 6 5 601 0
3 6 6 66 0
3 6 7 586 0
3 6 8 586 0
3 6 9 138 0
3 6 10 612 0
3 6 11 280 0
3 6 12 338 0
3 6 13 213 0
3 6 14 546 32
3 7 1 48 66
3 7 2 202 0
3 7 3 108 0
3 7 4 304 0
3 7 5 116 0
3 7 6 201 0
3 7 7 563 0
3 7 8 563 0
3 7 9 72 0
3 7 10 172 0
3 7 11 207 0
3 7 12 388 0
3 7 13 140 0
3 7 14 365 32
3 8 1 466 64
3 8 2 239 0
3 8 3 389 0
3 8 4 437 0
3 8 5 185 0
3 8 6 594 0
3 8 7 240 0
3 8 8 240 0
3 8 9 591 0
3 8 10 84 0
3 8 11 590 0
3 8 12 181 0
3 8 13 235 0
3 8 14 122 32
3 9 1 632 64
3 9 2 390 0
3 9 3 415 0
3 9 4 401 0
3 9 5 527 0
3 9 6 237 0
3 9 7 292 0
3 9 8 292 0
3 9 9 447 0
3 9 10 451 0
3 9 11 577 0
3 9 12 406 0
3 9 13 136 0
3 9 14 286 32
3 10 1 664 72
3 10 2 639 8
3 10 3 620 0
3 10 4 140 0
3 10 5 140 0
3 10 6 559 0
3 10 7 463 0
3 10 8 463 0
3 10 9 573 0
3 10 10 272 0
3 10 11 503 0
3 10 12 356 0
3 10 13 526 0
3 10 14 617 32
3 11 3 547 64
3 11 4 185 0
3 11 5 205 0
3 11 6 590 0
3 11 7 159 0
3 11 8 159 0
3 11 9 181 0
3 11 10 599 0
3 11 11 86 0
3 11 12 329 0
3 11 13 137 0
3 11 14 279 32
3 12 3 185 64
3 12 4 394 0
3 12 5 91 0
3 12 6 159 0
3 12 7 240 0
3 12 8 240 0
3 12 9 547 0
3 12 10 507 0
3 12 11 294 0
3 12 12 259 0
3 12 13 432 0
3 12 14 140 32
3 13 3 377 64
3 13 4 510 0
3 13 5 296 0
3 13 6 294 0
3 13 7 639 0
3 13 8 639 0
3 13 9 439 0
3 13 10 610 0
3 13 11 162 0
3 13 12 140 0
3 13 13 580 0
3 13 14 122 32
3 14 3 84 72
3 14 4 495 8
3 14 5 292 8
3 14 6 308 8
3 14 7 624 8
3 14 8 624 8
3 14 9 558 8
3 14 10 70 8
3 14 11 575 8
3 14 12 493 8
3 14 13 83 8
3 14 14 372 40
3 15 2 21 124
4 0 3 16 90
4 0 4 17 58
4 0 12 23 90
4 0 13 16 58
4 2 1 2 80
4 2 2 19 16
4 2 3 18 16
4 2 4 20 16
4 2 5 23 16
4 2 6 21 16
4 2 7 19 16
4 2 8 17 16
4 2 9 21 16
4 2 10 27 16
4 2 11 21 16
4 2 12 24 16
4 2 13 16 16
4 2 14 5 48
4 3 1 21 72
4 3 2 25 0
4 3 3 26 0
4 3 4 23 0
4 3 5 16 0
4 3 6 29 0
4 3 7 25 0
4 3 8 15 0
4 3 9 16 0
4 3 10 15 0
4 3 11 22 0
4 3 12 21 0
4 3 13 20 0
4 3 14 20 32
4 4 0 6 116
4 4 2 0 64
4 4 3 34 0
4 4 4 34 0
4 4 5 34 0
4 4 6 34 0
4 4 7 34 0
4 4 8 34 0
4 4 9 34 0
4 4 10 34 0
4 4 11 34 0
4 4 12 34 0
4 4 13 34 0
4 4 14 34 32
4 5 0 6 102
4 5 2 0 64
4 5 3 56 0
4 5 4 89 0
4 5 5 264 0
4 5 6 386 0
4 5 7 446 0
4 5 8 446 0
4 5 9 148 0
4 5 10 371 0
4 5 11 303 0
4 5 12 189 0
4 5 13 542 0
4 5 14 494 32
4 6 0 6 102
4 6 2 0 64
4 6 3 124 0
4 6 4 45 0
4 6 5 473 0
4 6 6 459 0
4 6 7 262 0
4 6 8 262 0
4 6 9 96 0
4 6 10 302 0
4 6 11 322 0
4 6 12 656 0
4 6 13 315 0
4 6 14 76 32
4 7 0 6 108
4 7 2 0 64
4 7 3 543 0
4 7 4 170 0
4 7 5 489 0
4 7 6 220 0
4 7 7 627 0
4 7 8 627 0
4 7 9 205 0
4 7 10 480 0
4 7 11 431 0
4 7 12 257 0
4 7 13 616 0
4 7 14 463 32
4 8 1 77 80
4 8 2 109 0
4 8 3 71 0
4 8 4 328 0
4 8 5 181 0
4 8 6 553 0
4 8 7 237 0
4 8 8 237 0
4 8 9 493 0
4 8 10 573 0
4 8 11 294 0
4 8 12 537 0
4 8 13 546 0
4 8 14 463 32
4 9 1 279 64
4 9 2 498 0
4 9 3 540 0
4 9 4 549 0
4 9 5 159 0
4 9 6 325 0
4 9 7 62 0
4 9 8 62 0
4 9 9 592 0
4 9 10 416 0
4 9 11 546 0
4 9 12 94 0
4 9 13 257 0
4 9 14 336 32
4 10 1 666 72
4 10 2 559 0
4 10 3 76 0
4 10 4 345 0
4 10 5 235 0
4 10 6 295 0
4 10 7 585 0
4 10 8 585 0
4 10 9 634 0
4 10 10 633 0
4 10 11 413 0
4 10 12 372 0
4 10 13 612 0
4 10 14 295 32
4 11 2 673 68
4 11 3 122 0
4 11 4 405 0
4 11 5 412 0
4 11 6 605 0
4 11 7 524 0
4 11 8 524 0
4 11 9 652 0
4 11 10 511 0
4 11 11 611 0
4 11 12 603 0
4 11 13 616 0
4 11 14 112 32
4 12 2 675 68
4 12 3 245 0
4 12 4 390 0
4 12 5 511 0
4 12 6 435 0
4 12 7 136 0
4 12 8 136 0
4 12 9 231 0
4 12 10 304 0
4 12 11 344 0
4 12 12 134 0
4 12 13 611 0
4 12 14 84 32
4 13 2 682 70
4 13 3 326 0
4 13 4 134 0
4 13 5 185 0
4 13 6 535 0
4 13 7 488 0
4 13 8 488 0
4 13 9 294 0
4 13 10 257 0
4 13 11 490 0
4 13 12 284 0
4 13 13 198 0
4 13 14 353 32
4 14 2 21 68
4 14 3 229 8
4 14 4 523 8
4 14 5 668 0
4 14 6 668 0
4 14 7 600 8
4 14 8 600 0
4 14 9 576 0
4 14 10 136 8
4 14 11 141 0
4 14 12 563 0
4 14 13 81 8
4 14 14 298 40
4 15 2 21 104
4 15 5 668 76
4 15 6 668 46
4 15 8 668 76
4 15 9 668 46
4 15 11 668 76
4 15 12 668 46
5 2 1 14 80
5 2 2 26 16
5 2 3 22 16
5 2 4 18 16
5 2 5 23 16
5 2 6 28 16
5 2 7 24 16
5 2 8 25 16
5 2 9 18 16
5 2 10 23 16
5 2 11 16 16
5 2 12 28 16
5 2 13 24 16
5 2 14 4 48
5 3 1 21 72
5 3 2 17 0
5 3 3 23 0
5 3 4 18 0
5 3 5 22 0
5 3 6 27 0
5 3 7 16 0
5 3 8 16 0
5 3 9 16 0
5 3 10 15 0
5 3 11 25 0
5 3 12 20 0
5 3 13 17 0
5 3 14 27 32
5 4 0 6 120
5 4 2 0 64
5 4 3 34 0
5 4 4 34 0
5 4 5 34 0
5 4 6 34 0
5 4 7 34 0
5 4 8 34 0
5 4 9 34 0
5 4 10 34 0
5 4 11 34 0
5 4 12 34 0
5 4 13 34 0
5 4 14 34 32
5 5 2 0 64
5 5 3 234 0
5 5 4 518 0
5 5 5 424 0
5 5 6 293 0
5 5 7 501 0
5 5 8 501 0
5 5 9 569 0
5 5 10 234 0
5 5 11 77 0
5 5 12 626 0
5 5 13 114 0
5 5 14 159 32
5 6 2 0 64
5 6 3 161 0
5 6 4 318 0
5 6 5 323 0
5 6 6 127 0
5 6 7 473 0
5 6 8 473 0
5 6 9 484 0
5 6 10 461 0
5 6 11 121 0
5 6 12 482 0
5 6 13 266 0
5 6 14 374 32
5 7 0 6 120
5 7 2 0 64
5 7 3 105 0
5 7 4 102 0
5 7 5 165 0
5 7 6 450 0
5 7 7 311 0
5 7 8 311 0
5 7 9 51 0
5 7 10 213 0
5 7 11 197 0
5 7 12 194 0
5 7 13 140 0
5 7 14 183 32
5 8 1 654 80
5 8 2 588 0
5 8 3 554 0
5 8 4 86 0
5 8 5 121 0
5 8 6 191 0
5 8 7 199 0
5 8 8 199 0
5 8 9 204 0
5 8 10 617 0
5 8 11 333 0
5 8 12 600 0
5 8 13 479 0
5 8 14 100 32
5 9 1 458 64
5 9 2 180 0
5 9 3 602 0
5 9 4 607 0
5 9 5 464 0
5 9 6 298 0
5 9 7 215 0
5 9 8 215 0
5 9 9 591 0
5 9 10 401 0
5 9 11 611 0
5 9 12 254 0
5 9 13 101 0
5 9 14 252 0
5 9 15 33 60
5 10 1 665 72
5 10 2 67 0
5 10 3 51 0
5 10 4 636 0
5 10 5 273 0
5 10 6 602 0
5 10 7 463 0
5 10 8 463 0
5 10 9 249 0
5 10 10 546 0
5 10 11 313 0
5 10 12 554 0
5 10 13 346 0
5 10 14 612 32
5 11 2 674 64
5 11 3 350 0
5 11 4 72 0
5 11 5 350 0
5 11 6 318 0
5 11 7 649 0
5 11 8 649 0
5 11 9 231 0
5 11 10 312 0
5 11 11 602 0
5 11 12 524 0
5 11 13 635 0
5 11 14 84 32
5 12 2 1 72
5 12 3 101 0
5 12 4 445 0
5 12 5 310 0
5 12 6 103 0
5 12 7 582 0
5 12 8 582 0
5 12 9 162 0
5 12 10 581 0
5 12 11 624 0
5 12 12 86 0
5 12 13 442 0
5 12 14 136 32
5 13 3 151 64
5 13 4 528 0
5 13 5 627 0
5 13 6 288 0
5 13 7 207 0
5 13 8 207 0
5 13 9 156 0
5 13 10 73 0
5 13 11 415 0
5 13 12 400 0
5 13 13 254 0
5 13 14 581 32
5 14 2 21 80
5 14 3 275 8
5 14 4 311 8
5 14 5 668 0
5 14 6 564 8
5 14 7 412 8
5 14 8 412 0
5 14 9 611 8
5 14 10 471 8
5 14 11 251 0
5 14 12 228 8
5 14 13 641 8
5 14 14 339 40
5 15 2 21 106
5 15 5 668 106
5 15 8 668 106
5 15 11 668 106
6 2 1 14 80
6 2 2 19 16
6 2 3 25 16
6 2 4 20 16
6 2 5 28 16
6 2 6 17 16
6 2 7 20 16
6 2 8 18 16
6 2 9 16 16
6 2 10 18 16
6 2 11 26 16
6 2 12 17 16
6 2 13 16 16
6 2 14 2 48
6 3 1 21 72
6 3 2 17 0
6 3 3 17 0
6 3 4 20 0
6 3 5 16 0
6 3 6 20 0
6 3 7 24 0
6 3 8 25 0
6 3 9 20 0
6 3 10 28 0
6 3 11 28 0
6 3 12 17 0
6 3 13 25 0
6 3 14 16 32
6 4 0 6 120
6 4 2 0 64
6 4 3 34 0
6 4 4 34 0
6 4 5 34 0
6 4 6 34 0
6 4 7 34 0
6 4 8 34 0
6 4 9 34 0
6 4 10 34 0
6 4 11 34 0
6 4 12 34 0
6 4 13 34 0
6 4 14 34 32
6 5 2 0 64
6 5 3 211 0
6 5 4 536 0
6 5 5 226 0
6 5 6 474 0
6 5 7 242 0
6 5 8 242 0
6 5 9 532 0
6 5 10 140 0
6 5 11 596 0
6 5 12 369 0
6 5 13 406 0
6 5 14 198 32
6 6 2 0 64
6 6 3 191 0
6 6 4 135 0
6 6 5 133 0
6 6 6 378 0
6 6 7 518 0
6 6 8 518 0
6 6 9 330 0
6 6 10 136 0
6 6 11 114 0
6 6 12 590 0
6 6 13 141 0
6 6 14 394 32
6 7 0 6 120
6 7 2 0 64
6 7 3 496 0
6 7 4 95 0
6 7 5 530 0
6 7 6 130 0
6 7 7 381 0
6 7 8 381 0
6 7 9 136 0
6 7 10 601 0
6 7 11 629 0
6 7 12 412 0
6 7 13 264 0
6 7 14 592 32
6 8 1 173 80
6 8 2 102 0
6 8 3 137 0
6 8 4 259 0
6 8 5 411 0
6 8 6 398 0
6 8 7 350 0
6 8 8 350 0
6 8 9 429 0
6 8 10 365 0
6 8 11 629 0
6 8 12 594 0
6 8 13 306 0
6 8 14 499 0
6 8 15 33 52
6 9 1 661 64
6 9 2 212 0
6 9 3 258 0
6 9 4 231 0
6 9 5 231 0
6 9 6 248 0
6 9 7 338 0
6 9 8 338 0
6 9 9 591 0
6 9 10 545 0
6 9 11 185 0
6 9 12 595 0
6 9 13 84 0
6 9 14 481 0
6 9 15 39 40
6 10 1 229 72
6 10 2 270 0
6 10 3 154 0
6 10 4 284 0
6 10 5 391 0
6 10 6 83 0
6 10 7 337 0
6 10 8 337 0
6 10 9 633 0
6 10 10 498 0
6 10 11 419 0
6 10 12 479 0
6 10 13 618 0
6 10 14 393 32
6 11 2 680 66
6 11 3 580 0
6 11 4 178 0
6 11 5 78 0
6 11 6 316 0
6 11 7 88 0
6 11 8 88 0
6 11 9 294 0
6 11 10 543 0
6 11 11 515 0
6 11 12 136 0
6 11 13 257 0
6 11 14 639 32
6 12 2 679 66
6 12 3 91 0
6 12 4 620 0
6 12 5 612 0
6 12 6 498 0
6 12 7 394 0
6 12 8 394 0
6 12 9 406 0
6 12 10 417 0
6 12 11 472 0
6 12 12 100 0
6 12 13 590 0
6 12 14 611 32
6 13 2 681 70
6 13 3 160 0
6 13 4 372 0
6 13 5 452 0
6 13 6 285 0
6 13 7 91 0
6 13 8 91 0
6 13 9 504 0
6 13 10 245 0
6 13 11 200 0
6 13 12 159 0
6 13 13 615 0
6 13 14 97 32
6 14 2 21 74
6 14 3 401 8
6 14 4 668 0
6 14 5 278 8
6 14 6 493 8
6 14 7 221 0
6 14 8 221 8
6 14 9 75 8
6 14 10 629 0
6 14 11 644 8
6 14 12 616 8
6 14 13 381 8
6 14 14 78 40
6 15 4 668 110
6 15 7 668 110
6 15 10 668 110
7 2 1 11 80
7 2 2 16 16
7 2 3 20 16
7 2 4 23 16
7 2 5 25 16
7 2 6 20 16
7 2 7 20 16
7 2 8 16 16
7 2 9 20 16
7 2 10 19 16
7 2 11 21 16
7 2 12 16 16
7 2 13 20 16
7 2 14 5 48
7 3 1 21 72
7 3 2 15 0
7 3 3 20 0
7 3 4 20 0
7 3 5 15 0
7 3 6 16 0
7 3 7 15 0
7 3 8 20 0
7 3 9 16 0
7 3 10 20 0
7 3 11 16 0
7 3 12 26 0
7 3 13 22 0
7 3 14 24 32
7 4 0 6 120
7 4 2 663 64
7 4 3 34 0
7 4 4 34 0
7 4 5 34 0
7 4 6 34 0
7 4 7 34 0
7 4 8 34 0
7 4 9 34 0
7 4 10 34 0
7 4 11 34 0
7 4 12 34 0
7 4 13 34 0
7 4 14 34 32
7 5 2 663 64
7 5 3 113 0
7 5 4 166 0
7 5 5 475 0
7 5 6 99 0
7 5 7 167 0
7 5 8 167 0
7 5 9 209 0
7 5 10 598 0
7 5 11 82 0
7 5 12 420 0
7 5 13 294 0
7 5 14 419 0
7 5 15 21 54
7 6 2 0 64
7 6 3 187 0
7 6 4 213 0
7 6 5 403 0
7 6 6 646 0
7 6 7 646 0
7 6 8 646 0
7 6 9 658 0
7 6 10 523 0
7 6 11 112 0
7 6 12 140 0
7 6 13 616 0
7 6 14 322 0
7 6 15 21 38
7 7 0 6 120
7 7 2 0 64
7 7 3 164 0
7 7 4 568 0
7 7 5 92 0
7 7 6 385 0
7 7 7 483 0
7 7 8 483 0
7 7 9 556 0
7 7 10 101 0
7 7 11 639 0
7 7 12 398 0
7 7 13 324 0
7 7 14 267 0
7 7 15 34 38
7 8 1 543 80
7 8 2 139 0
7 8 3 169 0
7 8 4 541 0
7 8 5 593 0
7 8 6 294 0
7 8 7 546 0
7 8 8 546 0
7 8 9 125 0
7 8 10 633 0
7 8 11 296 0
7 8 12 308 0
7 8 13 447 0
7 8 14 88 0
7 8 15 35 32
7 9 1 666 64
7 9 2 51 0
7 9 3 280 0
7 9 4 152 0
7 9 5 100 0
7 9 6 560 0
7 9 7 273 0
7 9 8 273 0
7 9 9 581 0
7 9 10 460 0
7 9 11 159 0
7 9 12 447 0
7 9 13 94 0
7 9 14 294 0
7 9 15 32 40
7 10 1 381 72
7 10 2 103 8
7 10 3 558 0
7 10 4 624 0
7 10 5 101 0
7 10 6 222 0
7 10 7 125 0
7 10 8 125 0
7 10 9 185 0
7 10 10 276 0
7 10 11 634 0
7 10 12 444 0
7 10 13 603 0
7 10 14 546 32
7 11 3 508 64
7 11 4 150 0
7 11 5 249 0
7 11 6 230 0
7 11 7 621 0
7 11 8 621 0
7 11 9 591 0
7 11 10 510 0
7 11 11 83 0
7 11 12 527 0
7 11 13 204 0
7 11 14 592 32
7 12 3 527 64
7 12 4 505 0
7 12 5 640 0
7 12 6 441 0
7 12 7 565 0
7 12 8 565 0
7 12 9 259 0
7 12 10 641 0
7 12 11 321 0
7 12 12 236 0
7 12 13 243 0
7 12 14 592 32
7 13 3 443 64
7 13 4 560 0
7 13 5 544 0
7 13 6 162 0
7 13 7 384 0
7 13 8 384 0
7 13 9 537 0
7 13 10 613 0
7 13 11 122 0
7 13 12 335 0
7 13 13 237 0
7 13 14 93 32
7 14 3 140 72
7 14 4 558 8
7 14 5 325 8
7 14 6 140 8
7 14 7 581 8
7 14 8 581 8
7 14 9 204 8
7 14 10 633 8
7 14 11 572 8
7 14 12 424 8
7 14 13 611 0
7 14 14 462 32
7 15 13 668 78
7 15 14 668 46
8 2 1 3 80
8 2 2 23 16
8 2 3 16 16
8 2 4 17 16
8 2 5 28 16
8 2 6 21 16
8 2 7 20 16
8 2 8 20 16
8 2 9 20 16
8 2 10 29 16
8 2 11 17 16
8 2 12 18 16
8 2 13 17 16
8 2 14 5 48
8 3 1 21 72
8 3 2 26 0
8 3 3 27 0
8 3 4 16 0
8 3 5 20 0
8 3 6 29 0
8 3 7 21 0
8 3 8 25 0
8 3 9 19 0
8 3 10 16 0
8 3 11 15 0
8 3 12 25 0
8 3 13 20 0
8 3 14 22 32
8 4 0 6 120
8 4 2 0 64
8 4 3 34 0
8 4 4 34 0
8 4 5 34 0
8 4 6 34 0
8 4 7 34 0
8 4 8 34 0
8 4 9 34 0
8 4 10 34 0
8 4 11 34 0
8 4 12 34 0
8 4 13 34 0
8 4 14 34 32
8 5 2 0 64
8 5 3 281 0
8 5 4 193 0
8 5 5 343 0
8 5 6 68 0
8 5 7 606 0
8 5 8 606 0
8 5 9 240 0
8 5 10 614 0
8 5 11 642 0
8 5 12 200 0
8 5 13 652 0
8 5 14 307 32
8 6 2 0 64
8 6 3 244 0
8 6 4 129 0
8 6 5 647 0
8 6 6 570 0
8 6 7 552 0
8 6 8 552 0
8 6 9 50 0
8 6 10 142 0
8 6 11 270 0
8 6 12 640 0
8 6 13 304 0
8 6 14 437 32
8 7 0 6 120
8 7 2 0 64
8 7 3 99 0
8 7 4 584 0
8 7 5 474 0
8 7 6 187 0
8 7 7 603 0
8 7 8 603 0
8 7 9 112 0
8 7 10 312 0
8 7 11 580 0
8 7 12 204 0
8 7 13 554 0
8 7 14 557 32
8 8 1 408 80
8 8 2 631 0
8 8 3 631 0
8 8 4 117 0
8 8 5 267 0
8 8 6 101 0
8 8 7 625 0
8 8 8 625 0
8 8 9 212 0
8 8 10 308 0
8 8 11 412 0
8 8 12 159 0
8 8 13 383 0
8 8 14 349 0
8 8 15 30 50
8 9 1 662 64
8 9 2 583 0
8 9 3 63 0
8 9 4 488 0
8 9 5 263 0
8 9 6 70 0
8 9 7 650 0
8 9 8 650 0
8 9 9 235 0
8 9 10 353 0
8 9 11 207 0
8 9 12 263 0
8 9 13 269 0
8 9 14 367 0
8 9 15 31 40
8 10 1 629 72
8 10 2 227 0
8 10 3 143 0
8 10 4 523 0
8 10 5 628 0
8 10 6 282 0
8 10 7 431 0
8 10 8 431 0
8 10 9 633 0
8 10 10 101 0
8 10 11 333 0
8 10 12 390 0
8 10 13 150 0
8 10 14 334 32
8 11 2 682 68
8 11 3 159 0
8 11 4 53 0
8 11 5 594 0
8 11 6 154 0
8 11 7 633 0
8 11 8 633 0
8 11 9 549 0
8 11 10 65 0
8 11 11 522 0
8 11 12 59 0
8 11 13 237 0
8 11 14 576 32
8 12 2 677 68
8 12 3 125 0
8 12 4 527 0
8 12 5 76 0
8 12 6 387 0
8 12 7 59 0
8 12 8 59 0
8 12 9 446 0
8 12 10 489 0
8 12 11 523 0
8 12 12 560 0
8 12 13 549 0
8 12 14 649 32
8 13 2 682 70
8 13 3 204 0
8 13 4 549 0
8 13 5 380 0
8 13 6 634 0
8 13 7 458 0
8 13 8 458 0
8 13 9 219 0
8 13 10 565 0
8 13 11 207 0
8 13 12 548 0
8 13 13 550 0
8 13 14 580 32
8 14 2 21 76
8 14 3 640 8
8 14 4 668 0
8 14 5 134 8
8 14 6 249 8
8 14 7 401 0
8 14 8 401 8
8 14 9 527 8
8 14 10 612 0
8 14 11 140 8
8 14 12 72 8
8 14 13 241 8
8 14 14 360 40
8 15 4 668 110
8 15 7 668 110
8 15 10 668 110
9 2 1 6 80
9 2 2 16 16
9 2 3 20 16
9 2 4 22 16
9 2 5 16 16
9 2 6 20 16
9 2 7 18 16
9 2 8 21 16
9 2 9 23 16
9 2 10 16 16
9 2 11 16 16
9 2 12 25 16
9 2 13 18 16
9 2 14 11 48
9 3 1 21 72
9 3 2 21 0
9 3 3 26 0
9 3 4 17 0
9 3 5 25 0
9 3 6 17 0
9 3 7 20 0
9 3 8 19 0
9 3 9 16 0
9 3 10 16 0
9 3 11 27 0
9 3 12 23 0
9 3 13 16 0
9 3 14 25 32
9 4 0 6 120
9 4 2 0 64
9 4 3 34 0
9 4 4 34 0
9 4 5 34 0
9 4 6 34 0
9 4 7 34 0
9 4 8 34 0
9 4 9 34 0
9 4 10 34 0
9 4 11 34 0
9 4 12 34 0
9 4 13 34 0
9 4 14 34 32
9 5 2 0 64
9 5 3 208 0
9 5 4 145 0
9 5 5 587 0
9 5 6 399 0
9 5 7 371 0
9 5 8 371 0
9 5 9 277 0
9 5 10 112 0
9 5 11 55 0
9 5 12 623 0
9 5 13 390 0
9 5 14 643 32
9 6 2 0 64
9 6 3 531 0
9 6 4 120 0
9 6 5 354 0
9 6 6 93 0
9 6 7 158 0
9 6 8 158 0
9 6 9 429 0
9 6 10 87 0
9 6 11 616 0
9 6 12 309 0
9 6 13 97 0
9 6 14 249 32
9 7 0 6 120
9 7 2 0 64
9 7 3 80 0
9 7 4 116 0
9 7 5 156 0
9 7 6 126 0
9 7 7 671 0
9 7 8 671 0
9 7 9 463 0
9 7 10 199 0
9 7 11 250 0
9 7 12 188 0
9 7 13 320 0
9 7 14 70 32
9 8 1 529 80
9 8 2 98 0
9 8 3 99 0
9 8 4 120 0
9 8 5 136 0
9 8 6 633 0
9 8 7 443 0
9 8 8 443 0
9 8 9 257 0
9 8 10 648 0
9 8 11 217 0
9 8 12 257 0
9 8 13 559 0
9 8 14 388 32
9 9 1 171 64
9 9 2 222 0
9 9 3 235 0
9 9 4 346 0
9 9 5 392 0
9 9 6 159 0
9 9 7 640 0
9 9 8 640 0
9 9 9 62 0
9 9 10 280 0
9 9 11 582 0
9 9 12 246 0
9 9 13 114 0
9 9 14 545 0
9 9 15 42 58
9 10 1 667 72
9 10 2 422 0
9 10 3 590 0
9 10 4 259 0
9 10 5 324 0
9 10 6 275 0
9 10 7 136 0
9 10 8 136 0
9 10 9 607 0
9 10 10 287 0
9 10 11 545 0
9 10 12 194 0
9 10 13 432 0
9 10 14 443 32
9 11 2 676 64
9 11 3 396 0
9 11 4 140 0
9 11 5 537 0
9 11 6 581 0
9 11 7 628 0
9 11 8 628 0
9 11 9 426 0
9 11 10 507 0
9 11 11 63 0
9 11 12 592 0
9 11 13 183 0
9 11 14 313 32
9 12 2 1 72
9 12 3 545 0
9 12 4 401 0
9 12 5 312 0
9 12 6 382 0
9 12 7 493 0
9 12 8 493 0
9 12 9 482 0
9 12 10 372 0
9 12 11 112 0
9 12 12 425 0
9 12 13 634 0
9 12 14 88 32
9 13 3 462 64
9 13 4 283 0
9 13 5 235 0
9 13 6 201 0
9 13 7 324 0
9 13 8 324 0
9 13 9 464 0
9 13 10 122 0
9 13 11 112 0
9 13 12 65 0
9 13 13 495 0
9 13 14 259 32
9 14 2 21 80
9 14 3 84 8
9 14 4 527 8
9 14 5 668 0
9 14 6 114 8
9 14 7 603 8
9 14 8 603 0
9 14 9 275 8
9 14 10 185 8
9 14 11 112 0
9 14 12 202 8
9 14 13 224 8
9 14 14 652 40
9 15 2 21 108
9 15 5 668 108
9 15 8 668 108
9 15 11 668 108
10 0 3 22 92
10 0 4 24 60
10 0 12 24 92
10 0 13 28 60
10 2 1 5 80
10 2 2 20 16
10 2 3 23 16
10 2 4 19 16
10 2 5 19 16
10 2 6 20 16
10 2 7 22 16
10 2 8 29 16
10 2 9 15 16
10 2 10 25 16
10 2 11 16 16
10 2 12 24 16
10 2 13 27 16
10 2 14 2 48
10 3 1 21 72
10 3 2 16 0
10 3 3 15 0
10 3 4 24 0
10 3 5 22 0
10 3 6 20 0
10 3 7 16 0
10 3 8 27 0
10 3 9 26 0
10 3 10 17 0
10 3 11 19 0
10 3 12 20 0
10 3 13 26 0
10 3 14 16 32
10 4 0 6 114
10 4 2 0 64
10 4 3 34 0
10 4 4 34 0
10 4 5 34 0
10 4 6 34 0
10 4 7 34 0
10 4 8 34 0
10 4 9 34 0
10 4 10 34 0
10 4 11 34 0
10 4 12 34 0
10 4 13 34 0
10 4 14 34 32
10 5 0 6 102
10 5 2 0 64
10 5 3 267 0
10 5 4 618 0
10 5 5 426 0
10 5 6 608 0
10 5 7 130 0
10 5 8 130 0
10 5 9 240 0
10 5 10 54 0
10 5 11 477 0
10 5 12 216 0
10 5 13 512 0
10 5 14 121 32
10 6 0 6 102
10 6 2 0 64
10 6 3 386 0
10 6 4 609 0
10 6 5 82 0
10 6 6 659 0
10 6 7 60 0
10 6 8 60 0
10 6 9 655 0
10 6 10 184 0
10 6 11 611 0
10 6 12 453 0
10 6 13 125 0
10 6 14 600 32
10 7 0 6 106
10 7 2 0 64
10 7 3 578 0
10 7 4 639 0
10 7 5 74 0
10 7 6 111 0
10 7 7 671 0
10 7 8 671 0
10 7 9 629 0
10 7 10 59 0
10 7 11 225 0
10 7 12 204 0
10 7 13 590 0
10 7 14 353 32
10 8 1 61 80
10 8 2 50 0
10 8 3 247 0
10 8 4 500 0
10 8 5 112 0
10 8 6 400 0
10 8 7 431 0
10 8 8 431 0
10 8 9 140 0
10 8 10 93 0
10 8 11 162 0
10 8 12 545 0
10 8 13 159 0
10 8 14 600 32
10 9 1 203 64
10 9 2 289 0
10 9 3 533 0
10 9 4 186 0
10 9 5 550 0
10 9 6 123 0
10 9 7 633 0
10 9 8 633 0
10 9 9 70 0
10 9 10 63 0
10 9 11 235 0
10 9 12 433 0
10 9 13 481 0
10 9 14 628 32
10 10 1 672 72
10 10 2 375 0
10 10 3 463 0
10 10 4 455 0
10 10 5 328 0
10 10 6 257 0
10 10 7 170 0
10 10 8 170 0
10 10 9 184 0
10 10 10 612 0
10 10 11 493 0
10 10 12 362 0
10 10 13 547 0
10 10 14 303 32
10 11 2 678 66
10 11 3 553 0
10 11 4 498 0
10 11 5 112 0
10 11 6 502 0
10 11 7 122 0
10 11 8 122 0
10 11 9 136 0
10 11 10 219 0
10 11 11 366 0
10 11 12 476 0
10 11 13 437 0
10 11 14 193 32
10 12 2 682 66
10 12 3 574 0
10 12 4 615 0
10 12 5 201 0
10 12 6 436 0
10 12 7 430 0
10 12 8 430 0
10 12 9 449 0
10 12 10 443 0
10 12 11 122 0
10 12 12 551 0
10 12 13 438 0
10 12 14 439 32
10 13 2 678 70
10 13 3 265 0
10 13 4 49 0
10 13 5 470 0
10 13 6 49 0
10 13 7 639 0
10 13 8 639 0
10 13 9 355 0
10 13 10 585 0
10 13 11 240 0
10 13 12 339 0
10 13 13 494 0
10 13 14 327 32
10 14 2 21 66
10 14 3 176 8
10 14 4 591 8
10 14 5 668 0
10 14 6 668 0
10 14 7 514 8
10 14 8 514 0
10 14 9 421 0
10 14 10 580 8
10 14 11 472 0
10 14 12 591 0
10 14 13 438 8
10 14 14 553 40
10 15 2 21 104
10 15 5 668 74
10 15 6 668 46
10 15 8 668 74
10 15 9 668 46
10 15 11 668 74
10 15 12 668 46
11 0 2 24 94
11 0 3 19 24
11 0 4 16 16
11 0 5 16 62
11 0 11 21 94
11 0 12 16 24
11 0 13 19 16
11 0 14 20 62
11 1 4 27 102
11 1 13 20 102
11 2 1 13 80
11 2 2 26 16
11 2 3 16 16
11 2 4 27 0
11 2 5 17 16
11 2 6 22 16
11 2 7 17 16
11 2 8 15 16
11 2 9 22 16
11 2 10 20 16
11 2 11 22 16
11 2 12 27 16
11 2 13 20 0
11 2 14 4 48
11 3 1 21 64
11 3 2 16 0
11 3 3 20 0
11 3 4 20 0
11 3 5 27 0
11 3 6 23 0
11 3 7 29 0
11 3 8 29 0
11 3 9 18 0
11 3 10 29 0
11 3 11 20 0
11 3 12 17 0
11 3 13 27 0
11 3 14 16 32
11 4 1 40 68
11 4 2 34 0
11 4 3 34 0
11 4 4 34 0
11 4 5 34 0
11 4 6 34 0
11 4 7 34 0
11 4 8 34 0
11 4 9 34 0
11 4 10 34 0
11 4 11 34 0
11 4 12 34 0
11 4 13 34 0
11 4 14 34 32
11 5 1 440 68
11 5 2 69 0
11 5 3 182 0
11 5 4 409 0
11 5 5 567 0
11 5 6 637 0
11 5 7 588 0
11 5 8 588 0
11 5 9 148 0
11 5 10 52 0
11 5 11 192 0
11 5 12 579 0
11 5 13 58 0
11 5 14 274 32
11 6 1 43 68
11 6 2 203 0
11 6 3 258 0
11 6 4 456 0
11 6 5 299 0
11 6 6 431 0
11 6 7 57 0
11 6 8 57 0
11 6 9 352 0
11 6 10 149 0
11 6 11 143 0
11 6 12 545 0
11 6 13 521 0
11 6 14 591 32
11 7 1 41 68
11 7 2 131 0
11 7 3 519 0
11 7 4 197 0
11 7 5 103 0
11 7 6 622 0
11 7 7 561 0
11 7 8 561 0
11 7 9 59 0
11 7 10 366 0
11 7 11 602 0
11 7 12 122 0
11 7 13 502 0
11 7 14 93 32
11 8 1 37 64
11 8 2 405 0
11 8 3 228 0
11 8 4 107 0
11 8 5 368 0
11 8 6 657 0
11 8 7 671 0
11 8 8 671 0
11 8 9 616 0
11 8 10 633 0
11 8 11 265 0
11 8 12 235 0
11 8 13 600 0
11 8 14 439 32
11 9 1 414 64
11 9 2 118 0
11 9 3 112 0
11 9 4 59 0
11 9 5 470 0
11 9 6 245 0
11 9 7 498 0
11 9 8 498 0
11 9 9 174 0
11 9 10 442 0
11 9 11 580 0
11 9 12 327 0
11 9 13 122 0
11 9 14 185 32
11 10 1 670 72
11 10 2 653 8
11 10 3 83 0
11 10 4 93 0
11 10 5 620 0
11 10 6 415 0
11 10 7 617 0
11 10 8 617 0
11 10 9 121 0
11 10 10 361 0
11 10 11 624 0
11 10 12 610 0
11 10 13 581 0
11 10 14 412 32
11 11 3 83 64
11 11 4 645 0
11 11 5 249 0
11 11 6 538 0
11 11 7 600 0
11 11 8 600 0
11 11 9 592 0
11 11 10 175 0
11 11 11 261 0
11 11 12 159 0
11 11 13 580 0
11 11 14 615 32
11 12 3 492 64
11 12 4 140 0
11 12 5 121 0
11 12 6 140 0
11 12 7 327 0
11 12 8 327 0
11 12 9 136 0
11 12 10 558 0
11 12 11 313 0
11 12 12 404 0
11 12 13 591 0
11 12 14 631 32
11 13 3 516 64
11 13 4 370 0
11 13 5 600 0
11 13 6 592 0
11 13 7 256 0
11 13 8 256 0
11 13 9 140 0
11 13 10 342 0
11 13 11 114 0
11 13 12 644 0
11 13 13 231 0
11 13 14 140 32
11 14 3 354 72
11 14 4 600 8
11 14 5 534 8
11 14 6 224 8
11 14 7 125 8
11 14 8 125 8
11 14 9 608 8
11 14 10 260 8
11 14 11 601 8
11 14 12 198 8
11 14 13 122 8
11 14 14 580 40
11 15 2 21 122
12 0 3 23 90
12 0 4 16 58
12 0 12 22 90
12 0 13 20 58
12 2 1 7 80
12 2 2 16 16
12 2 3 16 16
12 2 4 29 16
12 2 5 20 16
12 2 6 26 16
12 2 7 21 16
12 2 8 20 16
12 2 9 24 16
12 2 10 16 16
12 2 11 16 16
12 2 12 29 16
12 2 13 29 16
12 2 14 5 48
12 3 1 21 64
12 3 2 28 0
12 3 3 23 0
12 3 4 21 0
12 3 5 26 0
12 3 6 23 0
12 3 7 29 0
12 3 8 24 0
12 3 9 29 0
12 3 10 16 0
12 3 11 16 0
12 3 12 22 0
12 3 13 23 0
12 3 14 27 32
12 4 1 38 64
12 4 2 34 0
12 4 3 34 0
12 4 4 34 0
12 4 5 34 0
12 4 6 34 0
12 4 7 34 0
12 4 8 34 0
12 4 9 34 0
12 4 10 34 0
12 4 11 34 0
12 4 12 34 0
12 4 13 34 0
12 4 14 34 32
12 5 1 139 64
12 5 2 612 0
12 5 3 146 0
12 5 4 128 0
12 5 5 50 0
12 5 6 538 0
12 5 7 373 0
12 5 8 373 0
12 5 9 660 0
12 5 10 335 0
12 5 11 183 0
12 5 12 506 0
12 5 13 619 0
12 5 14 639 32
12 6 1 47 64
12 6 2 477 0
12 6 3 210 0
12 6 4 255 0
12 6 5 427 0
12 6 6 90 0
12 6 7 566 0
12 6 8 566 0
12 6 9 144 0
12 6 10 46 0
12 6 11 442 0
12 6 12 339 0
12 6 13 484 0
12 6 14 402 32
12 7 1 467 64
12 7 2 132 0
12 7 3 168 0
12 7 4 322 0
12 7 5 337 0
12 7 6 532 0
12 7 7 125 0
12 7 8 125 0
12 7 9 448 0
12 7 10 559 0
12 7 11 612 0
12 7 12 213 0
12 7 13 478 0
12 7 14 181 32
12 8 1 69 64
12 8 2 155 0
12 8 3 44 0
12 8 4 64 0
12 8 5 581 0
12 8 6 122 0
12 8 7 671 0
12 8 8 671 0
12 8 9 140 0
12 8 10 581 0
12 8 11 290 0
12 8 12 633 0
12 8 13 347 0
12 8 14 204 32
12 9 1 106 64
12 9 2 597 0
12 9 3 122 0
12 9 4 504 0
12 9 5 354 0
12 9 6 339 0
12 9 7 205 0
12 9 8 205 0
12 9 9 122 0
12 9 10 140 0
12 9 11 638 0
12 9 12 572 0
12 9 13 421 0
12 9 14 91 32
12 10 1 669 72
12 10 2 112 8
12 10 3 181 0
12 10 4 84 0
12 10 5 404 0
12 10 6 491 0
12 10 7 428 0
12 10 8 428 0
12 10 9 188 0
12 10 10 101 0
12 10 11 204 0
12 10 12 564 0
12 10 13 65 0
12 10 14 545 32
12 11 3 561 66
12 11 4 616 2
12 11 5 580 2
12 11 6 160 2
12 11 7 424 2
12 11 8 424 2
12 11 9 616 2
12 11 10 549 2
12 11 11 235 2
12 11 12 153 2
12 11 13 611 2
12 11 14 493 34
12 12 3 640 66
12 12 4 140 2
12 12 5 626 2
12 12 6 231 2
12 12 7 140 2
12 12 8 140 2
12 12 9 163 2
12 12 10 366 2
12 12 11 387 2
12 12 12 174 2
12 12 13 274 2
12 12 14 542 34
12 13 3 76 66
12 13 4 190 2
12 13 5 628 2
12 13 6 616 2
12 13 7 485 2
12 13 8 485 2
12 13 9 324 2
12 13 10 577 2
12 13 11 114 2
12 13 12 649 2
12 13 13 294 2
12 13 14 519 34
12 14 3 559 74
12 14 4 652 10
12 14 5 498 10
12 14 6 545 10
12 14 7 328 10
12 14 8 328 10
12 14 9 324 10
12 14 10 482 10
12 14 11 411 10
12 14 12 373 10
12 14 13 561 10
12 14 14 470 42
13 2 1 2 80
13 2 2 20 16
13 2 3 20 16
13 2 4 17 16
13 2 5 16 16
13 2 6 16 16
13 2 7 22 16
13 2 8 17 16
13 2 9 24 16
13 2 10 16 16
13 2 11 28 16
13 2 12 21 16
13 2 13 15 16
13 2 14 11 48
13 3 1 22 64
13 3 2 27 0
13 3 3 27 0
13 3 4 20 0
13 3 5 16 0
13 3 6 16 0
13 3 7 24 0
13 3 8 17 0
13 3 9 16 0
13 3 10 29 0
13 3 11 24 0
13 3 12 17 0
13 3 13 23 0
13 3 14 25 32
13 4 1 18 64
13 4 2 34 0
13 4 3 34 0
13 4 4 34 0
13 4 5 34 0
13 4 6 34 0
13 4 7 34 0
13 4 8 34 0
13 4 9 34 0
13 4 10 34 0
13 4 11 34 0
13 4 12 34 0
13 4 13 34 0
13 4 14 34 32
13 5 1 574 64
13 5 2 557 0
13 5 3 553 0
13 5 4 613 0
13 5 5 136 0
13 5 6 487 0
13 5 7 76 0
13 5 8 76 0
13 5 9 602 0
13 5 10 464 0
13 5 11 230 0
13 5 12 70 0
13 5 13 290 0
13 5 14 314 32
13 6 1 363 64
13 6 2 617 0
13 6 3 629 0
13 6 4 91 0
13 6 5 342 0
13 6 6 175 0
13 6 7 464 0
13 6 8 464 0
13 6 9 280 0
13 6 10 382 0
13 6 11 546 0
13 6 12 555 0
13 6 13 639 0
13 6 14 223 32
13 7 1 157 64
13 7 2 527 0
13 7 3 580 0
13 7 4 382 0
13 7 5 612 0
13 7 6 319 0
13 7 7 615 0
13 7 8 615 0
13 7 9 603 0
13 7 10 611 0
13 7 11 495 0
13 7 12 404 0
13 7 13 371 0
13 7 14 100 32
13 8 1 114 64
13 8 2 196 0
13 8 3 333 0
13 8 4 325 0
13 8 5 616 0
13 8 6 607 0
13 8 7 671 0
13 8 8 671 0
13 8 9 193 0
13 8 10 457 0
13 8 11 325 0
13 8 12 520 0
13 8 13 634 0
13 8 14 173 32
13 9 1 326 64
13 9 2 359 0
13 9 3 235 0
13 9 4 461 0
13 9 5 486 0
13 9 6 121 0
13 9 7 633 0
13 9 8 633 0
13 9 9 418 0
13 9 10 509 0
13 9 11 159 0
13 9 12 546 0
13 9 13 592 0
13 9 14 511 32
13 10 1 645 72
13 10 2 121 8
13 10 3 242 8
13 10 4 115 8
13 10 5 183 8
13 10 6 590 8
13 10 7 582 8
13 10 8 582 8
13 10 9 528 8
13 10 10 406 8
13 10 11 160 8
13 10 12 204 8
13 10 13 324 8
13 10 14 604 40
14 2 1 2 82
14 2 2 8 18
14 2 3 7 18
14 2 4 12 18
14 2 5 5 18
14 2 6 2 18
14 2 7 13 18
14 2 8 9 18
14 2 9 5 18
14 2 10 14 18
14 2 11 7 18
14 2 12 2 18
14 2 13 13 18
14 2 14 13 50
14 3 1 15 66
14 3 2 25 2
14 3 3 28 2
14 3 4 17 2
14 3 5 21 2
14 3 6 17 2
14 3 7 16 2
14 3 8 16 2
14 3 9 22 2
14 3 10 20 2
14 3 11 17 2
14 3 12 27 2
14 3 13 26 2
14 3 14 20 34
14 4 1 26 66
14 4 2 16 2
14 4 3 17 2
14 4 4 16 2
14 4 5 23 2
14 4 6 28 2
14 4 7 25 2
14 4 8 26 2
14 4 9 20 2
14 4 10 20 2
14 4 11 28 2
14 4 12 24 2
14 4 13 24 2
14 4 14 17 34
14 5 1 225 66
14 5 2 61 2
14 5 3 104 2
14 5 4 564 2
14 5 5 577 2
14 5 6 458 2
14 5 7 204 2
14 5 8 204 2
14 5 9 121 2
14 5 10 272 2
14 5 11 503 2
14 5 12 464 2
14 5 13 375 2
14 5 14 91 34
14 6 1 70 66
14 6 2 410 2
14 6 3 136 2
14 6 4 362 2
14 6 5 217 2
14 6 6 563 2
14 6 7 358 2
14 6 8 358 2
14 6 9 548 2
14 6 10 112 2
14 6 11 538 2
14 6 12 339 2
14 6 13 100 2
14 6 14 372 34
14 7 1 177 66
14 7 2 582 2
14 7 3 328 2
14 7 4 559 2
14 7 5 362 2
14 7 6 358 2
14 7 7 443 2
14 7 8 443 2
14 7 9 122 2
14 7 10 533 2
14 7 11 640 2
14 7 12 91 2
14 7 13 571 2
14 7 14 565 34
14 8 1 70 66
14 8 2 589 2
14 8 3 342 2
14 8 4 556 2
14 8 5 547 2
14 8 6 488 2
14 8 7 590 2
14 8 8 590 2
14 8 9 376 2
14 8 10 206 2
14 8 11 162 2
14 8 12 86 2
14 8 13 604 2
14 8 14 605 34
14 9 1 546 66
14 9 2 581 2
14 9 3 110 2
14 9 4 564 2
14 9 5 558 2
14 9 6 86 2
14 9 7 140 2
14 9 8 140 2
14 9 9 137 2
14 9 10 353 2
14 9 11 78 2
14 9 12 136 2
14 9 13 313 2
14 9 14 185 34
14 10 1 628 74
14 10 2 462 10
14 10 3 75 10
14 10 4 310 10
14 10 5 374 10
14 10 6 534 10
14 10 7 282 10
14 10 8 282 10
14 10 9 553 10
14 10 10 618 10
14 10 11 435 10
14 10 12 442 10
14 10 13 526 10
14 10 14 480 42
