Qubicle Exchange Format
Version 0.2
www.minddesk.com
16 16 16
668
0.039216 0.133333 0.043137
0.184314 0.129412 0.011765
0.200000 0.298039 0.027451
0.278431 0.419608 0.023529
0.278431 0.423529 0.023529
0.282353 0.427451 0.023529
0.282353 0.431373 0.023529
0.286275 0.431373 0.023529
0.286275 0.435294 0.023529
0.290196 0.439216 0.027451
0.294118 0.439216 0.031373
0.294118 0.443137 0.035294
0.298039 0.443137 0.039216
0.301961 0.447059 0.043137
0.301961 0.447059 0.047059
0.305882 0.450980 0.050980
0.309804 0.454902 0.054902
0.313726 0.454902 0.058824
0.376471 0.564706 0.039216
0.376471 0.568627 0.039216
0.376471 0.572549 0.039216
0.388235 0.588235 0.039216
0.400000 0.603922 0.043137
0.400000 0.603922 0.047059
0.407843 0.631373 0.015686
0.419608 0.647059 0.015686
0.419608 0.650980 0.015686
0.423529 0.615686 0.082353
0.423529 0.654902 0.023529
0.431373 0.658824 0.035294
0.435294 0.627451 0.105882
0.439216 0.662745 0.047059
0.443137 0.698039 0.000000
0.447059 0.698039 0.000000
0.447059 0.701961 0.000000
0.450980 0.705882 0.000000
0.454902 0.670588 0.078431
0.458824 0.713726 0.003922
0.458824 0.717647 0.000000
0.458824 0.717647 0.003922
0.458824 0.721569 0.000000
0.458824 0.721569 0.003922
0.462745 0.713726 0.019608
0.462745 0.717647 0.003922
0.462745 0.717647 0.011765
0.462745 0.717647 0.023529
0.462745 0.721569 0.000000
0.462745 0.721569 0.003922
0.462745 0.725490 0.000000
0.462745 0.725490 0.003922
0.462745 0.729412 0.003922
0.466667 0.725490 0.003922
0.466667 0.729412 0.000000
0.466667 0.729412 0.003922
0.466667 0.733333 0.000000
0.466667 0.737255 0.003922
0.470588 0.729412 0.000000
0.470588 0.733333 0.000000
0.470588 0.733333 0.003922
0.470588 0.737255 0.000000
0.470588 0.737255 0.003922
0.470588 0.741176 0.003922
0.474510 0.737255 0.000000
0.474510 0.737255 0.003922
0.474510 0.741176 0.003922
0.474510 0.745098 0.000000
0.474510 0.745098 0.003922
0.474510 0.749020 0.003922
0.478431 0.729412 0.043137
0.478431 0.741176 0.003922
0.478431 0.745098 0.000000
0.478431 0.745098 0.003922
0.478431 0.749020 0.003922
0.478431 0.752941 0.000000
0.478431 0.752941 0.003922
0.482353 0.733333 0.047059
0.482353 0.749020 0.003922
0.482353 0.749020 0.015686
0.482353 0.752941 0.000000
0.482353 0.752941 0.003922
0.482353 0.752941 0.007843
0.482353 0.756863 0.003922
0.482353 0.760784 0.003922
0.486275 0.749020 0.015686
0.486275 0.752941 0.000000
0.486275 0.752941 0.003922
0.486275 0.752941 0.011765
0.486275 0.752941 0.015686
0.486275 0.756863 0.003922
0.486275 0.760784 0.003922
0.486275 0.764706 0.000000
0.486275 0.764706 0.003922
0.486275 0.768627 0.003922
0.490196 0.745098 0.035294
0.490196 0.745098 0.043137
0.490196 0.749020 0.031373
0.490196 0.756863 0.023529
0.490196 0.756863 0.035294
0.490196 0.760784 0.003922
0.490196 0.760784 0.007843
0.490196 0.764706 0.003922
0.490196 0.768627 0.000000
0.490196 0.768627 0.003922
0.490196 0.772549 0.003922
0.494118 0.745098 0.050980
0.494118 0.756863 0.027451
0.494118 0.764706 0.000000
0.494118 0.764706 0.003922
0.494118 0.768627 0.000000
0.494118 0.768627 0.003922
0.494118 0.772549 0.003922
0.494118 0.772549 0.007843
0.494118 0.776471 0.000000
0.494118 0.776471 0.003922
0.498039 0.741176 0.070588
0.498039 0.749020 0.062745
0.498039 0.752941 0.027451
0.498039 0.756863 0.043137
0.498039 0.760784 0.023529
0.498039 0.760784 0.035294
0.498039 0.768627 0.015686
0.498039 0.768627 0.023529
0.498039 0.772549 0.003922
0.498039 0.772549 0.015686
0.498039 0.776471 0.003922
0.498039 0.776471 0.007843
0.498039 0.776471 0.015686
0.498039 0.780392 0.000000
0.498039 0.780392 0.003922
0.498039 0.780392 0.007843
0.498039 0.784314 0.000000
0.498039 0.784314 0.003922
0.501961 0.752941 0.050980
0.501961 0.752941 0.054902
0.501961 0.756863 0.039216
0.501961 0.756863 0.058824
0.501961 0.768627 0.035294
0.501961 0.772549 0.023529
0.501961 0.776471 0.011765
0.501961 0.776471 0.015686
0.501961 0.776471 0.019608
0.501961 0.776471 0.023529
0.501961 0.780392 0.003922
0.501961 0.780392 0.007843
0.501961 0.780392 0.011765
0.501961 0.780392 0.015686
0.501961 0.780392 0.019608
0.501961 0.784314 0.003922
0.501961 0.784314 0.007843
0.501961 0.784314 0.011765
0.501961 0.788235 0.003922
0.501961 0.792157 0.003922
0.505882 0.756863 0.058824
0.505882 0.760784 0.047059
0.505882 0.760784 0.062745
0.505882 0.764706 0.039216
0.505882 0.768627 0.043137
0.505882 0.772549 0.031373
0.505882 0.776471 0.019608
0.505882 0.776471 0.023529
0.505882 0.776471 0.027451
0.505882 0.776471 0.031373
0.505882 0.776471 0.039216
0.505882 0.780392 0.019608
0.505882 0.780392 0.023529
0.505882 0.780392 0.027451
0.505882 0.784314 0.011765
0.505882 0.784314 0.015686
0.505882 0.784314 0.023529
0.505882 0.788235 0.003922
0.505882 0.788235 0.007843
0.505882 0.788235 0.011765
0.505882 0.788235 0.015686
0.505882 0.792157 0.003922
0.505882 0.792157 0.007843
0.505882 0.796078 0.000000
0.505882 0.796078 0.003922
0.509804 0.756863 0.070588
0.509804 0.776471 0.031373
0.509804 0.776471 0.043137
0.509804 0.776471 0.047059
0.509804 0.780392 0.031373
0.509804 0.780392 0.039216
0.509804 0.780392 0.047059
0.509804 0.784314 0.023529
0.509804 0.784314 0.027451
0.509804 0.784314 0.031373
0.509804 0.788235 0.019608
0.509804 0.788235 0.023529
0.509804 0.792157 0.003922
0.509804 0.792157 0.015686
0.509804 0.792157 0.019608
0.509804 0.796078 0.003922
0.509804 0.796078 0.011765
0.509804 0.796078 0.015686
0.509804 0.800000 0.003922
0.509804 0.803922 0.000000
0.513726 0.764706 0.066667
0.513726 0.772549 0.066667
0.513726 0.776471 0.043137
0.513726 0.780392 0.035294
0.513726 0.780392 0.039216
0.513726 0.780392 0.043137
0.513726 0.780392 0.047059
0.513726 0.780392 0.050980
0.513726 0.780392 0.054902
0.513726 0.784314 0.039216
0.513726 0.788235 0.023529
0.513726 0.788235 0.027451
0.513726 0.788235 0.031373
0.513726 0.788235 0.039216
0.513726 0.792157 0.023529
0.513726 0.792157 0.027451
0.513726 0.796078 0.007843
0.513726 0.796078 0.011765
0.513726 0.796078 0.015686
0.513726 0.796078 0.019608
0.513726 0.796078 0.023529
0.513726 0.800000 0.003922
0.513726 0.800000 0.007843
0.513726 0.800000 0.015686
0.513726 0.803922 0.000000
0.513726 0.803922 0.003922
0.513726 0.803922 0.007843
0.513726 0.807843 0.003922
0.517647 0.772549 0.070588
0.517647 0.776471 0.047059
0.517647 0.780392 0.047059
0.517647 0.780392 0.058824
0.517647 0.780392 0.062745
0.517647 0.784314 0.039216
0.517647 0.784314 0.047059
0.517647 0.784314 0.050980
0.517647 0.784314 0.054902
0.517647 0.792157 0.035294
0.517647 0.792157 0.039216
0.517647 0.796078 0.027451
0.517647 0.796078 0.039216
0.517647 0.800000 0.011765
0.517647 0.800000 0.027451
0.517647 0.800000 0.031373
0.517647 0.803922 0.007843
0.517647 0.803922 0.011765
0.517647 0.807843 0.003922
0.517647 0.807843 0.007843
0.517647 0.811765 0.003922
0.517647 0.811765 0.007843
0.517647 0.815686 0.003922
0.521569 0.772549 0.070588
0.521569 0.780392 0.058824
0.521569 0.780392 0.066667
0.521569 0.784314 0.050980
0.521569 0.784314 0.054902
0.521569 0.784314 0.058824
0.521569 0.784314 0.062745
0.521569 0.788235 0.047059
0.521569 0.788235 0.054902
0.521569 0.788235 0.058824
0.521569 0.792157 0.043137
0.521569 0.792157 0.054902
0.521569 0.796078 0.035294
0.521569 0.796078 0.039216
0.521569 0.796078 0.047059
0.521569 0.800000 0.015686
0.521569 0.800000 0.019608
0.521569 0.800000 0.027451
0.521569 0.800000 0.031373
0.521569 0.800000 0.035294
0.521569 0.800000 0.039216
0.521569 0.803922 0.019608
0.521569 0.803922 0.023529
0.521569 0.803922 0.027451
0.521569 0.803922 0.031373
0.521569 0.807843 0.011765
0.521569 0.807843 0.023529
0.521569 0.807843 0.027451
0.521569 0.811765 0.003922
0.521569 0.811765 0.011765
0.521569 0.811765 0.015686
0.521569 0.811765 0.019608
0.521569 0.815686 0.003922
0.521569 0.815686 0.007843
0.521569 0.819608 0.003922
0.525490 0.780392 0.066667
0.525490 0.780392 0.070588
0.525490 0.780392 0.078431
0.525490 0.784314 0.062745
0.525490 0.784314 0.066667
0.525490 0.784314 0.074510
0.525490 0.788235 0.058824
0.525490 0.788235 0.062745
0.525490 0.788235 0.066667
0.525490 0.792157 0.054902
0.525490 0.792157 0.058824
0.525490 0.792157 0.062745
0.525490 0.796078 0.043137
0.525490 0.796078 0.054902
0.525490 0.800000 0.035294
0.525490 0.800000 0.039216
0.525490 0.800000 0.043137
0.525490 0.803922 0.027451
0.525490 0.803922 0.031373
0.525490 0.803922 0.035294
0.525490 0.803922 0.039216
0.525490 0.803922 0.047059
0.525490 0.807843 0.027451
0.525490 0.807843 0.031373
0.525490 0.811765 0.019608
0.525490 0.811765 0.023529
0.525490 0.811765 0.031373
0.525490 0.815686 0.011765
0.525490 0.815686 0.015686
0.525490 0.819608 0.003922
0.525490 0.819608 0.007843
0.525490 0.823529 0.003922
0.525490 0.827451 0.003922
0.529412 0.784314 0.070588
0.529412 0.784314 0.074510
0.529412 0.788235 0.066667
0.529412 0.788235 0.070588
0.529412 0.788235 0.074510
0.529412 0.792157 0.062745
0.529412 0.792157 0.066667
0.529412 0.792157 0.074510
0.529412 0.796078 0.058824
0.529412 0.796078 0.062745
0.529412 0.800000 0.043137
0.529412 0.800000 0.047059
0.529412 0.800000 0.054902
0.529412 0.800000 0.066667
0.529412 0.803922 0.035294
0.529412 0.803922 0.039216
0.529412 0.803922 0.047059
0.529412 0.803922 0.054902
0.529412 0.807843 0.035294
0.529412 0.807843 0.050980
0.529412 0.811765 0.027451
0.529412 0.811765 0.031373
0.529412 0.815686 0.015686
0.529412 0.815686 0.019608
0.529412 0.815686 0.023529
0.529412 0.815686 0.027451
0.529412 0.815686 0.031373
0.529412 0.819608 0.015686
0.529412 0.823529 0.011765
0.529412 0.823529 0.015686
0.529412 0.827451 0.007843
0.529412 0.831373 0.003922
0.529412 0.831373 0.007843
0.533333 0.784314 0.094118
0.533333 0.796078 0.066667
0.533333 0.796078 0.070588
0.533333 0.796078 0.074510
0.533333 0.796078 0.078431
0.533333 0.800000 0.066667
0.533333 0.800000 0.070588
0.533333 0.803922 0.050980
0.533333 0.803922 0.054902
0.533333 0.803922 0.058824
0.533333 0.803922 0.062745
0.533333 0.803922 0.066667
0.533333 0.807843 0.043137
0.533333 0.807843 0.047059
0.533333 0.807843 0.050980
0.533333 0.807843 0.054902
0.533333 0.807843 0.062745
0.533333 0.811765 0.035294
0.533333 0.811765 0.039216
0.533333 0.811765 0.043137
0.533333 0.811765 0.050980
0.533333 0.815686 0.023529
0.533333 0.815686 0.035294
0.533333 0.815686 0.039216
0.533333 0.819608 0.019608
0.533333 0.819608 0.023529
0.533333 0.819608 0.027451
0.533333 0.819608 0.031373
0.533333 0.823529 0.019608
0.533333 0.823529 0.023529
0.533333 0.827451 0.011765
0.533333 0.827451 0.015686
0.533333 0.827451 0.023529
0.533333 0.831373 0.011765
0.533333 0.831373 0.015686
0.533333 0.831373 0.019608
0.533333 0.835294 0.003922
0.533333 0.835294 0.007843
0.533333 0.835294 0.011765
0.537255 0.792157 0.086275
0.537255 0.800000 0.066667
0.537255 0.800000 0.070588
0.537255 0.800000 0.074510
0.537255 0.800000 0.078431
0.537255 0.800000 0.086275
0.537255 0.800000 0.090196
0.537255 0.803922 0.058824
0.537255 0.803922 0.066667
0.537255 0.803922 0.070588
0.537255 0.803922 0.078431
0.537255 0.807843 0.050980
0.537255 0.807843 0.066667
0.537255 0.807843 0.070588
0.537255 0.811765 0.047059
0.537255 0.811765 0.050980
0.537255 0.811765 0.054902
0.537255 0.815686 0.039216
0.537255 0.815686 0.043137
0.537255 0.815686 0.047059
0.537255 0.815686 0.058824
0.537255 0.819608 0.035294
0.537255 0.819608 0.039216
0.537255 0.819608 0.043137
0.537255 0.819608 0.047059
0.537255 0.823529 0.027451
0.537255 0.823529 0.031373
0.537255 0.827451 0.019608
0.537255 0.827451 0.023529
0.537255 0.827451 0.027451
0.537255 0.827451 0.031373
0.537255 0.831373 0.019608
0.537255 0.831373 0.023529
0.537255 0.835294 0.011765
0.537255 0.835294 0.015686
0.537255 0.835294 0.019608
0.541176 0.803922 0.074510
0.541176 0.803922 0.078431
0.541176 0.807843 0.058824
0.541176 0.807843 0.066667
0.541176 0.807843 0.070588
0.541176 0.807843 0.074510
0.541176 0.807843 0.078431
0.541176 0.811765 0.058824
0.541176 0.811765 0.062745
0.541176 0.811765 0.066667
0.541176 0.815686 0.050980
0.541176 0.819608 0.039216
0.541176 0.819608 0.043137
0.541176 0.819608 0.054902
0.541176 0.823529 0.039216
0.541176 0.823529 0.047059
0.541176 0.823529 0.050980
0.541176 0.827451 0.031373
0.541176 0.827451 0.035294
0.541176 0.827451 0.039216
0.541176 0.831373 0.023529
0.541176 0.831373 0.027451
0.541176 0.831373 0.031373
0.541176 0.835294 0.019608
0.541176 0.835294 0.023529
0.541176 0.835294 0.027451
0.541176 0.835294 0.031373
0.541176 0.843137 0.011765
0.545098 0.796078 0.109804
0.545098 0.800000 0.105882
0.545098 0.807843 0.074510
0.545098 0.807843 0.078431
0.545098 0.811765 0.066667
0.545098 0.811765 0.070588
0.545098 0.811765 0.074510
0.545098 0.811765 0.078431
0.545098 0.815686 0.062745
0.545098 0.815686 0.066667
0.545098 0.815686 0.070588
0.545098 0.815686 0.074510
0.545098 0.819608 0.058824
0.545098 0.819608 0.062745
0.545098 0.819608 0.066667
0.545098 0.823529 0.043137
0.545098 0.823529 0.047059
0.545098 0.823529 0.054902
0.545098 0.823529 0.058824
0.545098 0.827451 0.043137
0.545098 0.827451 0.050980
0.545098 0.831373 0.035294
0.545098 0.831373 0.039216
0.545098 0.831373 0.047059
0.545098 0.831373 0.050980
0.545098 0.835294 0.027451
0.545098 0.835294 0.031373
0.545098 0.835294 0.035294
0.545098 0.835294 0.039216
0.545098 0.835294 0.043137
0.545098 0.839216 0.027451
0.545098 0.839216 0.031373
0.545098 0.839216 0.035294
0.549020 0.792157 0.117647
0.549020 0.796078 0.105882
0.549020 0.811765 0.078431
0.549020 0.815686 0.074510
0.549020 0.815686 0.078431
0.549020 0.819608 0.066667
0.549020 0.819608 0.070588
0.549020 0.819608 0.074510
0.549020 0.819608 0.078431
0.549020 0.823529 0.058824
0.549020 0.823529 0.062745
0.549020 0.823529 0.066667
0.549020 0.823529 0.070588
0.549020 0.827451 0.047059
0.549020 0.827451 0.050980
0.549020 0.827451 0.054902
0.549020 0.831373 0.043137
0.549020 0.831373 0.047059
0.549020 0.831373 0.050980
0.549020 0.831373 0.054902
0.549020 0.831373 0.058824
0.549020 0.835294 0.035294
0.549020 0.835294 0.039216
0.549020 0.835294 0.043137
0.549020 0.835294 0.047059
0.549020 0.835294 0.050980
0.549020 0.839216 0.035294
0.549020 0.839216 0.039216
0.549020 0.839216 0.043137
0.549020 0.839216 0.047059
0.552941 0.811765 0.090196
0.552941 0.811765 0.098039
0.552941 0.819608 0.082353
0.552941 0.823529 0.070588
0.552941 0.823529 0.074510
0.552941 0.823529 0.078431
0.552941 0.827451 0.054902
0.552941 0.827451 0.062745
0.552941 0.827451 0.066667
0.552941 0.827451 0.070588
0.552941 0.827451 0.074510
0.552941 0.831373 0.058824
0.552941 0.831373 0.066667
0.552941 0.835294 0.054902
0.552941 0.835294 0.058824
0.552941 0.839216 0.043137
0.552941 0.839216 0.047059
0.552941 0.839216 0.050980
0.552941 0.839216 0.054902
0.552941 0.839216 0.058824
0.552941 0.843137 0.050980
0.552941 0.843137 0.054902
0.556863 0.800000 0.133333
0.556863 0.827451 0.078431
0.556863 0.831373 0.074510
0.556863 0.835294 0.062745
0.556863 0.835294 0.066667
0.556863 0.835294 0.074510
0.556863 0.839216 0.050980
0.556863 0.839216 0.054902
0.556863 0.839216 0.058824
0.556863 0.839216 0.062745
0.556863 0.839216 0.066667
0.556863 0.843137 0.054902
0.556863 0.843137 0.058824
0.556863 0.843137 0.062745
0.560784 0.803922 0.133333
0.560784 0.815686 0.105882
0.560784 0.819608 0.113725
0.560784 0.823529 0.105882
0.560784 0.827451 0.098039
0.560784 0.835294 0.070588
0.560784 0.835294 0.074510
0.560784 0.835294 0.078431
0.560784 0.839216 0.058824
0.560784 0.839216 0.062745
0.560784 0.839216 0.066667
0.560784 0.839216 0.070588
0.560784 0.839216 0.074510
0.560784 0.839216 0.078431
0.560784 0.843137 0.062745
0.560784 0.843137 0.066667
0.560784 0.843137 0.070588
0.560784 0.843137 0.074510
0.564706 0.815686 0.121569
0.564706 0.839216 0.078431
0.564706 0.839216 0.082353
0.564706 0.839216 0.086275
0.564706 0.839216 0.090196
0.564706 0.843137 0.066667
0.564706 0.843137 0.070588
0.564706 0.843137 0.074510
0.564706 0.843137 0.078431
0.564706 0.847059 0.074510
0.564706 0.847059 0.078431
0.564706 0.847059 0.082353
0.568627 0.823529 0.117647
0.568627 0.835294 0.105882
0.568627 0.839216 0.086275
0.568627 0.843137 0.078431
0.568627 0.843137 0.082353
0.568627 0.843137 0.086275
0.568627 0.847059 0.078431
0.568627 0.847059 0.082353
0.568627 0.847059 0.086275
0.568627 0.847059 0.090196
0.572549 0.835294 0.113725
0.572549 0.843137 0.086275
0.572549 0.843137 0.090196
0.572549 0.843137 0.094118
0.572549 0.847059 0.086275
0.572549 0.847059 0.090196
0.572549 0.847059 0.094118
0.572549 0.847059 0.098039
0.576471 0.843137 0.098039
0.576471 0.847059 0.094118
0.576471 0.847059 0.098039
0.576471 0.847059 0.101961
0.576471 0.847059 0.105882
0.576471 0.847059 0.109804
0.576471 0.850980 0.101961
0.576471 0.850980 0.105882
0.580392 0.843137 0.109804
0.580392 0.843137 0.113725
0.580392 0.847059 0.105882
0.580392 0.847059 0.109804
0.580392 0.847059 0.113725
0.580392 0.850980 0.105882
0.580392 0.850980 0.109804
0.580392 0.850980 0.113725
0.584314 0.847059 0.113725
0.584314 0.847059 0.117647
0.584314 0.847059 0.125490
0.584314 0.850980 0.113725
0.584314 0.850980 0.117647
0.584314 0.850980 0.121569
0.584314 0.854902 0.121569
0.588235 0.847059 0.125490
0.588235 0.850980 0.117647
0.588235 0.850980 0.121569
0.588235 0.850980 0.125490
0.588235 0.850980 0.129412
0.588235 0.850980 0.137255
0.588235 0.854902 0.125490
0.592157 0.850980 0.129412
0.592157 0.850980 0.133333
0.592157 0.850980 0.137255
0.592157 0.850980 0.141176
0.592157 0.854902 0.129412
0.592157 0.854902 0.133333
0.592157 0.854902 0.137255
0.596078 0.850980 0.141176
0.596078 0.854902 0.141176
0.596078 0.854902 0.145098
0.600000 0.850980 0.156863
0.600000 0.850980 0.160784
0.600000 0.854902 0.145098
0.600000 0.854902 0.149020
0.603922 0.854902 0.164706
0.607843 0.850980 0.172549
0.607843 0.854902 0.172549
0.678431 0.294118 0.074510
0.737255 0.333333 0.101961
0.745098 0.023529 0.023529
0.819608 0.352941 0.086275
0.854902 0.368627 0.090196
0.858824 0.368627 0.090196
0.870588 0.376471 0.090196
0.890196 0.094118 0.094118
0.890196 0.403922 0.125490
0.890196 0.411765 0.137255
0.890196 0.619608 0.094118
0.894118 0.427451 0.160784
0.901961 0.901961 0.901961
0.917647 0.917647 0.917647
0.921569 0.921569 0.921569
0.925490 0.925490 0.925490
0.937255 0.937255 0.937255
0.960784 0.960784 0.960784
0.964706 0.964706 0.964706
0.968627 0.968627 0.968627
0.988235 0.988235 0.988235
0.992157 0.992157 0.992157
0 3 1 8 84
0 3 2 6 20
0 3 3 16 20
0 3 4 16 20
0 3 5 17 20
0 3 6 15 20
0 3 7 11 20
0 3 8 8 20
0 3 9 8 20
0 3 10 8 20
0 3 11 8 20
0 3 12 7 20
0 3 13 16 20
0 3 14 11 52
0 4 1 4 68
0 4 2 8 4
0 4 3 8 4
0 4 4 4 4
0 4 5 14 4
0 4 6 6 4
0 4 7 8 4
0 4 8 8 4
0 4 9 4 4
0 4 10 7 4
0 4 11 16 4
0 4 12 10 4
0 4 13 13 4
0 4 14 4 36
0 5 1 124 68
0 5 2 445 4
0 5 3 167 4
0 5 4 589 4
0 5 5 371 4
0 5 6 579 4
0 5 7 527 4
0 5 8 527 4
0 5 9 549 4
0 5 10 243 4
0 5 11 575 4
0 5 12 499 4
0 5 13 584 4
0 5 14 252 36
0 6 1 437 68
0 6 2 333 4
0 6 3 600 4
0 6 4 578 4
0 6 5 443 4
0 6 6 535 4
0 6 7 173 4
0 6 8 173 4
0 6 9 578 4
0 6 10 266 4
0 6 11 448 4
0 6 12 110 4
0 6 13 330 4
0 6 14 529 36
0 7 1 336 68
0 7 2 380 4
0 7 3 202 4
0 7 4 576 4
0 7 5 438 4
0 7 6 420 4
0 7 7 422 4
0 7 8 422 4
0 7 9 612 4
0 7 10 372 4
0 7 11 401 4
0 7 12 242 4
0 7 13 109 4
0 7 14 383 36
0 8 1 501 68
0 8 2 575 4
0 8 3 296 4
0 8 4 625 4
0 8 5 346 4
0 8 6 222 4
0 8 7 110 4
0 8 8 110 4
0 8 9 473 4
0 8 10 587 4
0 8 11 124 4
0 8 12 89 4
0 8 13 575 4
0 8 14 448 36
0 9 1 69 68
0 9 2 300 4
0 9 3 477 4
0 9 4 50 4
0 9 5 596 4
0 9 6 113 4
0 9 7 482 4
0 9 8 482 4
0 9 9 110 4
0 9 10 641 4
0 9 11 589 4
0 9 12 64 4
0 9 13 231 4
0 9 14 341 36
0 10 1 621 76
0 10 2 589 12
0 10 3 618 12
0 10 4 420 12
0 10 5 567 12
0 10 6 576 12
0 10 7 286 12
0 10 8 286 12
0 10 9 128 12
0 10 10 566 12
0 10 11 110 12
0 10 12 342 12
0 10 13 427 12
0 10 14 566 44
1 3 1 9 80
1 3 2 11 16
1 3 3 10 16
1 3 4 4 16
1 3 5 17 16
1 3 6 8 16
1 3 7 13 16
1 3 8 3 16
1 3 9 7 16
1 3 10 5 16
1 3 11 15 16
1 3 12 5 16
1 3 13 4 16
1 3 14 10 48
1 4 1 12 64
1 4 2 22 0
1 4 3 22 0
1 4 4 22 0
1 4 5 22 0
1 4 6 22 0
1 4 7 22 0
1 4 8 22 0
1 4 9 22 0
1 4 10 22 0
1 4 11 22 0
1 4 12 22 0
1 4 13 22 0
1 4 14 22 32
1 5 1 593 64
1 5 2 277 0
1 5 3 91 0
1 5 4 125 0
1 5 5 351 0
1 5 6 47 0
1 5 7 532 0
1 5 8 532 0
1 5 9 343 0
1 5 10 424 0
1 5 11 347 0
1 5 12 64 0
1 5 13 66 0
1 5 14 128 32
1 6 1 318 64
1 6 2 103 0
1 6 3 257 0
1 6 4 566 0
1 6 5 79 0
1 6 6 50 0
1 6 7 395 0
1 6 8 395 0
1 6 9 601 0
1 6 10 334 0
1 6 11 597 0
1 6 12 512 0
1 6 13 619 0
1 6 14 575 32
1 7 1 609 64
1 7 2 615 0
1 7 3 376 0
1 7 4 532 0
1 7 5 79 0
1 7 6 447 0
1 7 7 524 0
1 7 8 524 0
1 7 9 109 0
1 7 10 454 0
1 7 11 113 0
1 7 12 382 0
1 7 13 267 0
1 7 14 234 32
1 8 1 71 64
1 8 2 589 0
1 8 3 408 0
1 8 4 391 0
1 8 5 322 0
1 8 6 327 0
1 8 7 576 0
1 8 8 576 0
1 8 9 392 0
1 8 10 417 0
1 8 11 448 0
1 8 12 39 0
1 8 13 67 0
1 8 14 418 32
1 9 1 107 64
1 9 2 420 0
1 9 3 340 0
1 9 4 260 0
1 9 5 283 0
1 9 6 109 0
1 9 7 624 0
1 9 8 624 0
1 9 9 64 0
1 9 10 43 0
1 9 11 300 0
1 9 12 395 0
1 9 13 397 0
1 9 14 448 32
1 10 1 473 72
1 10 2 322 8
1 10 3 128 8
1 10 4 508 8
1 10 5 113 8
1 10 6 281 8
1 10 7 336 8
1 10 8 336 8
1 10 9 512 8
1 10 10 60 8
1 10 11 450 8
1 10 12 163 8
1 10 13 109 8
1 10 14 367 40
2 0 3 11 92
2 0 4 11 60
2 0 12 5 92
2 0 13 8 60
2 3 1 9 80
2 3 2 7 16
2 3 3 9 16
2 3 4 5 16
2 3 5 10 16
2 3 6 9 16
2 3 7 5 16
2 3 8 8 16
2 3 9 11 16
2 3 10 13 16
2 3 11 12 16
2 3 12 4 16
2 3 13 5 16
2 3 14 15 48
2 4 1 26 64
2 4 2 22 0
2 4 3 22 0
2 4 4 22 0
2 4 5 22 0
2 4 6 22 0
2 4 7 22 0
2 4 8 22 0
2 4 9 22 0
2 4 10 22 0
2 4 11 22 0
2 4 12 22 0
2 4 13 22 0
2 4 14 22 32
2 5 1 628 64
2 5 2 577 0
2 5 3 314 0
2 5 4 53 0
2 5 5 264 0
2 5 6 449 0
2 5 7 319 0
2 5 8 319 0
2 5 9 455 0
2 5 10 262 0
2 5 11 71 0
2 5 12 623 0
2 5 13 350 0
2 5 14 595 32
2 6 1 531 64
2 6 2 254 0
2 6 3 89 0
2 6 4 270 0
2 6 5 245 0
2 6 6 312 0
2 6 7 173 0
2 6 8 173 0
2 6 9 592 0
2 6 10 613 0
2 6 11 447 0
2 6 12 337 0
2 6 13 312 0
2 6 14 345 32
2 7 1 602 64
2 7 2 291 0
2 7 3 602 0
2 7 4 150 0
2 7 5 589 0
2 7 6 289 0
2 7 7 82 0
2 7 8 82 0
2 7 9 227 0
2 7 10 232 0
2 7 11 426 0
2 7 12 256 0
2 7 13 264 0
2 7 14 219 32
2 8 1 587 64
2 8 2 502 0
2 8 3 615 0
2 8 4 597 0
2 8 5 508 0
2 8 6 194 0
2 8 7 503 0
2 8 8 503 0
2 8 9 636 0
2 8 10 584 0
2 8 11 100 0
2 8 12 124 0
2 8 13 586 0
2 8 14 575 32
2 9 1 512 64
2 9 2 243 0
2 9 3 467 0
2 9 4 176 0
2 9 5 239 0
2 9 6 461 0
2 9 7 71 0
2 9 8 71 0
2 9 9 290 0
2 9 10 297 0
2 9 11 195 0
2 9 12 531 0
2 9 13 109 0
2 9 14 128 32
2 10 1 654 72
2 10 2 336 8
2 10 3 183 0
2 10 4 378 0
2 10 5 557 0
2 10 6 358 0
2 10 7 641 0
2 10 8 641 0
2 10 9 618 0
2 10 10 287 0
2 10 11 447 0
2 10 12 558 0
2 10 13 314 0
2 10 14 595 32
2 11 3 71 68
2 11 4 449 4
2 11 5 566 4
2 11 6 575 4
2 11 7 603 4
2 11 8 603 4
2 11 9 303 4
2 11 10 504 4
2 11 11 64 4
2 11 12 317 4
2 11 13 398 4
2 11 14 89 44
2 12 3 364 68
2 12 4 386 4
2 12 5 81 4
2 12 6 319 4
2 12 7 510 4
2 12 8 510 4
2 12 9 66 4
2 12 10 69 4
2 12 11 147 4
2 12 12 359 4
2 12 13 550 36
2 13 3 601 68
2 13 4 37 4
2 13 5 85 4
2 13 6 548 4
2 13 7 439 4
2 13 8 439 4
2 13 9 144 4
2 13 10 577 4
2 13 11 100 4
2 13 12 206 4
2 13 13 179 44
2 14 3 588 76
2 14 4 100 12
2 14 5 567 12
2 14 6 566 12
2 14 7 512 12
2 14 8 512 12
2 14 9 228 12
2 14 10 565 12
2 14 11 618 12
2 14 12 509 44
3 0 2 6 94
3 0 3 17 24
3 0 4 16 16
3 0 5 17 62
3 0 11 5 94
3 0 12 13 24
3 0 13 8 16
3 0 14 3 62
3 1 4 9 102
3 1 13 8 102
3 2 4 9 102
3 2 13 9 102
3 3 1 9 80
3 3 2 3 16
3 3 3 7 16
3 3 4 4 0
3 3 5 7 16
3 3 6 10 16
3 3 7 8 16
3 3 8 4 16
3 3 9 10 16
3 3 10 13 16
3 3 11 17 16
3 3 12 7 16
3 3 13 13 0
3 3 14 4 48
3 4 1 24 66
3 4 2 22 0
3 4 3 22 0
3 4 4 22 0
3 4 5 22 0
3 4 6 22 0
3 4 7 22 0
3 4 8 22 0
3 4 9 22 0
3 4 10 22 0
3 4 11 22 0
3 4 12 22 0
3 4 13 22 0
3 4 14 22 32
3 5 1 317 66
3 5 2 419 0
3 5 3 371 0
3 5 4 321 0
3 5 5 135 0
3 5 6 498 0
3 5 7 349 0
3 5 8 349 0
3 5 9 73 0
3 5 10 453 0
3 5 11 220 0
3 5 12 326 0
3 5 13 257 0
3 5 14 359 32
3 6 1 451 66
3 6 2 547 0
3 6 3 371 0
3 6 4 225 0
3 6 5 586 0
3 6 6 54 0
3 6 7 571 0
3 6 8 571 0
3 6 9 126 0
3 6 10 597 0
3 6 11 266 0
3 6 12 324 0
3 6 13 201 0
3 6 14 531 32
3 7 1 36 66
3 7 2 190 0
3 7 3 96 0
3 7 4 290 0
3 7 5 104 0
3 7 6 189 0
3 7 7 548 0
3 7 8 548 0
3 7 9 60 0
3 7 10 160 0
3 7 11 195 0
3 7 12 373 0
3 7 13 128 0
3 7 14 350 32
3 8 1 451 64
3 8 2 226 0
3 8 3 374 0
3 8 4 422 0
3 8 5 173 0
3 8 6 579 0
3 8 7 227 0
3 8 8 227 0
3 8 9 576 0
3 8 10 72 0
3 8 11 575 0
3 8 12 169 0
3 8 13 222 0
3 8 14 110 32
3 9 1 617 64
3 9 2 375 0
3 9 3 400 0
3 9 4 386 0
3 9 5 512 0
3 9 6 224 0
3 9 7 278 0
3 9 8 278 0
3 9 9 432 0
3 9 10 436 0
3 9 11 562 0
3 9 12 391 0
3 9 13 124 0
3 9 14 272 32
3 10 1 649 72
3 10 2 624 8
3 10 3 605 0
3 10 4 128 0
3 10 5 128 0
3 10 6 544 0
3 10 7 448 0
3 10 8 448 0
3 10 9 558 0
3 10 10 258 0
3 10 11 488 0
3 10 12 342 0
3 10 13 511 0
3 10 14 602 32
3 11 3 532 64
3 11 4 173 0
3 11 5 193 0
3 11 6 575 0
3 11 7 147 0
3 11 8 147 0
3 11 9 169 0
3 11 10 584 0
3 11 11 74 0
3 11 12 315 0
3 11 13 125 0
3 11 14 265 40
3 12 3 173 64
3 12 4 379 0
3 12 5 79 0
3 12 6 147 0
3 12 7 227 0
3 12 8 227 0
3 12 9 532 0
3 12 10 492 0
3 12 11 280 0
3 12 12 245 0
3 12 13 417 32
3 13 3 362 64
3 13 4 495 0
3 13 5 282 0
3 13 6 280 0
3 13 7 624 0
3 13 8 624 0
3 13 9 424 0
3 13 10 595 0
3 13 11 150 0
3 13 12 128 0
3 13 13 565 40
3 14 3 72 72
3 14 4 480 8
3 14 5 278 8
3 14 6 294 8
3 14 7 609 8
3 14 8 609 8
3 14 9 543 8
3 14 10 58 8
3 14 11 560 8
3 14 12 478 40
3 15 2 9 124
4 0 3 4 90
4 0 4 5 58
4 0 12 11 90
4 0 13 4 58
4 3 1 9 88
4 3 2 13 16
4 3 3 14 16
4 3 4 11 16
4 3 5 4 16
4 3 6 17 16
4 3 7 13 16
4 3 8 3 16
4 3 9 4 16
4 3 10 3 16
4 3 11 10 16
4 3 12 9 16
4 3 13 8 16
4 3 14 8 48
4 4 0 2 116
4 4 2 0 64
4 4 3 22 0
4 4 4 22 0
4 4 5 22 0
4 4 6 22 0
4 4 7 22 0
4 4 8 22 0
4 4 9 22 0
4 4 10 22 0
4 4 11 22 0
4 4 12 22 0
4 4 13 22 0
4 4 14 22 32
4 5 0 2 102
4 5 2 0 64
4 5 3 44 0
4 5 4 77 0
4 5 5 250 0
4 5 6 371 0
4 5 7 431 0
4 5 8 431 0
4 5 9 136 0
4 5 10 356 0
4 5 11 289 0
4 5 12 177 0
4 5 13 527 0
4 5 14 479 32
4 6 0 2 102
4 6 2 0 64
4 6 3 112 0
4 6 4 33 0
4 6 5 458 0
4 6 6 444 0
4 6 7 248 0
4 6 8 248 0
4 6 9 84 0
4 6 10 288 0
4 6 11 308 0
4 6 12 641 0
4 6 13 301 0
4 6 14 64 32
4 7 0 2 108
4 7 2 0 64
4 7 3 528 0
4 7 4 158 0
4 7 5 474 0
4 7 6 207 0
4 7 7 612 0
4 7 8 612 0
4 7 9 193 0
4 7 10 465 0
4 7 11 416 0
4 7 12 243 0
4 7 13 601 0
4 7 14 448 32
4 8 1 65 80
4 8 2 97 0
4 8 3 59 0
4 8 4 314 0
4 8 5 169 0
4 8 6 538 0
4 8 7 224 0
4 8 8 224 0
4 8 9 478 0
4 8 10 558 0
4 8 11 280 0
4 8 12 522 0
4 8 13 531 0
4 8 14 448 32
4 9 1 265 64
4 9 2 483 0
4 9 3 525 0
4 9 4 534 0
4 9 5 147 0
4 9 6 311 0
4 9 7 50 0
4 9 8 50 0
4 9 9 577 0
4 9 10 401 0
4 9 11 531 0
4 9 12 82 0
4 9 13 243 0
4 9 14 322 32
4 10 1 651 72
4 10 2 544 0
4 10 3 64 0
4 10 4 331 0
4 10 5 222 0
4 10 6 281 0
4 10 7 570 0
4 10 8 570 0
4 10 9 619 0
4 10 10 618 0
4 10 11 398 0
4 10 12 357 0
4 10 13 597 0
4 10 14 281 32
4 11 2 658 68
4 11 3 110 0
4 11 4 390 0
4 11 5 397 0
4 11 6 590 0
4 11 7 509 0
4 11 8 509 0
4 11 9 637 0
4 11 10 496 0
4 11 11 596 0
4 11 12 588 0
4 11 13 601 0
4 11 14 100 40
4 12 2 660 68
4 12 3 231 0
4 12 4 375 0
4 12 5 496 0
4 12 6 420 0
4 12 7 124 0
4 12 8 124 0
4 12 9 218 0
4 12 10 290 0
4 12 11 330 0
4 12 12 122 0
4 12 13 596 32
4 13 2 667 70
4 13 3 312 0
4 13 4 122 0
4 13 5 173 0
4 13 6 520 0
4 13 7 473 0
4 13 8 473 0
4 13 9 280 0
4 13 10 243 0
4 13 11 475 0
4 13 12 270 0
4 13 13 186 40
4 14 2 9 68
4 14 3 216 8
4 14 4 508 8
4 14 5 653 0
4 14 6 653 0
4 14 7 585 8
4 14 8 585 0
4 14 9 561 0
4 14 10 124 8
4 14 11 129 0
4 14 12 548 32
4 15 2 9 104
4 15 5 653 76
4 15 6 653 46
4 15 8 653 76
4 15 9 653 46
4 15 11 653 76
4 15 12 653 46
5 3 1 9 88
5 3 2 5 16
5 3 3 11 16
5 3 4 6 16
5 3 5 10 16
5 3 6 15 16
5 3 7 4 16
5 3 8 4 16
5 3 9 4 16
5 3 10 3 16
5 3 11 13 16
5 3 12 8 16
5 3 13 5 16
5 3 14 15 48
5 4 0 2 120
5 4 2 0 64
5 4 3 22 0
5 4 4 22 0
5 4 5 22 0
5 4 6 22 0
5 4 7 22 0
5 4 8 22 0
5 4 9 22 0
5 4 10 22 0
5 4 11 22 0
5 4 12 22 0
5 4 13 22 0
5 4 14 22 32
5 5 2 0 64
5 5 3 221 0
5 5 4 503 0
5 5 5 409 0
5 5 6 279 0
5 5 7 486 0
5 5 8 486 0
5 5 9 554 0
5 5 10 221 0
5 5 11 65 0
5 5 12 611 0
5 5 13 102 0
5 5 14 147 32
5 6 2 0 64
5 6 3 149 0
5 6 4 304 0
5 6 5 309 0
5 6 6 115 0
5 6 7 458 0
5 6 8 458 0
5 6 9 469 0
5 6 10 446 0
5 6 11 109 0
5 6 12 467 0
5 6 13 252 0
5 6 14 359 32
5 7 0 2 120
5 7 2 0 64
5 7 3 93 0
5 7 4 90 0
5 7 5 153 0
5 7 6 435 0
5 7 7 297 0
5 7 8 297 0
5 7 9 39 0
5 7 10 201 0
5 7 11 185 0
5 7 12 182 0
5 7 13 128 0
5 7 14 171 32
5 8 1 639 80
5 8 2 573 0
5 8 3 539 0
5 8 4 74 0
5 8 5 109 0
5 8 6 179 0
5 8 7 187 0
5 8 8 187 0
5 8 9 192 0
5 8 10 602 0
5 8 11 319 0
5 8 12 585 0
5 8 13 464 0
5 8 14 88 32
5 9 1 443 64
5 9 2 168 0
5 9 3 587 0
5 9 4 592 0
5 9 5 449 0
5 9 6 284 0
5 9 7 203 0
5 9 8 203 0
5 9 9 576 0
5 9 10 386 0
5 9 11 596 0
5 9 12 240 0
5 9 13 89 0
5 9 14 238 0
5 9 15 21 60
5 10 1 650 72
5 10 2 55 0
5 10 3 39 0
5 10 4 621 0
5 10 5 259 0
5 10 6 587 0
5 10 7 448 0
5 10 8 448 0
5 10 9 235 0
5 10 10 531 0
5 10 11 299 0
5 10 12 539 0
5 10 13 332 0
5 10 14 597 32
5 11 2 659 64
5 11 3 336 0
5 11 4 60 0
5 11 5 336 0
5 11 6 304 0
5 11 7 634 0
5 11 8 634 0
5 11 9 218 0
5 11 10 298 0
5 11 11 587 0
5 11 12 509 0
5 11 13 620 0
5 11 14 72 40
5 12 2 1 72
5 12 3 89 0
5 12 4 430 0
5 12 5 296 0
5 12 6 91 0
5 12 7 567 0
5 12 8 567 0
5 12 9 150 0
5 12 10 566 0
5 12 11 609 0
5 12 12 74 0
5 12 13 427 32
5 13 3 139 64
5 13 4 513 0
5 13 5 612 0
5 13 6 274 0
5 13 7 195 0
5 13 8 195 0
5 13 9 144 0
5 13 10 61 0
5 13 11 400 0
5 13 12 385 0
5 13 13 240 40
5 14 2 9 80
5 14 3 261 8
5 14 4 297 8
5 14 5 653 0
5 14 6 549 8
5 14 7 397 8
5 14 8 397 0
5 14 9 596 8
5 14 10 456 8
5 14 11 237 0
5 14 12 215 40
5 15 2 9 106
5 15 5 653 106
5 15 8 653 106
5 15 11 653 106
6 3 1 9 88
6 3 2 5 16
6 3 3 5 16
6 3 4 8 16
6 3 5 4 16
6 3 6 8 16
6 3 7 12 16
6 3 8 13 16
6 3 9 8 16
6 3 10 16 16
6 3 11 16 16
6 3 12 5 16
6 3 13 13 16
6 3 14 4 48
6 4 0 2 120
6 4 2 0 64
6 4 3 22 0
6 4 4 22 0
6 4 5 22 0
6 4 6 22 0
6 4 7 22 0
6 4 8 22 0
6 4 9 22 0
6 4 10 22 0
6 4 11 22 0
6 4 12 22 0
6 4 13 22 0
6 4 14 22 32
6 5 2 0 64
6 5 3 199 0
6 5 4 521 0
6 5 5 213 0
6 5 6 459 0
6 5 7 228 0
6 5 8 228 0
6 5 9 517 0
6 5 10 128 0
6 5 11 581 0
6 5 12 354 0
6 5 13 391 0
6 5 14 186 32
6 6 2 0 64
6 6 3 179 0
6 6 4 123 0
6 6 5 121 0
6 6 6 363 0
6 6 7 503 0
6 6 8 503 0
6 6 9 316 0
6 6 10 124 0
6 6 11 102 0
6 6 12 575 0
6 6 13 129 0
6 6 14 379 32
6 7 0 2 120
6 7 2 0 64
6 7 3 481 0
6 7 4 83 0
6 7 5 515 0
6 7 6 118 0
6 7 7 366 0
6 7 8 366 0
6 7 9 124 0
6 7 10 586 0
6 7 11 614 0
6 7 12 397 0
6 7 13 250 0
6 7 14 577 32
6 8 1 161 80
6 8 2 90 0
6 8 3 125 0
6 8 4 245 0
6 8 5 396 0
6 8 6 383 0
6 8 7 336 0
6 8 8 336 0
6 8 9 414 0
6 8 10 350 0
6 8 11 614 0
6 8 12 579 0
6 8 13 292 0
6 8 14 484 0
6 8 15 21 52
6 9 1 646 64
6 9 2 200 0
6 9 3 244 0
6 9 4 218 0
6 9 5 218 0
6 9 6 234 0
6 9 7 324 0
6 9 8 324 0
6 9 9 576 0
6 9 10 530 0
6 9 11 173 0
6 9 12 580 0
6 9 13 72 0
6 9 14 466 0
6 9 15 27 40
6 10 1 216 72
6 10 2 256 0
6 10 3 142 0
6 10 4 270 0
6 10 5 376 0
6 10 6 71 0
6 10 7 323 0
6 10 8 323 0
6 10 9 618 0
6 10 10 483 0
6 10 11 404 0
6 10 12 464 0
6 10 13 603 0
6 10 14 378 32
6 11 2 665 66
6 11 3 565 0
6 11 4 166 0
6 11 5 66 0
6 11 6 302 0
6 11 7 76 0
6 11 8 76 0
6 11 9 280 0
6 11 10 528 0
6 11 11 500 0
6 11 12 124 0
6 11 13 243 0
6 11 14 624 40
6 12 2 664 66
6 12 3 79 0
6 12 4 605 0
6 12 5 597 0
6 12 6 483 0
6 12 7 379 0
6 12 8 379 0
6 12 9 391 0
6 12 10 402 0
6 12 11 457 0
6 12 12 88 0
6 12 13 575 32
6 13 2 666 70
6 13 3 148 0
6 13 4 357 0
6 13 5 437 0
6 13 6 271 0
6 13 7 79 0
6 13 8 79 0
6 13 9 489 0
6 13 10 231 0
6 13 11 188 0
6 13 12 147 0
6 13 13 600 40
6 14 2 9 74
6 14 3 386 8
6 14 4 653 0
6 14 5 264 8
6 14 6 478 8
6 14 7 208 0
6 14 8 208 8
6 14 9 63 8
6 14 10 614 0
6 14 11 629 8
6 14 12 601 40
6 15 4 653 110
6 15 7 653 110
6 15 10 653 110
7 3 1 9 88
7 3 2 3 16
7 3 3 8 16
7 3 4 8 16
7 3 5 3 16
7 3 6 4 16
7 3 7 3 16
7 3 8 8 16
7 3 9 4 16
7 3 10 8 16
7 3 11 4 16
7 3 12 14 16
7 3 13 10 16
7 3 14 12 48
7 4 0 2 120
7 4 2 648 64
7 4 3 22 0
7 4 4 22 0
7 4 5 22 0
7 4 6 22 0
7 4 7 22 0
7 4 8 22 0
7 4 9 22 0
7 4 10 22 0
7 4 11 22 0
7 4 12 22 0
7 4 13 22 0
7 4 14 22 32
7 5 2 648 64
7 5 3 101 0
7 5 4 154 0
7 5 5 460 0
7 5 6 87 0
7 5 7 155 0
7 5 8 155 0
7 5 9 197 0
7 5 10 583 0
7 5 11 70 0
7 5 12 405 0
7 5 13 280 0
7 5 14 404 0
7 5 15 9 54
7 6 2 0 64
7 6 3 175 0
7 6 4 201 0
7 6 5 388 0
7 6 6 631 0
7 6 7 631 0
7 6 8 631 0
7 6 9 643 0
7 6 10 508 0
7 6 11 100 0
7 6 12 128 0
7 6 13 601 0
7 6 14 308 0
7 6 15 9 38
7 7 0 2 120
7 7 2 0 64
7 7 3 152 0
7 7 4 553 0
7 7 5 80 0
7 7 6 370 0
7 7 7 468 0
7 7 8 468 0
7 7 9 541 0
7 7 10 89 0
7 7 11 624 0
7 7 12 383 0
7 7 13 310 0
7 7 14 253 0
7 7 15 22 38
7 8 1 528 80
7 8 2 127 0
7 8 3 157 0
7 8 4 526 0
7 8 5 578 0
7 8 6 280 0
7 8 7 531 0
7 8 8 531 0
7 8 9 113 0
7 8 10 618 0
7 8 11 282 0
7 8 12 294 0
7 8 13 432 0
7 8 14 76 0
7 8 15 23 32
7 9 1 651 64
7 9 2 39 0
7 9 3 266 0
7 9 4 140 0
7 9 5 88 0
7 9 6 545 0
7 9 7 259 0
7 9 8 259 0
7 9 9 566 0
7 9 10 445 0
7 9 11 147 0
7 9 12 432 0
7 9 13 82 0
7 9 14 280 0
7 9 15 20 40
7 10 1 366 72
7 10 2 91 8
7 10 3 543 0
7 10 4 609 0
7 10 5 89 0
7 10 6 209 0
7 10 7 113 0
7 10 8 113 0
7 10 9 173 0
7 10 10 262 0
7 10 11 619 0
7 10 12 429 0
7 10 13 588 0
7 10 14 531 32
7 11 3 493 64
7 11 4 138 0
7 11 5 235 0
7 11 6 217 0
7 11 7 606 0
7 11 8 606 0
7 11 9 576 0
7 11 10 495 0
7 11 11 71 0
7 11 12 512 0
7 11 13 192 0
7 11 14 577 40
7 12 3 512 64
7 12 4 490 0
7 12 5 625 0
7 12 6 426 0
7 12 7 550 0
7 12 8 550 0
7 12 9 245 0
7 12 10 626 0
7 12 11 307 0
7 12 12 223 0
7 12 13 229 32
7 13 3 428 64
7 13 4 545 0
7 13 5 529 0
7 13 6 150 0
7 13 7 369 0
7 13 8 369 0
7 13 9 522 0
7 13 10 598 0
7 13 11 110 0
7 13 12 321 0
7 13 13 224 40
7 14 3 128 72
7 14 4 543 8
7 14 5 311 8
7 14 6 128 8
7 14 7 566 8
7 14 8 566 8
7 14 9 192 8
7 14 10 618 8
7 14 11 557 8
7 14 12 409 32
7 15 12 648 78
7 15 13 648 62
8 3 1 9 88
8 3 2 14 16
8 3 3 15 16
8 3 4 4 16
8 3 5 8 16
8 3 6 17 16
8 3 7 9 16
8 3 8 13 16
8 3 9 7 16
8 3 10 4 16
8 3 11 3 16
8 3 12 13 16
8 3 13 8 16
8 3 14 10 48
8 4 0 2 120
8 4 2 0 64
8 4 3 22 0
8 4 4 22 0
8 4 5 22 0
8 4 6 22 0
8 4 7 22 0
8 4 8 22 0
8 4 9 22 0
8 4 10 22 0
8 4 11 22 0
8 4 12 22 0
8 4 13 22 0
8 4 14 22 32
8 5 2 0 64
8 5 3 267 0
8 5 4 181 0
8 5 5 329 0
8 5 6 56 0
8 5 7 591 0
8 5 8 591 0
8 5 9 227 0
8 5 10 599 0
8 5 11 627 0
8 5 12 188 0
8 5 13 637 0
8 5 14 293 32
8 6 2 0 64
8 6 3 230 0
8 6 4 117 0
8 6 5 632 0
8 6 6 555 0
8 6 7 537 0
8 6 8 537 0
8 6 9 38 0
8 6 10 130 0
8 6 11 256 0
8 6 12 625 0
8 6 13 290 0
8 6 14 422 32
8 7 0 2 120
8 7 2 0 64
8 7 3 87 0
8 7 4 569 0
8 7 5 459 0
8 7 6 175 0
8 7 7 588 0
8 7 8 588 0
8 7 9 100 0
8 7 10 298 0
8 7 11 565 0
8 7 12 192 0
8 7 13 539 0
8 7 14 542 32
8 8 1 393 80
8 8 2 616 0
8 8 3 616 0
8 8 4 105 0
8 8 5 253 0
8 8 6 89 0
8 8 7 610 0
8 8 8 610 0
8 8 9 200 0
8 8 10 294 0
8 8 11 397 0
8 8 12 147 0
8 8 13 368 0
8 8 14 335 0
8 8 15 18 50
8 9 1 647 64
8 9 2 568 0
8 9 3 51 0
8 9 4 473 0
8 9 5 249 0
8 9 6 58 0
8 9 7 635 0
8 9 8 635 0
8 9 9 222 0
8 9 10 339 0
8 9 11 195 0
8 9 12 249 0
8 9 13 255 0
8 9 14 352 0
8 9 15 19 40
8 10 1 614 72
8 10 2 214 0
8 10 3 131 0
8 10 4 508 0
8 10 5 613 0
8 10 6 268 0
8 10 7 416 0
8 10 8 416 0
8 10 9 618 0
8 10 10 89 0
8 10 11 319 0
8 10 12 375 0
8 10 13 138 0
8 10 14 320 32
8 11 2 667 68
8 11 3 147 0
8 11 4 41 0
8 11 5 579 0
8 11 6 142 0
8 11 7 618 0
8 11 8 618 0
8 11 9 534 0
8 11 10 53 0
8 11 11 507 0
8 11 12 47 0
8 11 13 224 0
8 11 14 561 40
8 12 2 662 68
8 12 3 113 0
8 12 4 512 0
8 12 5 64 0
8 12 6 372 0
8 12 7 47 0
8 12 8 47 0
8 12 9 431 0
8 12 10 474 0
8 12 11 508 0
8 12 12 545 0
8 12 13 534 32
8 13 2 667 70
8 13 3 192 0
8 13 4 534 0
8 13 5 365 0
8 13 6 619 0
8 13 7 443 0
8 13 8 443 0
8 13 9 206 0
8 13 10 550 0
8 13 11 195 0
8 13 12 533 0
8 13 13 535 40
8 14 2 9 76
8 14 3 625 8
8 14 4 653 0
8 14 5 122 8
8 14 6 235 8
8 14 7 386 0
8 14 8 386 8
8 14 9 512 8
8 14 10 597 0
8 14 11 128 8
8 14 12 60 40
8 15 4 653 110
8 15 7 653 110
8 15 10 653 110
9 3 1 9 88
9 3 2 9 16
9 3 3 14 16
9 3 4 5 16
9 3 5 13 16
9 3 6 5 16
9 3 7 8 16
9 3 8 7 16
9 3 9 4 16
9 3 10 4 16
9 3 11 15 16
9 3 12 11 16
9 3 13 4 16
9 3 14 13 48
9 4 0 2 120
9 4 2 0 64
9 4 3 22 0
9 4 4 22 0
9 4 5 22 0
9 4 6 22 0
9 4 7 22 0
9 4 8 22 0
9 4 9 22 0
9 4 10 22 0
9 4 11 22 0
9 4 12 22 0
9 4 13 22 0
9 4 14 22 32
9 5 2 0 64
9 5 3 196 0
9 5 4 133 0
9 5 5 572 0
9 5 6 384 0
9 5 7 356 0
9 5 8 356 0
9 5 9 263 0
9 5 10 100 0
9 5 11 43 0
9 5 12 608 0
9 5 13 375 0
9 5 14 628 32
9 6 2 0 64
9 6 3 516 0
9 6 4 108 0
9 6 5 340 0
9 6 6 81 0
9 6 7 146 0
9 6 8 146 0
9 6 9 414 0
9 6 10 75 0
9 6 11 601 0
9 6 12 295 0
9 6 13 85 0
9 6 14 235 32
9 7 0 2 120
9 7 2 0 64
9 7 3 68 0
9 7 4 104 0
9 7 5 144 0
9 7 6 114 0
9 7 7 656 0
9 7 8 656 0
9 7 9 448 0
9 7 10 187 0
9 7 11 236 0
9 7 12 176 0
9 7 13 306 0
9 7 14 58 32
9 8 1 514 80
9 8 2 86 0
9 8 3 87 0
9 8 4 108 0
9 8 5 124 0
9 8 6 618 0
9 8 7 428 0
9 8 8 428 0
9 8 9 243 0
9 8 10 633 0
9 8 11 205 0
9 8 12 243 0
9 8 13 544 0
9 8 14 373 32
9 9 1 159 64
9 9 2 209 0
9 9 3 222 0
9 9 4 332 0
9 9 5 377 0
9 9 6 147 0
9 9 7 625 0
9 9 8 625 0
9 9 9 50 0
9 9 10 266 0
9 9 11 567 0
9 9 12 232 0
9 9 13 102 0
9 9 14 530 0
9 9 15 30 58
9 10 1 652 72
9 10 2 407 0
9 10 3 575 0
9 10 4 245 0
9 10 5 310 0
9 10 6 261 0
9 10 7 124 0
9 10 8 124 0
9 10 9 592 0
9 10 10 273 0
9 10 11 530 0
9 10 12 182 0
9 10 13 417 0
9 10 14 428 32
9 11 2 661 64
9 11 3 381 0
9 11 4 128 0
9 11 5 522 0
9 11 6 566 0
9 11 7 613 0
9 11 8 613 0
9 11 9 411 0
9 11 10 492 0
9 11 11 51 0
9 11 12 577 0
9 11 13 171 0
9 11 14 299 40
9 12 2 1 72
9 12 3 530 0
9 12 4 386 0
9 12 5 298 0
9 12 6 367 0
9 12 7 478 0
9 12 8 478 0
9 12 9 467 0
9 12 10 357 0
9 12 11 100 0
9 12 12 410 0
9 12 13 619 32
9 13 3 447 64
9 13 4 269 0
9 13 5 222 0
9 13 6 189 0
9 13 7 310 0
9 13 8 310 0
9 13 9 449 0
9 13 10 110 0
9 13 11 100 0
9 13 12 53 0
9 13 13 480 40
9 14 2 9 80
9 14 3 72 8
9 14 4 512 8
9 14 5 653 0
9 14 6 102 8
9 14 7 588 8
9 14 8 588 0
9 14 9 261 8
9 14 10 173 8
9 14 11 100 0
9 14 12 190 40
9 15 2 9 108
9 15 5 653 108
9 15 8 653 108
9 15 11 653 108
10 0 3 10 92
10 0 4 12 60
10 0 12 12 92
10 0 13 16 60
10 3 1 9 88
10 3 2 4 16
10 3 3 3 16
10 3 4 12 16
10 3 5 10 16
10 3 6 8 16
10 3 7 4 16
10 3 8 15 16
10 3 9 14 16
10 3 10 5 16
10 3 11 7 16
10 3 12 8 16
10 3 13 14 16
10 3 14 4 48
10 4 0 2 114
10 4 2 0 64
10 4 3 22 0
10 4 4 22 0
10 4 5 22 0
10 4 6 22 0
10 4 7 22 0
10 4 8 22 0
10 4 9 22 0
10 4 10 22 0
10 4 11 22 0
10 4 12 22 0
10 4 13 22 0
10 4 14 22 32
10 5 0 2 102
10 5 2 0 64
10 5 3 253 0
10 5 4 603 0
10 5 5 411 0
10 5 6 593 0
10 5 7 118 0
10 5 8 118 0
10 5 9 227 0
10 5 10 42 0
10 5 11 462 0
10 5 12 204 0
10 5 13 497 0
10 5 14 109 32
10 6 0 2 102
10 6 2 0 64
10 6 3 371 0
10 6 4 594 0
10 6 5 70 0
10 6 6 644 0
10 6 7 48 0
10 6 8 48 0
10 6 9 640 0
10 6 10 172 0
10 6 11 596 0
10 6 12 438 0
10 6 13 113 0
10 6 14 585 32
10 7 0 2 106
10 7 2 0 64
10 7 3 563 0
10 7 4 624 0
10 7 5 62 0
10 7 6 99 0
10 7 7 656 0
10 7 8 656 0
10 7 9 614 0
10 7 10 47 0
10 7 11 212 0
10 7 12 192 0
10 7 13 575 0
10 7 14 339 32
10 8 1 49 80
10 8 2 38 0
10 8 3 233 0
10 8 4 485 0
10 8 5 100 0
10 8 6 385 0
10 8 7 416 0
10 8 8 416 0
10 8 9 128 0
10 8 10 81 0
10 8 11 150 0
10 8 12 530 0
10 8 13 147 0
10 8 14 585 32
10 9 1 191 64
10 9 2 275 0
10 9 3 518 0
10 9 4 174 0
10 9 5 535 0
10 9 6 111 0
10 9 7 618 0
10 9 8 618 0
10 9 9 58 0
10 9 10 51 0
10 9 11 222 0
10 9 12 418 0
10 9 13 466 0
10 9 14 613 32
10 10 1 657 72
10 10 2 360 0
10 10 3 448 0
10 10 4 440 0
10 10 5 314 0
10 10 6 243 0
10 10 7 158 0
10 10 8 158 0
10 10 9 172 0
10 10 10 597 0
10 10 11 478 0
10 10 12 347 0
10 10 13 532 0
10 10 14 289 32
10 11 2 663 66
10 11 3 538 0
10 11 4 483 0
10 11 5 100 0
10 11 6 487 0
10 11 7 110 0
10 11 8 110 0
10 11 9 124 0
10 11 10 206 0
10 11 11 351 0
10 11 12 461 0
10 11 13 422 0
10 11 14 181 40
10 12 2 667 66
10 12 3 559 0
10 12 4 600 0
10 12 5 189 0
10 12 6 421 0
10 12 7 415 0
10 12 8 415 0
10 12 9 434 0
10 12 10 428 0
10 12 11 110 0
10 12 12 536 0
10 12 13 423 32
10 13 2 663 70
10 13 3 251 0
10 13 4 37 0
10 13 5 455 0
10 13 6 37 0
10 13 7 624 0
10 13 8 624 0
10 13 9 341 0
10 13 10 570 0
10 13 11 227 0
10 13 12 325 0
10 13 13 479 40
10 14 2 9 66
10 14 3 164 8
10 14 4 576 8
10 14 5 653 0
10 14 6 653 0
10 14 7 499 8
10 14 8 499 0
10 14 9 406 0
10 14 10 565 8
10 14 11 457 0
10 14 12 576 32
10 15 2 9 104
10 15 5 653 74
10 15 6 653 46
10 15 8 653 74
10 15 9 653 46
10 15 11 653 74
10 15 12 653 46
11 0 2 12 94
11 0 3 7 24
11 0 4 4 16
11 0 5 4 62
11 0 11 9 94
11 0 12 4 24
11 0 13 7 16
11 0 14 8 62
11 1 4 15 102
11 1 13 8 102
11 2 4 9 102
11 2 13 9 102
11 3 1 9 80
11 3 2 4 16
11 3 3 8 16
11 3 4 8 0
11 3 5 15 16
11 3 6 11 16
11 3 7 17 16
11 3 8 17 16
11 3 9 6 16
11 3 10 17 16
11 3 11 8 16
11 3 12 5 16
11 3 13 15 0
11 3 14 4 48
11 4 1 28 68
11 4 2 22 0
11 4 3 22 0
11 4 4 22 0
11 4 5 22 0
11 4 6 22 0
11 4 7 22 0
11 4 8 22 0
11 4 9 22 0
11 4 10 22 0
11 4 11 22 0
11 4 12 22 0
11 4 13 22 0
11 4 14 22 32
11 5 1 425 68
11 5 2 57 0
11 5 3 170 0
11 5 4 394 0
11 5 5 552 0
11 5 6 622 0
11 5 7 573 0
11 5 8 573 0
11 5 9 136 0
11 5 10 40 0
11 5 11 180 0
11 5 12 564 0
11 5 13 46 0
11 5 14 260 32
11 6 1 31 68
11 6 2 191 0
11 6 3 244 0
11 6 4 441 0
11 6 5 285 0
11 6 6 416 0
11 6 7 45 0
11 6 8 45 0
11 6 9 338 0
11 6 10 137 0
11 6 11 131 0
11 6 12 530 0
11 6 13 506 0
11 6 14 576 32
11 7 1 29 68
11 7 2 119 0
11 7 3 504 0
11 7 4 185 0
11 7 5 91 0
11 7 6 607 0
11 7 7 546 0
11 7 8 546 0
11 7 9 47 0
11 7 10 351 0
11 7 11 587 0
11 7 12 110 0
11 7 13 487 0
11 7 14 81 32
11 8 1 25 64
11 8 2 390 0
11 8 3 215 0
11 8 4 95 0
11 8 5 353 0
11 8 6 642 0
11 8 7 656 0
11 8 8 656 0
11 8 9 601 0
11 8 10 618 0
11 8 11 251 0
11 8 12 222 0
11 8 13 585 0
11 8 14 424 32
11 9 1 399 64
11 9 2 106 0
11 9 3 100 0
11 9 4 47 0
11 9 5 455 0
11 9 6 231 0
11 9 7 483 0
11 9 8 483 0
11 9 9 162 0
11 9 10 427 0
11 9 11 565 0
11 9 12 313 0
11 9 13 110 0
11 9 14 173 32
11 10 1 655 72
11 10 2 638 8
11 10 3 71 0
11 10 4 81 0
11 10 5 605 0
11 10 6 400 0
11 10 7 602 0
11 10 8 602 0
11 10 9 109 0
11 10 10 346 0
11 10 11 609 0
11 10 12 595 0
11 10 13 566 0
11 10 14 397 32
11 11 3 71 64
11 11 4 630 0
11 11 5 235 0
11 11 6 523 0
11 11 7 585 0
11 11 8 585 0
11 11 9 577 0
11 11 10 163 0
11 11 11 247 0
11 11 12 147 0
11 11 13 565 0
11 11 14 600 40
11 12 3 477 64
11 12 4 128 0
11 12 5 109 0
11 12 6 128 0
11 12 7 313 0
11 12 8 313 0
11 12 9 124 0
11 12 10 543 0
11 12 11 299 0
11 12 12 389 0
11 12 13 576 32
11 13 3 501 64
11 13 4 355 0
11 13 5 585 0
11 13 6 577 0
11 13 7 242 0
11 13 8 242 0
11 13 9 128 0
11 13 10 328 0
11 13 11 102 0
11 13 12 629 0
11 13 13 218 40
11 14 3 340 72
11 14 4 585 8
11 14 5 519 8
11 14 6 211 8
11 14 7 113 8
11 14 8 113 8
11 14 9 593 8
11 14 10 246 8
11 14 11 586 8
11 14 12 186 40
11 15 2 9 122
12 0 3 11 90
12 0 4 4 58
12 0 12 10 90
12 0 13 8 58
12 3 1 9 80
12 3 2 16 16
12 3 3 11 16
12 3 4 9 16
12 3 5 14 16
12 3 6 11 16
12 3 7 17 16
12 3 8 12 16
12 3 9 17 16
12 3 10 4 16
12 3 11 4 16
12 3 12 10 16
12 3 13 11 16
12 3 14 15 48
12 4 1 26 64
12 4 2 22 0
12 4 3 22 0
12 4 4 22 0
12 4 5 22 0
12 4 6 22 0
12 4 7 22 0
12 4 8 22 0
12 4 9 22 0
12 4 10 22 0
12 4 11 22 0
12 4 12 22 0
12 4 13 22 0
12 4 14 22 32
12 5 1 127 64
12 5 2 597 0
12 5 3 134 0
12 5 4 116 0
12 5 5 38 0
12 5 6 523 0
12 5 7 358 0
12 5 8 358 0
12 5 9 645 0
12 5 10 321 0
12 5 11 171 0
12 5 12 491 0
12 5 13 604 0
12 5 14 624 32
12 6 1 35 64
12 6 2 462 0
12 6 3 198 0
12 6 4 241 0
12 6 5 412 0
12 6 6 78 0
12 6 7 551 0
12 6 8 551 0
12 6 9 132 0
12 6 10 34 0
12 6 11 427 0
12 6 12 325 0
12 6 13 469 0
12 6 14 387 32
12 7 1 452 64
12 7 2 120 0
12 7 3 156 0
12 7 4 308 0
12 7 5 323 0
12 7 6 517 0
12 7 7 113 0
12 7 8 113 0
12 7 9 433 0
12 7 10 544 0
12 7 11 597 0
12 7 12 201 0
12 7 13 463 0
12 7 14 169 32
12 8 1 57 64
12 8 2 143 0
12 8 3 32 0
12 8 4 52 0
12 8 5 566 0
12 8 6 110 0
12 8 7 656 0
12 8 8 656 0
12 8 9 128 0
12 8 10 566 0
12 8 11 276 0
12 8 12 618 0
12 8 13 333 0
12 8 14 192 32
12 9 1 94 64
12 9 2 582 0
12 9 3 110 0
12 9 4 489 0
12 9 5 340 0
12 9 6 325 0
12 9 7 193 0
12 9 8 193 0
12 9 9 110 0
12 9 10 128 0
12 9 11 623 0
12 9 12 557 0
12 9 13 406 0
12 9 14 79 32
12 10 1 654 72
12 10 2 100 8
12 10 3 169 0
12 10 4 72 0
12 10 5 389 0
12 10 6 476 0
12 10 7 413 0
12 10 8 413 0
12 10 9 176 0
12 10 10 89 0
12 10 11 192 0
12 10 12 549 0
12 10 13 53 0
12 10 14 530 32
12 11 3 546 66
12 11 4 601 2
12 11 5 565 2
12 11 6 148 2
12 11 7 409 2
12 11 8 409 2
12 11 9 601 2
12 11 10 534 2
12 11 11 222 2
12 11 12 141 2
12 11 13 596 2
12 11 14 478 42
12 12 3 625 66
12 12 4 128 2
12 12 5 611 2
12 12 6 218 2
12 12 7 128 2
12 12 8 128 2
12 12 9 151 2
12 12 10 351 2
12 12 11 372 2
12 12 12 162 2
12 12 13 260 34
12 13 3 64 66
12 13 4 178 2
12 13 5 613 2
12 13 6 601 2
12 13 7 470 2
12 13 8 470 2
12 13 9 310 2
12 13 10 562 2
12 13 11 102 2
12 13 12 634 2
12 13 13 280 42
12 14 3 544 74
12 14 4 637 10
12 14 5 483 10
12 14 6 530 10
12 14 7 314 10
12 14 8 314 10
12 14 9 310 10
12 14 10 467 10
12 14 11 396 10
12 14 12 358 42
13 3 1 10 80
13 3 2 15 16
13 3 3 15 16
13 3 4 8 16
13 3 5 4 16
13 3 6 4 16
13 3 7 12 16
13 3 8 5 16
13 3 9 4 16
13 3 10 17 16
13 3 11 12 16
13 3 12 5 16
13 3 13 11 16
13 3 14 13 48
13 4 1 6 64
13 4 2 22 0
13 4 3 22 0
13 4 4 22 0
13 4 5 22 0
13 4 6 22 0
13 4 7 22 0
13 4 8 22 0
13 4 9 22 0
13 4 10 22 0
13 4 11 22 0
13 4 12 22 0
13 4 13 22 0
13 4 14 22 32
13 5 1 559 64
13 5 2 542 0
13 5 3 538 0
13 5 4 598 0
13 5 5 124 0
13 5 6 472 0
13 5 7 64 0
13 5 8 64 0
13 5 9 587 0
13 5 10 449 0
13 5 11 217 0
13 5 12 58 0
13 5 13 276 0
13 5 14 300 32
13 6 1 348 64
13 6 2 602 0
13 6 3 614 0
13 6 4 79 0
13 6 5 328 0
13 6 6 163 0
13 6 7 449 0
13 6 8 449 0
13 6 9 266 0
13 6 10 367 0
13 6 11 531 0
13 6 12 540 0
13 6 13 624 0
13 6 14 210 32
13 7 1 145 64
13 7 2 512 0
13 7 3 565 0
13 7 4 367 0
13 7 5 597 0
13 7 6 305 0
13 7 7 600 0
13 7 8 600 0
13 7 9 588 0
13 7 10 596 0
13 7 11 480 0
13 7 12 389 0
13 7 13 356 0
13 7 14 88 32
13 8 1 102 64
13 8 2 184 0
13 8 3 319 0
13 8 4 311 0
13 8 5 601 0
13 8 6 592 0
13 8 7 656 0
13 8 8 656 0
13 8 9 181 0
13 8 10 442 0
13 8 11 311 0
13 8 12 505 0
13 8 13 619 0
13 8 14 161 32
13 9 1 312 64
13 9 2 345 0
13 9 3 222 0
13 9 4 446 0
13 9 5 471 0
13 9 6 109 0
13 9 7 618 0
13 9 8 618 0
13 9 9 403 0
13 9 10 494 0
13 9 11 147 0
13 9 12 531 0
13 9 13 577 0
13 9 14 496 32
13 10 1 630 72
13 10 2 109 8
13 10 3 228 8
13 10 4 103 8
13 10 5 171 8
13 10 6 575 8
13 10 7 567 8
13 10 8 567 8
13 10 9 513 8
13 10 10 391 8
13 10 11 148 8
13 10 12 192 8
13 10 13 310 8
13 10 14 589 40
14 3 1 3 82
14 3 2 13 18
14 3 3 16 18
14 3 4 5 18
14 3 5 9 18
14 3 6 5 18
14 3 7 4 18
14 3 8 4 18
14 3 9 10 18
14 3 10 8 18
14 3 11 5 18
14 3 12 15 18
14 3 13 14 18
14 3 14 8 50
14 4 1 14 66
14 4 2 4 2
14 4 3 5 2
14 4 4 4 2
14 4 5 11 2
14 4 6 16 2
14 4 7 13 2
14 4 8 14 2
14 4 9 8 2
14 4 10 8 2
14 4 11 16 2
14 4 12 12 2
14 4 13 12 2
14 4 14 5 34
14 5 1 212 66
14 5 2 49 2
14 5 3 92 2
14 5 4 549 2
14 5 5 562 2
14 5 6 443 2
14 5 7 192 2
14 5 8 192 2
14 5 9 109 2
14 5 10 258 2
14 5 11 488 2
14 5 12 449 2
14 5 13 360 2
14 5 14 79 34
14 6 1 58 66
14 6 2 395 2
14 6 3 124 2
14 6 4 347 2
14 6 5 205 2
14 6 6 548 2
14 6 7 344 2
14 6 8 344 2
14 6 9 533 2
14 6 10 100 2
14 6 11 523 2
14 6 12 325 2
14 6 13 88 2
14 6 14 357 34
14 7 1 165 66
14 7 2 567 2
14 7 3 314 2
14 7 4 544 2
14 7 5 347 2
14 7 6 344 2
14 7 7 428 2
14 7 8 428 2
14 7 9 110 2
14 7 10 518 2
14 7 11 625 2
14 7 12 79 2
14 7 13 556 2
14 7 14 550 34
14 8 1 58 66
14 8 2 574 2
14 8 3 328 2
14 8 4 541 2
14 8 5 532 2
14 8 6 473 2
14 8 7 575 2
14 8 8 575 2
14 8 9 361 2
14 8 10 194 2
14 8 11 150 2
14 8 12 74 2
14 8 13 589 2
14 8 14 590 34
14 9 1 531 66
14 9 2 566 2
14 9 3 98 2
14 9 4 549 2
14 9 5 543 2
14 9 6 74 2
14 9 7 128 2
14 9 8 128 2
14 9 9 125 2
14 9 10 339 2
14 9 11 66 2
14 9 12 124 2
14 9 13 299 2
14 9 14 173 34
14 10 1 613 74
14 10 2 447 10
14 10 3 63 10
14 10 4 296 10
14 10 5 359 10
14 10 6 519 10
14 10 7 268 10
14 10 8 268 10
14 10 9 538 10
14 10 10 603 10
14 10 11 420 10
14 10 12 427 10
14 10 13 511 10
14 10 14 465 42
