Qubicle Exchange Format
Version 0.2
www.minddesk.com
32 32 32
7
0.352941 0.247059 0.011765
0.423529 0.654902 0.019608
0.541176 0.843137 0.011765
0.831373 0.388235 0.388235
0.894118 0.470588 0.031373
1.000000 0.458824 0.101961
1.000000 1.000000 1.000000
9 0 1 3 94
9 0 2 2 54
9 0 4 2 86
9 0 5 3 62
9 0 12 3 94
9 0 13 2 54
9 0 15 2 86
9 0 16 3 62
9 1 2 2 78
9 1 3 2 20
9 1 4 2 46
9 1 13 2 78
9 1 14 2 20
9 1 15 2 46
9 2 3 2 110
9 2 14 2 110
10 0 3 2 116
10 0 14 2 116
10 1 3 2 106
10 1 14 2 106
11 0 3 3 122
11 0 14 3 122
22 0 2 3 94
22 0 3 2 54
22 0 5 2 86
22 0 6 3 62
22 0 11 3 94
22 0 12 2 54
22 0 14 2 86
22 0 15 3 62
22 1 3 2 78
22 1 4 2 20
22 1 5 2 46
22 1 12 2 78
22 1 13 2 20
22 1 14 2 46
22 2 4 2 110
22 2 13 2 110
23 0 4 2 116
23 0 13 2 116
23 1 4 2 106
23 1 13 2 106
24 0 4 3 122
24 0 13 3 122
1 0 8 2 126
2 0 9 2 126
3 0 8 2 124
4 0 8 2 114
4 1 8 2 108
5 1 8 2 82
5 1 9 2 62
5 2 8 2 108
6 2 8 2 82
6 2 9 2 62
6 3 8 2 108
7 3 8 2 82
7 3 9 2 54
7 4 8 2 78
7 4 9 2 46
8 2 5 2 92
8 2 6 2 52
8 2 11 2 84
8 2 12 2 60
8 3 6 2 76
8 3 7 2 28
8 3 8 2 20
8 3 9 2 20
8 3 10 2 28
8 3 11 2 44
8 4 8 2 76
8 4 9 2 44
9 2 4 2 92
9 2 5 2 16
9 2 6 2 48
9 2 11 2 80
9 2 12 2 16
9 2 13 2 60
9 3 5 2 76
9 3 6 2 8
9 3 7 2 16
9 3 8 2 16
9 3 9 2 16
9 3 10 2 16
9 3 11 2 8
9 3 12 2 44
9 4 7 2 76
9 4 8 2 0
9 4 9 2 0
9 4 10 2 44
9 5 8 2 76
9 5 9 2 44
10 2 4 2 88
10 2 5 2 16
10 2 6 2 16
10 2 7 2 54
10 2 10 2 86
10 2 11 2 16
10 2 12 2 16
10 2 13 2 56
10 3 5 2 72
10 3 6 2 0
10 3 7 2 0
10 3 8 2 16
10 3 9 2 16
10 3 10 2 0
10 3 11 2 0
10 3 12 2 40
10 4 6 2 76
10 4 7 2 8
10 4 8 2 0
10 4 9 2 0
10 4 10 2 8
10 4 11 2 44
10 5 8 2 72
10 5 9 2 40
11 2 4 2 90
11 2 5 2 18
11 2 6 2 50
11 2 11 2 82
11 2 12 2 18
11 2 13 2 58
11 3 5 2 74
11 3 6 2 0
11 3 7 2 16
11 3 8 2 16
11 3 9 2 16
11 3 10 2 16
11 3 11 2 0
11 3 12 2 42
11 4 6 2 74
11 4 7 2 0
11 4 8 2 0
11 4 9 2 0
11 4 10 2 0
11 4 11 2 42
11 5 7 2 76
11 5 8 2 8
11 5 9 2 8
11 5 10 2 44
12 3 6 2 88
12 3 7 2 16
12 3 8 2 16
12 3 9 2 16
12 3 10 2 16
12 3 11 2 56
12 4 7 2 64
12 4 8 2 0
12 4 9 2 0
12 4 10 2 32
12 5 7 5 72
12 5 8 2 8
12 5 9 2 8
12 5 10 5 40
13 3 6 2 88
13 3 7 2 16
13 3 8 2 16
13 3 9 2 16
13 3 10 2 16
13 3 11 2 56
13 4 7 2 64
13 4 8 2 0
13 4 9 2 0
13 4 10 2 32
13 5 7 2 72
13 5 8 5 8
13 5 9 5 8
13 5 10 2 40
14 3 6 2 88
14 3 7 2 16
14 3 8 2 16
14 3 9 2 16
14 3 10 2 16
14 3 11 2 56
14 4 7 2 64
14 4 8 2 0
14 4 9 2 0
14 4 10 2 32
14 5 7 2 72
14 5 8 2 8
14 5 9 2 8
14 5 10 2 40
15 3 6 2 88
15 3 7 2 16
15 3 8 2 16
15 3 9 2 16
15 3 10 2 16
15 3 11 2 56
15 4 7 2 64
15 4 8 2 0
15 4 9 2 0
15 4 10 2 32
15 5 7 5 72
15 5 8 2 8
15 5 9 2 8
15 5 10 5 40
16 3 6 2 88
16 3 7 2 16
16 3 8 2 16
16 3 9 2 16
16 3 10 2 16
16 3 11 2 56
16 4 7 2 64
16 4 8 2 0
16 4 9 2 0
16 4 10 2 32
16 5 7 2 72
16 5 8 5 8
16 5 9 5 8
16 5 10 2 40
17 3 6 2 88
17 3 7 2 16
17 3 8 2 16
17 3 9 2 16
17 3 10 2 16
17 3 11 2 56
17 4 7 2 64
17 4 8 2 0
17 4 9 2 0
17 4 10 2 32
17 5 7 2 72
17 5 8 2 8
17 5 9 2 8
17 5 10 2 40
18 3 6 2 88
18 3 7 2 16
18 3 8 2 16
18 3 9 2 16
18 3 10 2 16
18 3 11 2 56
18 4 7 2 64
18 4 8 2 0
18 4 9 2 0
18 4 10 2 32
18 5 7 5 72
18 5 8 2 8
18 5 9 2 8
18 5 10 5 40
19 3 6 2 88
19 3 7 2 16
19 3 8 2 16
19 3 9 2 16
19 3 10 2 16
19 3 11 2 56
19 4 7 2 64
19 4 8 2 0
19 4 9 2 0
19 4 10 2 32
19 5 7 2 72
19 5 8 5 8
19 5 9 5 8
19 5 10 2 40
20 3 6 2 88
20 3 7 2 16
20 3 8 2 16
20 3 9 2 16
20 3 10 2 16
20 3 11 2 56
20 4 7 2 64
20 4 8 2 0
20 4 9 2 0
20 4 10 2 32
20 5 7 2 72
20 5 8 2 8
20 5 9 2 8
20 5 10 2 40
21 2 5 2 92
21 2 6 2 52
21 2 11 2 84
21 2 12 2 60
21 3 6 2 72
21 3 7 2 16
21 3 8 2 16
21 3 9 2 16
21 3 10 2 16
21 3 11 2 42
21 4 7 2 64
21 4 8 2 0
21 4 9 2 0
21 4 10 2 32
21 5 7 2 74
21 5 8 2 8
21 5 9 2 8
21 5 10 2 42
22 2 5 2 88
22 2 6 2 48
22 2 11 2 88
22 2 12 2 56
22 3 6 2 72
22 3 7 2 16
22 3 8 2 16
22 3 9 2 16
22 3 10 2 48
22 3 11 2 40
22 4 7 2 72
22 4 8 2 0
22 4 9 2 0
22 4 10 2 40
22 5 8 2 72
22 5 9 2 40
23 2 5 2 90
23 2 6 2 126
23 2 11 2 90
23 2 12 2 58
23 3 6 2 126
23 3 7 2 18
23 3 8 2 126
23 3 9 2 18
23 3 10 2 50
23 3 11 2 46
23 4 7 2 126
23 4 8 2 126
23 4 9 2 126
23 4 10 2 126
23 5 8 2 72
23 5 9 2 40
24 4 8 2 126
24 4 9 2 50
24 5 8 2 72
24 5 9 2 40
25 4 8 1 126
25 4 9 1 126
25 5 8 2 90
25 5 9 2 126
26 4 8 2 84
26 4 9 2 52
26 5 8 2 68
26 5 9 2 44
26 6 8 4 126
26 6 9 4 126
27 4 7 2 84
27 4 8 2 16
27 4 9 2 16
27 4 10 2 52
27 5 7 2 68
27 5 8 6 0
27 5 9 6 0
27 5 10 2 36
27 6 7 2 76
27 6 8 2 8
27 6 9 2 12
27 6 10 2 44
28 4 7 2 80
28 4 8 2 16
28 4 9 2 16
28 4 10 2 48
28 5 7 2 64
28 5 8 2 0
28 5 9 2 0
28 5 10 2 32
28 6 7 0 74
28 6 8 2 8
28 6 9 2 8
28 6 10 0 42
29 4 7 2 82
29 4 8 2 16
29 4 9 2 16
29 4 10 2 50
29 5 7 2 74
29 5 8 2 0
29 5 9 2 0
29 5 10 2 42
29 6 8 2 74
29 6 9 2 42
30 4 7 2 126
30 4 8 2 80
30 4 9 2 48
30 4 10 2 126
30 5 8 1 126
30 5 9 1 126
31 4 8 2 90
31 4 9 2 58
