Qubicle Exchange Format
Version 0.2
www.minddesk.com
18 8 32
66
0.337255 0.235294 0.007843
0.392157 0.607843 0.015686
0.396078 0.298039 0.078431
0.403922 0.627451 0.015686
0.454902 0.670588 0.074510
0.458824 0.674510 0.086275
0.498039 0.776471 0.007843
0.498039 0.780392 0.007843
0.501961 0.780392 0.007843
0.501961 0.784314 0.007843
0.505882 0.788235 0.007843
0.505882 0.792157 0.007843
0.509804 0.796078 0.007843
0.509804 0.800000 0.007843
0.513726 0.800000 0.007843
0.517647 0.803922 0.007843
0.517647 0.807843 0.007843
0.521569 0.811765 0.007843
0.521569 0.815686 0.007843
0.525490 0.819608 0.007843
0.529412 0.823529 0.007843
0.529412 0.827451 0.007843
0.529412 0.831373 0.007843
0.533333 0.831373 0.007843
0.533333 0.835294 0.007843
0.537255 0.839216 0.007843
0.537255 0.839216 0.011765
0.541176 0.839216 0.015686
0.541176 0.839216 0.019608
0.545098 0.839216 0.023529
0.545098 0.839216 0.027451
0.549020 0.843137 0.031373
0.549020 0.843137 0.035294
0.552941 0.843137 0.039216
0.552941 0.843137 0.043137
0.556863 0.843137 0.047059
0.556863 0.843137 0.050980
0.556863 0.847059 0.054902
0.560784 0.847059 0.058824
0.560784 0.847059 0.062745
0.564706 0.847059 0.066667
0.564706 0.847059 0.070588
0.568627 0.847059 0.074510
0.568627 0.847059 0.078431
0.572549 0.850980 0.082353
0.772549 0.360784 0.360784
0.780392 0.364706 0.364706
0.792157 0.368627 0.368627
0.815686 0.380392 0.380392
0.819608 0.380392 0.380392
0.823529 0.431373 0.027451
0.831373 0.403922 0.403922
0.835294 0.411765 0.411765
0.835294 0.419608 0.419608
0.835294 0.423529 0.423529
0.862745 0.454902 0.027451
0.941176 0.431373 0.094118
0.952941 0.435294 0.094118
0.960784 0.439216 0.094118
0.968627 0.443137 0.098039
0.988235 0.450980 0.098039
0.992157 0.992157 0.992157
0.996078 0.458824 0.101961
0.996078 0.458824 0.105882
0.996078 0.466667 0.117647
0.996078 0.996078 0.996078
1 0 22 49 124
2 0 9 49 124
2 0 22 23 114
2 1 22 21 108
3 0 9 27 114
3 0 20 46 94
3 0 21 42 54
3 1 9 25 108
3 1 21 25 78
3 1 22 12 48
3 2 22 9 108
4 0 7 45 94
4 0 8 26 54
4 0 22 38 116
4 1 8 44 78
4 1 9 41 48
4 1 22 8 98
4 2 9 13 108
4 2 20 6 92
4 2 21 28 28
4 2 22 23 40
5 0 9 35 116
5 0 22 54 122
5 1 9 10 98
5 2 8 23 92
5 2 9 29 8
5 2 10 14 60
5 2 20 24 80
5 2 21 27 16
5 2 22 23 16
5 2 23 38 60
5 3 20 37 76
5 3 21 39 12
5 3 22 6 44
6 0 9 48 122
6 2 8 33 82
6 2 9 35 18
6 2 10 13 50
6 2 20 43 82
6 2 21 35 16
6 2 22 23 18
6 2 23 30 50
6 3 8 16 76
6 3 9 16 12
6 3 10 16 12
6 3 11 13 28
6 3 12 41 28
6 3 13 39 28
6 3 14 8 28
6 3 15 32 28
6 3 16 8 28
6 3 17 20 28
6 3 18 24 28
6 3 19 38 28
6 3 20 16 0
6 3 21 25 0
6 3 22 36 8
6 3 23 27 44
6 4 20 15 76
6 4 21 26 44
7 2 21 11 114
7 3 8 16 80
7 3 9 33 16
7 3 10 24 16
7 3 11 43 16
7 3 12 25 16
7 3 13 20 16
7 3 14 16 16
7 3 15 23 16
7 3 16 30 16
7 3 17 33 16
7 3 18 41 16
7 3 19 36 16
7 3 20 20 16
7 3 21 44 0
7 3 22 41 16
7 3 23 12 56
7 4 1 19 92
7 4 2 19 20
7 4 3 11 20
7 4 4 44 52
7 4 8 19 76
7 4 9 24 12
7 4 10 35 4
7 4 11 42 4
7 4 12 12 4
7 4 13 27 4
7 4 14 29 4
7 4 15 44 4
7 4 16 43 4
7 4 17 43 4
7 4 18 6 4
7 4 19 15 4
7 4 20 33 0
7 4 21 7 8
7 4 22 21 44
7 5 2 12 76
7 5 3 30 4
7 5 4 39 36
7 5 10 13 76
7 5 11 16 12
7 5 12 15 12
7 5 13 63 12
7 5 14 28 12
7 5 15 21 12
7 5 16 56 12
7 5 17 41 12
7 5 18 34 12
7 5 19 64 12
7 5 20 27 44
7 6 3 2 76
7 6 4 24 44
8 0 29 19 126
8 1 26 27 124
8 2 25 17 124
8 3 8 26 80
8 3 9 38 16
8 3 10 23 16
8 3 11 34 16
8 3 12 33 16
8 3 13 26 16
8 3 14 38 16
8 3 15 11 16
8 3 16 7 16
8 3 17 25 16
8 3 18 25 16
8 3 19 33 16
8 3 20 11 16
8 3 21 41 16
8 3 22 19 16
8 3 23 16 16
8 3 24 31 52
8 4 0 41 92
8 4 1 30 16
8 4 2 7 16
8 4 3 19 16
8 4 4 36 16
8 4 5 30 20
8 4 6 3 20
8 4 7 44 20
8 4 8 25 0
8 4 9 34 0
8 4 10 15 0
8 4 11 27 0
8 4 12 23 0
8 4 13 25 0
8 4 14 19 0
8 4 15 24 0
8 4 16 35 0
8 4 17 34 0
8 4 18 44 0
8 4 19 10 0
8 4 20 12 0
8 4 21 21 0
8 4 22 25 0
8 4 23 34 12
8 4 24 17 44
8 5 1 4 76
8 5 2 40 0
8 5 3 23 0
8 5 4 65 0
8 5 5 39 4
8 5 6 23 12
8 5 7 32 12
8 5 8 24 12
8 5 9 28 12
8 5 10 26 8
8 5 11 44 8
8 5 12 58 8
8 5 13 36 8
8 5 14 37 8
8 5 15 60 8
8 5 16 37 8
8 5 17 15 8
8 5 18 63 8
8 5 19 9 8
8 5 20 31 8
8 5 21 36 12
8 5 22 39 44
8 6 2 33 76
8 6 3 32 8
8 6 4 6 8
8 6 5 50 44
9 0 27 42 86
9 0 28 6 62
9 0 30 44 126
9 1 26 28 82
9 1 27 29 46
9 2 25 25 82
9 2 26 44 46
9 3 8 22 80
9 3 9 18 16
9 3 10 10 16
9 3 11 23 16
9 3 12 23 16
9 3 13 12 16
9 3 14 21 16
9 3 15 37 16
9 3 16 42 16
9 3 17 43 16
9 3 18 37 16
9 3 19 17 16
9 3 20 36 16
9 3 21 19 16
9 3 22 16 16
9 3 23 11 16
9 3 24 9 18
9 3 25 31 46
9 4 0 32 90
9 4 1 26 16
9 4 2 25 16
9 4 3 24 16
9 4 4 25 16
9 4 5 31 18
9 4 6 5 18
9 4 7 6 18
9 4 8 11 0
9 4 9 17 0
9 4 10 15 0
9 4 11 23 0
9 4 12 35 0
9 4 13 13 0
9 4 14 20 0
9 4 15 11 0
9 4 16 26 0
9 4 17 24 0
9 4 18 24 0
9 4 19 10 0
9 4 20 11 0
9 4 21 23 0
9 4 22 10 0
9 4 23 32 10
9 4 24 35 42
9 5 1 1 74
9 5 2 37 0
9 5 3 19 0
9 5 4 61 0
9 5 5 17 2
9 5 6 20 10
9 5 7 40 10
9 5 8 24 10
9 5 9 24 10
9 5 10 6 8
9 5 11 15 8
9 5 12 57 8
9 5 13 34 8
9 5 14 29 8
9 5 15 59 8
9 5 16 34 8
9 5 17 11 8
9 5 18 64 8
9 5 19 41 8
9 5 20 11 8
9 5 21 25 10
9 5 22 10 42
9 6 2 11 74
9 6 3 25 8
9 6 4 12 8
9 6 5 55 42
10 2 21 26 116
10 3 8 12 80
10 3 9 37 16
10 3 10 40 16
10 3 11 26 16
10 3 12 7 16
10 3 13 15 16
10 3 14 27 16
10 3 15 19 16
10 3 16 10 16
10 3 17 13 16
10 3 18 32 16
10 3 19 9 16
10 3 20 24 16
10 3 21 25 0
10 3 22 28 16
10 3 23 6 56
10 4 1 25 90
10 4 2 18 18
10 4 3 16 18
10 4 4 27 50
10 4 8 10 74
10 4 9 8 10
10 4 10 19 2
10 4 11 11 2
10 4 12 41 2
10 4 13 41 2
10 4 14 10 2
10 4 15 9 2
10 4 16 30 2
10 4 17 26 2
10 4 18 18 2
10 4 19 33 2
10 4 20 27 0
10 4 21 28 8
10 4 22 13 42
10 5 2 26 74
10 5 3 25 2
10 5 4 25 34
10 5 10 9 74
10 5 11 35 10
10 5 12 15 10
10 5 13 62 10
10 5 14 41 10
10 5 15 24 10
10 5 16 60 10
10 5 17 15 10
10 5 18 29 10
10 5 19 58 10
10 5 20 42 42
10 6 3 0 74
10 6 4 13 42
11 0 9 47 124
11 2 8 14 84
11 2 9 16 20
11 2 10 37 52
11 2 20 25 84
11 2 21 18 16
11 2 22 39 20
11 2 23 30 52
11 3 8 11 74
11 3 9 34 10
11 3 10 40 10
11 3 11 6 26
11 3 12 37 26
11 3 13 40 26
11 3 14 33 26
11 3 15 43 26
11 3 16 16 26
11 3 17 31 26
11 3 18 19 26
11 3 19 19 26
11 3 20 41 0
11 3 21 11 0
11 3 22 25 8
11 3 23 9 42
11 4 20 19 74
11 4 21 25 42
12 0 9 7 114
12 0 22 52 124
12 1 9 28 100
12 2 8 6 90
12 2 9 9 8
12 2 10 35 58
12 2 20 23 80
12 2 21 37 16
12 2 22 23 16
12 2 23 42 58
12 3 20 27 74
12 3 21 20 10
12 3 22 8 42
13 0 7 53 94
13 0 8 25 54
13 0 22 17 114
13 1 8 21 78
13 1 9 19 48
13 1 22 29 100
13 2 9 19 106
13 2 20 43 90
13 2 21 6 26
13 2 22 25 40
14 0 9 31 116
14 0 20 51 94
14 0 21 34 54
14 1 9 26 106
14 1 21 26 78
14 1 22 15 48
14 2 22 13 106
15 0 9 47 122
15 0 22 33 116
15 1 22 33 106
16 0 22 46 122
