Qubicle Exchange Format
Version 0.2
www.minddesk.com
32 32 32
66
0.337255 0.235294 0.007843
0.392157 0.607843 0.015686
0.396078 0.298039 0.078431
0.403922 0.627451 0.015686
0.454902 0.670588 0.074510
0.458824 0.674510 0.086275
0.498039 0.776471 0.007843
0.498039 0.780392 0.007843
0.501961 0.780392 0.007843
0.501961 0.784314 0.007843
0.505882 0.788235 0.007843
0.505882 0.792157 0.007843
0.509804 0.796078 0.007843
0.509804 0.800000 0.007843
0.513726 0.800000 0.007843
0.517647 0.803922 0.007843
0.517647 0.807843 0.007843
0.521569 0.811765 0.007843
0.521569 0.815686 0.007843
0.525490 0.819608 0.007843
0.529412 0.823529 0.007843
0.529412 0.827451 0.007843
0.529412 0.831373 0.007843
0.533333 0.831373 0.007843
0.533333 0.835294 0.007843
0.537255 0.839216 0.007843
0.537255 0.839216 0.011765
0.541176 0.839216 0.015686
0.541176 0.839216 0.019608
0.545098 0.839216 0.023529
0.545098 0.839216 0.027451
0.549020 0.843137 0.031373
0.549020 0.843137 0.035294
0.552941 0.843137 0.039216
0.552941 0.843137 0.043137
0.556863 0.843137 0.047059
0.556863 0.843137 0.050980
0.556863 0.847059 0.054902
0.560784 0.847059 0.058824
0.560784 0.847059 0.062745
0.564706 0.847059 0.066667
0.564706 0.847059 0.070588
0.568627 0.847059 0.074510
0.568627 0.847059 0.078431
0.572549 0.850980 0.082353
0.772549 0.360784 0.360784
0.780392 0.364706 0.364706
0.792157 0.368627 0.368627
0.815686 0.380392 0.380392
0.819608 0.380392 0.380392
0.823529 0.431373 0.027451
0.831373 0.403922 0.403922
0.835294 0.411765 0.411765
0.835294 0.419608 0.419608
0.835294 0.423529 0.423529
0.862745 0.454902 0.027451
0.941176 0.431373 0.094118
0.952941 0.435294 0.094118
0.960784 0.439216 0.094118
0.968627 0.443137 0.098039
0.988235 0.450980 0.098039
0.992157 0.992157 0.992157
0.996078 0.458824 0.101961
0.996078 0.458824 0.105882
0.996078 0.466667 0.117647
0.996078 0.996078 0.996078
9 0 1 46 94
9 0 2 33 54
9 0 4 17 86
9 0 5 52 62
9 0 12 54 94
9 0 13 38 54
9 0 15 23 86
9 0 16 49 62
9 1 2 33 78
9 1 3 15 20
9 1 4 29 46
9 1 13 8 78
9 1 14 12 20
9 1 15 21 46
9 2 3 13 110
9 2 14 9 110
10 0 3 34 116
10 0 14 42 116
10 1 3 26 106
10 1 14 25 106
11 0 3 51 122
11 0 14 46 122
22 0 2 47 94
22 0 3 31 54
22 0 5 7 86
22 0 6 47 62
22 0 11 48 94
22 0 12 35 54
22 0 14 27 86
22 0 15 49 62
22 1 3 26 78
22 1 4 19 20
22 1 5 28 46
22 1 12 10 78
22 1 13 41 20
22 1 14 25 46
22 2 4 19 110
22 2 13 13 110
23 0 4 25 116
23 0 13 26 116
23 1 4 21 106
23 1 13 44 106
24 0 4 53 122
24 0 13 45 122
1 0 8 44 126
2 0 9 19 126
3 0 8 6 124
4 0 8 42 114
4 1 8 29 108
5 1 8 28 82
5 1 9 27 62
5 2 8 44 108
6 2 8 25 82
6 2 9 17 62
6 3 8 31 108
7 3 8 9 82
7 3 9 31 54
7 4 8 35 78
7 4 9 17 46
8 2 5 42 92
8 2 6 30 52
8 2 11 30 84
8 2 12 38 60
8 3 6 9 76
8 3 7 6 28
8 3 8 11 20
8 3 9 16 20
8 3 10 12 28
8 3 11 27 44
8 4 8 32 76
8 4 9 34 44
9 2 4 25 92
9 2 5 23 16
9 2 6 39 48
9 2 11 23 80
9 2 12 23 16
9 2 13 23 60
9 3 5 8 76
9 3 6 25 8
9 3 7 28 16
9 3 8 16 16
9 3 9 19 16
9 3 10 41 16
9 3 11 36 8
9 3 12 6 44
9 4 7 13 76
9 4 8 10 0
9 4 9 25 0
9 4 10 21 44
9 5 8 10 76
9 5 9 39 44
10 2 4 6 88
10 2 5 37 16
10 2 6 18 16
10 2 7 26 54
10 2 10 11 86
10 2 11 35 16
10 2 12 27 16
10 2 13 28 56
10 3 5 20 72
10 3 6 11 0
10 3 7 25 0
10 3 8 19 16
10 3 9 41 16
10 3 10 44 0
10 3 11 25 0
10 3 12 39 40
10 4 6 25 76
10 4 7 28 8
10 4 8 23 0
10 4 9 21 0
10 4 10 7 8
10 4 11 26 44
10 5 8 25 72
10 5 9 36 40
11 2 4 43 90
11 2 5 23 18
11 2 6 25 50
11 2 11 43 82
11 2 12 24 18
11 2 13 6 58
11 3 5 27 74
11 3 6 41 0
11 3 7 24 16
11 3 8 36 16
11 3 9 11 16
11 3 10 20 16
11 3 11 16 0
11 3 12 37 42
11 4 6 19 74
11 4 7 27 0
11 4 8 11 0
11 4 9 12 0
11 4 10 33 0
11 4 11 15 42
11 5 7 42 76
11 5 8 11 8
11 5 9 31 8
11 5 10 27 44
12 3 6 19 88
12 3 7 9 16
12 3 8 17 16
12 3 9 33 16
12 3 10 36 16
12 3 11 38 56
12 4 7 33 64
12 4 8 10 0
12 4 9 10 0
12 4 10 15 32
12 5 7 58 72
12 5 8 41 8
12 5 9 9 8
12 5 10 64 40
13 3 6 19 88
13 3 7 32 16
13 3 8 37 16
13 3 9 25 16
13 3 10 41 16
13 3 11 24 56
13 4 7 18 64
13 4 8 24 0
13 4 9 44 0
13 4 10 6 32
13 5 7 29 72
13 5 8 64 8
13 5 9 63 8
13 5 10 34 40
14 3 6 31 88
14 3 7 13 16
14 3 8 43 16
14 3 9 25 16
14 3 10 33 16
14 3 11 20 56
14 4 7 26 64
14 4 8 24 0
14 4 9 34 0
14 4 10 43 32
14 5 7 15 72
14 5 8 11 8
14 5 9 15 8
14 5 10 41 40
15 3 6 16 88
15 3 7 10 16
15 3 8 42 16
15 3 9 7 16
15 3 10 30 16
15 3 11 8 56
15 4 7 30 64
15 4 8 26 0
15 4 9 35 0
15 4 10 43 32
15 5 7 60 72
15 5 8 34 8
15 5 9 37 8
15 5 10 56 40
16 3 6 43 88
16 3 7 19 16
16 3 8 37 16
16 3 9 11 16
16 3 10 23 16
16 3 11 32 56
16 4 7 9 64
16 4 8 11 0
16 4 9 24 0
16 4 10 44 32
16 5 7 24 72
16 5 8 59 8
16 5 9 60 8
16 5 10 21 40
17 3 6 33 88
17 3 7 27 16
17 3 8 21 16
17 3 9 38 16
17 3 10 16 16
17 3 11 8 56
17 4 7 10 64
17 4 8 20 0
17 4 9 19 0
17 4 10 29 32
17 5 7 41 72
17 5 8 29 8
17 5 9 37 8
17 5 10 28 40
18 3 6 40 88
18 3 7 15 16
18 3 8 12 16
18 3 9 26 16
18 3 10 20 16
18 3 11 39 56
18 4 7 41 64
18 4 8 13 0
18 4 9 25 0
18 4 10 27 32
18 5 7 62 72
18 5 8 34 8
18 5 9 36 8
18 5 10 63 40
19 3 6 37 88
19 3 7 7 16
19 3 8 23 16
19 3 9 33 16
19 3 10 25 16
19 3 11 41 56
19 4 7 41 64
19 4 8 35 0
19 4 9 23 0
19 4 10 12 32
19 5 7 15 72
19 5 8 57 8
19 5 9 58 8
19 5 10 15 40
20 3 6 6 88
20 3 7 26 16
20 3 8 23 16
20 3 9 34 16
20 3 10 43 16
20 3 11 13 56
20 4 7 11 64
20 4 8 23 0
20 4 9 27 0
20 4 10 42 32
20 5 7 35 72
20 5 8 15 8
20 5 9 44 8
20 5 10 16 40
21 2 5 35 92
21 2 6 37 52
21 2 11 13 84
21 2 12 14 60
21 3 6 40 72
21 3 7 40 16
21 3 8 10 16
21 3 9 23 16
21 3 10 24 16
21 3 11 16 40
21 4 7 19 64
21 4 8 15 0
21 4 9 15 0
21 4 10 35 32
21 5 7 9 74
21 5 8 6 8
21 5 9 26 8
21 5 10 13 42
22 2 5 9 88
22 2 6 16 48
22 2 11 35 80
22 2 12 29 56
22 3 6 34 72
22 3 7 37 16
22 3 8 18 16
22 3 9 38 16
22 3 10 33 16
22 3 11 16 40
22 4 7 8 72
22 4 8 17 0
22 4 9 34 0
22 4 10 24 40
22 5 8 24 72
22 5 9 28 40
23 2 5 6 90
23 2 6 14 50
23 2 11 33 82
23 2 12 23 58
23 3 6 11 74
23 3 7 12 18
23 3 8 22 18
23 3 9 26 18
23 3 10 16 18
23 3 11 16 42
23 4 7 10 74
23 4 8 11 0
23 4 9 25 0
23 4 10 19 42
23 5 8 24 72
23 5 9 24 40
24 4 8 6 80
24 4 9 44 48
24 5 8 40 72
24 5 9 32 40
25 4 8 5 82
25 4 9 3 50
25 5 8 20 74
25 5 9 23 42
26 4 8 31 84
26 4 9 30 52
26 5 8 17 68
26 5 9 39 36
26 6 8 55 76
26 6 9 50 44
27 4 7 27 84
27 4 8 25 16
27 4 9 36 16
27 4 10 44 52
27 5 7 25 68
27 5 8 61 0
27 5 9 65 0
27 5 10 39 36
27 6 7 13 76
27 6 8 12 8
27 6 9 6 8
27 6 10 24 44
28 4 7 16 80
28 4 8 24 16
28 4 9 19 16
28 4 10 11 48
28 5 7 25 64
28 5 8 19 0
28 5 9 23 0
28 5 10 30 32
28 6 7 0 74
28 6 8 25 8
28 6 9 32 8
28 6 10 2 42
29 4 7 18 80
29 4 8 25 16
29 4 9 7 16
29 4 10 19 48
29 5 7 26 74
29 5 8 37 0
29 5 9 40 0
29 5 10 12 42
29 6 8 11 74
29 6 9 33 42
30 4 7 25 90
30 4 8 26 16
30 4 9 30 16
30 4 10 19 58
30 5 8 1 74
30 5 9 4 42
31 4 8 32 90
31 4 9 41 58
