Qubicle Exchange Format
Version 0.2
www.minddesk.com
16 16 16
21
0.066667 0.050980 0.019608
0.282353 0.101961 0.203922
0.654902 0.000000 0.364706
0.941176 0.243137 0.631373
0.960784 0.686275 0.839216
0.964706 0.588235 0.796078
0.964706 0.690196 0.843137
0.968627 0.694118 0.847059
0.972549 0.694118 0.847059
0.976471 0.698039 0.850980
0.980392 0.505882 0.772549
0.980392 0.701961 0.854902
0.984314 0.603922 0.815686
0.984314 0.705882 0.858824
0.988235 0.705882 0.862745
0.992157 0.709804 0.866667
0.996078 0.713726 0.870588
0.996078 0.717647 0.870588
0.996078 0.721569 0.874510
1.000000 0.717647 0.874510
1.000000 1.000000 1.000000
0 2 1 17 84
0 2 2 8 20
0 2 3 8 20
0 2 4 7 20
0 2 5 8 20
0 2 6 16 20
0 2 7 16 20
0 2 8 7 20
0 2 9 16 20
0 2 10 18 20
0 2 11 15 20
0 2 12 14 20
0 2 13 11 20
0 2 14 6 52
0 3 1 4 68
0 3 2 17 4
0 3 3 6 4
0 3 4 16 4
0 3 5 8 4
0 3 6 18 4
0 3 7 18 4
0 3 8 16 4
0 3 9 17 4
0 3 10 4 4
0 3 11 17 4
0 3 12 11 4
0 3 13 15 4
0 3 14 11 36
0 4 1 11 68
0 4 2 16 4
0 4 3 18 4
0 4 4 14 4
0 4 5 7 4
0 4 6 7 4
0 4 7 7 4
0 4 8 16 4
0 4 9 16 4
0 4 10 16 4
0 4 11 16 4
0 4 12 14 4
0 4 13 16 4
0 4 14 8 36
0 5 1 17 68
0 5 2 16 4
0 5 3 11 4
0 5 4 13 4
0 5 5 17 4
0 5 6 16 4
0 5 7 16 4
0 5 8 18 4
0 5 9 16 4
0 5 10 19 4
0 5 11 18 4
0 5 12 17 4
0 5 13 8 4
0 5 14 18 36
0 6 1 19 68
0 6 2 18 4
0 6 3 18 4
0 6 4 4 4
0 6 5 7 4
0 6 6 14 4
0 6 7 14 4
0 6 8 4 4
0 6 9 16 4
0 6 10 9 4
0 6 11 13 4
0 6 12 17 4
0 6 13 14 4
0 6 14 17 36
0 7 1 15 68
0 7 2 7 4
0 7 3 18 4
0 7 4 15 4
0 7 5 16 4
0 7 6 8 4
0 7 7 8 4
0 7 8 16 4
0 7 9 18 4
0 7 10 17 4
0 7 11 17 4
0 7 12 8 4
0 7 13 18 4
0 7 14 17 36
0 8 1 7 68
0 8 2 15 4
0 8 3 14 4
0 8 4 6 4
0 8 5 15 4
0 8 6 9 4
0 8 7 9 4
0 8 8 18 4
0 8 9 17 4
0 8 10 6 4
0 8 11 6 4
0 8 12 16 4
0 8 13 16 4
0 8 14 17 36
0 9 1 18 68
0 9 2 8 4
0 9 3 16 4
0 9 4 17 4
0 9 5 18 4
0 9 6 13 4
0 9 7 13 4
0 9 8 17 4
0 9 9 17 4
0 9 10 17 4
0 9 11 13 4
0 9 12 17 4
0 9 13 8 4
0 9 14 9 36
0 10 1 11 68
0 10 2 13 4
0 10 3 18 4
0 10 4 16 4
0 10 5 16 4
0 10 6 6 4
0 10 7 6 4
0 10 8 16 4
0 10 9 9 4
0 10 10 17 4
0 10 11 7 4
0 10 12 9 4
0 10 13 16 4
0 10 14 17 36
0 11 1 11 68
0 11 2 4 4
0 11 3 14 4
0 11 4 8 4
0 11 5 11 4
0 11 6 8 4
0 11 7 8 4
0 11 8 8 4
0 11 9 16 4
0 11 10 15 4
0 11 11 16 4
0 11 12 17 4
0 11 13 11 4
0 11 14 18 36
0 12 1 7 68
0 12 2 7 4
0 12 3 18 4
0 12 4 11 4
0 12 5 16 4
0 12 6 18 4
0 12 7 18 4
0 12 8 14 4
0 12 9 14 4
0 12 10 16 4
0 12 11 14 4
0 12 12 13 4
0 12 13 17 4
0 12 14 16 36
0 13 1 12 76
0 13 2 12 4
0 13 3 12 12
0 13 4 12 12
0 13 5 12 12
0 13 6 12 12
0 13 7 12 12
0 13 8 12 12
0 13 9 12 12
0 13 10 12 12
0 13 11 12 12
0 13 12 12 12
0 13 13 12 12
0 13 14 12 44
0 14 2 12 108
1 2 1 17 80
1 2 2 8 16
1 2 3 8 16
1 2 4 7 16
1 2 5 8 16
1 2 6 16 16
1 2 7 16 16
1 2 8 7 16
1 2 9 16 16
1 2 10 18 16
1 2 11 15 16
1 2 12 14 16
1 2 13 11 16
1 2 14 6 48
1 3 1 4 64
1 3 2 17 0
1 3 3 6 0
1 3 4 16 0
1 3 5 8 0
1 3 6 18 0
1 3 7 18 0
1 3 8 16 0
1 3 9 17 0
1 3 10 4 0
1 3 11 17 0
1 3 12 11 0
1 3 13 15 0
1 3 14 11 32
1 4 1 11 64
1 4 2 16 0
1 4 3 18 0
1 4 4 14 0
1 4 5 7 0
1 4 6 7 0
1 4 7 7 0
1 4 8 16 0
1 4 9 16 0
1 4 10 16 0
1 4 11 16 0
1 4 12 14 0
1 4 13 16 0
1 4 14 8 32
1 5 1 17 64
1 5 2 16 0
1 5 3 11 0
1 5 4 13 0
1 5 5 17 0
1 5 6 16 0
1 5 7 16 0
1 5 8 18 0
1 5 9 16 0
1 5 10 19 0
1 5 11 18 0
1 5 12 17 0
1 5 13 8 0
1 5 14 18 32
1 6 1 5 64
1 6 2 18 0
1 6 3 18 0
1 6 4 4 0
1 6 5 7 0
1 6 6 14 0
1 6 7 14 0
1 6 8 4 0
1 6 9 16 0
1 6 10 9 0
1 6 11 13 0
1 6 12 17 0
1 6 13 14 0
1 6 14 17 32
1 7 1 15 64
1 7 2 7 0
1 7 3 18 0
1 7 4 15 0
1 7 5 16 0
1 7 6 8 0
1 7 7 8 0
1 7 8 16 0
1 7 9 18 0
1 7 10 17 0
1 7 11 17 0
1 7 12 8 0
1 7 13 18 0
1 7 14 17 32
1 8 1 7 64
1 8 2 15 0
1 8 3 14 0
1 8 4 6 0
1 8 5 15 0
1 8 6 9 0
1 8 7 9 0
1 8 8 18 0
1 8 9 17 0
1 8 10 6 0
1 8 11 6 0
1 8 12 16 0
1 8 13 16 0
1 8 14 17 32
1 9 1 18 64
1 9 2 8 0
1 9 3 16 0
1 9 4 17 0
1 9 5 18 0
1 9 6 13 0
1 9 7 13 0
1 9 8 17 0
1 9 9 17 0
1 9 10 17 0
1 9 11 13 0
1 9 12 17 0
1 9 13 8 0
1 9 14 9 32
1 10 1 11 64
1 10 2 13 0
1 10 3 18 0
1 10 4 16 0
1 10 5 16 0
1 10 6 6 0
1 10 7 6 0
1 10 8 16 0
1 10 9 9 0
1 10 10 17 0
1 10 11 7 0
1 10 12 9 0
1 10 13 16 0
1 10 14 17 32
1 11 1 11 64
1 11 2 4 0
1 11 3 14 0
1 11 4 8 0
1 11 5 11 0
1 11 6 8 0
1 11 7 8 0
1 11 8 8 0
1 11 9 16 0
1 11 10 15 0
1 11 11 16 0
1 11 12 17 0
1 11 13 11 0
1 11 14 18 32
1 12 1 7 64
1 12 2 7 0
1 12 3 18 0
1 12 4 11 0
1 12 5 16 0
1 12 6 18 0
1 12 7 18 0
1 12 8 14 0
1 12 9 14 0
1 12 10 16 0
1 12 11 14 0
1 12 12 13 0
1 12 13 17 0
1 12 14 16 32
1 13 1 12 72
1 13 2 12 0
1 13 3 12 0
1 13 4 12 8
1 13 5 12 8
1 13 6 12 8
1 13 7 12 8
1 13 8 12 8
1 13 9 12 8
1 13 10 12 8
1 13 11 12 8
1 13 12 12 8
1 13 13 12 8
1 13 14 12 40
1 14 2 2 64
1 14 3 12 44
1 15 2 12 108
2 0 3 2 118
2 0 12 2 118
2 1 2 2 84
2 1 3 2 4
2 1 4 2 52
2 1 11 2 84
2 1 12 2 4
2 1 13 2 52
2 2 1 14 80
2 2 2 17 0
2 2 3 16 0
2 2 4 8 0
2 2 5 16 16
2 2 6 17 16
2 2 7 17 16
2 2 8 17 16
2 2 9 8 16
2 2 10 15 16
2 2 11 9 0
2 2 12 15 0
2 2 13 16 0
2 2 14 14 48
2 3 1 18 64
2 3 2 17 0
2 3 3 7 0
2 3 4 17 0
2 3 5 16 0
2 3 6 11 0
2 3 7 11 0
2 3 8 17 0
2 3 9 16 0
2 3 10 18 0
2 3 11 17 0
2 3 12 15 0
2 3 13 8 0
2 3 14 11 32
2 4 1 18 64
2 4 2 6 0
2 4 3 16 0
2 4 4 17 0
2 4 5 14 0
2 4 6 11 0
2 4 7 11 0
2 4 8 16 0
2 4 9 16 0
2 4 10 7 0
2 4 11 16 0
2 4 12 18 0
2 4 13 8 0
2 4 14 8 32
2 5 1 5 64
2 5 2 9 0
2 5 3 17 0
2 5 4 13 0
2 5 5 16 0
2 5 6 6 0
2 5 7 6 0
2 5 8 16 0
2 5 9 4 0
2 5 10 4 0
2 5 11 11 0
2 5 12 14 0
2 5 13 6 0
2 5 14 13 32
2 6 1 5 64
2 6 2 13 0
2 6 3 4 0
2 6 4 17 0
2 6 5 18 0
2 6 6 8 0
2 6 7 8 0
2 6 8 17 0
2 6 9 18 0
2 6 10 11 0
2 6 11 7 0
2 6 12 17 0
2 6 13 18 0
2 6 14 13 32
2 7 1 5 64
2 7 2 17 0
2 7 3 15 0
2 7 4 15 0
2 7 5 18 0
2 7 6 16 0
2 7 7 16 0
2 7 8 16 0
2 7 9 17 0
2 7 10 13 0
2 7 11 16 0
2 7 12 6 0
2 7 13 18 0
2 7 14 17 32
2 8 1 6 64
2 8 2 14 0
2 8 3 17 0
2 8 4 6 0
2 8 5 17 0
2 8 6 17 0
2 8 7 17 0
2 8 8 6 0
2 8 9 9 0
2 8 10 17 0
2 8 11 18 0
2 8 12 16 0
2 8 13 17 0
2 8 14 17 32
2 9 1 16 64
2 9 2 17 0
2 9 3 18 0
2 9 4 14 0
2 9 5 11 0
2 9 6 14 0
2 9 7 14 0
2 9 8 18 0
2 9 9 16 0
2 9 10 18 0
2 9 11 17 0
2 9 12 9 0
2 9 13 13 0
2 9 14 15 32
2 10 1 16 64
2 10 2 7 0
2 10 3 17 0
2 10 4 9 0
2 10 5 16 0
2 10 6 16 0
2 10 7 16 0
2 10 8 18 0
2 10 9 14 0
2 10 10 4 0
2 10 11 16 0
2 10 12 18 0
2 10 13 16 0
2 10 14 16 32
2 11 1 16 64
2 11 2 9 0
2 11 3 17 0
2 11 4 15 0
2 11 5 15 0
2 11 6 16 0
2 11 7 16 0
2 11 8 16 0
2 11 9 8 0
2 11 10 16 0
2 11 11 17 0
2 11 12 17 0
2 11 13 13 0
2 11 14 11 32
2 12 1 16 64
2 12 2 15 0
2 12 3 11 0
2 12 4 16 0
2 12 5 15 0
2 12 6 8 0
2 12 7 8 0
2 12 8 4 0
2 12 9 17 0
2 12 10 8 0
2 12 11 9 0
2 12 12 4 0
2 12 13 6 0
2 12 14 17 32
2 13 0 3 92
2 13 1 12 8
2 13 2 17 0
2 13 3 7 0
2 13 4 16 0
2 13 5 14 8
2 13 6 8 8
2 13 7 8 8
2 13 8 17 8
2 13 9 16 8
2 13 10 16 8
2 13 11 15 8
2 13 12 18 8
2 13 13 7 8
2 13 14 12 40
2 14 2 2 64
2 14 3 12 8
2 14 4 12 44
2 15 2 2 104
3 1 2 2 80
3 1 3 2 16
3 1 4 2 48
3 1 11 2 80
3 1 12 2 16
3 1 13 2 48
3 2 1 16 80
3 2 2 11 0
3 2 3 17 0
3 2 4 11 0
3 2 5 4 16
3 2 6 15 16
3 2 7 15 16
3 2 8 17 16
3 2 9 13 16
3 2 10 15 16
3 2 11 16 0
3 2 12 11 0
3 2 13 16 0
3 2 14 9 48
3 3 1 19 64
3 3 2 19 0
3 3 3 11 0
3 3 4 16 0
3 3 5 16 0
3 3 6 13 0
3 3 7 13 0
3 3 8 11 0
3 3 9 8 0
3 3 10 6 0
3 3 11 13 0
3 3 12 16 0
3 3 13 17 0
3 3 14 16 32
3 4 1 19 64
3 4 2 19 0
3 4 3 16 0
3 4 4 11 0
3 4 5 18 0
3 4 6 11 0
3 4 7 11 0
3 4 8 18 0
3 4 9 17 0
3 4 10 18 0
3 4 11 16 0
3 4 12 15 0
3 4 13 11 0
3 4 14 18 32
3 5 1 19 64
3 5 2 19 0
3 5 3 11 0
3 5 4 8 0
3 5 5 16 0
3 5 6 16 0
3 5 7 16 0
3 5 8 17 0
3 5 9 14 0
3 5 10 16 0
3 5 11 15 0
3 5 12 9 0
3 5 13 13 0
3 5 14 16 32
3 6 1 5 64
3 6 2 19 0
3 6 3 16 0
3 6 4 17 0
3 6 5 17 0
3 6 6 17 0
3 6 7 17 0
3 6 8 11 0
3 6 9 8 0
3 6 10 18 0
3 6 11 17 0
3 6 12 9 0
3 6 13 17 0
3 6 14 18 32
3 7 1 6 64
3 7 2 6 0
3 7 3 18 0
3 7 4 17 0
3 7 5 13 0
3 7 6 9 0
3 7 7 9 0
3 7 8 7 0
3 7 9 18 0
3 7 10 13 0
3 7 11 18 0
3 7 12 9 0
3 7 13 18 0
3 7 14 4 32
3 8 1 6 64
3 8 2 17 0
3 8 3 4 0
3 8 4 15 0
3 8 5 17 0
3 8 6 6 0
3 8 7 6 0
3 8 8 15 0
3 8 9 18 0
3 8 10 11 0
3 8 11 16 0
3 8 12 18 0
3 8 13 16 0
3 8 14 18 32
3 9 0 0 84
3 9 1 18 0
3 9 2 16 0
3 9 3 13 0
3 9 4 16 0
3 9 5 11 0
3 9 6 17 0
3 9 7 17 0
3 9 8 16 0
3 9 9 11 0
3 9 10 8 0
3 9 11 17 0
3 9 12 13 0
3 9 13 18 0
3 9 14 9 32
3 10 0 20 68
3 10 1 20 0
3 10 2 20 0
3 10 3 16 0
3 10 4 18 0
3 10 5 11 0
3 10 6 4 0
3 10 7 4 0
3 10 8 15 0
3 10 9 15 0
3 10 10 16 0
3 10 11 9 0
3 10 12 15 0
3 10 13 9 0
3 10 14 8 32
3 11 0 20 76
3 11 1 5 0
3 11 2 20 0
3 11 3 18 0
3 11 4 4 0
3 11 5 18 0
3 11 6 6 0
3 11 7 6 0
3 11 8 17 0
3 11 9 16 0
3 11 10 4 0
3 11 11 17 0
3 11 12 17 0
3 11 13 17 0
3 11 14 14 32
3 12 1 7 64
3 12 2 7 0
3 12 3 8 0
3 12 4 15 0
3 12 5 16 0
3 12 6 14 0
3 12 7 14 0
3 12 8 15 0
3 12 9 17 0
3 12 10 18 0
3 12 11 18 0
3 12 12 13 0
3 12 13 17 0
3 12 14 9 32
3 13 0 3 88
3 13 1 12 8
3 13 2 16 0
3 13 3 8 0
3 13 4 7 0
3 13 5 16 8
3 13 6 17 8
3 13 7 17 8
3 13 8 11 8
3 13 9 8 8
3 13 10 14 8
3 13 11 16 8
3 13 12 16 8
3 13 13 18 8
3 13 14 12 40
3 14 2 2 64
3 14 3 12 8
3 14 4 12 42
3 15 2 2 104
4 0 3 2 118
4 0 12 2 118
4 1 2 2 82
4 1 3 2 2
4 1 4 2 50
4 1 11 2 82
4 1 12 2 2
4 1 13 2 50
4 2 1 18 80
4 2 2 16 0
4 2 3 11 0
4 2 4 17 0
4 2 5 18 16
4 2 6 7 16
4 2 7 7 16
4 2 8 18 16
4 2 9 18 16
4 2 10 18 16
4 2 11 16 0
4 2 12 6 0
4 2 13 13 0
4 2 14 18 48
4 3 1 19 66
4 3 2 19 0
4 3 3 16 0
4 3 4 18 0
4 3 5 18 0
4 3 6 17 0
4 3 7 17 0
4 3 8 17 0
4 3 9 17 0
4 3 10 8 0
4 3 11 13 0
4 3 12 15 0
4 3 13 16 0
4 3 14 11 32
4 4 1 11 64
4 4 2 14 0
4 4 3 11 0
4 4 4 18 0
4 4 5 13 0
4 4 6 17 0
4 4 7 17 0
4 4 8 13 0
4 4 9 16 0
4 4 10 8 0
4 4 11 14 0
4 4 12 16 0
4 4 13 14 0
4 4 14 9 32
4 5 1 16 64
4 5 2 4 0
4 5 3 16 0
4 5 4 8 0
4 5 5 17 0
4 5 6 18 0
4 5 7 18 0
4 5 8 6 0
4 5 9 13 0
4 5 10 17 0
4 5 11 17 0
4 5 12 15 0
4 5 13 16 0
4 5 14 15 32
4 6 1 17 64
4 6 2 11 0
4 6 3 13 0
4 6 4 15 0
4 6 5 18 0
4 6 6 14 0
4 6 7 14 0
4 6 8 17 0
4 6 9 11 0
4 6 10 18 0
4 6 11 8 0
4 6 12 11 0
4 6 13 18 0
4 6 14 4 32
4 7 1 17 64
4 7 2 16 0
4 7 3 18 0
4 7 4 16 0
4 7 5 14 0
4 7 6 16 0
4 7 7 16 0
4 7 8 16 0
4 7 9 7 0
4 7 10 9 0
4 7 11 17 0
4 7 12 14 0
4 7 13 17 0
4 7 14 17 32
4 8 1 19 64
4 8 2 8 0
4 8 3 8 0
4 8 4 17 0
4 8 5 15 0
4 8 6 17 0
4 8 7 17 0
4 8 8 17 0
4 8 9 13 0
4 8 10 18 0
4 8 11 18 0
4 8 12 7 0
4 8 13 13 0
4 8 14 15 32
4 9 0 0 80
4 9 1 0 0
4 9 2 0 0
4 9 3 6 0
4 9 4 17 0
4 9 5 11 0
4 9 6 9 0
4 9 7 9 0
4 9 8 18 0
4 9 9 18 0
4 9 10 14 0
4 9 11 7 0
4 9 12 15 0
4 9 13 16 0
4 9 14 15 32
4 10 0 0 64
4 10 1 20 0
4 10 2 20 0
4 10 3 9 0
4 10 4 17 0
4 10 5 15 0
4 10 6 16 0
4 10 7 16 0
4 10 8 16 0
4 10 9 9 0
4 10 10 15 0
4 10 11 16 0
4 10 12 6 0
4 10 13 18 0
4 10 14 18 32
4 11 0 20 72
4 11 1 20 0
4 11 2 20 0
4 11 3 18 0
4 11 4 17 0
4 11 5 18 0
4 11 6 16 0
4 11 7 16 0
4 11 8 11 0
4 11 9 18 0
4 11 10 17 0
4 11 11 6 0
4 11 12 18 0
4 11 13 14 0
4 11 14 15 32
4 12 1 19 64
4 12 2 11 0
4 12 3 16 0
4 12 4 13 0
4 12 5 4 0
4 12 6 18 0
4 12 7 18 0
4 12 8 16 0
4 12 9 16 0
4 12 10 6 0
4 12 11 17 0
4 12 12 16 0
4 12 13 18 0
4 12 14 13 32
4 13 0 3 88
4 13 1 12 8
4 13 2 17 0
4 13 3 16 0
4 13 4 14 8
4 13 5 18 8
4 13 6 6 8
4 13 7 6 8
4 13 8 16 8
4 13 9 14 8
4 13 10 13 8
4 13 11 6 8
4 13 12 19 8
4 13 13 16 8
4 13 14 12 40
4 14 2 2 64
4 14 3 12 42
4 15 2 12 106
5 2 1 12 88
5 2 2 13 16
5 2 3 6 16
5 2 4 17 16
5 2 5 17 16
5 2 6 17 16
5 2 7 17 16
5 2 8 17 16
5 2 9 16 16
5 2 10 15 16
5 2 11 18 16
5 2 12 7 16
5 2 13 9 16
5 2 14 16 48
5 3 2 2 64
5 3 3 18 0
5 3 4 18 0
5 3 5 16 0
5 3 6 11 0
5 3 7 11 0
5 3 8 17 0
5 3 9 11 0
5 3 10 7 0
5 3 11 16 0
5 3 12 9 0
5 3 13 18 0
5 3 14 8 32
5 4 1 8 80
5 4 2 16 0
5 4 3 16 0
5 4 4 18 0
5 4 5 15 0
5 4 6 4 0
5 4 7 4 0
5 4 8 16 0
5 4 9 16 0
5 4 10 16 0
5 4 11 18 0
5 4 12 18 0
5 4 13 17 0
5 4 14 6 32
5 5 0 10 84
5 5 1 9 0
5 5 2 18 0
5 5 3 16 0
5 5 4 17 0
5 5 5 8 0
5 5 6 4 0
5 5 7 4 0
5 5 8 16 0
5 5 9 7 0
5 5 10 16 0
5 5 11 18 0
5 5 12 16 0
5 5 13 13 0
5 5 14 7 32
5 6 0 10 70
5 6 1 13 0
5 6 2 16 0
5 6 3 18 0
5 6 4 6 0
5 6 5 13 0
5 6 6 15 0
5 6 7 15 0
5 6 8 15 0
5 6 9 18 0
5 6 10 16 0
5 6 11 11 0
5 6 12 18 0
5 6 13 16 0
5 6 14 16 32
5 7 0 10 76
5 7 1 18 0
5 7 2 18 0
5 7 3 17 0
5 7 4 18 0
5 7 5 16 0
5 7 6 16 0
5 7 7 16 0
5 7 8 13 0
5 7 9 9 0
5 7 10 17 0
5 7 11 18 0
5 7 12 16 0
5 7 13 7 0
5 7 14 17 32
5 8 1 15 64
5 8 2 16 0
5 8 3 15 0
5 8 4 17 0
5 8 5 16 0
5 8 6 17 0
5 8 7 17 0
5 8 8 18 0
5 8 9 17 0
5 8 10 15 0
5 8 11 7 0
5 8 12 16 0
5 8 13 4 0
5 8 14 17 32
5 9 0 0 82
5 9 1 0 0
5 9 2 0 0
5 9 3 11 0
5 9 4 9 0
5 9 5 18 0
5 9 6 16 0
5 9 7 16 0
5 9 8 6 0
5 9 9 16 0
5 9 10 18 0
5 9 11 15 0
5 9 12 8 0
5 9 13 14 0
5 9 14 18 32
5 10 0 20 66
5 10 1 20 0
5 10 2 20 0
5 10 3 18 0
5 10 4 8 0
5 10 5 17 0
5 10 6 16 0
5 10 7 16 0
5 10 8 16 0
5 10 9 8 0
5 10 10 17 0
5 10 11 11 0
5 10 12 8 0
5 10 13 8 0
5 10 14 8 32
5 11 0 20 74
5 11 1 20 0
5 11 2 20 0
5 11 3 11 0
5 11 4 17 0
5 11 5 16 0
5 11 6 16 0
5 11 7 16 0
5 11 8 18 0
5 11 9 13 0
5 11 10 9 0
5 11 11 16 0
5 11 12 18 0
5 11 13 7 0
5 11 14 4 32
5 12 1 19 64
5 12 2 18 0
5 12 3 11 0
5 12 4 17 0
5 12 5 8 0
5 12 6 18 0
5 12 7 18 0
5 12 8 16 0
5 12 9 11 0
5 12 10 7 0
5 12 11 6 0
5 12 12 7 0
5 12 13 17 0
5 12 14 17 32
5 13 0 3 90
5 13 1 12 8
5 13 2 14 0
5 13 3 13 8
5 13 4 14 8
5 13 5 11 8
5 13 6 16 8
5 13 7 16 8
5 13 8 18 8
5 13 9 18 8
5 13 10 9 8
5 13 11 16 8
5 13 12 17 8
5 13 13 11 8
5 13 14 12 40
5 14 2 12 106
6 2 1 12 88
6 2 2 13 16
6 2 3 6 16
6 2 4 17 16
6 2 5 17 16
6 2 6 17 16
6 2 7 17 16
6 2 8 17 16
6 2 9 16 16
6 2 10 15 16
6 2 11 18 16
6 2 12 7 16
6 2 13 9 16
6 2 14 16 48
6 3 2 1 64
6 3 3 18 0
6 3 4 18 0
6 3 5 16 0
6 3 6 11 0
6 3 7 11 0
6 3 8 17 0
6 3 9 11 0
6 3 10 7 0
6 3 11 16 0
6 3 12 9 0
6 3 13 18 0
6 3 14 8 32
6 4 1 12 80
6 4 2 16 0
6 4 3 16 0
6 4 4 18 0
6 4 5 15 0
6 4 6 4 0
6 4 7 4 0
6 4 8 16 0
6 4 9 16 0
6 4 10 16 0
6 4 11 18 0
6 4 12 18 0
6 4 13 17 0
6 4 14 6 32
6 5 0 10 88
6 5 1 9 0
6 5 2 18 0
6 5 3 16 0
6 5 4 17 0
6 5 5 8 0
6 5 6 4 0
6 5 7 4 0
6 5 8 16 0
6 5 9 7 0
6 5 10 16 0
6 5 11 18 0
6 5 12 16 0
6 5 13 13 0
6 5 14 7 32
6 6 1 1 64
6 6 2 16 0
6 6 3 18 0
6 6 4 6 0
6 6 5 13 0
6 6 6 15 0
6 6 7 15 0
6 6 8 15 0
6 6 9 18 0
6 6 10 16 0
6 6 11 11 0
6 6 12 18 0
6 6 13 16 0
6 6 14 16 32
6 7 0 10 88
6 7 1 18 0
6 7 2 18 0
6 7 3 17 0
6 7 4 18 0
6 7 5 16 0
6 7 6 16 0
6 7 7 16 0
6 7 8 13 0
6 7 9 9 0
6 7 10 17 0
6 7 11 18 0
6 7 12 16 0
6 7 13 7 0
6 7 14 17 32
6 8 1 15 64
6 8 2 16 0
6 8 3 15 0
6 8 4 17 0
6 8 5 16 0
6 8 6 17 0
6 8 7 17 0
6 8 8 18 0
6 8 9 17 0
6 8 10 15 0
6 8 11 7 0
6 8 12 16 0
6 8 13 4 0
6 8 14 17 32
6 9 1 19 64
6 9 2 0 0
6 9 3 11 0
6 9 4 9 0
6 9 5 18 0
6 9 6 16 0
6 9 7 16 0
6 9 8 6 0
6 9 9 16 0
6 9 10 18 0
6 9 11 15 0
6 9 12 8 0
6 9 13 14 0
6 9 14 18 0
6 9 15 10 60
6 10 1 19 64
6 10 2 20 0
6 10 3 18 0
6 10 4 8 0
6 10 5 17 0
6 10 6 16 0
6 10 7 16 0
6 10 8 16 0
6 10 9 8 0
6 10 10 17 0
6 10 11 11 0
6 10 12 8 0
6 10 13 8 0
6 10 14 8 32
6 11 1 19 64
6 11 2 20 0
6 11 3 11 0
6 11 4 17 0
6 11 5 16 0
6 11 6 16 0
6 11 7 16 0
6 11 8 18 0
6 11 9 13 0
6 11 10 9 0
6 11 11 16 0
6 11 12 18 0
6 11 13 7 0
6 11 14 4 32
6 12 1 19 64
6 12 2 18 0
6 12 3 11 0
6 12 4 17 0
6 12 5 8 0
6 12 6 18 0
6 12 7 18 0
6 12 8 16 0
6 12 9 11 0
6 12 10 7 0
6 12 11 6 0
6 12 12 7 0
6 12 13 17 0
6 12 14 17 32
6 13 1 12 72
6 13 2 14 8
6 13 3 13 8
6 13 4 14 8
6 13 5 11 8
6 13 6 16 8
6 13 7 16 8
6 13 8 18 8
6 13 9 18 8
6 13 10 9 8
6 13 11 16 8
6 13 12 17 8
6 13 13 11 8
6 13 14 12 40
7 2 1 2 88
7 2 2 16 16
7 2 3 16 16
7 2 4 18 16
7 2 5 16 16
7 2 6 17 16
7 2 7 17 16
7 2 8 15 16
7 2 9 16 16
7 2 10 17 16
7 2 11 18 16
7 2 12 15 16
7 2 13 15 16
7 2 14 17 48
7 3 2 1 64
7 3 3 14 0
7 3 4 14 0
7 3 5 15 0
7 3 6 8 0
7 3 7 8 0
7 3 8 11 0
7 3 9 18 0
7 3 10 14 0
7 3 11 8 0
7 3 12 7 0
7 3 13 16 0
7 3 14 14 32
7 4 1 2 80
7 4 2 18 0
7 4 3 4 0
7 4 4 7 0
7 4 5 6 0
7 4 6 6 0
7 4 7 6 0
7 4 8 18 0
7 4 9 16 0
7 4 10 13 0
7 4 11 17 0
7 4 12 16 0
7 4 13 7 0
7 4 14 16 32
7 5 0 10 80
7 5 1 4 0
7 5 2 11 0
7 5 3 15 0
7 5 4 15 0
7 5 5 18 0
7 5 6 18 0
7 5 7 18 0
7 5 8 8 0
7 5 9 18 0
7 5 10 7 0
7 5 11 9 0
7 5 12 17 0
7 5 13 17 0
7 5 14 6 32
7 6 0 10 68
7 6 1 1 0
7 6 2 17 0
7 6 3 14 0
7 6 4 4 0
7 6 5 8 0
7 6 6 8 0
7 6 7 8 0
7 6 8 16 0
7 6 9 16 0
7 6 10 18 0
7 6 11 16 0
7 6 12 6 0
7 6 13 16 0
7 6 14 7 0
7 6 15 10 52
7 7 0 10 72
7 7 1 8 0
7 7 2 16 0
7 7 3 15 0
7 7 4 11 0
7 7 5 6 0
7 7 6 4 0
7 7 7 4 0
7 7 8 9 0
7 7 9 9 0
7 7 10 7 0
7 7 11 16 0
7 7 12 13 0
7 7 13 18 0
7 7 14 11 0
7 7 15 10 46
7 8 1 18 64
7 8 2 6 0
7 8 3 17 0
7 8 4 16 0
7 8 5 15 0
7 8 6 16 0
7 8 7 16 0
7 8 8 15 0
7 8 9 4 0
7 8 10 14 0
7 8 11 7 0
7 8 12 17 0
7 8 13 17 0
7 8 14 16 32
7 9 1 13 64
7 9 2 13 0
7 9 3 15 0
7 9 4 17 0
7 9 5 7 0
7 9 6 15 0
7 9 7 15 0
7 9 8 15 0
7 9 9 17 0
7 9 10 6 0
7 9 11 14 0
7 9 12 16 0
7 9 13 15 0
7 9 14 11 0
7 9 15 10 56
7 10 1 19 64
7 10 2 20 0
7 10 3 17 0
7 10 4 17 0
7 10 5 16 0
7 10 6 16 0
7 10 7 16 0
7 10 8 17 0
7 10 9 18 0
7 10 10 18 0
7 10 11 17 0
7 10 12 16 0
7 10 13 18 0
7 10 14 7 32
7 11 1 19 64
7 11 2 20 0
7 11 3 16 0
7 11 4 13 0
7 11 5 11 0
7 11 6 8 0
7 11 7 8 0
7 11 8 16 0
7 11 9 17 0
7 11 10 16 0
7 11 11 16 0
7 11 12 9 0
7 11 13 16 0
7 11 14 16 32
7 12 1 8 64
7 12 2 17 0
7 12 3 18 0
7 12 4 8 0
7 12 5 18 0
7 12 6 16 0
7 12 7 16 0
7 12 8 18 0
7 12 9 6 0
7 12 10 17 0
7 12 11 14 0
7 12 12 8 0
7 12 13 11 0
7 12 14 16 32
7 13 1 12 72
7 13 2 16 8
7 13 3 16 8
7 13 4 17 8
7 13 5 7 8
7 13 6 6 8
7 13 7 6 8
7 13 8 9 8
7 13 9 6 8
7 13 10 11 8
7 13 11 8 8
7 13 12 16 8
7 13 13 17 8
7 13 14 12 40
8 2 1 2 88
8 2 2 13 16
8 2 3 4 16
8 2 4 4 16
8 2 5 17 16
8 2 6 18 16
8 2 7 18 16
8 2 8 16 16
8 2 9 16 16
8 2 10 16 16
8 2 11 4 16
8 2 12 4 16
8 2 13 16 16
8 2 14 15 48
8 3 2 1 64
8 3 3 18 0
8 3 4 17 0
8 3 5 18 0
8 3 6 4 0
8 3 7 4 0
8 3 8 13 0
8 3 9 6 0
8 3 10 7 0
8 3 11 16 0
8 3 12 16 0
8 3 13 16 0
8 3 14 8 32
8 4 1 2 80
8 4 2 4 0
8 4 3 18 0
8 4 4 11 0
8 4 5 18 0
8 4 6 15 0
8 4 7 15 0
8 4 8 17 0
8 4 9 17 0
8 4 10 9 0
8 4 11 17 0
8 4 12 18 0
8 4 13 15 0
8 4 14 6 32
8 5 0 10 80
8 5 1 14 0
8 5 2 18 0
8 5 3 18 0
8 5 4 16 0
8 5 5 18 0
8 5 6 18 0
8 5 7 18 0
8 5 8 17 0
8 5 9 18 0
8 5 10 11 0
8 5 11 16 0
8 5 12 15 0
8 5 13 14 0
8 5 14 16 32
8 6 0 10 66
8 6 1 17 0
8 6 2 7 0
8 6 3 16 0
8 6 4 9 0
8 6 5 18 0
8 6 6 18 0
8 6 7 18 0
8 6 8 16 0
8 6 9 6 0
8 6 10 9 0
8 6 11 17 0
8 6 12 18 0
8 6 13 13 0
8 6 14 9 0
8 6 15 10 56
8 7 0 10 72
8 7 1 17 0
8 7 2 8 0
8 7 3 17 0
8 7 4 16 0
8 7 5 15 0
8 7 6 6 0
8 7 7 6 0
8 7 8 4 0
8 7 9 17 0
8 7 10 7 0
8 7 11 17 0
8 7 12 14 0
8 7 13 14 0
8 7 14 18 32
8 8 1 17 64
8 8 2 4 0
8 8 3 17 0
8 8 4 4 0
8 8 5 18 0
8 8 6 18 0
8 8 7 18 0
8 8 8 18 0
8 8 9 7 0
8 8 10 14 0
8 8 11 17 0
8 8 12 17 0
8 8 13 17 0
8 8 14 16 32
8 9 1 17 64
8 9 2 17 0
8 9 3 7 0
8 9 4 8 0
8 9 5 11 0
8 9 6 17 0
8 9 7 17 0
8 9 8 16 0
8 9 9 18 0
8 9 10 11 0
8 9 11 17 0
8 9 12 7 0
8 9 13 11 0
8 9 14 17 0
8 9 15 10 56
8 10 1 16 64
8 10 2 14 0
8 10 3 17 0
8 10 4 7 0
8 10 5 17 0
8 10 6 17 0
8 10 7 17 0
8 10 8 16 0
8 10 9 18 0
8 10 10 16 0
8 10 11 16 0
8 10 12 18 0
8 10 13 17 0
8 10 14 4 32
8 11 1 17 64
8 11 2 6 0
8 11 3 18 0
8 11 4 4 0
8 11 5 16 0
8 11 6 18 0
8 11 7 18 0
8 11 8 16 0
8 11 9 16 0
8 11 10 16 0
8 11 11 16 0
8 11 12 4 0
8 11 13 9 0
8 11 14 11 32
8 12 1 11 64
8 12 2 17 0
8 12 3 18 0
8 12 4 11 0
8 12 5 16 0
8 12 6 6 0
8 12 7 6 0
8 12 8 16 0
8 12 9 11 0
8 12 10 16 0
8 12 11 18 0
8 12 12 18 0
8 12 13 4 0
8 12 14 7 32
8 13 1 12 72
8 13 2 18 8
8 13 3 6 8
8 13 4 15 8
8 13 5 4 8
8 13 6 17 8
8 13 7 17 8
8 13 8 8 8
8 13 9 11 8
8 13 10 11 8
8 13 11 13 8
8 13 12 4 8
8 13 13 16 8
8 13 14 12 40
9 2 1 12 88
9 2 2 16 16
9 2 3 15 16
9 2 4 16 16
9 2 5 11 16
9 2 6 16 16
9 2 7 16 16
9 2 8 18 16
9 2 9 16 16
9 2 10 15 16
9 2 11 11 16
9 2 12 16 16
9 2 13 7 16
9 2 14 15 48
9 3 2 1 64
9 3 3 4 0
9 3 4 17 0
9 3 5 9 0
9 3 6 7 0
9 3 7 7 0
9 3 8 18 0
9 3 9 16 0
9 3 10 4 0
9 3 11 14 0
9 3 12 9 0
9 3 13 18 0
9 3 14 8 32
9 4 1 12 80
9 4 2 7 0
9 4 3 7 0
9 4 4 17 0
9 4 5 8 0
9 4 6 16 0
9 4 7 16 0
9 4 8 8 0
9 4 9 7 0
9 4 10 18 0
9 4 11 16 0
9 4 12 7 0
9 4 13 18 0
9 4 14 16 32
9 5 0 10 88
9 5 1 13 0
9 5 2 4 0
9 5 3 9 0
9 5 4 16 0
9 5 5 9 0
9 5 6 4 0
9 5 7 4 0
9 5 8 14 0
9 5 9 17 0
9 5 10 17 0
9 5 11 17 0
9 5 12 18 0
9 5 13 17 0
9 5 14 16 32
9 6 1 1 64
9 6 2 4 0
9 6 3 14 0
9 6 4 16 0
9 6 5 17 0
9 6 6 8 0
9 6 7 8 0
9 6 8 6 0
9 6 9 15 0
9 6 10 18 0
9 6 11 7 0
9 6 12 17 0
9 6 13 17 0
9 6 14 11 0
9 6 15 10 50
9 7 0 10 88
9 7 1 16 0
9 7 2 15 0
9 7 3 7 0
9 7 4 9 0
9 7 5 7 0
9 7 6 15 0
9 7 7 15 0
9 7 8 15 0
9 7 9 9 0
9 7 10 13 0
9 7 11 15 0
9 7 12 16 0
9 7 13 15 0
9 7 14 18 0
9 7 15 10 38
9 8 1 18 64
9 8 2 16 0
9 8 3 11 0
9 8 4 4 0
9 8 5 16 0
9 8 6 17 0
9 8 7 17 0
9 8 8 13 0
9 8 9 16 0
9 8 10 9 0
9 8 11 4 0
9 8 12 8 0
9 8 13 8 0
9 8 14 17 0
9 8 15 10 38
9 9 1 6 64
9 9 2 14 0
9 9 3 11 0
9 9 4 18 0
9 9 5 16 0
9 9 6 18 0
9 9 7 18 0
9 9 8 17 0
9 9 9 17 0
9 9 10 7 0
9 9 11 17 0
9 9 12 15 0
9 9 13 13 0
9 9 14 18 0
9 9 15 10 42
9 10 1 19 64
9 10 2 20 0
9 10 3 13 0
9 10 4 17 0
9 10 5 11 0
9 10 6 17 0
9 10 7 17 0
9 10 8 11 0
9 10 9 17 0
9 10 10 18 0
9 10 11 4 0
9 10 12 18 0
9 10 13 16 0
9 10 14 17 32
9 11 1 19 64
9 11 2 20 0
9 11 3 7 0
9 11 4 18 0
9 11 5 17 0
9 11 6 13 0
9 11 7 13 0
9 11 8 8 0
9 11 9 7 0
9 11 10 17 0
9 11 11 6 0
9 11 12 13 0
9 11 13 6 0
9 11 14 18 32
9 12 1 4 64
9 12 2 17 0
9 12 3 9 0
9 12 4 15 0
9 12 5 17 0
9 12 6 16 0
9 12 7 16 0
9 12 8 11 0
9 12 9 9 0
9 12 10 9 0
9 12 11 17 0
9 12 12 16 0
9 12 13 18 0
9 12 14 7 32
9 13 1 12 72
9 13 2 13 8
9 13 3 16 8
9 13 4 4 8
9 13 5 18 8
9 13 6 7 8
9 13 7 7 8
9 13 8 4 8
9 13 9 16 8
9 13 10 13 8
9 13 11 8 8
9 13 12 15 8
9 13 13 17 8
9 13 14 12 40
10 2 1 19 88
10 2 2 11 16
10 2 3 17 16
10 2 4 16 16
10 2 5 8 16
10 2 6 18 16
10 2 7 18 16
10 2 8 17 16
10 2 9 15 16
10 2 10 4 16
10 2 11 16 16
10 2 12 17 16
10 2 13 17 16
10 2 14 18 48
10 3 2 2 64
10 3 3 9 0
10 3 4 16 0
10 3 5 7 0
10 3 6 18 0
10 3 7 18 0
10 3 8 18 0
10 3 9 13 0
10 3 10 17 0
10 3 11 16 0
10 3 12 7 0
10 3 13 17 0
10 3 14 11 32
10 4 1 8 80
10 4 2 17 0
10 4 3 9 0
10 4 4 7 0
10 4 5 16 0
10 4 6 18 0
10 4 7 18 0
10 4 8 17 0
10 4 9 17 0
10 4 10 6 0
10 4 11 17 0
10 4 12 17 0
10 4 13 17 0
10 4 14 17 32
10 5 0 10 82
10 5 1 13 0
10 5 2 7 0
10 5 3 17 0
10 5 4 9 0
10 5 5 16 0
10 5 6 14 0
10 5 7 14 0
10 5 8 14 0
10 5 9 7 0
10 5 10 16 0
10 5 11 17 0
10 5 12 9 0
10 5 13 18 0
10 5 14 17 32
10 6 0 10 70
10 6 1 9 0
10 6 2 8 0
10 6 3 16 0
10 6 4 17 0
10 6 5 17 0
10 6 6 18 0
10 6 7 18 0
10 6 8 17 0
10 6 9 17 0
10 6 10 17 0
10 6 11 18 0
10 6 12 16 0
10 6 13 17 0
10 6 14 16 32
10 7 0 10 74
10 7 1 16 0
10 7 2 11 0
10 7 3 17 0
10 7 4 11 0
10 7 5 16 0
10 7 6 18 0
10 7 7 18 0
10 7 8 14 0
10 7 9 17 0
10 7 10 16 0
10 7 11 16 0
10 7 12 8 0
10 7 13 16 0
10 7 14 6 32
10 8 1 17 64
10 8 2 15 0
10 8 3 9 0
10 8 4 13 0
10 8 5 4 0
10 8 6 15 0
10 8 7 15 0
10 8 8 6 0
10 8 9 13 0
10 8 10 18 0
10 8 11 7 0
10 8 12 8 0
10 8 13 14 0
10 8 14 9 32
10 9 0 0 84
10 9 1 0 0
10 9 2 0 0
10 9 3 15 0
10 9 4 16 0
10 9 5 17 0
10 9 6 18 0
10 9 7 18 0
10 9 8 18 0
10 9 9 14 0
10 9 10 14 0
10 9 11 16 0
10 9 12 6 0
10 9 13 17 0
10 9 14 16 32
10 10 0 20 68
10 10 1 20 0
10 10 2 20 0
10 10 3 4 0
10 10 4 16 0
10 10 5 13 0
10 10 6 11 0
10 10 7 11 0
10 10 8 15 0
10 10 9 15 0
10 10 10 15 0
10 10 11 17 0
10 10 12 7 0
10 10 13 4 0
10 10 14 14 32
10 11 0 20 76
10 11 1 20 0
10 11 2 20 0
10 11 3 4 0
10 11 4 18 0
10 11 5 6 0
10 11 6 13 0
10 11 7 13 0
10 11 8 17 0
10 11 9 16 0
10 11 10 4 0
10 11 11 13 0
10 11 12 18 0
10 11 13 18 0
10 11 14 14 32
10 12 1 19 64
10 12 2 4 0
10 12 3 7 0
10 12 4 8 0
10 12 5 18 0
10 12 6 17 0
10 12 7 17 0
10 12 8 16 0
10 12 9 16 0
10 12 10 16 0
10 12 11 17 0
10 12 12 16 0
10 12 13 14 0
10 12 14 9 32
10 13 0 3 92
10 13 1 12 8
10 13 2 9 0
10 13 3 16 8
10 13 4 18 8
10 13 5 8 8
10 13 6 16 8
10 13 7 16 8
10 13 8 8 8
10 13 9 15 8
10 13 10 11 8
10 13 11 17 8
10 13 12 14 8
10 13 13 17 8
10 13 14 12 40
10 14 2 12 108
11 0 3 2 118
11 0 12 2 118
11 1 2 2 84
11 1 3 2 4
11 1 4 2 52
11 1 11 2 84
11 1 12 2 4
11 1 13 2 52
11 2 1 16 80
11 2 2 9 0
11 2 3 18 0
11 2 4 17 0
11 2 5 17 16
11 2 6 8 16
11 2 7 8 16
11 2 8 14 16
11 2 9 16 16
11 2 10 16 16
11 2 11 15 0
11 2 12 17 0
11 2 13 16 0
11 2 14 16 48
11 3 1 19 68
11 3 2 19 0
11 3 3 18 0
11 3 4 11 0
11 3 5 18 0
11 3 6 17 0
11 3 7 17 0
11 3 8 11 0
11 3 9 16 0
11 3 10 16 0
11 3 11 17 0
11 3 12 13 0
11 3 13 6 0
11 3 14 18 32
11 4 1 13 64
11 4 2 11 0
11 4 3 4 0
11 4 4 16 0
11 4 5 18 0
11 4 6 16 0
11 4 7 16 0
11 4 8 16 0
11 4 9 18 0
11 4 10 15 0
11 4 11 17 0
11 4 12 9 0
11 4 13 16 0
11 4 14 8 32
11 5 1 17 64
11 5 2 16 0
11 5 3 15 0
11 5 4 8 0
11 5 5 8 0
11 5 6 17 0
11 5 7 17 0
11 5 8 18 0
11 5 9 17 0
11 5 10 13 0
11 5 11 17 0
11 5 12 16 0
11 5 13 13 0
11 5 14 13 32
11 6 1 16 64
11 6 2 14 0
11 6 3 8 0
11 6 4 11 0
11 6 5 8 0
11 6 6 7 0
11 6 7 7 0
11 6 8 13 0
11 6 9 11 0
11 6 10 8 0
11 6 11 18 0
11 6 12 17 0
11 6 13 16 0
11 6 14 9 32
11 7 1 8 64
11 7 2 11 0
11 7 3 16 0
11 7 4 7 0
11 7 5 17 0
11 7 6 17 0
11 7 7 17 0
11 7 8 18 0
11 7 9 16 0
11 7 10 4 0
11 7 11 4 0
11 7 12 18 0
11 7 13 13 0
11 7 14 17 32
11 8 1 19 64
11 8 2 16 0
11 8 3 16 0
11 8 4 6 0
11 8 5 17 0
11 8 6 16 0
11 8 7 16 0
11 8 8 8 0
11 8 9 17 0
11 8 10 18 0
11 8 11 15 0
11 8 12 18 0
11 8 13 18 0
11 8 14 18 32
11 9 0 0 80
11 9 1 0 0
11 9 2 0 0
11 9 3 17 0
11 9 4 18 0
11 9 5 4 0
11 9 6 17 0
11 9 7 17 0
11 9 8 14 0
11 9 9 18 0
11 9 10 15 0
11 9 11 16 0
11 9 12 16 0
11 9 13 18 0
11 9 14 17 32
11 10 0 0 64
11 10 1 20 0
11 10 2 20 0
11 10 3 4 0
11 10 4 14 0
11 10 5 17 0
11 10 6 4 0
11 10 7 4 0
11 10 8 17 0
11 10 9 18 0
11 10 10 14 0
11 10 11 8 0
11 10 12 4 0
11 10 13 6 0
11 10 14 17 32
11 11 0 20 72
11 11 1 20 0
11 11 2 20 0
11 11 3 17 0
11 11 4 14 0
11 11 5 18 0
11 11 6 15 0
11 11 7 15 0
11 11 8 17 0
11 11 9 16 0
11 11 10 16 0
11 11 11 17 0
11 11 12 16 0
11 11 13 13 0
11 11 14 17 32
11 12 1 19 64
11 12 2 16 0
11 12 3 18 0
11 12 4 16 0
11 12 5 17 0
11 12 6 13 0
11 12 7 13 0
11 12 8 4 0
11 12 9 16 0
11 12 10 16 0
11 12 11 16 0
11 12 12 9 0
11 12 13 16 0
11 12 14 17 32
11 13 0 3 88
11 13 1 12 8
11 13 2 18 0
11 13 3 14 0
11 13 4 14 8
11 13 5 16 8
11 13 6 17 8
11 13 7 17 8
11 13 8 8 8
11 13 9 16 8
11 13 10 16 8
11 13 11 18 8
11 13 12 4 8
11 13 13 8 8
11 13 14 12 40
11 14 2 2 64
11 14 3 12 44
11 15 2 12 108
12 1 2 2 80
12 1 3 2 16
12 1 4 2 48
12 1 11 2 80
12 1 12 2 16
12 1 13 2 48
12 2 1 16 80
12 2 2 16 0
12 2 3 16 0
12 2 4 9 0
12 2 5 11 16
12 2 6 7 16
12 2 7 7 16
12 2 8 16 16
12 2 9 17 16
12 2 10 7 16
12 2 11 16 0
12 2 12 4 0
12 2 13 7 0
12 2 14 17 48
12 3 1 19 64
12 3 2 19 0
12 3 3 17 0
12 3 4 17 0
12 3 5 15 0
12 3 6 8 0
12 3 7 8 0
12 3 8 14 0
12 3 9 15 0
12 3 10 18 0
12 3 11 7 0
12 3 12 17 0
12 3 13 18 0
12 3 14 16 32
12 4 1 19 64
12 4 2 19 0
12 4 3 16 0
12 4 4 17 0
12 4 5 8 0
12 4 6 18 0
12 4 7 18 0
12 4 8 15 0
12 4 9 9 0
12 4 10 16 0
12 4 11 16 0
12 4 12 4 0
12 4 13 17 0
12 4 14 16 32
12 5 1 19 64
12 5 2 8 0
12 5 3 9 0
12 5 4 17 0
12 5 5 11 0
12 5 6 17 0
12 5 7 17 0
12 5 8 16 0
12 5 9 17 0
12 5 10 4 0
12 5 11 16 0
12 5 12 6 0
12 5 13 16 0
12 5 14 17 32
12 6 1 12 64
12 6 2 16 0
12 6 3 17 0
12 6 4 16 0
12 6 5 8 0
12 6 6 17 0
12 6 7 17 0
12 6 8 15 0
12 6 9 17 0
12 6 10 16 0
12 6 11 18 0
12 6 12 11 0
12 6 13 17 0
12 6 14 8 32
12 7 1 17 64
12 7 2 17 0
12 7 3 6 0
12 7 4 16 0
12 7 5 18 0
12 7 6 4 0
12 7 7 4 0
12 7 8 18 0
12 7 9 15 0
12 7 10 15 0
12 7 11 8 0
12 7 12 8 0
12 7 13 6 0
12 7 14 18 32
12 8 1 16 64
12 8 2 4 0
12 8 3 4 0
12 8 4 16 0
12 8 5 15 0
12 8 6 17 0
12 8 7 17 0
12 8 8 16 0
12 8 9 16 0
12 8 10 18 0
12 8 11 18 0
12 8 12 16 0
12 8 13 17 0
12 8 14 8 32
12 9 0 0 82
12 9 1 0 0
12 9 2 14 0
12 9 3 8 0
12 9 4 14 0
12 9 5 17 0
12 9 6 17 0
12 9 7 17 0
12 9 8 18 0
12 9 9 16 0
12 9 10 17 0
12 9 11 17 0
12 9 12 11 0
12 9 13 16 0
12 9 14 18 32
12 10 0 20 66
12 10 1 20 0
12 10 2 20 0
12 10 3 4 0
12 10 4 8 0
12 10 5 17 0
12 10 6 17 0
12 10 7 17 0
12 10 8 17 0
12 10 9 18 0
12 10 10 17 0
12 10 11 15 0
12 10 12 17 0
12 10 13 4 0
12 10 14 13 32
12 11 0 20 74
12 11 1 5 0
12 11 2 20 0
12 11 3 13 0
12 11 4 11 0
12 11 5 15 0
12 11 6 15 0
12 11 7 15 0
12 11 8 16 0
12 11 9 14 0
12 11 10 18 0
12 11 11 16 0
12 11 12 9 0
12 11 13 13 0
12 11 14 17 32
12 12 1 7 64
12 12 2 13 0
12 12 3 17 0
12 12 4 16 0
12 12 5 11 0
12 12 6 7 0
12 12 7 7 0
12 12 8 17 0
12 12 9 14 0
12 12 10 9 0
12 12 11 17 0
12 12 12 18 0
12 12 13 18 0
12 12 14 9 32
12 13 0 3 88
12 13 1 12 8
12 13 2 16 0
12 13 3 16 0
12 13 4 17 0
12 13 5 18 8
12 13 6 16 8
12 13 7 16 8
12 13 8 7 8
12 13 9 6 8
12 13 10 14 8
12 13 11 8 8
12 13 12 11 8
12 13 13 6 8
12 13 14 12 40
12 14 2 2 64
12 14 3 12 8
12 14 4 12 44
12 15 2 2 104
13 1 2 2 80
13 1 3 2 16
13 1 4 2 48
13 1 11 2 80
13 1 12 2 16
13 1 13 2 48
13 2 1 16 80
13 2 2 16 0
13 2 3 16 0
13 2 4 9 0
13 2 5 11 16
13 2 6 7 16
13 2 7 7 16
13 2 8 16 16
13 2 9 17 16
13 2 10 7 16
13 2 11 16 0
13 2 12 4 0
13 2 13 7 0
13 2 14 17 48
13 3 1 19 64
13 3 2 19 0
13 3 3 17 0
13 3 4 17 0
13 3 5 15 0
13 3 6 8 0
13 3 7 8 0
13 3 8 14 0
13 3 9 15 0
13 3 10 18 0
13 3 11 7 0
13 3 12 17 0
13 3 13 18 0
13 3 14 16 32
13 4 1 19 64
13 4 2 19 0
13 4 3 16 0
13 4 4 17 0
13 4 5 8 0
13 4 6 18 0
13 4 7 18 0
13 4 8 15 0
13 4 9 9 0
13 4 10 16 0
13 4 11 16 0
13 4 12 4 0
13 4 13 17 0
13 4 14 16 32
13 5 1 12 64
13 5 2 8 0
13 5 3 9 0
13 5 4 17 0
13 5 5 11 0
13 5 6 17 0
13 5 7 17 0
13 5 8 16 0
13 5 9 17 0
13 5 10 4 0
13 5 11 16 0
13 5 12 6 0
13 5 13 16 0
13 5 14 17 32
13 6 1 5 64
13 6 2 16 0
13 6 3 17 0
13 6 4 16 0
13 6 5 8 0
13 6 6 17 0
13 6 7 17 0
13 6 8 15 0
13 6 9 17 0
13 6 10 16 0
13 6 11 18 0
13 6 12 11 0
13 6 13 17 0
13 6 14 8 32
13 7 1 12 64
13 7 2 17 0
13 7 3 6 0
13 7 4 16 0
13 7 5 18 0
13 7 6 4 0
13 7 7 4 0
13 7 8 18 0
13 7 9 15 0
13 7 10 15 0
13 7 11 8 0
13 7 12 8 0
13 7 13 6 0
13 7 14 18 32
13 8 1 16 64
13 8 2 4 0
13 8 3 4 0
13 8 4 16 0
13 8 5 15 0
13 8 6 17 0
13 8 7 17 0
13 8 8 16 0
13 8 9 16 0
13 8 10 18 0
13 8 11 18 0
13 8 12 16 0
13 8 13 17 0
13 8 14 8 32
13 9 1 6 64
13 9 2 14 0
13 9 3 8 0
13 9 4 14 0
13 9 5 17 0
13 9 6 17 0
13 9 7 17 0
13 9 8 18 0
13 9 9 16 0
13 9 10 17 0
13 9 11 17 0
13 9 12 11 0
13 9 13 16 0
13 9 14 18 32
13 10 1 19 64
13 10 2 20 0
13 10 3 4 0
13 10 4 8 0
13 10 5 17 0
13 10 6 17 0
13 10 7 17 0
13 10 8 17 0
13 10 9 18 0
13 10 10 17 0
13 10 11 15 0
13 10 12 17 0
13 10 13 4 0
13 10 14 13 32
13 11 1 19 64
13 11 2 20 0
13 11 3 13 0
13 11 4 11 0
13 11 5 15 0
13 11 6 15 0
13 11 7 15 0
13 11 8 16 0
13 11 9 14 0
13 11 10 18 0
13 11 11 16 0
13 11 12 9 0
13 11 13 13 0
13 11 14 17 32
13 12 1 7 64
13 12 2 13 0
13 12 3 17 0
13 12 4 16 0
13 12 5 11 0
13 12 6 7 0
13 12 7 7 0
13 12 8 17 0
13 12 9 14 0
13 12 10 9 0
13 12 11 17 0
13 12 12 18 0
13 12 13 18 0
13 12 14 9 32
13 13 0 3 90
13 13 1 12 8
13 13 2 16 0
13 13 3 16 0
13 13 4 17 0
13 13 5 18 8
13 13 6 16 8
13 13 7 16 8
13 13 8 7 8
13 13 9 6 8
13 13 10 14 8
13 13 11 8 8
13 13 12 11 8
13 13 13 6 8
13 13 14 12 40
13 14 2 2 64
13 14 3 12 8
13 14 4 12 42
13 15 2 2 104
14 0 3 2 118
14 0 12 2 118
14 1 2 2 82
14 1 3 2 2
14 1 4 2 50
14 1 11 2 82
14 1 12 2 2
14 1 13 2 50
14 2 1 6 80
14 2 2 18 0
14 2 3 18 0
14 2 4 16 0
14 2 5 4 16
14 2 6 17 16
14 2 7 17 16
14 2 8 16 16
14 2 9 16 16
14 2 10 17 16
14 2 11 4 0
14 2 12 18 0
14 2 13 17 0
14 2 14 16 48
14 3 1 8 64
14 3 2 16 0
14 3 3 14 0
14 3 4 13 0
14 3 5 18 0
14 3 6 8 0
14 3 7 8 0
14 3 8 9 0
14 3 9 14 0
14 3 10 11 0
14 3 11 18 0
14 3 12 7 0
14 3 13 9 0
14 3 14 14 32
14 4 1 13 64
14 4 2 16 0
14 4 3 16 0
14 4 4 15 0
14 4 5 18 0
14 4 6 17 0
14 4 7 17 0
14 4 8 18 0
14 4 9 14 0
14 4 10 14 0
14 4 11 4 0
14 4 12 6 0
14 4 13 9 0
14 4 14 18 32
14 5 1 19 64
14 5 2 16 0
14 5 3 14 0
14 5 4 18 0
14 5 5 6 0
14 5 6 18 0
14 5 7 18 0
14 5 8 4 0
14 5 9 17 0
14 5 10 18 0
14 5 11 17 0
14 5 12 16 0
14 5 13 16 0
14 5 14 17 32
14 6 1 12 64
14 6 2 11 0
14 6 3 16 0
14 6 4 9 0
14 6 5 17 0
14 6 6 14 0
14 6 7 14 0
14 6 8 18 0
14 6 9 18 0
14 6 10 13 0
14 6 11 17 0
14 6 12 18 0
14 6 13 17 0
14 6 14 6 32
14 7 1 19 64
14 7 2 9 0
14 7 3 15 0
14 7 4 6 0
14 7 5 17 0
14 7 6 18 0
14 7 7 18 0
14 7 8 13 0
14 7 9 18 0
14 7 10 4 0
14 7 11 17 0
14 7 12 17 0
14 7 13 8 0
14 7 14 9 32
14 8 1 6 64
14 8 2 8 0
14 8 3 6 0
14 8 4 11 0
14 8 5 17 0
14 8 6 8 0
14 8 7 8 0
14 8 8 6 0
14 8 9 16 0
14 8 10 4 0
14 8 11 11 0
14 8 12 18 0
14 8 13 18 0
14 8 14 15 32
14 9 1 16 64
14 9 2 9 0
14 9 3 8 0
14 9 4 13 0
14 9 5 16 0
14 9 6 16 0
14 9 7 16 0
14 9 8 11 0
14 9 9 17 0
14 9 10 18 0
14 9 11 7 0
14 9 12 18 0
14 9 13 8 0
14 9 14 8 32
14 10 1 17 64
14 10 2 18 0
14 10 3 4 0
14 10 4 16 0
14 10 5 16 0
14 10 6 16 0
14 10 7 16 0
14 10 8 16 0
14 10 9 7 0
14 10 10 8 0
14 10 11 8 0
14 10 12 16 0
14 10 13 15 0
14 10 14 11 32
14 11 1 19 64
14 11 2 8 0
14 11 3 13 0
14 11 4 4 0
14 11 5 14 0
14 11 6 14 0
14 11 7 14 0
14 11 8 16 0
14 11 9 4 0
14 11 10 17 0
14 11 11 16 0
14 11 12 17 0
14 11 13 16 0
14 11 14 4 32
14 12 1 8 64
14 12 2 18 0
14 12 3 16 0
14 12 4 17 0
14 12 5 16 0
14 12 6 8 0
14 12 7 8 0
14 12 8 7 0
14 12 9 15 0
14 12 10 11 0
14 12 11 18 0
14 12 12 16 0
14 12 13 9 0
14 12 14 14 32
14 13 1 12 72
14 13 2 6 0
14 13 3 16 0
14 13 4 13 8
14 13 5 9 8
14 13 6 16 8
14 13 7 16 8
14 13 8 17 8
14 13 9 17 8
14 13 10 4 8
14 13 11 17 8
14 13 12 7 8
14 13 13 17 8
14 13 14 12 40
14 14 2 2 64
14 14 3 12 42
14 15 2 12 106
15 2 1 7 82
15 2 2 13 18
15 2 3 16 18
15 2 4 17 18
15 2 5 9 18
15 2 6 16 18
15 2 7 16 18
15 2 8 11 18
15 2 9 17 18
15 2 10 14 18
15 2 11 17 18
15 2 12 16 18
15 2 13 9 18
15 2 14 6 50
15 3 1 17 66
15 3 2 17 2
15 3 3 8 2
15 3 4 17 2
15 3 5 14 2
15 3 6 17 2
15 3 7 17 2
15 3 8 9 2
15 3 9 17 2
15 3 10 18 2
15 3 11 9 2
15 3 12 9 2
15 3 13 9 2
15 3 14 7 34
15 4 1 18 66
15 4 2 17 2
15 4 3 6 2
15 4 4 7 2
15 4 5 16 2
15 4 6 17 2
15 4 7 17 2
15 4 8 14 2
15 4 9 18 2
15 4 10 17 2
15 4 11 17 2
15 4 12 6 2
15 4 13 13 2
15 4 14 17 34
15 5 1 4 66
15 5 2 15 2
15 5 3 15 2
15 5 4 4 2
15 5 5 16 2
15 5 6 17 2
15 5 7 17 2
15 5 8 8 2
15 5 9 9 2
15 5 10 18 2
15 5 11 16 2
15 5 12 8 2
15 5 13 16 2
15 5 14 18 34
15 6 1 19 66
15 6 2 17 2
15 6 3 18 2
15 6 4 18 2
15 6 5 15 2
15 6 6 16 2
15 6 7 16 2
15 6 8 11 2
15 6 9 4 2
15 6 10 16 2
15 6 11 6 2
15 6 12 13 2
15 6 13 7 2
15 6 14 17 34
15 7 1 16 66
15 7 2 7 2
15 7 3 11 2
15 7 4 15 2
15 7 5 17 2
15 7 6 16 2
15 7 7 16 2
15 7 8 9 2
15 7 9 16 2
15 7 10 18 2
15 7 11 9 2
15 7 12 13 2
15 7 13 17 2
15 7 14 16 34
15 8 1 16 66
15 8 2 4 2
15 8 3 16 2
15 8 4 16 2
15 8 5 14 2
15 8 6 17 2
15 8 7 17 2
15 8 8 17 2
15 8 9 14 2
15 8 10 18 2
15 8 11 14 2
15 8 12 17 2
15 8 13 13 2
15 8 14 13 34
15 9 1 16 66
15 9 2 11 2
15 9 3 8 2
15 9 4 16 2
15 9 5 16 2
15 9 6 16 2
15 9 7 16 2
15 9 8 16 2
15 9 9 18 2
15 9 10 4 2
15 9 11 16 2
15 9 12 7 2
15 9 13 18 2
15 9 14 16 34
15 10 1 17 66
15 10 2 18 2
15 10 3 6 2
15 10 4 6 2
15 10 5 18 2
15 10 6 17 2
15 10 7 17 2
15 10 8 4 2
15 10 9 4 2
15 10 10 13 2
15 10 11 8 2
15 10 12 18 2
15 10 13 17 2
15 10 14 13 34
15 11 1 13 66
15 11 2 13 2
15 11 3 7 2
15 11 4 18 2
15 11 5 18 2
15 11 6 16 2
15 11 7 16 2
15 11 8 18 2
15 11 9 18 2
15 11 10 18 2
15 11 11 16 2
15 11 12 18 2
15 11 13 16 2
15 11 14 18 34
15 12 1 9 66
15 12 2 16 2
15 12 3 13 2
15 12 4 6 2
15 12 5 4 2
15 12 6 14 2
15 12 7 14 2
15 12 8 18 2
15 12 9 16 2
15 12 10 6 2
15 12 11 16 2
15 12 12 13 2
15 12 13 17 2
15 12 14 16 34
15 13 1 12 74
15 13 2 12 2
15 13 3 12 10
15 13 4 12 10
15 13 5 12 10
15 13 6 12 10
15 13 7 12 10
15 13 8 12 10
15 13 9 12 10
15 13 10 12 10
15 13 11 12 10
15 13 12 12 10
15 13 13 12 10
15 13 14 12 42
15 14 2 12 106
